Workbook

Sheet Свод
A1: СВОД: ТО АПС, АУПТ, СОУЭ — АО «РИР Энерго» «Воронежская генерация», 2027 г.
A2: Внутренний документ НЕОСТРОЙ — заказчику не передавать. Все суммы — руб. без НДС за 12 месяцев 2027 г.
B4: Статья себестоимости | C4: Сумма, руб. | D4: Доля | G4: Откуда
B5: ФОТ техников ТО (штат, Воронеж) | C5: ='Персонал ТО'!C16 -> 10290000 | D5: =C5/C$10 -> 0.63360262 | G5: Персонал ТО: численность × на руки × 1,5 × 14
B6: Расходники к работам | C6: =Работы!O109 -> 197111.89 | D6: =C6/C$10 -> 0.012137085 | G6: % к оплате труда (ELM, справочник)
B7: Субподряд и прочие прямые разовых работ (ЦСМ, ЭТЛ, аренда опрессовочного оборудования) | C7: =Работы!P109 -> 89170 | D7: =C7/C$10 -> 0.005490607 | G7: Работы, раздел «Разовые»
B8: Материалы ЗИП (с/с) | C8: =Материалы!M22 -> 177141.03 | D8: =C8/C$10 -> 0.010907388 | G8: Материалы
B9: Косвенные проекта | C9: =Косвенные!G21 -> 5487040.2 | D9: =C9/C$10 -> 0.3378623 | G9: Косвенные
B10: ПОЛНАЯ СЕБЕСТОИМОСТЬ | C10: =SUM(C5:C9) -> 16240463 | D10: =SUM(D5:D9) -> 1
B12: Коммерческое предложение | C12: Сумма, руб. | D12: Доля | G12: Откуда
B13: Регламентное ТО (12 мес.) | C13: =Работы!J99 -> 17898182 | D13: =C13/C$16 -> 0.92870877 | G13: Работы
B14: Разовые работы 2027 | C14: =Работы!J107 -> 1206585 | D14: =C14/C$16 -> 0.062607814 | G14: Работы
B15: Материалы ЗИП | C15: =Материалы!Q22 -> 167347.83 | D15: =C15/C$16 -> 0.008683418 | G15: Материалы
B16: КП БЕЗ НДС | C16: =SUM(C13:C15) -> 19272115
B17: НДС 22 % | C17: =ROUND(C16*0.22,2) -> 4239865.3
B18: КП С НДС | C18: =C16+C17 -> 23511980
B19: КП в месяц без НДС (регламентное ТО) | C19: =Работы!K99 -> 1491515.2
B21: Показатели | C21: Значение | G21: Комментарий
B22: Наценка = КП ÷ с/с − 1 | C22: =C16/C10-1 -> 0.18667275
B23: Маржа = 1 − с/с ÷ КП | C23: =1-C10/C16 -> 0.15730769
B24: Маржа, руб. | C24: =C16-C10 -> 3031651.8
B25: Тип тендера | C25: Госзакупки 44-ФЗ / 223-ФЗ
B26: Целевой диапазон наценки (лист «Тип тендера») | C26: 15–30 %
B27: Проверка по типу тендера | C27: =IF(C22<0.15,"НИЖЕ 15 % — согласование ГД",IF(C22>0.3,"выше диапазона","в диапазоне")) -> в диапазоне
B28: Наценка на материалы (средняя) | C28: =Материалы!Q22/Материалы!M22-1 -> -0.055284764
B29: Наценка на работы (ТО + разовые) к прямой с/с работ + косвенным | C29: =(Работы!J109)/(Свод!C10-Материалы!M22)-1 -> 0.18934097
B30: НМЦК | C30: не опубликована в папке лота | G30: В папке только ТЗ. Минимально допустимая цена = с/с × 1,15 (строка 36)
B32: Сценарии | C32: КП б/НДС | D32: Маржа, руб. | E32: Маржа, % | F32: Наценка | G32: Комментарий
B33: Базовый | C33: =ROUND($C$16*1,2) -> 19272115 | D33: =C33-$C$10 -> 3031651.8 | E33: =D33/C33 -> 0.15730769 | F33: =C33/$C$10-1 -> 0.18667275
B34: Переторжка −5 % | C34: =ROUND($C$16*0.95,2) -> 18308509 | D34: =C34-$C$10 -> 2068046.1 | E34: =D34/C34 -> 0.11295546 | F34: =C34/$C$10-1 -> 0.12733911
B35: Переторжка −10 % | C35: =ROUND($C$16*0.9,2) -> 17344903 | D35: =C35-$C$10 -> 1104440.3 | E35: =D35/C35 -> 0.063675209 | F35: =C35/$C$10-1 -> 0.068005471
B36: Минимальная цена (наценка 15 %, ниже — только ГД) | C36: =ROUND($C$10*1.15,2) -> 18676533 | D36: =C36-$C$10 -> 2436069.5 | E36: =D36/C36 -> 0.13043478 | F36: =C36/$C$10-1 -> 0.15 | G36: =TEXT(1-C36/C16,"0.0%")&" — максимальная скидка от КП" -> 3.1% — максимальная скидка от КП

Sheet Паспорт тендера
A1: ПАСПОРТ ТЕНДЕРА
A3: Заказчик | B3: АО «РИР Энерго», филиал «Воронежская генерация» (группа Росатом), закупка по 223-ФЗ: план закупки на 2027 г., закупка № 637, лот 1, спецификация 1
A4: Предмет | B4: Оказание услуг по ТО установок автоматической пожарной сигнализации (АПС), автоматических установок пожаротушения (АУПТ) и систем оповещения и управления эвакуацией (СОУЭ); плановая и предупредительная замена вышедшего из строя оборудования; ведение документации
A5: Объекты и адреса | B5: г. Воронеж: ПП ТЭЦ-1 (ул. Лебедева, 2), ПП ТЭЦ-2 (пр. Ясный, 1а), ПП Тепловые сети (ул. С. Перовской, 7; ул. Пешестрелецкая, 84; пр. Ясный, 1а; ул. Лебедева, 2), ПП ГТС (ул. Кольцовская, 78; ул. Плехановская, 17; ул. Туполева, 31к; ул. Б. Хмельницкого, 79к) — 10 адресов
A6: Регион | B6: Воронеж (регион): тарификатор СПб/Мск не применим напрямую → цены — рынок Воронежа/ЦФО; персонал — местный найм; доставка материалов 10 % (параметр «Регион»)
A7: Объём (Прил. 1–8) | B7: АПС/СОУЭ: ~120 ППК и пультов, 146 блоков, 67 источников питания, 76 АКБ, 3 569 автоматических извещателей + 70 взрывозащищённых + 26 пламени + 5 линейных, 1 920 м термокабеля, 558 ручных/УДП/ЭДУ, 224 охранных, 880 оповещателей, 5 приборов речевого оповещения, 4 модуля «Буран», ~52,7 км шлейфов. АУПТ ТЭЦ-1/ТЭЦ-2: 9,6 км трубопроводов, 217 ручных и 64 электрифицированных задвижек/затворов, 987 оросителей/пеногенераторов/стволов, 40 манометров и сигнализаторов, 8 насосов, 3 бака
A8: Периодичность (Прил. 9, 10) | B8: АПС: ежемесячно — осмотр, контроль индикации, питания, проверка работоспособности; ежеквартально (мар, июн, сен, дек) — профилактика; июнь — измерение сопротивления заземления. АУПТ: ежемесячно — узлы, оросители, трубопроводы; фев/май/авг/ноя — вводы, арматура, задвижки с ЭП и схемы пуска; май, ноябрь — манометры; май — полная проверка манометров с опломбированием/клеймением; 1 раз в 3 года — опрессовка, промывка и опробование с реальным пуском: ТЭЦ-2 (ГК, ПГУ-115, ВК, МН) — июль–август 2027; ТЭЦ-1 — проведено в июне–июле 2026, в 2027 не требуется
A9: Срок | B9: 2027 год (12 месяцев); точные даты начала/окончания — в проекте договора (в папке лота нет)
A10: НМЦК | B10: Не опубликована: на b2b-center (лот № 57697, организатор АО «Квадра-ГК» для АО «РИР Энерго» — «Воронежская генерация») начальная цена 0, оценивается цена с НДС; вскрытие 30.10.2026 08:00 МСК. Аналог 2023 г. (ЕИС 32211915005) — НМЦК 2 399 999 руб.
A11: Форма КП | B11: Формы заказчика нет → наша форма КП (xlsx) + письмо на бланке
A12: Цены с НДС / без | B12: Не указано; считаем без НДС, НДС 22 % сверху
A13: Оплата | B13: В течение 7 рабочих дней от даты подписания акта оказанных услуг (раздел ТЗ). Аванса нет
A14: Гарантия | B14: Работоспособность систем в течение срока договора; устранение дефектов за свой счёт, гарантийный период продлевается на время гарантийных работ (п. 3.3)
... A18: ОКПД2 | B18: 43.21.10.140 (в ТЗ — монтаж систем пожарной и охранной сигнализации; для услуги ТО обычно 33.12/80.20 — несоответствие, вопрос заказчику не критичен)

Sheet Ставки ТО
A1: СТАВКИ ТО ПО ВИДАМ ОБОРУДОВАНИЯ: РЫНОК, ЦЕНА КП, НОРМА ТРУДОЗАТРАТ
A2: Работ нет в тарификаторе v2 → цена = рынок подрядчиков (б/НДС, руб. за ед. в месяц), норма — чел.-ч на ед. в месяц в среднем за год (ежемесячные операции + ежеквартальная профилактика + годовые проверки). Жёлтые ячейки — вводные.
A4: Код | B4: Услуга | C4: Ед. | D4: Норма, чел.-ч/ед./мес | E4: Основание нормы | F4: Рынок 1, руб/ед/мес б/НДС | G4: Источник 1 | H4: Рынок 2 | I4: Источник 2 | J4: Рынок 3 | K4: Источник 3 | L4: Медиана рынка | M4: Коэф. к рынку | N4: ЦЕНА КП, руб/ед/мес б/НДС | O4: Примечание
A5: PPK | B5: ТО прибора приёмно-контрольного, пульта, прибора управления (С2000М, Сигнал-20П/10, Гранит, С2000-АСПТ, Рубеж-20П и др.) | C5: шт | D5: 1 | E5: Экспертно 1,0 ч/мес (между пультом 1,0 и ППК средней ёмкости 3,0 ч/мес по нормативы МВД (у.у. = 1,67 ч/мес), ivtechno.ru) | F5: 500 | G5: Пожарный Арсенал, Воронеж (pozharsenal.ru), «от» | H5: 1431 | I5: Прейскурант 2661 × 39,43 (t-as.ru, расчёт): 371 + 106 × 10 ШС | J5: 1800 | K5: Квазар-Сервис, Краснодар (ecq.ru), ППК до 16 ШС | L5: =MEDIAN(F5,H5,J5) -> 1431 | M5: 2.53 | N5: =ROUND(L5*M5,2) -> 3620.43 | O5: Москва 2 090–2 600 (Стройпожсервис, montage-ssb) — не брали; коэф. 2.53 — цена от с/с (наценка ≈ 17 %): по рыночной медиане КП не покрывает с/с штатного ТО
A6: BLOCK | B6: ТО блока системы (С2000-КДЛ, СП1/СП2, КПБ, БКИ, ПИ, ПТ, БРИЗ, барьеры искрозащиты и др.) | C6: шт | D6: 0.2 | E6: Адресный расширитель 0,33 ч/мес (нормативы МВД (у.у. = 1,67 ч/мес), ivtechno.ru); экспертно 0,2 — проверка в составе ППК | F6: 49 | G6: samss.ru, Самара, руб/мес, блок управления | H6: 95 | I6: Стройпожсервис, Москва (stroipozhservis.ru), релейный блок | J6: 100 | K6: ООО «Интех», Воронеж (inteh36.ru), «от» | L6: =MEDIAN(F6,H6,J6) -> 95 | M6: 2.53 | N6: =ROUND(L6*M6,2) -> 240.35 | O6: коэф. 2.53 — цена от с/с (наценка ≈ 17 %): по рыночной медиане КП не покрывает с/с штатного ТО
A7: PSU | B7: ТО источника электропитания резервированного (РИП, Скат, ИВЭПР, ББП) | C7: шт | D7: 0.25 | E7: РИП с АКБ 0,5 ч/мес (нормативы МВД (у.у. = 1,67 ч/мес), ivtechno.ru); экспертно 0,25 (АКБ — отдельной строкой) | F7: 80 | G7: Квазар-Сервис, Краснодар (ecq.ru), ИБП | H7: 195 | I7: Стройпожсервис, Москва (stroipozhservis.ru) | J7: 200 | K7: Пожарный Арсенал, Воронеж (pozharsenal.ru), «от» | L7: =MEDIAN(F7,H7,J7) -> 195 | M7: 2.53 | N7: =ROUND(L7*M7,2) -> 493.35 | O7: коэф. 2.53 — цена от с/с (наценка ≈ 17 %): по рыночной медиане КП не покрывает с/с штатного ТО
A8: AKB | B8: ТО аккумуляторной батареи (контроль напряжения и ёмкости) | C8: шт | D8: 0.05 | E8: Экспертно: замер напряжения/ёмкости при ТО РИП | F8: 82 | G8: СБ-ГРУПП, Москва (ooosbg.ru), 100 с НДС ÷ 1,22 | H8: 95 | I8: Стройпожсервис, Москва (stroipozhservis.ru) | J8: 150 | K8: Формула охраны, Москва (naoxrane.ru), 2021 | L8: =MEDIAN(F8,H8,J8) -> 95 | M8: 2.53 | N8: =ROUND(L8*M8,2) -> 240.35 | O8: коэф. 2.53 — цена от с/с (наценка ≈ 17 %): по рыночной медиане КП не покрывает с/с штатного ТО
A9: DET_AUTO | B9: ТО извещателя пожарного автоматического точечного (дымового, теплового) | C9: шт | D9: 0.04 | E9: Экспертно: ежемес. осмотр + проверка аэрозолем 1 раз в квартал ~6 мин/шт; верхняя граница — дымовой 0,17 ч/мес (нормативы МВД (у.у. = 1,67 ч/мес), ivtechno.ru) | F9: 30 | G9: Пожарный Арсенал, Воронеж (pozharsenal.ru), «от» | H9: 40 | I9: Квазар-Сервис, Краснодар (ecq.ru), адресный дымовой | J9: 49 | K9: samss.ru, Самара, руб/мес | L9: =MEDIAN(F9,H9,J9) -> 40 | M9: 2.53 | N9: =ROUND(L9*M9,2) -> 101.2 | O9: Москва 48–60 (Стройпожсервис, Контур); коэф. 2.53 — цена от с/с (наценка ≈ 17 %): по рыночной медиане КП не покрывает с/с штатного ТО
A10: DET_EX | B10: ТО извещателя пожарного во взрывозащищённом/искробезопасном исполнении | C10: шт | D10: 0.15 | E10: Экспертно: × 3–4 к обычному (наряд-допуск, взрывоопасная зона) | F10: 95 | G10: Стройпожсервис, Москва (stroipozhservis.ru) | H10: 100 | I10: montage-ssb, Мск/СПб (city-ser.com) | L10: =MEDIAN(F10,H10,J10) -> 97.5 | M10: 2.53 | N10: =ROUND(L10*M10,2) -> 246.68 | O10: коэф. 2.53 — цена от с/с (наценка ≈ 17 %): по рыночной медиане КП не покрывает с/с штатного ТО
A11: DET_FLAME | B11: ТО извещателя пожарного пламени (Спектрон, Пульсар, Набат) | C11: шт | D11: 0.15 | E11: Экспертно: проверка тест-фонарём | F11: 50 | G11: montage-ssb, Мск/СПб (city-ser.com) | H11: 41 | I11: СБ-ГРУПП, 50 с НДС ÷ 1,22 | J11: 60 | K11: Контур безопасности, Москва (scontur.ru) | L11: =MEDIAN(F11,H11,J11) -> 50 | M11: 2.53 | N11: =ROUND(L11*M11,2) -> 126.5 | O11: коэф. 2.53 — цена от с/с (наценка ≈ 17 %): по рыночной медиане КП не покрывает с/с штатного ТО
A12: LINEAR | B12: ТО извещателя пожарного дымового линейного ИПДЛ | C12: к-т | D12: 0.3 | E12: ИПДЛ 0,5 ч/мес (нормативы МВД (у.у. = 1,67 ч/мес), ivtechno.ru); экспертно 0,3 | F12: 145 | G12: Стройпожсервис, Москва (stroipozhservis.ru) | H12: 200 | I12: Квазар-Сервис, Краснодар (ecq.ru) | J12: 440 | K12: samss.ru, Самара, руб/мес | L12: =MEDIAN(F12,H12,J12) -> 200 | M12: 2.53 | N12: =ROUND(L12*M12,2) -> 506 | O12: коэф. 2.53 — цена от с/с (наценка ≈ 17 %): по рыночной медиане КП не покрывает с/с штатного ТО
A13: THERMO | B13: ТО линейного теплового извещателя (термокабель) | C13: 100 м | D13: 0.15 | E13: Экспертно: осмотр трассы, проверка шлейфа на 100 м | F13: 150 | G13: ОЦЕНКА по аналогии с ИПДЛ (1 зона ≈ 100 м); рыночной цены нет — montage-ssb «договорная» | L13: =MEDIAN(F13,H13,J13) -> 150 | M13: 2.53 | N13: =ROUND(L13*M13,2) -> 379.5 | O13: ОЦЕНКА — уточнить запросом у ВДПО Воронеж / ИПС / Интех; коэф. 2.53 — цена от с/с (наценка ≈ 17 %): по рыночной медиане КП не покрывает с/с штатного ТО
A14: DET_MAN | B14: ТО извещателя пожарного ручного, УДП, ЭДУ | C14: шт | D14: 0.04 | E14: Экспертно, как автоматический извещатель | F14: 30 | G14: Пожарный Арсенал, Воронеж (pozharsenal.ru), «от» | H14: 35 | I14: Квазар-Сервис, Краснодар (ecq.ru) | J14: 49 | K14: samss.ru, Самара, руб/мес | L14: =MEDIAN(F14,H14,J14) -> 35 | M14: 2.53 | N14: =ROUND(L14*M14,2) -> 88.55 | O14: коэф. 2.53 — цена от с/с (наценка ≈ 17 %): по рыночной медиане КП не покрывает с/с штатного ТО
A15: DET_SEC | B15: ТО извещателя охранного (магнитоконтактного, ИК) в составе систем | C15: шт | D15: 0.03 | E15: Экспертно | F15: 25 | G15: Формула охраны, тепловой/простой | H15: 30 | I15: Пожарный Арсенал, Воронеж (pozharsenal.ru), «от» | J15: 49 | K15: samss.ru, Самара, руб/мес | L15: =MEDIAN(F15,H15,J15) -> 30 | M15: 2.53 | N15: =ROUND(L15*M15,2) -> 75.9 | O15: коэф. 2.53 — цена от с/с (наценка ≈ 17 %): по рыночной медиане КП не покрывает с/с штатного ТО
A16: ANN | B16: ТО оповещателя (светового, звукового, речевого, табло «Выход») | C16: шт | D16: 0.04 | E16: Оповещатель 0,17 ч/мес (нормативы МВД (у.у. = 1,67 ч/мес), ivtechno.ru) — верхняя граница; экспертно 0,04 (проверка зонами при пуске) | F16: 40 | G16: Квазар-Сервис, Краснодар (ecq.ru), световой/звуковой | H16: 49 | I16: samss.ru, Самара, руб/мес | J16: 50 | K16: montage-ssb, Мск/СПб (city-ser.com) | L16: =MEDIAN(F16,H16,J16) -> 49 | M16: 2.53 | N16: =ROUND(L16*M16,2) -> 123.97 | O16: коэф. 2.53 — цена от с/с (наценка ≈ 17 %): по рыночной медиане КП не покрывает с/с штатного ТО
A17: SOUE | B17: ТО прибора речевого оповещения СОУЭ (Орфей, Рокот, Соната) | C17: шт | D17: 1 | E17: Экспертно (как ППК) | F17: 340 | G17: samss.ru, Самара, руб/мес, блок управления СОУЭ | H17: 500 | I17: Квазар-Сервис, Краснодар (ecq.ru), предусилитель | J17: 800 | K17: montage-ssb, Мск/СПб (city-ser.com), блок речевого оповещения | L17: =MEDIAN(F17,H17,J17) -> 500 | M17: 2.53 | N17: =ROUND(L17*M17,2) -> 1265 | O17: коэф. 2.53 — цена от с/с (наценка ≈ 17 %): по рыночной медиане КП не покрывает с/с штатного ТО
A18: MPP | B18: ТО модуля порошкового пожаротушения (Буран-8взр) | C18: шт | D18: 0.3 | E18: Экспертно: осмотр, контроль цепей пуска | F18: 375 | G18: Нормативные затраты МВД 4 500/год | H18: 450 | I18: k-systemy.ru, Красноярск | J18: 725 | K18: ogneboy.ru, 1–10 модулей 2 900 / 4 мод. | L18: =MEDIAN(F18,H18,J18) -> 450 | M18: 2.53 | N18: =ROUND(L18*M18,2) -> 1138.5 | O18: коэф. 2.53 — цена от с/с (наценка ≈ 17 %): по рыночной медиане КП не покрывает с/с штатного ТО
A19: SW | B19: Сопровождение ПО АРМ «Орион Про» (резервное копирование баз, проверка связи) | C19: к-т | D19: 2 | E19: Экспертно: резервное копирование БД, проверка связи ППК–АРМ | F19: 1639 | G19: СБ-ГРУПП, АРМ 2 000 с НДС ÷ 1,22 | H19: 1700 | I19: Квазар-Сервис, Краснодар (ecq.ru), АРМ | J19: 1990 | K19: Стройпожсервис, Москва (stroipozhservis.ru), АРМ | L19: =MEDIAN(F19,H19,J19) -> 1700 | M19: 2.53 | N19: =ROUND(L19*M19,2) -> 4301 | O19: коэф. 2.53 — цена от с/с (наценка ≈ 17 %): по рыночной медиане КП не покрывает с/с штатного ТО
A20: CABLE | B20: ТО шлейфов сигнализации и линий связи (осмотр, измерение параметров) | C20: 100 м | D20: 0.02 | E20: Экспертно: шлейф контролируется ППК; осмотр трасс + выборочные замеры | F20: 10 | G20: ОЦЕНКА: на рынке входит в цену ТО ППК; отдельной цены нет | L20: =MEDIAN(F20,H20,J20) -> 10 | M20: 2.53 | N20: =ROUND(L20*M20,2) -> 25.3 | O20: ОЦЕНКА — 10 руб./100 м/мес; коэф. 2.53 — цена от с/с (наценка ≈ 17 %): по рыночной медиане КП не покрывает с/с штатного ТО
A21: BOX | B21: ТО коробок коммутационных/распределительных, шкафов, автоматов питания | C21: шт | D21: 0.03 | E21: Экспертно: осмотр, протяжка | F21: 10 | G21: ОЦЕНКА: на рынке входит в ТО системы | L21: =MEDIAN(F21,H21,J21) -> 10 | M21: 2.53 | N21: =ROUND(L21*M21,2) -> 25.3 | O21: ОЦЕНКА; коэф. 2.53 — цена от с/с (наценка ≈ 17 %): по рыночной медиане КП не покрывает с/с штатного ТО
A22: PIPE | B22: ТО трубопроводов АУПТ (течи, уклоны, крепления, окраска) | C22: 100 м | D22: 0.25 | E22: 3,7–7,1 чел.-ч/год на 100 м (РТМ 25.488-82 (ТО + текущий ремонт), meganorm.ru) ≈ 0,3–0,6 ч/мес; экспертно 0,25 (без ремонта) | F22: 200 | G22: ОЦЕНКА; рынок даёт ТО АУПТ по площади от 35 руб/м² (Центр «Каска», Воронеж) — к метражу не приводится | L22: =MEDIAN(F22,H22,J22) -> 200 | M22: 2.53 | N22: =ROUND(L22*M22,2) -> 506 | O22: ОЦЕНКА — уточнить запросом; коэф. 2.53 — цена от с/с (наценка ≈ 17 %): по рыночной медиане КП не покрывает с/с штатного ТО
A23: VALVE_MAN | B23: ТО запорной арматуры с ручным приводом (задвижки, затворы, вентили, клапаны, краны) | C23: шт | D23: 0.25 | E23: 7,9–13,8 чел.-ч/год (РТМ 25.488-82 (ТО + текущий ремонт), meganorm.ru) ≈ 0,7–1,1 ч/мес с ремонтом; экспертно 0,25 | F23: 150 | G23: ОЦЕНКА: поштучной цены нет (рынок — в составе узла управления 750–800 руб/мес) | L23: =MEDIAN(F23,H23,J23) -> 150 | M23: 2.53 | N23: =ROUND(L23*M23,2) -> 379.5 | O23: ОЦЕНКА; коэф. 2.53 — цена от с/с (наценка ≈ 17 %): по рыночной медиане КП не покрывает с/с штатного ТО
A24: VALVE_EL | B24: ТО задвижки/затвора с электроприводом и схемой управления | C24: шт | D24: 1 | E24: 27,6 чел.-ч/год мех.+эл. часть (РТМ 25.488-82), 34,9 (ПП РФ 2072) ≈ 2,3–2,9 ч/мес; экспертно 1,0 | F24: 750 | G24: mk-gost.ru, Саратов: разовая проверка 2 000–2 500, ежеквартально → ÷ 3 | H24: 800 | I24: Прейскурант 2661 × 39,43 (t-as.ru, расчёт): узел управления ≈ 800 | L24: =MEDIAN(F24,H24,J24) -> 775 | M24: 2.53 | N24: =ROUND(L24*M24,2) -> 1960.75 | O24: коэф. 2.53 — цена от с/с (наценка ≈ 17 %): по рыночной медиане КП не покрывает с/с штатного ТО
A25: SPRINK | B25: ТО оросителя, пеногенератора, лафетного ствола (осмотр, очистка) | C25: шт | D25: 0.03 | E25: 1,2–1,8 чел.-ч/год (РТМ 25.488-82 (ТО + текущий ремонт), meganorm.ru) ≈ 0,1–0,15 ч/мес; экспертно 0,03 (осмотр без демонтажа) | F25: 2 | G25: k-systemy.ru: 200 руб. за 100 оросителей | H25: 26 | I25: Прейскурант 2661 × 39,43 (t-as.ru, расчёт): 260 на 10 оросителей | L25: =MEDIAN(F25,H25,J25) -> 14 | M25: 2.53 | N25: =ROUND(L25*M25,2) -> 35.42 | O25: коэф. 2.53 — цена от с/с (наценка ≈ 17 %): по рыночной медиане КП не покрывает с/с штатного ТО
A26: GAUGE | B26: ТО манометра, сигнализатора/реле давления | C26: шт | D26: 0.25 | E26: 6,3–18,6 чел.-ч/год (РТМ 25.488-82 (ТО + текущий ремонт), meganorm.ru); экспертно 0,25 | F26: 138 | G26: Прейскурант 2661 × 39,43 (t-as.ru, расчёт): сигнализатор давления | L26: =MEDIAN(F26,H26,J26) -> 138 | M26: 2.53 | N26: =ROUND(L26*M26,2) -> 349.14 | O26: Цены ТО манометра в месяц на рынке нет; коэф. 2.53 — цена от с/с (наценка ≈ 17 %): по рыночной медиане КП не покрывает с/с штатного ТО
A27: PUMP | B27: ТО насосного агрегата пожаротушения | C27: шт | D27: 4 | E27: 35–176 чел.-ч/год (РТМ 25.488-82 (ТО + текущий ремонт), meganorm.ru), 96 (ПП РФ 2072) ≈ 3–15 ч/мес; экспертно 4,0 | F27: 1995 | G27: Инфомакс, Москва: насосная до 100 м² | H27: 2646 | I27: Прейскурант 2661 × 39,43 (t-as.ru, расчёт): технолог. часть насосной | J27: 6000 | K27: k-systemy.ru: насосная станция | L27: =MEDIAN(F27,H27,J27) -> 2646 | M27: 2.53 | N27: =ROUND(L27*M27,2) -> 6694.38 | O27: коэф. 2.53 — цена от с/с (наценка ≈ 17 %): по рыночной медиане КП не покрывает с/с штатного ТО
A28: TANK | B28: ТО бака (пенообразователя, мембранного) | C28: шт | D28: 1 | E28: Экспертно | F28: 300 | G28: ОЦЕНКА | L28: =MEDIAN(F28,H28,J28) -> 300 | M28: 2.53 | N28: =ROUND(L28*M28,2) -> 759 | O28: ОЦЕНКА; коэф. 2.53 — цена от с/с (наценка ≈ 17 %): по рыночной медиане КП не покрывает с/с штатного ТО

Sheet Работы
A1: РАБОТЫ: РЕГЛАМЕНТНОЕ ТО ПО ОБЪЕКТАМ И ВИДАМ ОБОРУДОВАНИЯ + РАЗОВЫЕ РАБОТЫ 2027
A2: Кол-во — из Приложений 1–8 ТЗ (кабель и трубы пересчитаны в 100 м). Цена КП — лист «Ставки ТО». С/с труда = чел.-ч × себестоимость чел.-ч (лист «Персонал ТО»). Расходники — % к оплате труда (ELM).
A4: № | B4: Объект | C4: Код | D4: Услуга | E4: Ед. | F4: Кол-во | G4: Сопоставление с тарификатором | H4: Цена КП, руб/ед/мес | I4: Мес. | J4: КП в год, руб. б/НДС | K4: КП в месяц, руб. | L4: Норма, чел.-ч/ед/мес | M4: Чел.-ч/год | N4: С/с труда, руб. | O4: Расходники, руб. | P4: Субподряд/прочие прямые, руб. | Q4: Прямая с/с, руб. | R4: Маржа строки, руб. | S4: Маржа, %
A5: ПП ТЭЦ-1 (ул. Лебедева, 2) — АПС, СОУЭ (Прил. 1)
A6: 1 | B6: ПП ТЭЦ-1 (ул. Лебедева, 2) | C6: PPK | D6: ТО прибора приёмно-контрольного, пульта, прибора управления (С2000М, Сигнал-20П/10, Гранит, С2000-АСПТ, Рубеж-20П и др.) | E6: шт | F6: 34 | G6: нет в тарификаторе → рынок | H6: ='Ставки ТО'!$N$5 -> 3620.43 | I6: 12 | J6: =K6*I6 -> 1477135.4 | K6: =ROUND(F6*H6,2) -> 123094.62 | L6: ='Ставки ТО'!$D$5 -> 1 | M6: =F6*L6*I6 -> 408 | N6: =M6*'Персонал ТО'!$C$17*(1+'Персонал ТО'!$C$9) -> 473833.73 | O6: =N6*0.02 -> 9476.6746 | P6: 0 | Q6: =N6+O6+P6 -> 483310.41 | R6: =J6-Q6 -> 993825.03 | S6: =IF(J6>0,R6/J6,"") -> 0.67280563
A7: 2 | B7: ПП ТЭЦ-1 (ул. Лебедева, 2) | C7: BLOCK | D7: ТО блока системы (С2000-КДЛ, СП1/СП2, КПБ, БКИ, ПИ, ПТ, БРИЗ, барьеры искрозащиты и др.) | E7: шт | F7: 12 | G7: нет в тарификаторе → рынок | H7: ='Ставки ТО'!$N$6 -> 240.35 | I7: 12 | J7: =K7*I7 -> 34610.4 | K7: =ROUND(F7*H7,2) -> 2884.2 | L7: ='Ставки ТО'!$D$6 -> 0.2 | M7: =F7*L7*I7 -> 28.8 | N7: =M7*'Персонал ТО'!$C$17*(1+'Персонал ТО'!$C$9) -> 33447.087 | O7: =N7*0.02 -> 668.94174 | P7: 0 | Q7: =N7+O7+P7 -> 34116.029 | R7: =J7-Q7 -> 494.37137 | S7: =IF(J7>0,R7/J7,"") -> 0.014283896
A8: 3 | B8: ПП ТЭЦ-1 (ул. Лебедева, 2) | C8: PSU | D8: ТО источника электропитания резервированного (РИП, Скат, ИВЭПР, ББП) | E8: шт | F8: 9 | G8: нет в тарификаторе → рынок | H8: ='Ставки ТО'!$N$7 -> 493.35 | I8: 12 | J8: =K8*I8 -> 53281.8 | K8: =ROUND(F8*H8,2) -> 4440.15 | L8: ='Ставки ТО'!$D$7 -> 0.25 | M8: =F8*L8*I8 -> 27 | N8: =M8*'Персонал ТО'!$C$17*(1+'Персонал ТО'!$C$9) -> 31356.644 | O8: =N8*0.02 -> 627.13288 | P8: 0 | Q8: =N8+O8+P8 -> 31983.777 | R8: =J8-Q8 -> 21298.023 | S8: =IF(J8>0,R8/J8,"") -> 0.39972417
A9: 4 | B9: ПП ТЭЦ-1 (ул. Лебедева, 2) | C9: AKB | D9: ТО аккумуляторной батареи (контроль напряжения и ёмкости) | E9: шт | F9: 21 | G9: нет в тарификаторе → рынок | H9: ='Ставки ТО'!$N$8 -> 240.35 | I9: 12 | J9: =K9*I9 -> 60568.2 | K9: =ROUND(F9*H9,2) -> 5047.35 | L9: ='Ставки ТО'!$D$8 -> 0.05 | M9: =F9*L9*I9 -> 12.6 | N9: =M9*'Персонал ТО'!$C$17*(1+'Персонал ТО'!$C$9) -> 14633.101 | O9: =N9*0.02 -> 292.66201 | P9: 0 | Q9: =N9+O9+P9 -> 14925.763 | R9: =J9-Q9 -> 45642.437 | S9: =IF(J9>0,R9/J9,"") -> 0.75357097
A10: 5 | B10: ПП ТЭЦ-1 (ул. Лебедева, 2) | C10: DET_AUTO | D10: ТО извещателя пожарного автоматического точечного (дымового, теплового) | E10: шт | F10: 1318 | G10: нет в тарификаторе → рынок | H10: ='Ставки ТО'!$N$9 -> 101.2 | I10: 12 | J10: =K10*I10 -> 1600579.2 | K10: =ROUND(F10*H10,2) -> 133381.6 | L10: ='Ставки ТО'!$D$9 -> 0.04 | M10: =F10*L10*I10 -> 632.64 | N10: =M10*'Персонал ТО'!$C$17*(1+'Персонал ТО'!$C$9) -> 734721.01 | O10: =N10*0.02 -> 14694.42 | P10: 0 | Q10: =N10+O10+P10 -> 749415.43 | R10: =J10-Q10 -> 851163.77 | S10: =IF(J10>0,R10/J10,"") -> 0.53178485
A11: 6 | B11: ПП ТЭЦ-1 (ул. Лебедева, 2) | C11: DET_FLAME | D11: ТО извещателя пожарного пламени (Спектрон, Пульсар, Набат) | E11: шт | F11: 12 | G11: нет в тарификаторе → рынок | H11: ='Ставки ТО'!$N$11 -> 126.5 | I11: 12 | J11: =K11*I11 -> 18216 | K11: =ROUND(F11*H11,2) -> 1518 | L11: ='Ставки ТО'!$D$11 -> 0.15 | M11: =F11*L11*I11 -> 21.6 | N11: =M11*'Персонал ТО'!$C$17*(1+'Персонал ТО'!$C$9) -> 25085.315 | O11: =N11*0.02 -> 501.7063 | P11: 0 | Q11: =N11+O11+P11 -> 25587.021 | R11: =J11-Q11 -> -7371.0215 | S11: =IF(J11>0,R11/J11,"") -> -0.40464545
A12: 7 | B12: ПП ТЭЦ-1 (ул. Лебедева, 2) | C12: DET_MAN | D12: ТО извещателя пожарного ручного, УДП, ЭДУ | E12: шт | F12: 144 | G12: нет в тарификаторе → рынок | H12: ='Ставки ТО'!$N$14 -> 88.55 | I12: 12 | J12: =K12*I12 -> 153014.4 | K12: =ROUND(F12*H12,2) -> 12751.2 | L12: ='Ставки ТО'!$D$14 -> 0.04 | M12: =F12*L12*I12 -> 69.12 | N12: =M12*'Персонал ТО'!$C$17*(1+'Персонал ТО'!$C$9) -> 80273.009 | O12: =N12*0.02 -> 1605.4602 | P12: 0 | Q12: =N12+O12+P12 -> 81878.469 | R12: =J12-Q12 -> 71135.931 | S12: =IF(J12>0,R12/J12,"") -> 0.46489697
A13: 8 | B13: ПП ТЭЦ-1 (ул. Лебедева, 2) | C13: ANN | D13: ТО оповещателя (светового, звукового, речевого, табло «Выход») | E13: шт | F13: 205 | G13: нет в тарификаторе → рынок | H13: ='Ставки ТО'!$N$16 -> 123.97 | I13: 12 | J13: =K13*I13 -> 304966.2 | K13: =ROUND(F13*H13,2) -> 25413.85 | L13: ='Ставки ТО'!$D$16 -> 0.04 | M13: =F13*L13*I13 -> 98.4 | N13: =M13*'Персонал ТО'!$C$17*(1+'Персонал ТО'!$C$9) -> 114277.55 | O13: =N13*0.02 -> 2285.5509 | P13: 0 | Q13: =N13+O13+P13 -> 116563.1 | R13: =J13-Q13 -> 188403.1 | S13: =IF(J13>0,R13/J13,"") -> 0.61778355
A14: 9 | B14: ПП ТЭЦ-1 (ул. Лебедева, 2) | C14: SOUE | D14: ТО прибора речевого оповещения СОУЭ (Орфей, Рокот, Соната) | E14: шт | F14: 4 | G14: нет в тарификаторе → рынок | H14: ='Ставки ТО'!$N$17 -> 1265 | I14: 12 | J14: =K14*I14 -> 60720 | K14: =ROUND(F14*H14,2) -> 5060 | L14: ='Ставки ТО'!$D$17 -> 1 | M14: =F14*L14*I14 -> 48 | N14: =M14*'Персонал ТО'!$C$17*(1+'Персонал ТО'!$C$9) -> 55745.145 | O14: =N14*0.02 -> 1114.9029 | P14: 0 | Q14: =N14+O14+P14 -> 56860.048 | R14: =J14-Q14 -> 3859.9523 | S14: =IF(J14>0,R14/J14,"") -> 0.063569702
A15: 10 | B15: ПП ТЭЦ-1 (ул. Лебедева, 2) | C15: CABLE | D15: ТО шлейфов сигнализации и линий связи (осмотр, измерение параметров) | E15: 100 м | F15: 162.2 | G15: нет в тарификаторе → рынок | H15: ='Ставки ТО'!$N$20 -> 25.3 | I15: 12 | J15: =K15*I15 -> 49243.92 | K15: =ROUND(F15*H15,2) -> 4103.66 | L15: ='Ставки ТО'!$D$20 -> 0.02 | M15: =F15*L15*I15 -> 38.928 | N15: =M15*'Персонал ТО'!$C$17*(1+'Персонал ТО'!$C$9) -> 45209.312 | O15: =N15*0.02 -> 904.18625 | P15: 0 | Q15: =N15+O15+P15 -> 46113.499 | R15: =J15-Q15 -> 3130.4213 | S15: =IF(J15>0,R15/J15,"") -> 0.063569702
A16: 11 | B16: ПП ТЭЦ-1 (ул. Лебедева, 2) | C16: BOX | D16: ТО коробок коммутационных/распределительных, шкафов, автоматов питания | E16: шт | F16: 201 | G16: нет в тарификаторе → рынок | H16: ='Ставки ТО'!$N$21 -> 25.3 | I16: 12 | J16: =K16*I16 -> 61023.6 | K16: =ROUND(F16*H16,2) -> 5085.3 | L16: ='Ставки ТО'!$D$21 -> 0.03 | M16: =F16*L16*I16 -> 72.36 | N16: =M16*'Персонал ТО'!$C$17*(1+'Персонал ТО'!$C$9) -> 84035.806 | O16: =N16*0.02 -> 1680.7161 | P16: 0 | Q16: =N16+O16+P16 -> 85716.522 | R16: =J16-Q16 -> -24692.922 | S16: =IF(J16>0,R16/J16,"") -> -0.40464545
D17: Итого по объекту | J17: =SUM(J6:J16) -> 3873359.2 | K17: =SUM(K6:K16) -> 322779.93 | M17: =SUM(M6:M16) -> 1457.448 | N17: =SUM(N6:N16) -> 1692617.7 | O17: =SUM(O6:O16) -> 33852.354 | P17: =SUM(P6:P16) -> 0 | Q17: =SUM(Q6:Q16) -> 1726470.1 | R17: =SUM(R6:R16) -> 2146889.1
A18: ПГУ-223 ПП ТЭЦ-1 — АПС, управление АУПТ (Прил. 2)
A19: 12 | B19: ПГУ-223 ПП ТЭЦ-1 | C19: PPK | D19: ТО прибора приёмно-контрольного, пульта, прибора управления (С2000М, Сигнал-20П/10, Гранит, С2000-АСПТ, Рубеж-20П и др.) | E19: шт | F19: 22 | G19: нет в тарификаторе → рынок | H19: ='Ставки ТО'!$N$5 -> 3620.43 | I19: 12 | J19: =K19*I19 -> 955793.52 | K19: =ROUND(F19*H19,2) -> 79649.46 | L19: ='Ставки ТО'!$D$5 -> 1 | M19: =F19*L19*I19 -> 264 | N19: =M19*'Персонал ТО'!$C$17*(1+'Персонал ТО'!$C$9) -> 306598.3 | O19: =N19*0.02 -> 6131.9659 | P19: 0 | Q19: =N19+O19+P19 -> 312730.26 | R19: =J19-Q19 -> 643063.26 | S19: =IF(J19>0,R19/J19,"") -> 0.67280563
A20: 13 | B20: ПГУ-223 ПП ТЭЦ-1 | C20: BLOCK | D20: ТО блока системы (С2000-КДЛ, СП1/СП2, КПБ, БКИ, ПИ, ПТ, БРИЗ, барьеры искрозащиты и др.) | E20: шт | F20: 45 | G20: нет в тарификаторе → рынок | H20: ='Ставки ТО'!$N$6 -> 240.35 | I20: 12 | J20: =K20*I20 -> 129789 | K20: =ROUND(F20*H20,2) -> 10815.75 | L20: ='Ставки ТО'!$D$6 -> 0.2 | M20: =F20*L20*I20 -> 108 | N20: =M20*'Персонал ТО'!$C$17*(1+'Персонал ТО'!$C$9) -> 125426.58 | O20: =N20*0.02 -> 2508.5315 | P20: 0 | Q20: =N20+O20+P20 -> 127935.11 | R20: =J20-Q20 -> 1853.8926 | S20: =IF(J20>0,R20/J20,"") -> 0.014283896
A21: 14 | B21: ПГУ-223 ПП ТЭЦ-1 | C21: PSU | D21: ТО источника электропитания резервированного (РИП, Скат, ИВЭПР, ББП) | E21: шт | F21: 26 | G21: нет в тарификаторе → рынок | H21: ='Ставки ТО'!$N$7 -> 493.35 | I21: 12 | J21: =K21*I21 -> 153925.2 | K21: =ROUND(F21*H21,2) -> 12827.1 | L21: ='Ставки ТО'!$D$7 -> 0.25 | M21: =F21*L21*I21 -> 78 | N21: =M21*'Персонал ТО'!$C$17*(1+'Персонал ТО'!$C$9) -> 90585.86 | O21: =N21*0.02 -> 1811.7172 | P21: 0 | Q21: =N21+O21+P21 -> 92397.578 | R21: =J21-Q21 -> 61527.622 | S21: =IF(J21>0,R21/J21,"") -> 0.39972417
A22: 15 | B22: ПГУ-223 ПП ТЭЦ-1 | C22: AKB | D22: ТО аккумуляторной батареи (контроль напряжения и ёмкости) | E22: шт | F22: 35 | G22: нет в тарификаторе → рынок | H22: ='Ставки ТО'!$N$8 -> 240.35 | I22: 12 | J22: =K22*I22 -> 100947 | K22: =ROUND(F22*H22,2) -> 8412.25 | L22: ='Ставки ТО'!$D$8 -> 0.05 | M22: =F22*L22*I22 -> 21 | N22: =M22*'Персонал ТО'!$C$17*(1+'Персонал ТО'!$C$9) -> 24388.501 | O22: =N22*0.02 -> 487.77002 | P22: 0 | Q22: =N22+O22+P22 -> 24876.271 | R22: =J22-Q22 -> 76070.729 | S22: =IF(J22>0,R22/J22,"") -> 0.75357097
A23: 16 | B23: ПГУ-223 ПП ТЭЦ-1 | C23: DET_AUTO | D23: ТО извещателя пожарного автоматического точечного (дымового, теплового) | E23: шт | F23: 436 | G23: нет в тарификаторе → рынок | H23: ='Ставки ТО'!$N$9 -> 101.2 | I23: 12 | J23: =K23*I23 -> 529478.4 | K23: =ROUND(F23*H23,2) -> 44123.2 | L23: ='Ставки ТО'!$D$9 -> 0.04 | M23: =F23*L23*I23 -> 209.28 | N23: =M23*'Персонал ТО'!$C$17*(1+'Персонал ТО'!$C$9) -> 243048.83 | O23: =N23*0.02 -> 4860.9766 | P23: 0 | Q23: =N23+O23+P23 -> 247909.81 | R23: =J23-Q23 -> 281568.59 | S23: =IF(J23>0,R23/J23,"") -> 0.53178485
A24: 17 | B24: ПГУ-223 ПП ТЭЦ-1 | C24: DET_EX | D24: ТО извещателя пожарного во взрывозащищённом/искробезопасном исполнении | E24: шт | F24: 12 | G24: нет в тарификаторе → рынок | H24: ='Ставки ТО'!$N$10 -> 246.68 | I24: 12 | J24: =K24*I24 -> 35521.92 | K24: =ROUND(F24*H24,2) -> 2960.16 | L24: ='Ставки ТО'!$D$10 -> 0.15 | M24: =F24*L24*I24 -> 21.6 | N24: =M24*'Персонал ТО'!$C$17*(1+'Персонал ТО'!$C$9) -> 25085.315 | O24: =N24*0.02 -> 501.7063 | P24: 0 | Q24: =N24+O24+P24 -> 25587.021 | R24: =J24-Q24 -> 9934.8985 | S24: =IF(J24>0,R24/J24,"") -> 0.2796836
A25: 18 | B25: ПГУ-223 ПП ТЭЦ-1 | C25: DET_FLAME | D25: ТО извещателя пожарного пламени (Спектрон, Пульсар, Набат) | E25: шт | F25: 14 | G25: нет в тарификаторе → рынок | H25: ='Ставки ТО'!$N$11 -> 126.5 | I25: 12 | J25: =K25*I25 -> 21252 | K25: =ROUND(F25*H25,2) -> 1771 | L25: ='Ставки ТО'!$D$11 -> 0.15 | M25: =F25*L25*I25 -> 25.2 | N25: =M25*'Персонал ТО'!$C$17*(1+'Персонал ТО'!$C$9) -> 29266.201 | O25: =N25*0.02 -> 585.32402 | P25: 0 | Q25: =N25+O25+P25 -> 29851.525 | R25: =J25-Q25 -> -8599.5251 | S25: =IF(J25>0,R25/J25,"") -> -0.40464545
A26: 19 | B26: ПГУ-223 ПП ТЭЦ-1 | C26: THERMO | D26: ТО линейного теплового извещателя (термокабель) | E26: 100 м | F26: 14.2 | G26: нет в тарификаторе → рынок | H26: ='Ставки ТО'!$N$13 -> 379.5 | I26: 12 | J26: =K26*I26 -> 64666.8 | K26: =ROUND(F26*H26,2) -> 5388.9 | L26: ='Ставки ТО'!$D$13 -> 0.15 | M26: =F26*L26*I26 -> 25.56 | N26: =M26*'Персонал ТО'!$C$17*(1+'Персонал ТО'!$C$9) -> 29684.29 | O26: =N26*0.02 -> 593.68579 | P26: 0 | Q26: =N26+O26+P26 -> 30277.975 | R26: =J26-Q26 -> 34388.825 | S26: =IF(J26>0,R26/J26,"") -> 0.53178485
A27: 20 | B27: ПГУ-223 ПП ТЭЦ-1 | C27: DET_MAN | D27: ТО извещателя пожарного ручного, УДП, ЭДУ | E27: шт | F27: 201 | G27: нет в тарификаторе → рынок | H27: ='Ставки ТО'!$N$14 -> 88.55 | I27: 12 | J27: =K27*I27 -> 213582.6 | K27: =ROUND(F27*H27,2) -> 17798.55 | L27: ='Ставки ТО'!$D$14 -> 0.04 | M27: =F27*L27*I27 -> 96.48 | N27: =M27*'Персонал ТО'!$C$17*(1+'Персонал ТО'!$C$9) -> 112047.74 | O27: =N27*0.02 -> 2240.9548 | P27: 0 | Q27: =N27+O27+P27 -> 114288.7 | R27: =J27-Q27 -> 99293.904 | S27: =IF(J27>0,R27/J27,"") -> 0.46489697
A28: 21 | B28: ПГУ-223 ПП ТЭЦ-1 | C28: DET_SEC | D28: ТО извещателя охранного (магнитоконтактного, ИК) в составе систем | E28: шт | F28: 190 | G28: нет в тарификаторе → рынок | H28: ='Ставки ТО'!$N$15 -> 75.9 | I28: 12 | J28: =K28*I28 -> 173052 | K28: =ROUND(F28*H28,2) -> 14421 | L28: ='Ставки ТО'!$D$15 -> 0.03 | M28: =F28*L28*I28 -> 68.4 | N28: =M28*'Персонал ТО'!$C$17*(1+'Персонал ТО'!$C$9) -> 79436.831 | O28: =N28*0.02 -> 1588.7366 | P28: 0 | Q28: =N28+O28+P28 -> 81025.568 | R28: =J28-Q28 -> 92026.432 | S28: =IF(J28>0,R28/J28,"") -> 0.53178485
A29: 22 | B29: ПГУ-223 ПП ТЭЦ-1 | C29: ANN | D29: ТО оповещателя (светового, звукового, речевого, табло «Выход») | E29: шт | F29: 283 | G29: нет в тарификаторе → рынок | H29: ='Ставки ТО'!$N$16 -> 123.97 | I29: 12 | J29: =K29*I29 -> 421002.12 | K29: =ROUND(F29*H29,2) -> 35083.51 | L29: ='Ставки ТО'!$D$16 -> 0.04 | M29: =F29*L29*I29 -> 135.84 | N29: =M29*'Персонал ТО'!$C$17*(1+'Персонал ТО'!$C$9) -> 157758.76 | O29: =N29*0.02 -> 3155.1752 | P29: 0 | Q29: =N29+O29+P29 -> 160913.94 | R29: =J29-Q29 -> 260088.18 | S29: =IF(J29>0,R29/J29,"") -> 0.61778355
A30: 23 | B30: ПГУ-223 ПП ТЭЦ-1 | C30: SW | D30: Сопровождение ПО АРМ «Орион Про» (резервное копирование баз, проверка связи) | E30: к-т | F30: 1 | G30: нет в тарификаторе → рынок | H30: ='Ставки ТО'!$N$19 -> 4301 | I30: 12 | J30: =K30*I30 -> 51612 | K30: =ROUND(F30*H30,2) -> 4301 | L30: ='Ставки ТО'!$D$19 -> 2 | M30: =F30*L30*I30 -> 24 | N30: =M30*'Персонал ТО'!$C$17*(1+'Персонал ТО'!$C$9) -> 27872.572 | O30: =N30*0.02 -> 557.45145 | P30: 0 | Q30: =N30+O30+P30 -> 28430.024 | R30: =J30-Q30 -> 23181.976 | S30: =IF(J30>0,R30/J30,"") -> 0.44915865
A31: 24 | B31: ПГУ-223 ПП ТЭЦ-1 | C31: CABLE | D31: ТО шлейфов сигнализации и линий связи (осмотр, измерение параметров) | E31: 100 м | F31: 121.505 | G31: нет в тарификаторе → рынок | H31: ='Ставки ТО'!$N$20 -> 25.3 | I31: 12 | J31: =K31*I31 -> 36888.96 | K31: =ROUND(F31*H31,2) -> 3074.08 | L31: ='Ставки ТО'!$D$20 -> 0.02 | M31: =F31*L31*I31 -> 29.1612 | N31: =M31*'Персонал ТО'!$C$17*(1+'Персонал ТО'!$C$9) -> 33866.569 | O31: =N31*0.02 -> 677.33138 | P31: 0 | Q31: =N31+O31+P31 -> 34543.9 | R31: =J31-Q31 -> 2345.0595 | S31: =IF(J31>0,R31/J31,"") -> 0.063570768
D32: Итого по объекту | J32: =SUM(J19:J31) -> 2887511.5 | K32: =SUM(K19:K31) -> 240625.96 | M32: =SUM(M19:M31) -> 1106.5212 | N32: =SUM(N19:N31) -> 1285066.3 | O32: =SUM(O19:O31) -> 25701.327 | P32: =SUM(P19:P31) -> 0 | Q32: =SUM(Q19:Q31) -> 1310767.7 | R32: =SUM(R19:R31) -> 1576743.8
A33: ПП ТЭЦ-2, старая часть (пр. Ясный, 1а) — АПС, СОУЭ (Прил. 3)
A34: 25 | B34: ПП ТЭЦ-2, старая часть (пр. Ясный, 1а) | C34: PPK | D34: ТО прибора приёмно-контрольного, пульта, прибора управления (С2000М, Сигнал-20П/10, Гранит, С2000-АСПТ, Рубеж-20П и др.) | E34: шт | F34: 22 | G34: нет в тарификаторе → рынок | H34: ='Ставки ТО'!$N$5 -> 3620.43 | I34: 12 | J34: =K34*I34 -> 955793.52 | K34: =ROUND(F34*H34,2) -> 79649.46 | L34: ='Ставки ТО'!$D$5 -> 1 | M34: =F34*L34*I34 -> 264 | N34: =M34*'Персонал ТО'!$C$17*(1+'Персонал ТО'!$C$9) -> 306598.3 | O34: =N34*0.02 -> 6131.9659 | P34: 0 | Q34: =N34+O34+P34 -> 312730.26 | R34: =J34-Q34 -> 643063.26 | S34: =IF(J34>0,R34/J34,"") -> 0.67280563
A35: 26 | B35: ПП ТЭЦ-2, старая часть (пр. Ясный, 1а) | C35: BLOCK | D35: ТО блока системы (С2000-КДЛ, СП1/СП2, КПБ, БКИ, ПИ, ПТ, БРИЗ, барьеры искрозащиты и др.) | E35: шт | F35: 34 | G35: нет в тарификаторе → рынок | H35: ='Ставки ТО'!$N$6 -> 240.35 | I35: 12 | J35: =K35*I35 -> 98062.8 | K35: =ROUND(F35*H35,2) -> 8171.9 | L35: ='Ставки ТО'!$D$6 -> 0.2 | M35: =F35*L35*I35 -> 81.6 | N35: =M35*'Персонал ТО'!$C$17*(1+'Персонал ТО'!$C$9) -> 94766.746 | O35: =N35*0.02 -> 1895.3349 | P35: 0 | Q35: =N35+O35+P35 -> 96662.081 | R35: =J35-Q35 -> 1400.7189 | S35: =IF(J35>0,R35/J35,"") -> 0.014283896
A36: 27 | B36: ПП ТЭЦ-2, старая часть (пр. Ясный, 1а) | C36: PSU | D36: ТО источника электропитания резервированного (РИП, Скат, ИВЭПР, ББП) | E36: шт | F36: 19 | G36: нет в тарификаторе → рынок | H36: ='Ставки ТО'!$N$7 -> 493.35 | I36: 12 | J36: =K36*I36 -> 112483.8 | K36: =ROUND(F36*H36,2) -> 9373.65 | L36: ='Ставки ТО'!$D$7 -> 0.25 | M36: =F36*L36*I36 -> 57 | N36: =M36*'Персонал ТО'!$C$17*(1+'Персонал ТО'!$C$9) -> 66197.359 | O36: =N36*0.02 -> 1323.9472 | P36: 0 | Q36: =N36+O36+P36 -> 67521.307 | R36: =J36-Q36 -> 44962.493 | S36: =IF(J36>0,R36/J36,"") -> 0.39972417
A37: 28 | B37: ПП ТЭЦ-2, старая часть (пр. Ясный, 1а) | C37: AKB | D37: ТО аккумуляторной батареи (контроль напряжения и ёмкости) | E37: шт | F37: 14 | G37: нет в тарификаторе → рынок | H37: ='Ставки ТО'!$N$8 -> 240.35 | I37: 12 | J37: =K37*I37 -> 40378.8 | K37: =ROUND(F37*H37,2) -> 3364.9 | L37: ='Ставки ТО'!$D$8 -> 0.05 | M37: =F37*L37*I37 -> 8.4 | N37: =M37*'Персонал ТО'!$C$17*(1+'Персонал ТО'!$C$9) -> 9755.4003 | O37: =N37*0.02 -> 195.10801 | P37: 0 | Q37: =N37+O37+P37 -> 9950.5084 | R37: =J37-Q37 -> 30428.292 | S37: =IF(J37>0,R37/J37,"") -> 0.75357097
A38: 29 | B38: ПП ТЭЦ-2, старая часть (пр. Ясный, 1а) | C38: DET_AUTO | D38: ТО извещателя пожарного автоматического точечного (дымового, теплового) | E38: шт | F38: 773 | G38: нет в тарификаторе → рынок | H38: ='Ставки ТО'!$N$9 -> 101.2 | I38: 12 | J38: =K38*I38 -> 938731.2 | K38: =ROUND(F38*H38,2) -> 78227.6 | L38: ='Ставки ТО'!$D$9 -> 0.04 | M38: =F38*L38*I38 -> 371.04 | N38: =M38*'Персонал ТО'!$C$17*(1+'Персонал ТО'!$C$9) -> 430909.97 | O38: =N38*0.02 -> 8618.1994 | P38: 0 | Q38: =N38+O38+P38 -> 439528.17 | R38: =J38-Q38 -> 499203.03 | S38: =IF(J38>0,R38/J38,"") -> 0.53178485
A39: 30 | B39: ПП ТЭЦ-2, старая часть (пр. Ясный, 1а) | C39: DET_EX | D39: ТО извещателя пожарного во взрывозащищённом/искробезопасном исполнении | E39: шт | F39: 25 | G39: нет в тарификаторе → рынок | H39: ='Ставки ТО'!$N$10 -> 246.68 | I39: 12 | J39: =K39*I39 -> 74004 | K39: =ROUND(F39*H39,2) -> 6167 | L39: ='Ставки ТО'!$D$10 -> 0.15 | M39: =F39*L39*I39 -> 45 | N39: =M39*'Персонал ТО'!$C$17*(1+'Персонал ТО'!$C$9) -> 52261.073 | O39: =N39*0.02 -> 1045.2215 | P39: 0 | Q39: =N39+O39+P39 -> 53306.295 | R39: =J39-Q39 -> 20697.705 | S39: =IF(J39>0,R39/J39,"") -> 0.2796836
A40: 31 | B40: ПП ТЭЦ-2, старая часть (пр. Ясный, 1а) | C40: LINEAR | D40: ТО извещателя пожарного дымового линейного ИПДЛ | E40: к-т | F40: 5 | G40: нет в тарификаторе → рынок | H40: ='Ставки ТО'!$N$12 -> 506 | I40: 12 | J40: =K40*I40 -> 30360 | K40: =ROUND(F40*H40,2) -> 2530 | L40: ='Ставки ТО'!$D$12 -> 0.3 | M40: =F40*L40*I40 -> 18 | N40: =M40*'Персонал ТО'!$C$17*(1+'Персонал ТО'!$C$9) -> 20904.429 | O40: =N40*0.02 -> 418.08859 | P40: 0 | Q40: =N40+O40+P40 -> 21322.518 | R40: =J40-Q40 -> 9037.4821 | S40: =IF(J40>0,R40/J40,"") -> 0.29767728
A41: 32 | B41: ПП ТЭЦ-2, старая часть (пр. Ясный, 1а) | C41: THERMO | D41: ТО линейного теплового извещателя (термокабель) | E41: 100 м | F41: 5 | G41: нет в тарификаторе → рынок | H41: ='Ставки ТО'!$N$13 -> 379.5 | I41: 12 | J41: =K41*I41 -> 22770 | K41: =ROUND(F41*H41,2) -> 1897.5 | L41: ='Ставки ТО'!$D$13 -> 0.15 | M41: =F41*L41*I41 -> 9 | N41: =M41*'Персонал ТО'!$C$17*(1+'Персонал ТО'!$C$9) -> 10452.215 | O41: =N41*0.02 -> 209.04429 | P41: 0 | Q41: =N41+O41+P41 -> 10661.259 | R41: =J41-Q41 -> 12108.741 | S41: =IF(J41>0,R41/J41,"") -> 0.53178485
...

Sheet Персонал ТО
A1: ПЕРСОНАЛ ТО: ТРУДОЁМКОСТЬ → ЧИСЛЕННОСТЬ → ФОТ
A2: Техники ТО — штатные работники (лицензия МЧС требует работников в штате лицензиата). ФОТ = на руки × 1,5 (налоги и взносы) × 14/12 в годовом расчёте.
B4: Показатель | C4: Значение | D4: Основание
B5: Трудоёмкость регламентного ТО, чел.-ч/год | C5: =Работы!M99 -> 7695.5832 | D5: Лист «Работы», итог регламентного ТО (кол-во × норма × 12 мес.)
B6: Трудоёмкость разовых работ (гидроиспытания, поверка, ЭТЛ), чел.-ч/год | C6: =Работы!M107 -> 790.69 | D6: Лист «Работы», разовые работы
B7: Первичное обследование систем (январь–февраль), чел.-ч | C7: 260 | D7: Первичное обследование (п. 3.2.1 ТЗ): ~20 % месячной трудоёмкости ТО × 2 мес. ≈ 260 чел.-ч
B8: Замена вышедшего из строя оборудования (ЗИП), чел.-ч/год | C8: =Материалы!N22 -> 114.05 | D8: Лист «Материалы», чел.-ч на замену
B9: Оформление журналов, актов, паспортов, отчётов — % к трудоёмкости | C9: 0.1 | D9: Журналы ТО и ППР, акты, паспорта установок, ежемесячные отчёты — экспертно 10 %
B10: ИТОГО трудоёмкость, чел.-ч/год | C10: =(C5+C6+C7+C8)*(1+C9) -> 9746.3555
B11: Фонд рабочего времени 1 работника, ч/год (40-часовая неделя, 2027) | C11: 1812 | D11: Норма 2027 при 40-ч неделе 1 972 ч (КонсультантПлюс, производственный календарь 2027) − отпуск 20 раб. дней (160 ч)
B12: Коэффициент использования (переезды между 10 площадками, наряды-допуски, инструктажи) | C12: 0.8 | D12: Экспертно 0,80: основная часть оборудования на 2 промплощадках (ТЭЦ-1, ТЭЦ-2), 8 городских адресов; потери — наряды-допуски, инструктажи, переезды
B13: Требуемая численность техников, чел. (расчёт) | C13: =C10/(C11*C12) -> 6.7234792
B14: Принятая численность техников, чел. (целая) | C14: =ROUNDUP(C13,0) -> 7
B15: Оплата техника на руки, руб./мес (Воронеж) | C15: 70000 | D15: 70 000 руб./мес на руки: Воронеж 2026 — монтажник-слаботочник медиана 75 тыс. (ГородРабот, май 2026), Галерея Чижова 55–75 тыс., ТЕКС Групп 70–120 тыс., НПО РИФ от 70 тыс., ВДПО Воронеж от 80 тыс. (hh.ru, careerist, dreamjob)
B16: ФОТ техников за год, руб. = чел. × на руки × 1,5 × 14 | C16: =C14*C15*1.5*14 -> 10290000 | D16: ×1,5 — НДФЛ сверху «на руки» и страховые взносы; ×14 — 12 мес. × 14/12 (отпускные, замены, премии) по правилу промта
B17: Себестоимость 1 чел.-ч для распределения по строкам, руб. | C17: =C16/C10 -> 1055.7793

Sheet Материалы
A1: МАТЕРИАЛЫ: ЗИП ДЛЯ ПЛАНОВОЙ И ПРЕДУПРЕДИТЕЛЬНОЙ ЗАМЕНЫ (п. 2.1.2, 2.2.3 ТЗ)
A2: Объёмы замены в ТЗ не заданы → допущение: доля парка оборудования в год (колонка E). С/с = закупка × (1+отходы) × (1+доставка) × (1+резерв роста + стоимость денег). Наценка — раздельная форма.
A4: № | B4: Материал / оборудование | C4: Ед. | D4: Парк по ТЗ | E4: Доля замены в год | F4: Кол-во | G4: Закупка б/НДС, руб/ед | H4: Категория (справочник) | I4: Отходы | J4: Доставка | K4: Резерв + деньги | L4: С/с за ед. | M4: С/с всего | N4: Чел.-ч на замену (всего) | O4: Наценка | P4: Цена КП за ед. (не выше розницы) | Q4: КП всего | R4: Розница б/НДС (макс. источник) | S4: Проверка ≤ розницы | T4: С/с труда на замену, руб.
A5: 1 | B5: Извещатель дымовой ИП 212-141 (Рубеж) или аналог | C5: шт | D5: 3569 | E5: 0.02 | F5: =MAX(1,ROUND(D5*E5,0)) -> 71 | G5: ='Цены материалов (источники)'!J5 -> 368.85 | H5: Электроустановочные изделия, щиты, автоматы | I5: 0.01 | J5: 0.1 | K5: 0.105 | L5: =ROUND(G5*(1+I5)*(1+J5)*(1+K5),2) -> 452.82 | M5: =L5*F5 -> 32150.22 | N5: =F5*0.5 -> 35.5 | O5: 0.12 | P5: =ROUND(MIN(L5*(1+O5),R5),2) -> 488.52 | Q5: =P5*F5 -> 34684.92 | R5: ='Цены материалов (источники)'!K5 -> 488.52 | S5: =IF(L5*(1+O5)<=R5,"ок",IF(P5>=L5,"ограничено розницей","розница ниже с/с")) -> ограничено розницей | T5: =N5*'Персонал ТО'!$C$17*(1+'Персонал ТО'!$C$9) -> 41228.18
A6: 2 | B6: Извещатель адресный ДИП-34А-04 (Болид) | C6: шт | D6: 3569 | E6: 0.005 | F6: =MAX(1,ROUND(D6*E6,0)) -> 18 | G6: ='Цены материалов (источники)'!J6 -> 959.02 | H6: Электроустановочные изделия, щиты, автоматы | I6: 0.01 | J6: 0.1 | K6: 0.105 | L6: =ROUND(G6*(1+I6)*(1+J6)*(1+K6),2) -> 1177.35 | M6: =L6*F6 -> 21192.3 | N6: =F6*0.5 -> 9 | O6: 0.12 | P6: =ROUND(MIN(L6*(1+O6),R6),2) -> 1318.63 | Q6: =P6*F6 -> 23735.34 | R6: ='Цены материалов (источники)'!K6 -> 1477.05 | S6: =IF(L6*(1+O6)<=R6,"ок",IF(P6>=L6,"ограничено розницей","розница ниже с/с")) -> ок | T6: =N6*'Персонал ТО'!$C$17*(1+'Персонал ТО'!$C$9) -> 10452.215
A7: 3 | B7: Извещатель тепловой ИП 103-5/1-А3 | C7: шт | D7: 3569 | E7: 0.01 | F7: =MAX(1,ROUND(D7*E7,0)) -> 36 | G7: ='Цены материалов (источники)'!J7 -> 87.05 | H7: Электроустановочные изделия, щиты, автоматы | I7: 0.01 | J7: 0.1 | K7: 0.105 | L7: =ROUND(G7*(1+I7)*(1+J7)*(1+K7),2) -> 106.87 | M7: =L7*F7 -> 3847.32 | N7: =F7*0.5 -> 18 | O7: 0.12 | P7: =ROUND(MIN(L7*(1+O7),R7),2) -> 96.72 | Q7: =P7*F7 -> 3481.92 | R7: ='Цены материалов (источники)'!K7 -> 96.72 | S7: =IF(L7*(1+O7)<=R7,"ок",IF(P7>=L7,"ограничено розницей","розница ниже с/с")) -> розница ниже с/с | T7: =N7*'Персонал ТО'!$C$17*(1+'Персонал ТО'!$C$9) -> 20904.429
A8: 4 | B8: Извещатель ручной ИПР 513-10 (Рубеж) | C8: шт | D8: 558 | E8: 0.01 | F8: =MAX(1,ROUND(D8*E8,0)) -> 6 | G8: ='Цены материалов (источники)'!J8 -> 317.21 | H8: Электроустановочные изделия, щиты, автоматы | I8: 0.01 | J8: 0.1 | K8: 0.105 | L8: =ROUND(G8*(1+I8)*(1+J8)*(1+K8),2) -> 389.42 | M8: =L8*F8 -> 2336.52 | N8: =F8*0.5 -> 3 | O8: 0.12 | P8: =ROUND(MIN(L8*(1+O8),R8),2) -> 318.03 | Q8: =P8*F8 -> 1908.18 | R8: ='Цены материалов (источники)'!K8 -> 318.03 | S8: =IF(L8*(1+O8)<=R8,"ок",IF(P8>=L8,"ограничено розницей","розница ниже с/с")) -> розница ниже с/с | T8: =N8*'Персонал ТО'!$C$17*(1+'Персонал ТО'!$C$9) -> 3484.0716
A9: 5 | B9: Извещатель ручной адресный ИПР 513-3АМ (Болид) | C9: шт | D9: 558 | E9: 0.005 | F9: =MAX(1,ROUND(D9*E9,0)) -> 3 | G9: ='Цены материалов (источники)'!J9 -> 781.97 | H9: Электроустановочные изделия, щиты, автоматы | I9: 0.01 | J9: 0.1 | K9: 0.105 | L9: =ROUND(G9*(1+I9)*(1+J9)*(1+K9),2) -> 959.99 | M9: =L9*F9 -> 2879.97 | N9: =F9*0.5 -> 1.5 | O9: 0.12 | P9: =ROUND(MIN(L9*(1+O9),R9),2) -> 936 | Q9: =P9*F9 -> 2808 | R9: ='Цены материалов (источники)'!K9 -> 936 | S9: =IF(L9*(1+O9)<=R9,"ок",IF(P9>=L9,"ограничено розницей","розница ниже с/с")) -> розница ниже с/с | T9: =N9*'Персонал ТО'!$C$17*(1+'Персонал ТО'!$C$9) -> 1742.0358
A10: 6 | B10: Оповещатель светозвуковой Маяк-12-КП | C10: шт | D10: 880 | E10: 0.01 | F10: =MAX(1,ROUND(D10*E10,0)) -> 9 | G10: ='Цены материалов (источники)'!J10 -> 551.64 | H10: Электроустановочные изделия, щиты, автоматы | I10: 0.01 | J10: 0.1 | K10: 0.105 | L10: =ROUND(G10*(1+I10)*(1+J10)*(1+K10),2) -> 677.22 | M10: =L10*F10 -> 6094.98 | N10: =F10*0.5 -> 4.5 | O10: 0.12 | P10: =ROUND(MIN(L10*(1+O10),R10),2) -> 727.87 | Q10: =P10*F10 -> 6550.83 | R10: ='Цены материалов (источники)'!K10 -> 727.87 | S10: =IF(L10*(1+O10)<=R10,"ок",IF(P10>=L10,"ограничено розницей","розница ниже с/с")) -> ограничено розницей | T10: =N10*'Персонал ТО'!$C$17*(1+'Персонал ТО'!$C$9) -> 5226.1073
A11: 7 | B11: Табло «Выход» Молния-12 | C11: шт | D11: 880 | E11: 0.005 | F11: =MAX(1,ROUND(D11*E11,0)) -> 4 | G11: ='Цены материалов (источники)'!J11 -> 282.79 | H11: Электроустановочные изделия, щиты, автоматы | I11: 0.01 | J11: 0.1 | K11: 0.105 | L11: =ROUND(G11*(1+I11)*(1+J11)*(1+K11),2) -> 347.17 | M11: =L11*F11 -> 1388.68 | N11: =F11*0.5 -> 2 | O11: 0.12 | P11: =ROUND(MIN(L11*(1+O11),R11),2) -> 291.8 | Q11: =P11*F11 -> 1167.2 | R11: ='Цены материалов (источники)'!K11 -> 291.8 | S11: =IF(L11*(1+O11)<=R11,"ок",IF(P11>=L11,"ограничено розницей","розница ниже с/с")) -> розница ниже с/с | T11: =N11*'Персонал ТО'!$C$17*(1+'Персонал ТО'!$C$9) -> 2322.7144
A12: 8 | B12: Оповещатель звуковой Маяк-12-3М | C12: шт | D12: 880 | E12: 0.005 | F12: =MAX(1,ROUND(D12*E12,0)) -> 4 | G12: ='Цены материалов (источники)'!J12 -> 210.66 | H12: Электроустановочные изделия, щиты, автоматы | I12: 0.01 | J12: 0.1 | K12: 0.105 | L12: =ROUND(G12*(1+I12)*(1+J12)*(1+K12),2) -> 258.62 | M12: =L12*F12 -> 1034.48 | N12: =F12*0.5 -> 2 | O12: 0.12 | P12: =ROUND(MIN(L12*(1+O12),R12),2) -> 289.65 | Q12: =P12*F12 -> 1158.6 | R12: ='Цены материалов (источники)'!K12 -> 407.38 | S12: =IF(L12*(1+O12)<=R12,"ок",IF(P12>=L12,"ограничено розницей","розница ниже с/с")) -> ок | T12: =N12*'Персонал ТО'!$C$17*(1+'Персонал ТО'!$C$9) -> 2322.7144
A13: 9 | B13: Аккумулятор 12 В 7 А·ч Delta DTM 1207 | C13: шт | D13: 40 | E13: 0.25 | F13: =MAX(1,ROUND(D13*E13,0)) -> 10 | G13: ='Цены материалов (источники)'!J13 -> 1640.98 | H13: Электроустановочные изделия, щиты, автоматы | I13: 0 | J13: 0.1 | K13: 0.105 | L13: =ROUND(G13*(1+I13)*(1+J13)*(1+K13),2) -> 1994.61 | M13: =L13*F13 -> 19946.1 | N13: =F13*0.3 -> 3 | O13: 0.12 | P13: =ROUND(MIN(L13*(1+O13),R13),2) -> 1649.18 | Q13: =P13*F13 -> 16491.8 | R13: ='Цены материалов (источники)'!K13 -> 1649.18 | S13: =IF(L13*(1+O13)<=R13,"ок",IF(P13>=L13,"ограничено розницей","розница ниже с/с")) -> розница ниже с/с | T13: =N13*'Персонал ТО'!$C$17*(1+'Персонал ТО'!$C$9) -> 3484.0716
A14: 10 | B14: Аккумулятор 12 В 12 А·ч Delta DTM 1212 | C14: шт | D14: 20 | E14: 0.25 | F14: =MAX(1,ROUND(D14*E14,0)) -> 5 | G14: ='Цены материалов (источники)'!J14 -> 2671.31 | H14: Электроустановочные изделия, щиты, автоматы | I14: 0 | J14: 0.1 | K14: 0.105 | L14: =ROUND(G14*(1+I14)*(1+J14)*(1+K14),2) -> 3246.98 | M14: =L14*F14 -> 16234.9 | N14: =F14*0.3 -> 1.5 | O14: 0.12 | P14: =ROUND(MIN(L14*(1+O14),R14),2) -> 3001.64 | Q14: =P14*F14 -> 15008.2 | R14: ='Цены материалов (источники)'!K14 -> 3001.64 | S14: =IF(L14*(1+O14)<=R14,"ок",IF(P14>=L14,"ограничено розницей","розница ниже с/с")) -> розница ниже с/с | T14: =N14*'Персонал ТО'!$C$17*(1+'Персонал ТО'!$C$9) -> 1742.0358
A15: 11 | B15: Аккумулятор 12 В 17 А·ч Delta DTM 1217 | C15: шт | D15: 10 | E15: 0.25 | F15: =MAX(1,ROUND(D15*E15,0)) -> 3 | G15: ='Цены материалов (источники)'!J15 -> 3945.08 | H15: Электроустановочные изделия, щиты, автоматы | I15: 0 | J15: 0.1 | K15: 0.105 | L15: =ROUND(G15*(1+I15)*(1+J15)*(1+K15),2) -> 4795.24 | M15: =L15*F15 -> 14385.72 | N15: =F15*0.3 -> 0.9 | O15: 0.12 | P15: =ROUND(MIN(L15*(1+O15),R15),2) -> 3952.46 | Q15: =P15*F15 -> 11857.38 | R15: ='Цены материалов (источники)'!K15 -> 3952.46 | S15: =IF(L15*(1+O15)<=R15,"ок",IF(P15>=L15,"ограничено розницей","розница ниже с/с")) -> розница ниже с/с | T15: =N15*'Персонал ТО'!$C$17*(1+'Персонал ТО'!$C$9) -> 1045.2215
A16: 12 | B16: Аккумулятор 12 В 40 А·ч Delta DTM 1240 L | C16: шт | D16: 6 | E16: 0.25 | F16: =MAX(1,ROUND(D16*E16,0)) -> 2 | G16: ='Цены материалов (источники)'!J16 -> 10869.67 | H16: Электроустановочные изделия, щиты, автоматы | I16: 0 | J16: 0.1 | K16: 0.105 | L16: =ROUND(G16*(1+I16)*(1+J16)*(1+K16),2) -> 13212.08 | M16: =L16*F16 -> 26424.16 | N16: =F16*0.5 -> 1 | O16: 0.12 | P16: =ROUND(MIN(L16*(1+O16),R16),2) -> 10876.77 | Q16: =P16*F16 -> 21753.54 | R16: ='Цены материалов (источники)'!K16 -> 10876.77 | S16: =IF(L16*(1+O16)<=R16,"ок",IF(P16>=L16,"ограничено розницей","розница ниже с/с")) -> розница ниже с/с | T16: =N16*'Персонал ТО'!$C$17*(1+'Персонал ТО'!$C$9) -> 1161.3572
A17: 13 | B17: Источник питания РИП-12 исп.01 (Болид) | C17: шт | D17: 67 | E17: 0.03 | F17: =MAX(1,ROUND(D17*E17,0)) -> 2 | G17: ='Цены материалов (источники)'!J17 -> 5413.97 | H17: Электроустановочные изделия, щиты, автоматы | I17: 0 | J17: 0.1 | K17: 0.105 | L17: =ROUND(G17*(1+I17)*(1+J17)*(1+K17),2) -> 6580.68 | M17: =L17*F17 -> 13161.36 | N17: =F17*1 -> 2 | O17: 0.12 | P17: =ROUND(MIN(L17*(1+O17),R17),2) -> 5504.2 | Q17: =P17*F17 -> 11008.4 | R17: ='Цены материалов (источники)'!K17 -> 5504.2 | S17: =IF(L17*(1+O17)<=R17,"ок",IF(P17>=L17,"ограничено розницей","розница ниже с/с")) -> розница ниже с/с | T17: =N17*'Персонал ТО'!$C$17*(1+'Персонал ТО'!$C$9) -> 2322.7144
A18: 14 | B18: Кабель КПСнг(А)-FRLS 1×2×0,75 | C18: м | D18: 52655 | E18: 0.005 | F18: =MAX(1,ROUND(D18*E18,0)) -> 263 | G18: ='Цены материалов (источники)'!J18 -> 21.25 | H18: Кабель и провод | I18: 0.04 | J18: 0.1 | K18: 0.105 | L18: =ROUND(G18*(1+I18)*(1+J18)*(1+K18),2) -> 26.86 | M18: =L18*F18 -> 7064.18 | N18: =F18*0.05 -> 13.15 | O18: 0.12 | P18: =ROUND(MIN(L18*(1+O18),R18),2) -> 29.48 | Q18: =P18*F18 -> 7753.24 | R18: ='Цены материалов (источники)'!K18 -> 29.48 | S18: =IF(L18*(1+O18)<=R18,"ок",IF(P18>=L18,"ограничено розницей","розница ниже с/с")) -> ограничено розницей | T18: =N18*'Персонал ТО'!$C$17*(1+'Персонал ТО'!$C$9) -> 15271.847
A19: 15 | B19: Манометр МП-100 0–1,6 МПа | C19: шт | D19: 35 | E19: 0.1 | F19: =MAX(1,ROUND(D19*E19,0)) -> 4 | G19: ='Цены материалов (источники)'!J19 -> 523.25 | H19: Трубы и фитинги ВиК, отопления | I19: 0 | J19: 0.1 | K19: 0.105 | L19: =ROUND(G19*(1+I19)*(1+J19)*(1+K19),2) -> 636.01 | M19: =L19*F19 -> 2544.04 | N19: =F19*0.5 -> 2 | O19: 0.12 | P19: =ROUND(MIN(L19*(1+O19),R19),2) -> 659.02 | Q19: =P19*F19 -> 2636.08 | R19: ='Цены материалов (источники)'!K19 -> 659.02 | S19: =IF(L19*(1+O19)<=R19,"ок",IF(P19>=L19,"ограничено розницей","розница ниже с/с")) -> ограничено розницей | T19: =N19*'Персонал ТО'!$C$17*(1+'Персонал ТО'!$C$9) -> 2322.7144
A20: 16 | B20: Ороситель спринклерный СВН-15 (68 °С) | C20: шт | D20: 987 | E20: 0.01 | F20: =MAX(1,ROUND(D20*E20,0)) -> 10 | G20: ='Цены материалов (источники)'!J20 -> 413.11 | H20: Трубы и фитинги ВиК, отопления | I20: 0 | J20: 0.1 | K20: 0.105 | L20: =ROUND(G20*(1+I20)*(1+J20)*(1+K20),2) -> 502.14 | M20: =L20*F20 -> 5021.4 | N20: =F20*1 -> 10 | O20: 0.12 | P20: =ROUND(MIN(L20*(1+O20),R20),2) -> 413.11 | Q20: =P20*F20 -> 4131.1 | R20: ='Цены материалов (источники)'!K20 -> 413.11 | S20: =IF(L20*(1+O20)<=R20,"ок",IF(P20>=L20,"ограничено розницей","розница ниже с/с")) -> розница ниже с/с | T20: =N20*'Персонал ТО'!$C$17*(1+'Персонал ТО'!$C$9) -> 11613.572
A21: 17 | B21: Ороситель дренчерный ДВН-15 | C21: шт | D21: 987 | E21: 0.005 | F21: =MAX(1,ROUND(D21*E21,0)) -> 5 | G21: ='Цены материалов (источники)'!J21 -> 236.07 | H21: Трубы и фитинги ВиК, отопления | I21: 0 | J21: 0.1 | K21: 0.105 | L21: =ROUND(G21*(1+I21)*(1+J21)*(1+K21),2) -> 286.94 | M21: =L21*F21 -> 1434.7 | N21: =F21*1 -> 5 | O21: 0.12 | P21: =ROUND(MIN(L21*(1+O21),R21),2) -> 242.62 | Q21: =P21*F21 -> 1213.1 | R21: ='Цены материалов (источники)'!K21 -> 242.62 | S21: =IF(L21*(1+O21)<=R21,"ок",IF(P21>=L21,"ограничено розницей","розница ниже с/с")) -> розница ниже с/с | T21: =N21*'Персонал ТО'!$C$17*(1+'Персонал ТО'!$C$9) -> 5806.7859
B22: ИТОГО ЗИП | M22: =SUM(M5:M21) -> 177141.03 | N22: =SUM(N5:N21) -> 114.05 | Q22: =SUM(Q5:Q21) -> 167347.83 | T22: =SUM(T5:T21) -> 132452.79
B24: Параметры: доставка — «Регион» по листу «Параметры» справочника материалов; резерв роста цен — закупки равномерно в течение 2027 г., в среднем через 8 мес. после КП → (8 − 2) × 1,25 % = 7,5 %; стоимость денег — закупка без аванса, оплата через ~1,5 мес. → 3 %.

Sheet Цены материалов (источники)
A1: ЦЕНЫ МАТЕРИАЛОВ (ИСТОЧНИКИ)
A2: Цены сайтов с НДС 22 % → ÷ 1,22. Закупка = минимальная цена без НДС. Дата проверки — 28.10.2026.
A4: № | B4: Позиция | C4: Ед. | D4: Магазин 1 | E4: Цена 1 с НДС | F4: URL 1 | G4: Магазин 2 | H4: Цена 2 с НДС | I4: URL 2 | J4: Закупка б/НДС = мин ÷ 1,22 | K4: Розница б/НДС = макс ÷ 1,22 | L4: Отметка
A5: 1 | B5: Извещатель дымовой ИП 212-141 (Рубеж) или аналог | C5: шт | D5: Тинко | E5: 596 | F5: https://www.tinko.ru/catalog/product/208489/ | G5: Сектор СБ | H5: 450 | I5: https://sector-sb.ru/catalog/ops/izveschateli_pojarnye/izveschateli_dymovye/ip_212-141 | J5: =ROUND(MIN(E5,H5)/1.22,2) -> 368.85 | K5: =ROUND(MAX(E5,H5)/1.22,2) -> 488.52 | L5: Замена ИП 212-41М (снят с производства с 2022)
A6: 2 | B6: Извещатель адресный ДИП-34А-04 (Болид) | C6: шт | D6: Юнитрекс | E6: 1802 | F6: https://unitrex.ru/catalog/ohranno-pojarnaya-signalizaciya/integrirovannaya-sistema-orion/adresno-analogovaya-sistema-na-baze-s2000-kdl/dip-34a-04 | G6: Альфа-сети | H6: 1170 | I6: https://alphanets.ru/catalog/bolid-dip-34a-04-dymovoy-optiko-elektronnyy-pozharnyy-izveshc | J6: =ROUND(MIN(E6,H6)/1.22,2) -> 959.02 | K6: =ROUND(MAX(E6,H6)/1.22,2) -> 1477.05 | L6: Мин. цена 1 170 сильно ниже рынка (X-Com 1 841) — проверить
A7: 3 | B7: Извещатель тепловой ИП 103-5/1-А3 | C7: шт | D7: Тинко | E7: 118 | F7: https://www.tinko.ru/catalog/product/005010/ | G7: Тинко-СБ | H7: 106.2 | I7: https://tinko-sb.ru/products/ip-103-5-1-a3-5010/ | J7: =ROUND(MIN(E7,H7)/1.22,2) -> 87.05 | K7: =ROUND(MAX(E7,H7)/1.22,2) -> 96.72
A8: 4 | B8: Извещатель ручной ИПР 513-10 (Рубеж) | C8: шт | D8: Тинко | E8: 388 | F8: https://www.tinko.ru/catalog/product/205151/ | G8: ТК «ИВС» | H8: 387 | I8: https://tkivs.ru/unit.php?id_unit=1147 | J8: =ROUND(MIN(E8,H8)/1.22,2) -> 317.21 | K8: =ROUND(MAX(E8,H8)/1.22,2) -> 318.03
A9: 5 | B9: Извещатель ручной адресный ИПР 513-3АМ (Болид) | C9: шт | D9: Тинко | E9: 1141.92 | F9: https://www.tinko.ru/catalog/product/224799/ | G9: РВН-Групп | H9: 954 | I9: https://rvn-group.ru/catalog/okhranno_pozharnye_sistemy/adresnye_sistemy_bolid/izveshchateli_bolid/22121/ | J9: =ROUND(MIN(E9,H9)/1.22,2) -> 781.97 | K9: =ROUND(MAX(E9,H9)/1.22,2) -> 936
A10: 6 | B10: Оповещатель светозвуковой Маяк-12-КП | C10: шт | D10: Тинко-СБ | E10: 888 | F10: https://tinko-sb.ru/products/mayak-12kp-19230/ | G10: Enex | H10: 673 | I10: https://enex.market/product/kombinirovannyy-svetozvukovoy-opoveshchatel-mayak-12-kp/ | J10: =ROUND(MIN(E10,H10)/1.22,2) -> 551.64 | K10: =ROUND(MAX(E10,H10)/1.22,2) -> 727.87
A11: 7 | B11: Табло «Выход» Молния-12 | C11: шт | D11: Тинко | E11: 356 | F11: https://www.tinko.ru/catalog/product/309882/ | G11: Мегаполис | H11: 345 | I11: https://www.megapolys.com/catalog/tekhnicheskie_sredstva_bezopasnosti/196514/ | J11: =ROUND(MIN(E11,H11)/1.22,2) -> 282.79 | K11: =ROUND(MAX(E11,H11)/1.22,2) -> 291.8
A12: 8 | B12: Оповещатель звуковой Маяк-12-3М | C12: шт | D12: Тинко | E12: 497 | F12: https://www.tinko.ru/catalog/product/200098/ | G12: Радтек | H12: 257 | I12: https://radtek.ru/catalog/pozharnye_opoveshchateli/opoveshchateli_pozharnye_zvukovye/seriya_mayak2/ | J12: =ROUND(MIN(E12,H12)/1.22,2) -> 210.66 | K12: =ROUND(MAX(E12,H12)/1.22,2) -> 407.38 | L12: Мин. цена — страница каталога, проверить
A13: 9 | B13: Аккумулятор 12 В 7 А·ч Delta DTM 1207 | C13: шт | D13: delta-battery.ru | E13: 2002 | F13: https://www.delta-battery.ru/catalog/dtm/delta-dtm-1207/ | G13: СЕК-ГРУПП | H13: 2012 | I13: https://sec-group.ru/p/delta-18539/ | J13: =ROUND(MIN(E13,H13)/1.22,2) -> 1640.98 | K13: =ROUND(MAX(E13,H13)/1.22,2) -> 1649.18 | L13: Парк по ёмкостям — допущение (76 АКБ всего), срок службы 4–5 лет → 25 %/год
A14: 10 | B14: Аккумулятор 12 В 12 А·ч Delta DTM 1212 | C14: шт | D14: DSSL | E14: 3259 | F14: https://www.dssl.ru/products/dtm-1212-akkumulyatornaya-batareya/ | G14: СЕК-ГРУПП | H14: 3662 | I14: https://sec-group.ru/p/delta-18540/ | J14: =ROUND(MIN(E14,H14)/1.22,2) -> 2671.31 | K14: =ROUND(MAX(E14,H14)/1.22,2) -> 3001.64
A15: 11 | B15: Аккумулятор 12 В 17 А·ч Delta DTM 1217 | C15: шт | D15: delta-battery.ru | E15: 4813 | F15: https://www.delta-battery.ru/catalog/dtm/delta-dtm-1217/ | G15: АктивСБ | H15: 4822 | I15: https://www.aktivsb.ru/prod-22791.html | J15: =ROUND(MIN(E15,H15)/1.22,2) -> 3945.08 | K15: =ROUND(MAX(E15,H15)/1.22,2) -> 3952.46
A16: 12 | B16: Аккумулятор 12 В 40 А·ч Delta DTM 1240 L | C16: шт | D16: delta-battery.ru | E16: 13261 | F16: https://www.delta-battery.ru/catalog/dtm-l/delta-dtm-1240-l/ | G16: Сатро-Паладин | H16: 13269.66 | I16: https://satro-paladin.com/catalog/product/15300/ | J16: =ROUND(MIN(E16,H16)/1.22,2) -> 10869.67 | K16: =ROUND(MAX(E16,H16)/1.22,2) -> 10876.77
A17: 13 | B17: Источник питания РИП-12 исп.01 (Болид) | C17: шт | D17: Тинко | E17: 6715.12 | F17: https://www.tinko.ru/catalog/product/008539/ | G17: ЦСБ-Про | H17: 6605.04 | I17: https://www.csbpro.ru/catalog/bolid/rip_12_isp_01_istochnik_pitaniya_12v_3a/ | J17: =ROUND(MIN(E17,H17)/1.22,2) -> 5413.97 | K17: =ROUND(MAX(E17,H17)/1.22,2) -> 5504.2
A18: 14 | B18: Кабель КПСнг(А)-FRLS 1×2×0,75 | C18: м | D18: Тинко | E18: 35.97 | F18: https://www.tinko.ru/catalog/product/216213/ | G18: elgroup24 (ИВКЗ) | H18: 25.92 | I18: https://elgroup24.ru/kpsng-a-frls-series-750/ | J18: =ROUND(MIN(E18,H18)/1.22,2) -> 21.25 | K18: =ROUND(MAX(E18,H18)/1.22,2) -> 29.48 | L18: Мин. — малоизвестный магазин; Тинко 35,97
A19: 15 | B19: Манометр МП-100 0–1,6 МПа | C19: шт | D19: ОСТ-М | E19: 638.37 | F19: https://www.ost-m.ru/catalog/truboprovodnaya_armatura_pribory_ucheta_i_kipia_manometry_i_komplektuyushchie_manometry_tekhnicheskie_mp_100_mp_160/ | G19: Сантур | H19: 804 | I19: https://santur.ru/product/00000002376 | J19: =ROUND(MIN(E19,H19)/1.22,2) -> 523.25 | K19: =ROUND(MAX(E19,H19)/1.22,2) -> 659.02
A20: 16 | B20: Ороситель спринклерный СВН-15 (68 °С) | C20: шт | D20: Сатро-Паладин | E20: 504 | F20: https://satro-paladin.com/catalog/product/107170/ | G20: Спецавтоматика Бийск | H20: 504 | I20: https://sa-biysk.ru/catalog/1368/17147/ | J20: =ROUND(MIN(E20,H20)/1.22,2) -> 413.11 | K20: =ROUND(MAX(E20,H20)/1.22,2) -> 413.11
