Workbook

Sheet КП
A1: КОММЕРЧЕСКОЕ ПРЕДЛОЖЕНИЕ ООО «НЕОСТРОЙ»
A2: Техническое обслуживание установок АПС, АУПТ и СОУЭ производственных подразделений филиала АО «РИР Энерго» — «Воронежская генерация», период оказания услуг: 01.01.2027–31.12.2027 (закупка № 637, лот 1, спецификация 1)
A3: Цены — руб. без НДС; НДС 22 % начисляется на итог. Количество оборудования — по Приложениям 1–8 ТЗ.
A5: № | B5: Наименование услуги / материала | C5: Ед. изм. | D5: Кол-во | E5: Цена за ед. в месяц, руб. без НДС | F5: Стоимость в месяц, руб. без НДС | G5: Кол-во месяцев | H5: Стоимость за период, руб. без НДС | I5: Примечание
A6: 1. | B6: ПП ТЭЦ-1 (ул. Лебедева, 2) — АПС, СОУЭ (Прил. 1)
A7: 1.1 | B7: ТО прибора приёмно-контрольного, пульта, прибора управления (С2000М, Сигнал-20П/10, Гранит, С2000-АСПТ, Рубеж-20П и др.) | C7: шт | D7: 34 | E7: 3620.43 | F7: =ROUND(D7*E7,2) -> 123094.62 | G7: 12 | H7: =F7*G7 -> 1477135.4
A8: 1.2 | B8: ТО блока системы (С2000-КДЛ, СП1/СП2, КПБ, БКИ, ПИ, ПТ, БРИЗ, барьеры искрозащиты и др.) | C8: шт | D8: 12 | E8: 240.35 | F8: =ROUND(D8*E8,2) -> 2884.2 | G8: 12 | H8: =F8*G8 -> 34610.4
A9: 1.3 | B9: ТО источника электропитания резервированного (РИП, Скат, ИВЭПР, ББП) | C9: шт | D9: 9 | E9: 493.35 | F9: =ROUND(D9*E9,2) -> 4440.15 | G9: 12 | H9: =F9*G9 -> 53281.8
A10: 1.4 | B10: ТО аккумуляторной батареи (контроль напряжения и ёмкости) | C10: шт | D10: 21 | E10: 240.35 | F10: =ROUND(D10*E10,2) -> 5047.35 | G10: 12 | H10: =F10*G10 -> 60568.2
A11: 1.5 | B11: ТО извещателя пожарного автоматического точечного (дымового, теплового) | C11: шт | D11: 1318 | E11: 101.2 | F11: =ROUND(D11*E11,2) -> 133381.6 | G11: 12 | H11: =F11*G11 -> 1600579.2
A12: 1.6 | B12: ТО извещателя пожарного пламени (Спектрон, Пульсар, Набат) | C12: шт | D12: 12 | E12: 126.5 | F12: =ROUND(D12*E12,2) -> 1518 | G12: 12 | H12: =F12*G12 -> 18216
A13: 1.7 | B13: ТО извещателя пожарного ручного, УДП, ЭДУ | C13: шт | D13: 144 | E13: 88.55 | F13: =ROUND(D13*E13,2) -> 12751.2 | G13: 12 | H13: =F13*G13 -> 153014.4
A14: 1.8 | B14: ТО оповещателя (светового, звукового, речевого, табло «Выход») | C14: шт | D14: 205 | E14: 123.97 | F14: =ROUND(D14*E14,2) -> 25413.85 | G14: 12 | H14: =F14*G14 -> 304966.2
A15: 1.9 | B15: ТО прибора речевого оповещения СОУЭ (Орфей, Рокот, Соната) | C15: шт | D15: 4 | E15: 1265 | F15: =ROUND(D15*E15,2) -> 5060 | G15: 12 | H15: =F15*G15 -> 60720
A16: 1.10 | B16: ТО шлейфов сигнализации и линий связи (осмотр, измерение параметров) | C16: 100 м | D16: 162.2 | E16: 25.3 | F16: =ROUND(D16*E16,2) -> 4103.66 | G16: 12 | H16: =F16*G16 -> 49243.92
A17: 1.11 | B17: ТО коробок коммутационных/распределительных, шкафов, автоматов питания | C17: шт | D17: 201 | E17: 25.3 | F17: =ROUND(D17*E17,2) -> 5085.3 | G17: 12 | H17: =F17*G17 -> 61023.6
B18: Итого по разделу | F18: =SUM(F7:F17) -> 322779.93 | H18: =SUM(H7:H17) -> 3873359.2
A19: 2. | B19: ПГУ-223 ПП ТЭЦ-1 — АПС, управление АУПТ (Прил. 2)
A20: 2.1 | B20: ТО прибора приёмно-контрольного, пульта, прибора управления (С2000М, Сигнал-20П/10, Гранит, С2000-АСПТ, Рубеж-20П и др.) | C20: шт | D20: 22 | E20: 3620.43 | F20: =ROUND(D20*E20,2) -> 79649.46 | G20: 12 | H20: =F20*G20 -> 955793.52
A21: 2.2 | B21: ТО блока системы (С2000-КДЛ, СП1/СП2, КПБ, БКИ, ПИ, ПТ, БРИЗ, барьеры искрозащиты и др.) | C21: шт | D21: 45 | E21: 240.35 | F21: =ROUND(D21*E21,2) -> 10815.75 | G21: 12 | H21: =F21*G21 -> 129789
A22: 2.3 | B22: ТО источника электропитания резервированного (РИП, Скат, ИВЭПР, ББП) | C22: шт | D22: 26 | E22: 493.35 | F22: =ROUND(D22*E22,2) -> 12827.1 | G22: 12 | H22: =F22*G22 -> 153925.2
A23: 2.4 | B23: ТО аккумуляторной батареи (контроль напряжения и ёмкости) | C23: шт | D23: 35 | E23: 240.35 | F23: =ROUND(D23*E23,2) -> 8412.25 | G23: 12 | H23: =F23*G23 -> 100947
A24: 2.5 | B24: ТО извещателя пожарного автоматического точечного (дымового, теплового) | C24: шт | D24: 436 | E24: 101.2 | F24: =ROUND(D24*E24,2) -> 44123.2 | G24: 12 | H24: =F24*G24 -> 529478.4
A25: 2.6 | B25: ТО извещателя пожарного во взрывозащищённом/искробезопасном исполнении | C25: шт | D25: 12 | E25: 246.68 | F25: =ROUND(D25*E25,2) -> 2960.16 | G25: 12 | H25: =F25*G25 -> 35521.92
A26: 2.7 | B26: ТО извещателя пожарного пламени (Спектрон, Пульсар, Набат) | C26: шт | D26: 14 | E26: 126.5 | F26: =ROUND(D26*E26,2) -> 1771 | G26: 12 | H26: =F26*G26 -> 21252
A27: 2.8 | B27: ТО линейного теплового извещателя (термокабель) | C27: 100 м | D27: 14.2 | E27: 379.5 | F27: =ROUND(D27*E27,2) -> 5388.9 | G27: 12 | H27: =F27*G27 -> 64666.8
A28: 2.9 | B28: ТО извещателя пожарного ручного, УДП, ЭДУ | C28: шт | D28: 201 | E28: 88.55 | F28: =ROUND(D28*E28,2) -> 17798.55 | G28: 12 | H28: =F28*G28 -> 213582.6
A29: 2.10 | B29: ТО извещателя охранного (магнитоконтактного, ИК) в составе систем | C29: шт | D29: 190 | E29: 75.9 | F29: =ROUND(D29*E29,2) -> 14421 | G29: 12 | H29: =F29*G29 -> 173052
A30: 2.11 | B30: ТО оповещателя (светового, звукового, речевого, табло «Выход») | C30: шт | D30: 283 | E30: 123.97 | F30: =ROUND(D30*E30,2) -> 35083.51 | G30: 12 | H30: =F30*G30 -> 421002.12
A31: 2.12 | B31: Сопровождение ПО АРМ «Орион Про» (резервное копирование баз, проверка связи) | C31: к-т | D31: 1 | E31: 4301 | F31: =ROUND(D31*E31,2) -> 4301 | G31: 12 | H31: =F31*G31 -> 51612
A32: 2.13 | B32: ТО шлейфов сигнализации и линий связи (осмотр, измерение параметров) | C32: 100 м | D32: 121.505 | E32: 25.3 | F32: =ROUND(D32*E32,2) -> 3074.08 | G32: 12 | H32: =F32*G32 -> 36888.96
B33: Итого по разделу | F33: =SUM(F20:F32) -> 240625.96 | H33: =SUM(H20:H32) -> 2887511.5
A34: 3. | B34: ПП ТЭЦ-2, старая часть (пр. Ясный, 1а) — АПС, СОУЭ (Прил. 3)
A35: 3.1 | B35: ТО прибора приёмно-контрольного, пульта, прибора управления (С2000М, Сигнал-20П/10, Гранит, С2000-АСПТ, Рубеж-20П и др.) | C35: шт | D35: 22 | E35: 3620.43 | F35: =ROUND(D35*E35,2) -> 79649.46 | G35: 12 | H35: =F35*G35 -> 955793.52
A36: 3.2 | B36: ТО блока системы (С2000-КДЛ, СП1/СП2, КПБ, БКИ, ПИ, ПТ, БРИЗ, барьеры искрозащиты и др.) | C36: шт | D36: 34 | E36: 240.35 | F36: =ROUND(D36*E36,2) -> 8171.9 | G36: 12 | H36: =F36*G36 -> 98062.8
A37: 3.3 | B37: ТО источника электропитания резервированного (РИП, Скат, ИВЭПР, ББП) | C37: шт | D37: 19 | E37: 493.35 | F37: =ROUND(D37*E37,2) -> 9373.65 | G37: 12 | H37: =F37*G37 -> 112483.8
A38: 3.4 | B38: ТО аккумуляторной батареи (контроль напряжения и ёмкости) | C38: шт | D38: 14 | E38: 240.35 | F38: =ROUND(D38*E38,2) -> 3364.9 | G38: 12 | H38: =F38*G38 -> 40378.8
A39: 3.5 | B39: ТО извещателя пожарного автоматического точечного (дымового, теплового) | C39: шт | D39: 773 | E39: 101.2 | F39: =ROUND(D39*E39,2) -> 78227.6 | G39: 12 | H39: =F39*G39 -> 938731.2
A40: 3.6 | B40: ТО извещателя пожарного во взрывозащищённом/искробезопасном исполнении | C40: шт | D40: 25 | E40: 246.68 | F40: =ROUND(D40*E40,2) -> 6167 | G40: 12 | H40: =F40*G40 -> 74004
A41: 3.7 | B41: ТО извещателя пожарного дымового линейного ИПДЛ | C41: к-т | D41: 5 | E41: 506 | F41: =ROUND(D41*E41,2) -> 2530 | G41: 12 | H41: =F41*G41 -> 30360
...

Sheet Помесячно
A1: СТОИМОСТЬ УСЛУГ ПО МЕСЯЦАМ 2027 г. (для актов), руб.
A3: Месяц | B3: Регламентное ТО, б/НДС | C3: Разовые работы, б/НДС | D3: Итого б/НДС | E3: НДС 22 % | F3: Итого с НДС | G3: Состав разовых работ
A4: Январь | B4: =КП!F100 -> 1491515.2 | C4: 0 | D4: =B4+C4 -> 1491515.2 | E4: =ROUND(D4*0.22,2) -> 328133.34 | F4: =D4+E4 -> 1819648.5
A5: Февраль | B5: =КП!F100 -> 1491515.2 | C5: 0 | D5: =B5+C5 -> 1491515.2 | E5: =ROUND(D5*0.22,2) -> 328133.34 | F5: =D5+E5 -> 1819648.5
A6: Март | B6: =КП!F100 -> 1491515.2 | C6: 0 | D6: =B6+C6 -> 1491515.2 | E6: =ROUND(D6*0.22,2) -> 328133.34 | F6: =D6+E6 -> 1819648.5
A7: Апрель | B7: =КП!F100 -> 1491515.2 | C7: 0 | D7: =B7+C7 -> 1491515.2 | E7: =ROUND(D7*0.22,2) -> 328133.34 | F7: =D7+E7 -> 1819648.5
A8: Май | B8: =КП!F100 -> 1491515.2 | C8: 28000 | D8: =B8+C8 -> 1519515.2 | E8: =ROUND(D8*0.22,2) -> 334293.34 | F8: =D8+E8 -> 1853808.5 | G8: Поверка манометров
A9: Июнь | B9: =КП!F100 -> 1491515.2 | C9: 90425 | D9: =B9+C9 -> 1581940.2 | E9: =ROUND(D9*0.22,2) -> 348026.84 | F9: =D9+E9 -> 1929967 | G9: Измерения ЭТЛ (металлосвязь, заземляющие устройства)
A10: Июль | B10: =КП!F100 -> 1491515.2 | C10: 478080 | D10: =B10+C10 -> 1969595.2 | E10: =ROUND(D10*0.22,2) -> 433310.94 | F10: =D10+E10 -> 2402906.1 | G10: Гидроиспытания и промывка ТЭЦ-2 (50 %)
A11: Август | B11: =КП!F100 -> 1491515.2 | C11: 610080 | D11: =B11+C11 -> 2101595.2 | E11: =ROUND(D11*0.22,2) -> 462350.94 | F11: =D11+E11 -> 2563946.1 | G11: Гидроиспытания и промывка ТЭЦ-2 (50 %), опробование с пуском
A12: Сентябрь | B12: =КП!F100 -> 1491515.2 | C12: 0 | D12: =B12+C12 -> 1491515.2 | E12: =ROUND(D12*0.22,2) -> 328133.34 | F12: =D12+E12 -> 1819648.5
A13: Октябрь | B13: =КП!F100 -> 1491515.2 | C13: 0 | D13: =B13+C13 -> 1491515.2 | E13: =ROUND(D13*0.22,2) -> 328133.34 | F13: =D13+E13 -> 1819648.5
A14: Ноябрь | B14: =КП!F100 -> 1491515.2 | C14: 0 | D14: =B14+C14 -> 1491515.2 | E14: =ROUND(D14*0.22,2) -> 328133.34 | F14: =D14+E14 -> 1819648.5
A15: Декабрь | B15: =КП!F100 -> 1491515.2 | C15: 0 | D15: =B15+C15 -> 1491515.2 | E15: =ROUND(D15*0.22,2) -> 328133.34 | F15: =D15+E15 -> 1819648.5
A16: Итого | B16: =SUM(B4:B15) -> 17898182 | C16: =SUM(C4:C15) -> 1206585 | D16: =SUM(D4:D15) -> 19104767 | E16: =SUM(E4:E15) -> 4203048.8 | F16: =SUM(F4:F15) -> 23307816
A18: Материалы ЗИП выставляются дополнительно по факту замены (лимит — раздел ЗИП листа «КП»).
