Workbook
Name VAT_DIV: Параметры!$B$4
Name DELIV: Параметры!$B$5
Name GROWTH: Параметры!$B$6
Name MONEY: Параметры!$B$7
Name P_LOG: Параметры!$B$8
Name P_ITR: Параметры!$B$9
Name P_HOLD: Параметры!$B$10
Name P_WAR: Параметры!$B$11
Name P_RISK: Параметры!$B$12

Sheet Свод
A1: Бюджет себестоимости — OZON склады МСК-2
A3: Статья | B3: Значение
A4: Материалы, с/с | B4: =SUM(Материалы!S4:S800)
A5: Оплата бригадам | B5: =SUM(Работы!L4:L800)
A6: Расходники | B6: =SUM(Работы!M4:M800)
A7: Косвенные | B7: =Косвенные!C9
A8: Полная себестоимость | B8: =B4+B5+B6+B7
A9: КП работ (с косвенными) | B9: =SUM(Работы!Q4:Q800)
A10: КП материалов | B10: =SUM(Материалы!T4:T800)
A11: КП без НДС | B11: =B9+B10
A12: НДС 22 % | B12: =B11*(VAT_DIV-1)
A13: КП с НДС | B13: =B11*VAT_DIV
A14: Наценка на с/с | B14: =IF(B8=0,0,B11/B8-1)
A15: Маржа | B15: =IF(B11=0,0,1-B8/B11)
A16: Диапазон типа тендера | B16: 15% – 25%
A17: Переторжка −5 % (КП б/НДС) | B17: =B11*0.95
A18: Маржа при −5 % | B18: =IF(B17=0,0,1-B8/B17)
A19: Переторжка −10 % (КП б/НДС) | B19: =B11*0.9
A20: Маржа при −10 % | B20: =IF(B19=0,0,1-B8/B19)
A21: Минимальная цена, наценка 15 % | B21: =B8*1.15
A22: Трудоёмкость, чел.-ч | B22: =SUM(Работы!U4:U800)
A23: Проверка: сумма единичных цен × объём | B23: =SUMPRODUCT(Работы!T4:T672,Работы!D4:D672)
A24: Расхождение проверки и КП | B24: =B23-B11
A26: Жёлтые ячейки — ввод. Зелёные — формулы. Объём на листе «Форма», колонка G. Заказчику этот файл не передавать.

Sheet Параметры
A1: Параметры расчёта — жёлтые ячейки можно менять, остальное пересчитается
A3: Параметр | B3: Значение | C3: Что это
A4: НДС, делитель | B4: 1.22 | C4: Цена с НДС делится на это число
A5: Доставка | B5: 0.05 | C5: Подмосковье, доля к закупке
A6: Резерв роста | B6: 0 | C6: 0: закупка под заявку
A7: Стоимость денег | B7: 0.04 | C7: Постоплата около 2 месяцев
A8: Разъезды | B8: 0.1 | C8: Доля от оплаты бригадам
A9: Мастер на заявках | B9: 0.08 | C9: Доля от оплаты бригадам
A10: Удержание цены | B10: 0.04 | C10: Доля от закупки материалов без НДС
A11: Гарантия | B11: 0.015 | C11: Доля от бригады и закупки
A12: Риски склада | B12: 0.03 | C12: Доля от бригады и закупки

Sheet Расходники
A1: Процент расходников к оплате бригаде. Жёлтое можно менять.
A3: Код | B3: Процент | C3: Кто
A4: BET | B4: 0.02 | C4: Бетонщик / арматурщик
A5: BLG | B5: 0.02 | C5: Благоустройство
A6: DER | B6: 0.02 | C6: Дезинфектор (ОЗДС)
A7: DVR | B7: 0.02 | C7: Двери, окна, перегородки
A8: ELM | B8: 0.02 | C8: Электромонтажник
A9: ETL | B9: 0.01 | C9: Электролаборатория / ПНР
A10: FAS | B10: 0.02 | C10: Фасадчик / промальп
A11: HOL | B11: 0.02 | C11: Холодильщик / кондиционеры
A12: KAM | B12: 0.02 | C12: Каменщик
A13: KRO | B13: 0.02 | C13: Кровельщик
A14: NAR | B14: 0.02 | C14: Наружные сети
A15: OTD | B15: 0.03 | C15: Отделочник
... A23: ZEM | B23: 0.01 | C23: Землекоп

Sheet Работы
A1: Работы. Жёлтые — ввод (цена КП, бригада, норма). Объём берётся с листа «Форма».
A3: Артикул | B3: Позиция ВОР | C3: Ед. | D3: Объём | E3: Метка | F3: Код | G3: КП тарифа | H3: Бригада | I3: Норма, чел.-ч | J3: Подтянута | K3: % расходников | L3: Оплата бригаде | M3: Расходники | N3: С/с материалов | O3: Прямая с/с | P3: Косвенные | Q3: КП работ | R3: Работа за ед. | S3: Материалы за ед. | T3: Услуга за ед. | U3: Чел.-ч
A4: 9.1.34 | B4: 2. Гидродинамическим спосбом включая вызов спец.техники | C4: м.п. | D4: =IF('Форма'!G2="","",'Форма'!G2) | E4: точно | F4: SAN | G4: 202 | H4: 125 | I4: 0.08 | K4: =IF(F4="",0,IFERROR(VLOOKUP(F4,Расходники!$A$4:$B$23,2,FALSE),0)) | L4: =H4*D4 | M4: =L4*K4 | N4: =SUMIF(Материалы!$A$4:$A$800,SUBSTITUTE(SUBSTITUTE(SUBSTITUTE(B4,"~","~~"),"*","~*"),"?","~?"),Материалы!$S$4:$S$800) | O4: =L4+M4+N4 | P4: =IF(SUM($O$4:$O$672)=0,0,Косвенные!$C$9*O4/SUM($O$4:$O$672)) | Q4: =G4*D4+P4 | R4: =IF(D4=0,0,Q4/D4) | S4: =IF(D4=0,0,SUMIF(Материалы!$A$4:$A$800,SUBSTITUTE(SUBSTITUTE(SUBSTITUTE(B4,"~","~~"),"*","~*"),"?","~?"),Материалы!$T$4:$T$800)/D4) | T4: =R4+S4 | U4: =I4*D4
A5: 11.2.N1 | B5: 3. Ручным способом с применением спец.инструмента | C5: м.п. | D5: =IF('Форма'!G3="","",'Форма'!G3) | E5: аналог (11.2.N1) | F5: SAN | G5: 288 | H5: 172 | I5: 0.05 | K5: =IF(F5="",0,IFERROR(VLOOKUP(F5,Расходники!$A$4:$B$23,2,FALSE),0)) | L5: =H5*D5 | M5: =L5*K5 | N5: =SUMIF(Материалы!$A$4:$A$800,SUBSTITUTE(SUBSTITUTE(SUBSTITUTE(B5,"~","~~"),"*","~*"),"?","~?"),Материалы!$S$4:$S$800) | O5: =L5+M5+N5 | P5: =IF(SUM($O$4:$O$672)=0,0,Косвенные!$C$9*O5/SUM($O$4:$O$672)) | Q5: =G5*D5+P5 | R5: =IF(D5=0,0,Q5/D5) | S5: =IF(D5=0,0,SUMIF(Материалы!$A$4:$A$800,SUBSTITUTE(SUBSTITUTE(SUBSTITUTE(B5,"~","~~"),"*","~*"),"?","~?"),Материалы!$T$4:$T$800)/D5) | T5: =R5+S5 | U5: =I5*D5
B6: 4. Ручная очистка пескоуловителя объемом до 1м3 включая разбоку и сборку,утилизацию мусора | C6: шт. | D6: =IF('Форма'!G4="","",'Форма'!G4) | E6: нет в тарификаторе | F6: SAN | G6: 6270 | H6: 3060 | I6: 3 | K6: =IF(F6="",0,IFERROR(VLOOKUP(F6,Расходники!$A$4:$B$23,2,FALSE),0)) | L6: =H6*D6 | M6: =L6*K6 | N6: =SUMIF(Материалы!$A$4:$A$800,SUBSTITUTE(SUBSTITUTE(SUBSTITUTE(B6,"~","~~"),"*","~*"),"?","~?"),Материалы!$S$4:$S$800) | O6: =L6+M6+N6 | P6: =IF(SUM($O$4:$O$672)=0,0,Косвенные!$C$9*O6/SUM($O$4:$O$672)) | Q6: =G6*D6+P6 | R6: =IF(D6=0,0,Q6/D6) | S6: =IF(D6=0,0,SUMIF(Материалы!$A$4:$A$800,SUBSTITUTE(SUBSTITUTE(SUBSTITUTE(B6,"~","~~"),"*","~*"),"?","~?"),Материалы!$T$4:$T$800)/D6) | T6: =R6+S6 | U6: =I6*D6
B7: 5. Диагностика и дефектовка: Проверка механизма подъема (пружин или гидравлики), состояния аппарели и шарнирных соединений. | C7: шт. | D7: =IF('Форма'!G5="","",'Форма'!G5) | E7: нет в тарификаторе | F7: VOR | G7: 4710 | H7: 2160 | I7: 1.5 | K7: =IF(F7="",0,IFERROR(VLOOKUP(F7,Расходники!$A$4:$B$23,2,FALSE),0)) | L7: =H7*D7 | M7: =L7*K7 | N7: =SUMIF(Материалы!$A$4:$A$800,SUBSTITUTE(SUBSTITUTE(SUBSTITUTE(B7,"~","~~"),"*","~*"),"?","~?"),Материалы!$S$4:$S$800) | O7: =L7+M7+N7 | P7: =IF(SUM($O$4:$O$672)=0,0,Косвенные!$C$9*O7/SUM($O$4:$O$672)) | Q7: =G7*D7+P7 | R7: =IF(D7=0,0,Q7/D7) | S7: =IF(D7=0,0,SUMIF(Материалы!$A$4:$A$800,SUBSTITUTE(SUBSTITUTE(SUBSTITUTE(B7,"~","~~"),"*","~*"),"?","~?"),Материалы!$T$4:$T$800)/D7) | T7: =R7+S7 | U7: =I7*D7
B8: 6. Восстановление шарниров: Замена осей крепления, шплинтов, втулок и очистка петель от загрязнений. | C8: шт. | D8: =IF('Форма'!G6="","",'Форма'!G6) | E8: нет в тарификаторе | F8: VOR | G8: 6280 | H8: 2880 | I8: 2 | K8: =IF(F8="",0,IFERROR(VLOOKUP(F8,Расходники!$A$4:$B$23,2,FALSE),0)) | L8: =H8*D8 | M8: =L8*K8 | N8: =SUMIF(Материалы!$A$4:$A$800,SUBSTITUTE(SUBSTITUTE(SUBSTITUTE(B8,"~","~~"),"*","~*"),"?","~?"),Материалы!$S$4:$S$800) | O8: =L8+M8+N8 | P8: =IF(SUM($O$4:$O$672)=0,0,Косвенные!$C$9*O8/SUM($O$4:$O$672)) | Q8: =G8*D8+P8 | R8: =IF(D8=0,0,Q8/D8) | S8: =IF(D8=0,0,SUMIF(Материалы!$A$4:$A$800,SUBSTITUTE(SUBSTITUTE(SUBSTITUTE(B8,"~","~~"),"*","~*"),"?","~?"),Материалы!$T$4:$T$800)/D8) | T8: =R8+S8 | U8: =I8*D8
B9: 7. Сварочные работы, усиление или замена листов с противоскользящим покрытием. | C9: шт. | D9: =IF('Форма'!G7="","",'Форма'!G7) | E9: аналог (14.11) | F9: SVA | G9: 6840 | H9: 3240 | I9: 3 | K9: =IF(F9="",0,IFERROR(VLOOKUP(F9,Расходники!$A$4:$B$23,2,FALSE),0)) | L9: =H9*D9 | M9: =L9*K9 | N9: =SUMIF(Материалы!$A$4:$A$800,SUBSTITUTE(SUBSTITUTE(SUBSTITUTE(B9,"~","~~"),"*","~*"),"?","~?"),Материалы!$S$4:$S$800) | O9: =L9+M9+N9 | P9: =IF(SUM($O$4:$O$672)=0,0,Косвенные!$C$9*O9/SUM($O$4:$O$672)) | Q9: =G9*D9+P9 | R9: =IF(D9=0,0,Q9/D9) | S9: =IF(D9=0,0,SUMIF(Материалы!$A$4:$A$800,SUBSTITUTE(SUBSTITUTE(SUBSTITUTE(B9,"~","~~"),"*","~*"),"?","~?"),Материалы!$T$4:$T$800)/D9) | T9: =R9+S9 | U9: =I9*D9
B10: 8. Замена пружин для плавного опускания/поднятия. | C10: шт. | D10: =IF('Форма'!G8="","",'Форма'!G8) | E10: нет в тарификаторе | F10: VOR | G10: 4710 | H10: 2160 | I10: 1.5 | K10: =IF(F10="",0,IFERROR(VLOOKUP(F10,Расходники!$A$4:$B$23,2,FALSE),0)) | L10: =H10*D10 | M10: =L10*K10 | N10: =SUMIF(Материалы!$A$4:$A$800,SUBSTITUTE(SUBSTITUTE(SUBSTITUTE(B10,"~","~~"),"*","~*"),"?","~?"),Материалы!$S$4:$S$800) | O10: =L10+M10+N10 | P10: =IF(SUM($O$4:$O$672)=0,0,Косвенные!$C$9*O10/SUM($O$4:$O$672)) | Q10: =G10*D10+P10 | R10: =IF(D10=0,0,Q10/D10) | S10: =IF(D10=0,0,SUMIF(Материалы!$A$4:$A$800,SUBSTITUTE(SUBSTITUTE(SUBSTITUTE(B10,"~","~~"),"*","~*"),"?","~?"),Материалы!$T$4:$T$800)/D10) | T10: =R10+S10 | U10: =I10*D10
B11: 9. Демонтажные работы, включая резку. | C11: шт. | D11: =IF('Форма'!G9="","",'Форма'!G9) | E11: нет в тарификаторе | F11: SVA | G11: 5700 | H11: 2700 | I11: 2.5 | K11: =IF(F11="",0,IFERROR(VLOOKUP(F11,Расходники!$A$4:$B$23,2,FALSE),0)) | L11: =H11*D11 | M11: =L11*K11 | N11: =SUMIF(Материалы!$A$4:$A$800,SUBSTITUTE(SUBSTITUTE(SUBSTITUTE(B11,"~","~~"),"*","~*"),"?","~?"),Материалы!$S$4:$S$800) | O11: =L11+M11+N11 | P11: =IF(SUM($O$4:$O$672)=0,0,Косвенные!$C$9*O11/SUM($O$4:$O$672)) | Q11: =G11*D11+P11 | R11: =IF(D11=0,0,Q11/D11) | S11: =IF(D11=0,0,SUMIF(Материалы!$A$4:$A$800,SUBSTITUTE(SUBSTITUTE(SUBSTITUTE(B11,"~","~~"),"*","~*"),"?","~?"),Материалы!$T$4:$T$800)/D11) | T11: =R11+S11 | U11: =I11*D11
A12: 9.1.3 | B12: 10. Замена арматуры сливного бачка типа «Компакт» (включая материалы и з/части) | C12: шт. | D12: =IF('Форма'!G10="","",'Форма'!G10) | E12: точно | F12: SAN | G12: 1725 | H12: 1069 | I12: 0.8 | K12: =IF(F12="",0,IFERROR(VLOOKUP(F12,Расходники!$A$4:$B$23,2,FALSE),0)) | L12: =H12*D12 | M12: =L12*K12 | N12: =SUMIF(Материалы!$A$4:$A$800,SUBSTITUTE(SUBSTITUTE(SUBSTITUTE(B12,"~","~~"),"*","~*"),"?","~?"),Материалы!$S$4:$S$800) | O12: =L12+M12+N12 | P12: =IF(SUM($O$4:$O$672)=0,0,Косвенные!$C$9*O12/SUM($O$4:$O$672)) | Q12: =G12*D12+P12 | R12: =IF(D12=0,0,Q12/D12) | S12: =IF(D12=0,0,SUMIF(Материалы!$A$4:$A$800,SUBSTITUTE(SUBSTITUTE(SUBSTITUTE(B12,"~","~~"),"*","~*"),"?","~?"),Материалы!$T$4:$T$800)/D12) | T12: =R12+S12 | U12: =I12*D12
B13: 11. Замена сливного бачка унитаза типа «Компакт» (включая материалы и з/части) | C13: шт. | D13: =IF('Форма'!G11="","",'Форма'!G11) | E13: аналог (9.1.3) | F13: SAN | G13: 2508 | H13: 1224 | I13: 1.2 | K13: =IF(F13="",0,IFERROR(VLOOKUP(F13,Расходники!$A$4:$B$23,2,FALSE),0)) | L13: =H13*D13 | M13: =L13*K13 | N13: =SUMIF(Материалы!$A$4:$A$800,SUBSTITUTE(SUBSTITUTE(SUBSTITUTE(B13,"~","~~"),"*","~*"),"?","~?"),Материалы!$S$4:$S$800) | O13: =L13+M13+N13 | P13: =IF(SUM($O$4:$O$672)=0,0,Косвенные!$C$9*O13/SUM($O$4:$O$672)) | Q13: =G13*D13+P13 | R13: =IF(D13=0,0,Q13/D13) | S13: =IF(D13=0,0,SUMIF(Материалы!$A$4:$A$800,SUBSTITUTE(SUBSTITUTE(SUBSTITUTE(B13,"~","~~"),"*","~*"),"?","~?"),Материалы!$T$4:$T$800)/D13) | T13: =R13+S13 | U13: =I13*D13
A14: 9.1.72 | B14: 12. Замена унитаза типа «Компакт» (включая материалы и з/части) | C14: шт. | D14: =IF('Форма'!G12="","",'Форма'!G12) | E14: точно | F14: SAN | G14: 3220 | H14: 1996 | I14: 2 | K14: =IF(F14="",0,IFERROR(VLOOKUP(F14,Расходники!$A$4:$B$23,2,FALSE),0)) | L14: =H14*D14 | M14: =L14*K14 | N14: =SUMIF(Материалы!$A$4:$A$800,SUBSTITUTE(SUBSTITUTE(SUBSTITUTE(B14,"~","~~"),"*","~*"),"?","~?"),Материалы!$S$4:$S$800) | O14: =L14+M14+N14 | P14: =IF(SUM($O$4:$O$672)=0,0,Косвенные!$C$9*O14/SUM($O$4:$O$672)) | Q14: =G14*D14+P14 | R14: =IF(D14=0,0,Q14/D14) | S14: =IF(D14=0,0,SUMIF(Материалы!$A$4:$A$800,SUBSTITUTE(SUBSTITUTE(SUBSTITUTE(B14,"~","~~"),"*","~*"),"?","~?"),Материалы!$T$4:$T$800)/D14) | T14: =R14+S14 | U14: =I14*D14
B15: 13. Замена гибкой подводки сантехнической до 60 см (включая материалы и з/части) | C15: шт. | D15: =IF('Форма'!G13="","",'Форма'!G13) | E15: аналог (9.2.72) | F15: SAN | G15: 836 | H15: 408 | I15: 0.4 | K15: =IF(F15="",0,IFERROR(VLOOKUP(F15,Расходники!$A$4:$B$23,2,FALSE),0)) | L15: =H15*D15 | M15: =L15*K15 | N15: =SUMIF(Материалы!$A$4:$A$800,SUBSTITUTE(SUBSTITUTE(SUBSTITUTE(B15,"~","~~"),"*","~*"),"?","~?"),Материалы!$S$4:$S$800) | O15: =L15+M15+N15 | P15: =IF(SUM($O$4:$O$672)=0,0,Косвенные!$C$9*O15/SUM($O$4:$O$672)) | Q15: =G15*D15+P15 | R15: =IF(D15=0,0,Q15/D15) | S15: =IF(D15=0,0,SUMIF(Материалы!$A$4:$A$800,SUBSTITUTE(SUBSTITUTE(SUBSTITUTE(B15,"~","~~"),"*","~*"),"?","~?"),Материалы!$T$4:$T$800)/D15) | T15: =R15+S15 | U15: =I15*D15
B16: 14. Замена смесителя раковины (включая материалы и з/части) | C16: шт. | D16: =IF('Форма'!G14="","",'Форма'!G14) | E16: нет в тарификаторе | F16: SAN | G16: 2090 | H16: 1020 | I16: 1 | K16: =IF(F16="",0,IFERROR(VLOOKUP(F16,Расходники!$A$4:$B$23,2,FALSE),0)) | L16: =H16*D16 | M16: =L16*K16 | N16: =SUMIF(Материалы!$A$4:$A$800,SUBSTITUTE(SUBSTITUTE(SUBSTITUTE(B16,"~","~~"),"*","~*"),"?","~?"),Материалы!$S$4:$S$800) | O16: =L16+M16+N16 | P16: =IF(SUM($O$4:$O$672)=0,0,Косвенные!$C$9*O16/SUM($O$4:$O$672)) | Q16: =G16*D16+P16 | R16: =IF(D16=0,0,Q16/D16) | S16: =IF(D16=0,0,SUMIF(Материалы!$A$4:$A$800,SUBSTITUTE(SUBSTITUTE(SUBSTITUTE(B16,"~","~~"),"*","~*"),"?","~?"),Материалы!$T$4:$T$800)/D16) | T16: =R16+S16 | U16: =I16*D16
A17: 9.1.63 | B17: 15. Замена раковины керамической с пьедесталом (включая материалы и з/части) | C17: шт. | D17: =IF('Форма'!G15="","",'Форма'!G15) | E17: точно | F17: SAN | G17: 2300 | H17: 1426 | I17: 1.5 | K17: =IF(F17="",0,IFERROR(VLOOKUP(F17,Расходники!$A$4:$B$23,2,FALSE),0)) | L17: =H17*D17 | M17: =L17*K17 | N17: =SUMIF(Материалы!$A$4:$A$800,SUBSTITUTE(SUBSTITUTE(SUBSTITUTE(B17,"~","~~"),"*","~*"),"?","~?"),Материалы!$S$4:$S$800) | O17: =L17+M17+N17 | P17: =IF(SUM($O$4:$O$672)=0,0,Косвенные!$C$9*O17/SUM($O$4:$O$672)) | Q17: =G17*D17+P17 | R17: =IF(D17=0,0,Q17/D17) | S17: =IF(D17=0,0,SUMIF(Материалы!$A$4:$A$800,SUBSTITUTE(SUBSTITUTE(SUBSTITUTE(B17,"~","~~"),"*","~*"),"?","~?"),Материалы!$T$4:$T$800)/D17) | T17: =R17+S17 | U17: =I17*D17
A18: 9.1.64 | B18: 16. Замена раковины металлической (включая материалы и з/части) | C18: шт. | D18: =IF('Форма'!G16="","",'Форма'!G16) | E18: точно | F18: SAN | G18: 2070 | H18: 1283 | I18: 1.4 | K18: =IF(F18="",0,IFERROR(VLOOKUP(F18,Расходники!$A$4:$B$23,2,FALSE),0)) | L18: =H18*D18 | M18: =L18*K18 | N18: =SUMIF(Материалы!$A$4:$A$800,SUBSTITUTE(SUBSTITUTE(SUBSTITUTE(B18,"~","~~"),"*","~*"),"?","~?"),Материалы!$S$4:$S$800) | O18: =L18+M18+N18 | P18: =IF(SUM($O$4:$O$672)=0,0,Косвенные!$C$9*O18/SUM($O$4:$O$672)) | Q18: =G18*D18+P18 | R18: =IF(D18=0,0,Q18/D18) | S18: =IF(D18=0,0,SUMIF(Материалы!$A$4:$A$800,SUBSTITUTE(SUBSTITUTE(SUBSTITUTE(B18,"~","~~"),"*","~*"),"?","~?"),Материалы!$T$4:$T$800)/D18) | T18: =R18+S18 | U18: =I18*D18
B19: 17. Замена смесителя для ванны с душевой лейкой (включая материалы и з/части) | C19: шт. | D19: =IF('Форма'!G17="","",'Форма'!G17) | E19: нет в тарификаторе | F19: SAN | G19: 2508 | H19: 1224 | I19: 1.2 | K19: =IF(F19="",0,IFERROR(VLOOKUP(F19,Расходники!$A$4:$B$23,2,FALSE),0)) | L19: =H19*D19 | M19: =L19*K19 | N19: =SUMIF(Материалы!$A$4:$A$800,SUBSTITUTE(SUBSTITUTE(SUBSTITUTE(B19,"~","~~"),"*","~*"),"?","~?"),Материалы!$S$4:$S$800) | O19: =L19+M19+N19 | P19: =IF(SUM($O$4:$O$672)=0,0,Косвенные!$C$9*O19/SUM($O$4:$O$672)) | Q19: =G19*D19+P19 | R19: =IF(D19=0,0,Q19/D19) | S19: =IF(D19=0,0,SUMIF(Материалы!$A$4:$A$800,SUBSTITUTE(SUBSTITUTE(SUBSTITUTE(B19,"~","~~"),"*","~*"),"?","~?"),Материалы!$T$4:$T$800)/D19) | T19: =R19+S19 | U19: =I19*D19
B20: 18. Замена душевого поддона 90*90 см (включая материалы и з/части) | C20: шт. | D20: =IF('Форма'!G18="","",'Форма'!G18) | E20: нет в тарификаторе | F20: SAN | G20: 1672 | H20: 816 | I20: 0.8 | K20: =IF(F20="",0,IFERROR(VLOOKUP(F20,Расходники!$A$4:$B$23,2,FALSE),0)) | L20: =H20*D20 | M20: =L20*K20 | N20: =SUMIF(Материалы!$A$4:$A$800,SUBSTITUTE(SUBSTITUTE(SUBSTITUTE(B20,"~","~~"),"*","~*"),"?","~?"),Материалы!$S$4:$S$800) | O20: =L20+M20+N20 | P20: =IF(SUM($O$4:$O$672)=0,0,Косвенные!$C$9*O20/SUM($O$4:$O$672)) | Q20: =G20*D20+P20 | R20: =IF(D20=0,0,Q20/D20) | S20: =IF(D20=0,0,SUMIF(Материалы!$A$4:$A$800,SUBSTITUTE(SUBSTITUTE(SUBSTITUTE(B20,"~","~~"),"*","~*"),"?","~?"),Материалы!$T$4:$T$800)/D20) | T20: =R20+S20 | U20: =I20*D20
A21: 9.1.64 | B21: 19. Замена сифона раковины (включая материалы и з/части) | C21: шт. | D21: =IF('Форма'!G19="","",'Форма'!G19) | E21: точно | F21: SAN | G21: 2070 | H21: 1283 | I21: 1.4 | K21: =IF(F21="",0,IFERROR(VLOOKUP(F21,Расходники!$A$4:$B$23,2,FALSE),0)) | L21: =H21*D21 | M21: =L21*K21 | N21: =SUMIF(Материалы!$A$4:$A$800,SUBSTITUTE(SUBSTITUTE(SUBSTITUTE(B21,"~","~~"),"*","~*"),"?","~?"),Материалы!$S$4:$S$800) | O21: =L21+M21+N21 | P21: =IF(SUM($O$4:$O$672)=0,0,Косвенные!$C$9*O21/SUM($O$4:$O$672)) | Q21: =G21*D21+P21 | R21: =IF(D21=0,0,Q21/D21) | S21: =IF(D21=0,0,SUMIF(Материалы!$A$4:$A$800,SUBSTITUTE(SUBSTITUTE(SUBSTITUTE(B21,"~","~~"),"*","~*"),"?","~?"),Материалы!$T$4:$T$800)/D21) | T21: =R21+S21 | U21: =I21*D21
B22: 20. Замена крана писсуара (включая материалы и з/части) | C22: шт. | D22: =IF('Форма'!G20="","",'Форма'!G20) | E22: аналог (9.1.N12) | F22: SAN | G22: 1672 | H22: 816 | I22: 0.8 | K22: =IF(F22="",0,IFERROR(VLOOKUP(F22,Расходники!$A$4:$B$23,2,FALSE),0)) | L22: =H22*D22 | M22: =L22*K22 | N22: =SUMIF(Материалы!$A$4:$A$800,SUBSTITUTE(SUBSTITUTE(SUBSTITUTE(B22,"~","~~"),"*","~*"),"?","~?"),Материалы!$S$4:$S$800) | O22: =L22+M22+N22 | P22: =IF(SUM($O$4:$O$672)=0,0,Косвенные!$C$9*O22/SUM($O$4:$O$672)) | Q22: =G22*D22+P22 | R22: =IF(D22=0,0,Q22/D22) | S22: =IF(D22=0,0,SUMIF(Материалы!$A$4:$A$800,SUBSTITUTE(SUBSTITUTE(SUBSTITUTE(B22,"~","~~"),"*","~*"),"?","~?"),Материалы!$T$4:$T$800)/D22) | T22: =R22+S22 | U22: =I22*D22
A23: 9.4.37 | B23: 21. Прокладка трубопровода ХВС, ГВС из полипропиленовых труб Ø20-32 мм (включая материалы, комплетующие и з/части) за 1 п.м. | C23: м.п. | D23: =IF('Форма'!G21="","",'Форма'!G21) | E23: точно | F23: SAN | G23: 483 | H23: 299 | I23: 0.3 | K23: =IF(F23="",0,IFERROR(VLOOKUP(F23,Расходники!$A$4:$B$23,2,FALSE),0)) | L23: =H23*D23 | M23: =L23*K23 | N23: =SUMIF(Материалы!$A$4:$A$800,SUBSTITUTE(SUBSTITUTE(SUBSTITUTE(B23,"~","~~"),"*","~*"),"?","~?"),Материалы!$S$4:$S$800) | O23: =L23+M23+N23 | P23: =IF(SUM($O$4:$O$672)=0,0,Косвенные!$C$9*O23/SUM($O$4:$O$672)) | Q23: =G23*D23+P23 | R23: =IF(D23=0,0,Q23/D23) | S23: =IF(D23=0,0,SUMIF(Материалы!$A$4:$A$800,SUBSTITUTE(SUBSTITUTE(SUBSTITUTE(B23,"~","~~"),"*","~*"),"?","~?"),Материалы!$T$4:$T$800)/D23) | T23: =R23+S23 | U23: =I23*D23
B24: 22. Прокладка трубопровода внутренней канализации Ø40 мм (включая материалы и з/части) за 1 п.м. | C24: м.п. | D24: =IF('Форма'!G22="","",'Форма'!G22) | E24: аналог (9.4.35) | F24: SAN | G24: 585.2 | H24: 285.6 | I24: 0.28 | K24: =IF(F24="",0,IFERROR(VLOOKUP(F24,Расходники!$A$4:$B$23,2,FALSE),0)) | L24: =H24*D24 | M24: =L24*K24 | N24: =SUMIF(Материалы!$A$4:$A$800,SUBSTITUTE(SUBSTITUTE(SUBSTITUTE(B24,"~","~~"),"*","~*"),"?","~?"),Материалы!$S$4:$S$800) | O24: =L24+M24+N24 | P24: =IF(SUM($O$4:$O$672)=0,0,Косвенные!$C$9*O24/SUM($O$4:$O$672)) | Q24: =G24*D24+P24 | R24: =IF(D24=0,0,Q24/D24) | S24: =IF(D24=0,0,SUMIF(Материалы!$A$4:$A$800,SUBSTITUTE(SUBSTITUTE(SUBSTITUTE(B24,"~","~~"),"*","~*"),"?","~?"),Материалы!$T$4:$T$800)/D24) | T24: =R24+S24 | U24: =I24*D24
B25: 23. Прокладка трубопровода внутренней канализации Ø50 мм (включая материалы и з/части) за 1 п.м. | C25: м.п. | D25: =IF('Форма'!G23="","",'Форма'!G23) | E25: аналог (9.4.35) | F25: SAN | G25: 585.2 | H25: 285.6 | I25: 0.28 | K25: =IF(F25="",0,IFERROR(VLOOKUP(F25,Расходники!$A$4:$B$23,2,FALSE),0)) | L25: =H25*D25 | M25: =L25*K25 | N25: =SUMIF(Материалы!$A$4:$A$800,SUBSTITUTE(SUBSTITUTE(SUBSTITUTE(B25,"~","~~"),"*","~*"),"?","~?"),Материалы!$S$4:$S$800) | O25: =L25+M25+N25 | P25: =IF(SUM($O$4:$O$672)=0,0,Косвенные!$C$9*O25/SUM($O$4:$O$672)) | Q25: =G25*D25+P25 | R25: =IF(D25=0,0,Q25/D25) | S25: =IF(D25=0,0,SUMIF(Материалы!$A$4:$A$800,SUBSTITUTE(SUBSTITUTE(SUBSTITUTE(B25,"~","~~"),"*","~*"),"?","~?"),Материалы!$T$4:$T$800)/D25) | T25: =R25+S25 | U25: =I25*D25
B26: 24. Прокладка трубопровода внутренней канализации Ø100 мм (включая материалы и з/части) за 1 п.м. | C26: м.п. | D26: =IF('Форма'!G24="","",'Форма'!G24) | E26: аналог (9.4.35) | F26: SAN | G26: 585.2 | H26: 285.6 | I26: 0.28 | K26: =IF(F26="",0,IFERROR(VLOOKUP(F26,Расходники!$A$4:$B$23,2,FALSE),0)) | L26: =H26*D26 | M26: =L26*K26 | N26: =SUMIF(Материалы!$A$4:$A$800,SUBSTITUTE(SUBSTITUTE(SUBSTITUTE(B26,"~","~~"),"*","~*"),"?","~?"),Материалы!$S$4:$S$800) | O26: =L26+M26+N26 | P26: =IF(SUM($O$4:$O$672)=0,0,Косвенные!$C$9*O26/SUM($O$4:$O$672)) | Q26: =G26*D26+P26 | R26: =IF(D26=0,0,Q26/D26) | S26: =IF(D26=0,0,SUMIF(Материалы!$A$4:$A$800,SUBSTITUTE(SUBSTITUTE(SUBSTITUTE(B26,"~","~~"),"*","~*"),"?","~?"),Материалы!$T$4:$T$800)/D26) | T26: =R26+S26 | U26: =I26*D26
B27: 25. Устранение протечек в сантехническом оборудовании (включая материалы и з/части) за 1 ед. | C27: шт. | D27: =IF('Форма'!G25="","",'Форма'!G25) | E27: нет в тарификаторе | F27: SAN | G27: 2090 | H27: 1020 | I27: 1 | K27: =IF(F27="",0,IFERROR(VLOOKUP(F27,Расходники!$A$4:$B$23,2,FALSE),0)) | L27: =H27*D27 | M27: =L27*K27 | N27: =SUMIF(Материалы!$A$4:$A$800,SUBSTITUTE(SUBSTITUTE(SUBSTITUTE(B27,"~","~~"),"*","~*"),"?","~?"),Материалы!$S$4:$S$800) | O27: =L27+M27+N27 | P27: =IF(SUM($O$4:$O$672)=0,0,Косвенные!$C$9*O27/SUM($O$4:$O$672)) | Q27: =G27*D27+P27 | R27: =IF(D27=0,0,Q27/D27) | S27: =IF(D27=0,0,SUMIF(Материалы!$A$4:$A$800,SUBSTITUTE(SUBSTITUTE(SUBSTITUTE(B27,"~","~~"),"*","~*"),"?","~?"),Материалы!$T$4:$T$800)/D27) | T27: =R27+S27 | U27: =I27*D27
A28: 9.4.N1 | B28: 26. Замена запорной арматуры трубопроводов (включая материалы и з/части) за 1 ед. | C28: шт. | D28: =IF('Форма'!G26="","",'Форма'!G26) | E28: точно | F28: SAN | G28: 1380 | H28: 856 | I28: 0.8 | K28: =IF(F28="",0,IFERROR(VLOOKUP(F28,Расходники!$A$4:$B$23,2,FALSE),0)) | L28: =H28*D28 | M28: =L28*K28 | N28: =SUMIF(Материалы!$A$4:$A$800,SUBSTITUTE(SUBSTITUTE(SUBSTITUTE(B28,"~","~~"),"*","~*"),"?","~?"),Материалы!$S$4:$S$800) | O28: =L28+M28+N28 | P28: =IF(SUM($O$4:$O$672)=0,0,Косвенные!$C$9*O28/SUM($O$4:$O$672)) | Q28: =G28*D28+P28 | R28: =IF(D28=0,0,Q28/D28) | S28: =IF(D28=0,0,SUMIF(Материалы!$A$4:$A$800,SUBSTITUTE(SUBSTITUTE(SUBSTITUTE(B28,"~","~~"),"*","~*"),"?","~?"),Материалы!$T$4:$T$800)/D28) | T28: =R28+S28 | U28: =I28*D28
B29: 27. Подключение к системе ХВС, ГВС приборов (водонагреватель, кулер, пурифайр, стиральная машинка и т.д.) (включая материалы, комплектующие, фитинги, з/части и т.д.) за 1 ед. | C29: шт. | D29: =IF('Форма'!G27="","",'Форма'!G27) | E29: нет в тарификаторе | F29: SAN | G29: 2508 | H29: 1224 | I29: 1.2 | K29: =IF(F29="",0,IFERROR(VLOOKUP(F29,Расходники!$A$4:$B$23,2,FALSE),0)) | L29: =H29*D29 | M29: =L29*K29 | N29: =SUMIF(Материалы!$A$4:$A$800,SUBSTITUTE(SUBSTITUTE(SUBSTITUTE(B29,"~","~~"),"*","~*"),"?","~?"),Материалы!$S$4:$S$800) | O29: =L29+M29+N29 | P29: =IF(SUM($O$4:$O$672)=0,0,Косвенные!$C$9*O29/SUM($O$4:$O$672)) | Q29: =G29*D29+P29 | R29: =IF(D29=0,0,Q29/D29) | S29: =IF(D29=0,0,SUMIF(Материалы!$A$4:$A$800,SUBSTITUTE(SUBSTITUTE(SUBSTITUTE(B29,"~","~~"),"*","~*"),"?","~?"),Материалы!$T$4:$T$800)/D29) | T29: =R29+S29 | U29: =I29*D29
B30: 28. Стоимость нормо-часа для работ, не вошедших в основной перечень | C30: н/час | D30: =IF('Форма'!G28="","",'Форма'!G28) | E30: нет в тарификаторе | F30: SAN | G30: 2090 | H30: 1020 | I30: 1 | K30: =IF(F30="",0,IFERROR(VLOOKUP(F30,Расходники!$A$4:$B$23,2,FALSE),0)) | L30: =H30*D30 | M30: =L30*K30 | N30: =SUMIF(Материалы!$A$4:$A$800,SUBSTITUTE(SUBSTITUTE(SUBSTITUTE(B30,"~","~~"),"*","~*"),"?","~?"),Материалы!$S$4:$S$800) | O30: =L30+M30+N30 | P30: =IF(SUM($O$4:$O$672)=0,0,Косвенные!$C$9*O30/SUM($O$4:$O$672)) | Q30: =G30*D30+P30 | R30: =IF(D30=0,0,Q30/D30) | S30: =IF(D30=0,0,SUMIF(Материалы!$A$4:$A$800,SUBSTITUTE(SUBSTITUTE(SUBSTITUTE(B30,"~","~~"),"*","~*"),"?","~?"),Материалы!$T$4:$T$800)/D30) | T30: =R30+S30 | U30: =I30*D30
B31: 29. Планка примыкания верхняя, нижняя 150 х 250 с полимерным покрытием по RAL по согласованию | C31: п.м | D31: =IF('Форма'!G29="","",'Форма'!G29) | E31: аналог (6.2.5) | F31: KRO | G31: 452.5 | H31: 237.5 | I31: 0.25 | K31: =IF(F31="",0,IFERROR(VLOOKUP(F31,Расходники!$A$4:$B$23,2,FALSE),0)) | L31: =H31*D31 | M31: =L31*K31 | N31: =SUMIF(Материалы!$A$4:$A$800,SUBSTITUTE(SUBSTITUTE(SUBSTITUTE(B31,"~","~~"),"*","~*"),"?","~?"),Материалы!$S$4:$S$800) | O31: =L31+M31+N31 | P31: =IF(SUM($O$4:$O$672)=0,0,Косвенные!$C$9*O31/SUM($O$4:$O$672)) | Q31: =G31*D31+P31 | R31: =IF(D31=0,0,Q31/D31) | S31: =IF(D31=0,0,SUMIF(Материалы!$A$4:$A$800,SUBSTITUTE(SUBSTITUTE(SUBSTITUTE(B31,"~","~~"),"*","~*"),"?","~?"),Материалы!$T$4:$T$800)/D31) | T31: =R31+S31 | U31: =I31*D31
A32: 5.5.2 | B32: 30. Монтаж профлиста С8-115 - 0,50 окрашенный | C32: м2 | D32: =IF('Форма'!G30="","",'Форма'!G30) | E32: аналог (5.5.2) по готовому каркасу | F32: FAS | G32: 600 | H32: 350 | I32: 0.3 | K32: =IF(F32="",0,IFERROR(VLOOKUP(F32,Расходники!$A$4:$B$23,2,FALSE),0)) | L32: =H32*D32 | M32: =L32*K32 | N32: =SUMIF(Материалы!$A$4:$A$800,SUBSTITUTE(SUBSTITUTE(SUBSTITUTE(B32,"~","~~"),"*","~*"),"?","~?"),Материалы!$S$4:$S$800) | O32: =L32+M32+N32 | P32: =IF(SUM($O$4:$O$672)=0,0,Косвенные!$C$9*O32/SUM($O$4:$O$672)) | Q32: =G32*D32+P32 | R32: =IF(D32=0,0,Q32/D32) | S32: =IF(D32=0,0,SUMIF(Материалы!$A$4:$A$800,SUBSTITUTE(SUBSTITUTE(SUBSTITUTE(B32,"~","~~"),"*","~*"),"?","~?"),Материалы!$T$4:$T$800)/D32) | T32: =R32+S32 | U32: =I32*D32
A33: 5.5.2 | B33: 31. Монтаж профлиста С8, 0,45мм | C33: м2 | D33: =IF('Форма'!G31="","",'Форма'!G31) | E33: аналог (5.5.2) по готовому каркасу | F33: FAS | G33: 600 | H33: 350 | I33: 0.3 | K33: =IF(F33="",0,IFERROR(VLOOKUP(F33,Расходники!$A$4:$B$23,2,FALSE),0)) | L33: =H33*D33 | M33: =L33*K33 | N33: =SUMIF(Материалы!$A$4:$A$800,SUBSTITUTE(SUBSTITUTE(SUBSTITUTE(B33,"~","~~"),"*","~*"),"?","~?"),Материалы!$S$4:$S$800) | O33: =L33+M33+N33 | P33: =IF(SUM($O$4:$O$672)=0,0,Косвенные!$C$9*O33/SUM($O$4:$O$672)) | Q33: =G33*D33+P33 | R33: =IF(D33=0,0,Q33/D33) | S33: =IF(D33=0,0,SUMIF(Материалы!$A$4:$A$800,SUBSTITUTE(SUBSTITUTE(SUBSTITUTE(B33,"~","~~"),"*","~*"),"?","~?"),Материалы!$T$4:$T$800)/D33) | T33: =R33+S33 | U33: =I33*D33
A34: 5.5.2 | B34: 32. Монтаж профлиста С20, 0,45мм | C34: м2 | D34: =IF('Форма'!G32="","",'Форма'!G32) | E34: аналог (5.5.2) по готовому каркасу | F34: FAS | G34: 600 | H34: 350 | I34: 0.3 | K34: =IF(F34="",0,IFERROR(VLOOKUP(F34,Расходники!$A$4:$B$23,2,FALSE),0)) | L34: =H34*D34 | M34: =L34*K34 | N34: =SUMIF(Материалы!$A$4:$A$800,SUBSTITUTE(SUBSTITUTE(SUBSTITUTE(B34,"~","~~"),"*","~*"),"?","~?"),Материалы!$S$4:$S$800) | O34: =L34+M34+N34 | P34: =IF(SUM($O$4:$O$672)=0,0,Косвенные!$C$9*O34/SUM($O$4:$O$672)) | Q34: =G34*D34+P34 | R34: =IF(D34=0,0,Q34/D34) | S34: =IF(D34=0,0,SUMIF(Материалы!$A$4:$A$800,SUBSTITUTE(SUBSTITUTE(SUBSTITUTE(B34,"~","~~"),"*","~*"),"?","~?"),Материалы!$T$4:$T$800)/D34) | T34: =R34+S34 | U34: =I34*D34
B35: 33. Поручни из нержавеющей стали ( с 3 ригелями ) | C35: м.п. | D35: =IF('Форма'!G33="","",'Форма'!G33) | E35: аналог (5.1.10) | F35: SVA | G35: 1824 | H35: 864 | I35: 0.8 | K35: =IF(F35="",0,IFERROR(VLOOKUP(F35,Расходники!$A$4:$B$23,2,FALSE),0)) | L35: =H35*D35 | M35: =L35*K35 | N35: =SUMIF(Материалы!$A$4:$A$800,SUBSTITUTE(SUBSTITUTE(SUBSTITUTE(B35,"~","~~"),"*","~*"),"?","~?"),Материалы!$S$4:$S$800) | O35: =L35+M35+N35 | P35: =IF(SUM($O$4:$O$672)=0,0,Косвенные!$C$9*O35/SUM($O$4:$O$672)) | Q35: =G35*D35+P35 | R35: =IF(D35=0,0,Q35/D35) | S35: =IF(D35=0,0,SUMIF(Материалы!$A$4:$A$800,SUBSTITUTE(SUBSTITUTE(SUBSTITUTE(B35,"~","~~"),"*","~*"),"?","~?"),Материалы!$T$4:$T$800)/D35) | T35: =R35+S35 | U35: =I35*D35
B36: 34. Поручни из нержавеющей стали ( с 2 ригелями, с двойным ) | C36: м.п. | D36: =IF('Форма'!G34="","",'Форма'!G34) | E36: аналог (5.1.10) | F36: SVA | G36: 1824 | H36: 864 | I36: 0.8 | K36: =IF(F36="",0,IFERROR(VLOOKUP(F36,Расходники!$A$4:$B$23,2,FALSE),0)) | L36: =H36*D36 | M36: =L36*K36 | N36: =SUMIF(Материалы!$A$4:$A$800,SUBSTITUTE(SUBSTITUTE(SUBSTITUTE(B36,"~","~~"),"*","~*"),"?","~?"),Материалы!$S$4:$S$800) | O36: =L36+M36+N36 | P36: =IF(SUM($O$4:$O$672)=0,0,Косвенные!$C$9*O36/SUM($O$4:$O$672)) | Q36: =G36*D36+P36 | R36: =IF(D36=0,0,Q36/D36) | S36: =IF(D36=0,0,SUMIF(Материалы!$A$4:$A$800,SUBSTITUTE(SUBSTITUTE(SUBSTITUTE(B36,"~","~~"),"*","~*"),"?","~?"),Материалы!$T$4:$T$800)/D36) | T36: =R36+S36 | U36: =I36*D36
A37: 7.2.25 | B37: 35. Керамогранит 300х300х8 мм типа "Эстима" (цвет белый )RW-01 (вкл. За основу клей, грунтовку, затирку швов) | C37: м2 | D37: =IF('Форма'!G35="","",'Форма'!G35) | E37: точно | F37: PLI | G37: 2160 | H37: 1150 | I37: 1.5 | J37: да | K37: =IF(F37="",0,IFERROR(VLOOKUP(F37,Расходники!$A$4:$B$23,2,FALSE),0)) | L37: =H37*D37 | M37: =L37*K37 | N37: =SUMIF(Материалы!$A$4:$A$800,SUBSTITUTE(SUBSTITUTE(SUBSTITUTE(B37,"~","~~"),"*","~*"),"?","~?"),Материалы!$S$4:$S$800) | O37: =L37+M37+N37 | P37: =IF(SUM($O$4:$O$672)=0,0,Косвенные!$C$9*O37/SUM($O$4:$O$672)) | Q37: =G37*D37+P37 | R37: =IF(D37=0,0,Q37/D37) | S37: =IF(D37=0,0,SUMIF(Материалы!$A$4:$A$800,SUBSTITUTE(SUBSTITUTE(SUBSTITUTE(B37,"~","~~"),"*","~*"),"?","~?"),Материалы!$T$4:$T$800)/D37) | T37: =R37+S37 | U37: =I37*D37
A38: 7.2.25 | B38: 36. Керамогранит 400х400х9 мм типа "Эстима" (цвет белый))RW-01 (вкл. За основу клей, грунтовку, затирку швов) | C38: м2 | D38: =IF('Форма'!G36="","",'Форма'!G36) | E38: точно | F38: PLI | G38: 2160 | H38: 1150 | I38: 1.5 | J38: да | K38: =IF(F38="",0,IFERROR(VLOOKUP(F38,Расходники!$A$4:$B$23,2,FALSE),0)) | L38: =H38*D38 | M38: =L38*K38 | N38: =SUMIF(Материалы!$A$4:$A$800,SUBSTITUTE(SUBSTITUTE(SUBSTITUTE(B38,"~","~~"),"*","~*"),"?","~?"),Материалы!$S$4:$S$800) | O38: =L38+M38+N38 | P38: =IF(SUM($O$4:$O$672)=0,0,Косвенные!$C$9*O38/SUM($O$4:$O$672)) | Q38: =G38*D38+P38 | R38: =IF(D38=0,0,Q38/D38) | S38: =IF(D38=0,0,SUMIF(Материалы!$A$4:$A$800,SUBSTITUTE(SUBSTITUTE(SUBSTITUTE(B38,"~","~~"),"*","~*"),"?","~?"),Материалы!$T$4:$T$800)/D38) | T38: =R38+S38 | U38: =I38*D38
A39: 7.2.25 | B39: 37. Керамогранит 600х600х10 мм типа "Эстима" (цвет белый))RW-01 (вкл. За основу клей, грунтовку, затирку швов) | C39: м2 | D39: =IF('Форма'!G37="","",'Форма'!G37) | E39: точно | F39: PLI | G39: 2160 | H39: 1150 | I39: 1.5 | J39: да | K39: =IF(F39="",0,IFERROR(VLOOKUP(F39,Расходники!$A$4:$B$23,2,FALSE),0)) | L39: =H39*D39 | M39: =L39*K39 | N39: =SUMIF(Материалы!$A$4:$A$800,SUBSTITUTE(SUBSTITUTE(SUBSTITUTE(B39,"~","~~"),"*","~*"),"?","~?"),Материалы!$S$4:$S$800) | O39: =L39+M39+N39 | P39: =IF(SUM($O$4:$O$672)=0,0,Косвенные!$C$9*O39/SUM($O$4:$O$672)) | Q39: =G39*D39+P39 | R39: =IF(D39=0,0,Q39/D39) | S39: =IF(D39=0,0,SUMIF(Материалы!$A$4:$A$800,SUBSTITUTE(SUBSTITUTE(SUBSTITUTE(B39,"~","~~"),"*","~*"),"?","~?"),Материалы!$T$4:$T$800)/D39) | T39: =R39+S39 | U39: =I39*D39
A40: 7.2.25 | B40: 38. Плитка керамогранита 200*200*12 мм типа "Эстима" (цвет-серый ) ST-101 (вкл. За основу клей, грунтовку, затирку швов) | C40: м2 | D40: =IF('Форма'!G38="","",'Форма'!G38) | E40: точно | F40: PLI | G40: 2160 | H40: 1150 | I40: 1.5 | J40: да | K40: =IF(F40="",0,IFERROR(VLOOKUP(F40,Расходники!$A$4:$B$23,2,FALSE),0)) | L40: =H40*D40 | M40: =L40*K40 | N40: =SUMIF(Материалы!$A$4:$A$800,SUBSTITUTE(SUBSTITUTE(SUBSTITUTE(B40,"~","~~"),"*","~*"),"?","~?"),Материалы!$S$4:$S$800) | O40: =L40+M40+N40 | P40: =IF(SUM($O$4:$O$672)=0,0,Косвенные!$C$9*O40/SUM($O$4:$O$672)) | Q40: =G40*D40+P40 | R40: =IF(D40=0,0,Q40/D40) | S40: =IF(D40=0,0,SUMIF(Материалы!$A$4:$A$800,SUBSTITUTE(SUBSTITUTE(SUBSTITUTE(B40,"~","~~"),"*","~*"),"?","~?"),Материалы!$T$4:$T$800)/D40) | T40: =R40+S40 | U40: =I40*D40
A41: 7.2.25 | B41: 39. Плитка керамогранита 300*300*12 мм типа "Эстима" (цвет-серый ) ST-101 (вкл. За основу клей, грунтовку, затирку швов) | C41: м2 | D41: =IF('Форма'!G39="","",'Форма'!G39) | E41: точно | F41: PLI | G41: 2160 | H41: 1150 | I41: 1.5 | J41: да | K41: =IF(F41="",0,IFERROR(VLOOKUP(F41,Расходники!$A$4:$B$23,2,FALSE),0)) | L41: =H41*D41 | M41: =L41*K41 | N41: =SUMIF(Материалы!$A$4:$A$800,SUBSTITUTE(SUBSTITUTE(SUBSTITUTE(B41,"~","~~"),"*","~*"),"?","~?"),Материалы!$S$4:$S$800) | O41: =L41+M41+N41 | P41: =IF(SUM($O$4:$O$672)=0,0,Косвенные!$C$9*O41/SUM($O$4:$O$672)) | Q41: =G41*D41+P41 | R41: =IF(D41=0,0,Q41/D41) | S41: =IF(D41=0,0,SUMIF(Материалы!$A$4:$A$800,SUBSTITUTE(SUBSTITUTE(SUBSTITUTE(B41,"~","~~"),"*","~*"),"?","~?"),Материалы!$T$4:$T$800)/D41) | T41: =R41+S41 | U41: =I41*D41
...

Sheet Материалы
A1: Материалы. Жёлтые — ввод. Кол-во = норма на единицу работы × объём этой работы.
A3: К работе | B3: Материал | C3: Категория | D3: Ед. | E3: Норма на ед. | F3: Кол-во | G3: Цена источника | H3: НДС в цене (1/0) | I3: Отходы | J3: Наценка | K3: Розница с НДС | L3: Магазин | M3: Ссылка | N3: Дата | O3: Примечание | P3: Закупка б/НДС | Q3: С/с ед. | R3: Цена КП ед. | S3: С/с итого | T3: КП итого | U3: Выше розницы | V3: Закупка итого б/НДС
A4: 6. Восстановление шарниров: Замена осей крепления, шплинтов, втулок и очистка петель от загрязнений. | B4: Оси, втулки, шплинты доклевеллера, комплект | C4: Металлопрокат и метизы | D4: компл | E4: 1 | F4: =E4*IFERROR(INDEX(Работы!$D$4:$D$672,MATCH(SUBSTITUTE(SUBSTITUTE(SUBSTITUTE(A4,"~","~~"),"*","~*"),"?","~?"),Работы!$B$4:$B$672,0)),0) | G4: 1800 | H4: 1 | I4: 0.05 | J4: 0.1 | L4: оценка | N4: 2026-10-29 | O4: оценка комплекта шарнира, запросить DoorHan В Петрович, Лемана ПРО и Сатурн открытой карточки нет, оставлен прежний источник. | P4: =IF(H4=1,G4/VAT_DIV,G4) | Q4: =P4*(1+I4)*(1+DELIV)*(1+GROWTH+MONEY) | R4: =IF(AND(K4<>"",Q4*(1+J4)>K4/VAT_DIV),K4/VAT_DIV,Q4*(1+J4)) | S4: =Q4*F4 | T4: =R4*F4 | U4: =IF(AND(K4<>"",Q4*(1+J4)>K4/VAT_DIV+0.01),"ДА","") | V4: =P4*F4
A5: 7. Сварочные работы, усиление или замена листов с противоскользящим покрытием. | B5: Лист рифлёный на аппарель, до 0,5 м2 | C5: Металлопрокат и метизы | D5: кг | E5: 8 | F5: =E5*IFERROR(INDEX(Работы!$D$4:$D$672,MATCH(SUBSTITUTE(SUBSTITUTE(SUBSTITUTE(A5,"~","~~"),"*","~*"),"?","~?"),Работы!$B$4:$B$672,0)),0) | G5: 79.76 | H5: 1 | I5: 0.05 | J5: 0.1 | L5: Петрович | M5: https://moscow.petrovich.ru/product/108534/ | N5: 2026-10-29 | O5: Петрович, труба 40х40х2, 587 руб/3 м с НДС, 7,36 кг. Цена кг с НДС 79.76. Карта клуба не учитывалась. | P5: =IF(H5=1,G5/VAT_DIV,G5) | Q5: =P5*(1+I5)*(1+DELIV)*(1+GROWTH+MONEY) | R5: =IF(AND(K5<>"",Q5*(1+J5)>K5/VAT_DIV),K5/VAT_DIV,Q5*(1+J5)) | S5: =Q5*F5 | T5: =R5*F5 | U5: =IF(AND(K5<>"",Q5*(1+J5)>K5/VAT_DIV+0.01),"ДА","") | V5: =P5*F5
A6: 8. Замена пружин для плавного опускания/поднятия. | B6: Пружина доклевеллера | C6: Изделия под заказ (ворота, двери, окна, перегородки) | D6: шт | E6: 1 | F6: =E6*IFERROR(INDEX(Работы!$D$4:$D$672,MATCH(SUBSTITUTE(SUBSTITUTE(SUBSTITUTE(A6,"~","~~"),"*","~*"),"?","~?"),Работы!$B$4:$B$672,0)),0) | G6: 4500 | H6: 1 | I6: 0 | J6: 0.12 | L6: оценка | N6: 2026-10-29 | O6: оценка, запросить DoorHan В Петрович, Лемана ПРО и Сатурн открытой карточки нет, оставлен прежний источник. | P6: =IF(H6=1,G6/VAT_DIV,G6) | Q6: =P6*(1+I6)*(1+DELIV)*(1+GROWTH+MONEY) | R6: =IF(AND(K6<>"",Q6*(1+J6)>K6/VAT_DIV),K6/VAT_DIV,Q6*(1+J6)) | S6: =Q6*F6 | T6: =R6*F6 | U6: =IF(AND(K6<>"",Q6*(1+J6)>K6/VAT_DIV+0.01),"ДА","") | V6: =P6*F6
A7: 10. Замена арматуры сливного бачка типа «Компакт» (включая материалы и з/части) | B7: Арматура бачка компакт | C7: Сантехприборы | D7: шт | E7: 1 | F7: =E7*IFERROR(INDEX(Работы!$D$4:$D$672,MATCH(SUBSTITUTE(SUBSTITUTE(SUBSTITUTE(A7,"~","~~"),"*","~*"),"?","~?"),Работы!$B$4:$B$672,0)),0) | G7: 650 | H7: 1 | I7: 0 | J7: 0.12 | L7: оценка | N7: 2026-10-29 | O7: оценка полки Петрович/Лемана В Петрович, Лемана ПРО и Сатурн открытой карточки нет, оставлен прежний источник. | P7: =IF(H7=1,G7/VAT_DIV,G7) | Q7: =P7*(1+I7)*(1+DELIV)*(1+GROWTH+MONEY) | R7: =IF(AND(K7<>"",Q7*(1+J7)>K7/VAT_DIV),K7/VAT_DIV,Q7*(1+J7)) | S7: =Q7*F7 | T7: =R7*F7 | U7: =IF(AND(K7<>"",Q7*(1+J7)>K7/VAT_DIV+0.01),"ДА","") | V7: =P7*F7
A8: 11. Замена сливного бачка унитаза типа «Компакт» (включая материалы и з/части) | B8: Бачок компакт с арматурой | C8: Сантехприборы | D8: шт | E8: 1 | F8: =E8*IFERROR(INDEX(Работы!$D$4:$D$672,MATCH(SUBSTITUTE(SUBSTITUTE(SUBSTITUTE(A8,"~","~~"),"*","~*"),"?","~?"),Работы!$B$4:$B$672,0)),0) | G8: 1800 | H8: 1 | I8: 0 | J8: 0.12 | L8: оценка | N8: 2026-10-29 | O8: оценка В Петрович, Лемана ПРО и Сатурн открытой карточки нет, оставлен прежний источник. | P8: =IF(H8=1,G8/VAT_DIV,G8) | Q8: =P8*(1+I8)*(1+DELIV)*(1+GROWTH+MONEY) | R8: =IF(AND(K8<>"",Q8*(1+J8)>K8/VAT_DIV),K8/VAT_DIV,Q8*(1+J8)) | S8: =Q8*F8 | T8: =R8*F8 | U8: =IF(AND(K8<>"",Q8*(1+J8)>K8/VAT_DIV+0.01),"ДА","") | V8: =P8*F8
A9: 12. Замена унитаза типа «Компакт» (включая материалы и з/части) | B9: Унитаз-компакт | C9: Сантехприборы | D9: шт | E9: 1 | F9: =E9*IFERROR(INDEX(Работы!$D$4:$D$672,MATCH(SUBSTITUTE(SUBSTITUTE(SUBSTITUTE(A9,"~","~~"),"*","~*"),"?","~?"),Работы!$B$4:$B$672,0)),0) | G9: 4990 | H9: 1 | I9: 0 | J9: 0.12 | L9: Лемана ПРО | M9: https://lemanapro.ru/product/unitaz-kompakt-yauza-82199701/ | N9: 2026-10-29 | O9: Минимум: Лемана ПРО Яуза 4 990 руб. Сатурн Sanita Эталон 5 666, Петрович Cersanit Trento 8 130. | P9: =IF(H9=1,G9/VAT_DIV,G9) | Q9: =P9*(1+I9)*(1+DELIV)*(1+GROWTH+MONEY) | R9: =IF(AND(K9<>"",Q9*(1+J9)>K9/VAT_DIV),K9/VAT_DIV,Q9*(1+J9)) | S9: =Q9*F9 | T9: =R9*F9 | U9: =IF(AND(K9<>"",Q9*(1+J9)>K9/VAT_DIV+0.01),"ДА","") | V9: =P9*F9
A10: 13. Замена гибкой подводки сантехнической до 60 см (включая материалы и з/части) | B10: Подводка гибкая 60 см | C10: Трубы и фитинги ВиК, отопления | D10: шт | E10: 1 | F10: =E10*IFERROR(INDEX(Работы!$D$4:$D$672,MATCH(SUBSTITUTE(SUBSTITUTE(SUBSTITUTE(A10,"~","~~"),"*","~*"),"?","~?"),Работы!$B$4:$B$672,0)),0) | G10: 250 | H10: 1 | I10: 0.04 | J10: 0.12 | L10: оценка | N10: 2026-10-29 | O10: оценка В Петрович, Лемана ПРО и Сатурн открытой карточки нет, оставлен прежний источник. | P10: =IF(H10=1,G10/VAT_DIV,G10) | Q10: =P10*(1+I10)*(1+DELIV)*(1+GROWTH+MONEY) | R10: =IF(AND(K10<>"",Q10*(1+J10)>K10/VAT_DIV),K10/VAT_DIV,Q10*(1+J10)) | S10: =Q10*F10 | T10: =R10*F10 | U10: =IF(AND(K10<>"",Q10*(1+J10)>K10/VAT_DIV+0.01),"ДА","") | V10: =P10*F10
A11: 14. Замена смесителя раковины (включая материалы и з/части) | B11: Смеситель для раковины | C11: Сантехприборы | D11: шт | E11: 1 | F11: =E11*IFERROR(INDEX(Работы!$D$4:$D$672,MATCH(SUBSTITUTE(SUBSTITUTE(SUBSTITUTE(A11,"~","~~"),"*","~*"),"?","~?"),Работы!$B$4:$B$672,0)),0) | G11: 1108 | H11: 1 | I11: 0 | J11: 0.12 | L11: Сатурн | M11: https://msk.saturn.net/product/smesitel-dlya-rakovini-klip-803/ | N11: 2026-10-29 | O11: Минимум: Сатурн Klip 803 = 1 108 руб. Петрович РМС 1 176, Лемана ПРО Fixsen 3 680. | P11: =IF(H11=1,G11/VAT_DIV,G11) | Q11: =P11*(1+I11)*(1+DELIV)*(1+GROWTH+MONEY) | R11: =IF(AND(K11<>"",Q11*(1+J11)>K11/VAT_DIV),K11/VAT_DIV,Q11*(1+J11)) | S11: =Q11*F11 | T11: =R11*F11 | U11: =IF(AND(K11<>"",Q11*(1+J11)>K11/VAT_DIV+0.01),"ДА","") | V11: =P11*F11
A12: 15. Замена раковины керамической с пьедесталом (включая материалы и з/части) | B12: Замена раковины керамической с пьедесталом (включая материалы и з/части) | C12: Сантехприборы | D12: шт | E12: 1 | F12: =E12*IFERROR(INDEX(Работы!$D$4:$D$672,MATCH(SUBSTITUTE(SUBSTITUTE(SUBSTITUTE(A12,"~","~~"),"*","~*"),"?","~?"),Работы!$B$4:$B$672,0)),0) | G12: 3840 | H12: 1 | I12: 0 | J12: 0.12 | L12: Петрович | M12: https://moscow.petrovich.ru/product/1094953/ | N12: 2026-10-29 | O12: Петрович, комплект Sanita Аттика 55 см (раковина и пьедестал) 3 840 руб. Прочие размеры — тот же аналог. | P12: =IF(H12=1,G12/VAT_DIV,G12) | Q12: =P12*(1+I12)*(1+DELIV)*(1+GROWTH+MONEY) | R12: =IF(AND(K12<>"",Q12*(1+J12)>K12/VAT_DIV),K12/VAT_DIV,Q12*(1+J12)) | S12: =Q12*F12 | T12: =R12*F12 | U12: =IF(AND(K12<>"",Q12*(1+J12)>K12/VAT_DIV+0.01),"ДА","") | V12: =P12*F12
A13: 16. Замена раковины металлической (включая материалы и з/части) | B13: Замена раковины металлической (включая материалы и з/части) | C13: Сантехприборы | D13: шт | E13: 1 | F13: =E13*IFERROR(INDEX(Работы!$D$4:$D$672,MATCH(SUBSTITUTE(SUBSTITUTE(SUBSTITUTE(A13,"~","~~"),"*","~*"),"?","~?"),Работы!$B$4:$B$672,0)),0) | G13: 3840 | H13: 1 | I13: 0 | J13: 0.12 | L13: Петрович | M13: https://moscow.petrovich.ru/product/1094953/ | N13: 2026-10-29 | O13: Петрович, комплект Sanita Аттика 55 см (раковина и пьедестал) 3 840 руб. Прочие размеры — тот же аналог. | P13: =IF(H13=1,G13/VAT_DIV,G13) | Q13: =P13*(1+I13)*(1+DELIV)*(1+GROWTH+MONEY) | R13: =IF(AND(K13<>"",Q13*(1+J13)>K13/VAT_DIV),K13/VAT_DIV,Q13*(1+J13)) | S13: =Q13*F13 | T13: =R13*F13 | U13: =IF(AND(K13<>"",Q13*(1+J13)>K13/VAT_DIV+0.01),"ДА","") | V13: =P13*F13
A14: 17. Замена смесителя для ванны с душевой лейкой (включая материалы и з/части) | B14: Смеситель для ванны с лейкой | C14: Сантехприборы | D14: шт | E14: 1 | F14: =E14*IFERROR(INDEX(Работы!$D$4:$D$672,MATCH(SUBSTITUTE(SUBSTITUTE(SUBSTITUTE(A14,"~","~~"),"*","~*"),"?","~?"),Работы!$B$4:$B$672,0)),0) | G14: 3200 | H14: 1 | I14: 0 | J14: 0.12 | L14: оценка | N14: 2026-10-29 | O14: оценка средний сегмент В Петрович, Лемана ПРО и Сатурн открытой карточки нет, оставлен прежний источник. | P14: =IF(H14=1,G14/VAT_DIV,G14) | Q14: =P14*(1+I14)*(1+DELIV)*(1+GROWTH+MONEY) | R14: =IF(AND(K14<>"",Q14*(1+J14)>K14/VAT_DIV),K14/VAT_DIV,Q14*(1+J14)) | S14: =Q14*F14 | T14: =R14*F14 | U14: =IF(AND(K14<>"",Q14*(1+J14)>K14/VAT_DIV+0.01),"ДА","") | V14: =P14*F14
A15: 19. Замена сифона раковины (включая материалы и з/части) | B15: Замена сифона раковины (включая материалы и з/части) | C15: Сантехприборы | D15: шт | E15: 1 | F15: =E15*IFERROR(INDEX(Работы!$D$4:$D$672,MATCH(SUBSTITUTE(SUBSTITUTE(SUBSTITUTE(A15,"~","~~"),"*","~*"),"?","~?"),Работы!$B$4:$B$672,0)),0) | G15: 3840 | H15: 1 | I15: 0 | J15: 0.12 | L15: Петрович | M15: https://moscow.petrovich.ru/product/1094953/ | N15: 2026-10-29 | O15: Петрович, комплект Sanita Аттика 55 см (раковина и пьедестал) 3 840 руб. Прочие размеры — тот же аналог. | P15: =IF(H15=1,G15/VAT_DIV,G15) | Q15: =P15*(1+I15)*(1+DELIV)*(1+GROWTH+MONEY) | R15: =IF(AND(K15<>"",Q15*(1+J15)>K15/VAT_DIV),K15/VAT_DIV,Q15*(1+J15)) | S15: =Q15*F15 | T15: =R15*F15 | U15: =IF(AND(K15<>"",Q15*(1+J15)>K15/VAT_DIV+0.01),"ДА","") | V15: =P15*F15
A16: 20. Замена крана писсуара (включая материалы и з/части) | B16: Кран писсуара | C16: Сантехприборы | D16: шт | E16: 1 | F16: =E16*IFERROR(INDEX(Работы!$D$4:$D$672,MATCH(SUBSTITUTE(SUBSTITUTE(SUBSTITUTE(A16,"~","~~"),"*","~*"),"?","~?"),Работы!$B$4:$B$672,0)),0) | G16: 1400 | H16: 1 | I16: 0 | J16: 0.12 | L16: оценка | N16: 2026-10-29 | O16: оценка В Петрович, Лемана ПРО и Сатурн открытой карточки нет, оставлен прежний источник. | P16: =IF(H16=1,G16/VAT_DIV,G16) | Q16: =P16*(1+I16)*(1+DELIV)*(1+GROWTH+MONEY) | R16: =IF(AND(K16<>"",Q16*(1+J16)>K16/VAT_DIV),K16/VAT_DIV,Q16*(1+J16)) | S16: =Q16*F16 | T16: =R16*F16 | U16: =IF(AND(K16<>"",Q16*(1+J16)>K16/VAT_DIV+0.01),"ДА","") | V16: =P16*F16
A17: 21. Прокладка трубопровода ХВС, ГВС из полипропиленовых труб Ø20-32 мм (включая материалы, комплетующие и з/части) за 1 п.м. | B17: Труба ПП d32 | C17: Трубы и фитинги ВиК, отопления | D17: м | E17: 1 | F17: =E17*IFERROR(INDEX(Работы!$D$4:$D$672,MATCH(SUBSTITUTE(SUBSTITUTE(SUBSTITUTE(A17,"~","~~"),"*","~*"),"?","~?"),Работы!$B$4:$B$672,0)),0) | G17: 120.1 | H17: 1 | I17: 0.04 | J17: 0.12 | L17: Петрович | M17: https://moscow.petrovich.ru/product/1154066/ | N17: 2026-10-29 | O17: Якорь Петрович Lammin PN25 d25 = 85 руб/м (Лемана ПРО 85,5). Остальные диаметры — прежний коэффициент к d25. | P17: =IF(H17=1,G17/VAT_DIV,G17) | Q17: =P17*(1+I17)*(1+DELIV)*(1+GROWTH+MONEY) | R17: =IF(AND(K17<>"",Q17*(1+J17)>K17/VAT_DIV),K17/VAT_DIV,Q17*(1+J17)) | S17: =Q17*F17 | T17: =R17*F17 | U17: =IF(AND(K17<>"",Q17*(1+J17)>K17/VAT_DIV+0.01),"ДА","") | V17: =P17*F17
A18: 22. Прокладка трубопровода внутренней канализации Ø40 мм (включая материалы и з/части) за 1 п.м. | B18: Труба канализация d40 | C18: Трубы и фитинги ВиК, отопления | D18: м | E18: 1 | F18: =E18*IFERROR(INDEX(Работы!$D$4:$D$672,MATCH(SUBSTITUTE(SUBSTITUTE(SUBSTITUTE(A18,"~","~~"),"*","~*"),"?","~?"),Работы!$B$4:$B$672,0)),0) | G18: 85 | H18: 1 | I18: 0.04 | J18: 0.12 | L18: оценка | N18: 2026-10-29 | O18: оценка ПВХ/ПП внутренней канализации В Петрович, Лемана ПРО и Сатурн открытой карточки нет, оставлен прежний источник. | P18: =IF(H18=1,G18/VAT_DIV,G18) | Q18: =P18*(1+I18)*(1+DELIV)*(1+GROWTH+MONEY) | R18: =IF(AND(K18<>"",Q18*(1+J18)>K18/VAT_DIV),K18/VAT_DIV,Q18*(1+J18)) | S18: =Q18*F18 | T18: =R18*F18 | U18: =IF(AND(K18<>"",Q18*(1+J18)>K18/VAT_DIV+0.01),"ДА","") | V18: =P18*F18
A19: 23. Прокладка трубопровода внутренней канализации Ø50 мм (включая материалы и з/части) за 1 п.м. | B19: Труба канализация d50 | C19: Трубы и фитинги ВиК, отопления | D19: м | E19: 1 | F19: =E19*IFERROR(INDEX(Работы!$D$4:$D$672,MATCH(SUBSTITUTE(SUBSTITUTE(SUBSTITUTE(A19,"~","~~"),"*","~*"),"?","~?"),Работы!$B$4:$B$672,0)),0) | G19: 110 | H19: 1 | I19: 0.04 | J19: 0.12 | L19: оценка | N19: 2026-10-29 | O19: оценка ПВХ/ПП внутренней канализации В Петрович, Лемана ПРО и Сатурн открытой карточки нет, оставлен прежний источник. | P19: =IF(H19=1,G19/VAT_DIV,G19) | Q19: =P19*(1+I19)*(1+DELIV)*(1+GROWTH+MONEY) | R19: =IF(AND(K19<>"",Q19*(1+J19)>K19/VAT_DIV),K19/VAT_DIV,Q19*(1+J19)) | S19: =Q19*F19 | T19: =R19*F19 | U19: =IF(AND(K19<>"",Q19*(1+J19)>K19/VAT_DIV+0.01),"ДА","") | V19: =P19*F19
A20: 24. Прокладка трубопровода внутренней канализации Ø100 мм (включая материалы и з/части) за 1 п.м. | B20: Труба канализация d32 | C20: Трубы и фитинги ВиК, отопления | D20: м | E20: 1 | F20: =E20*IFERROR(INDEX(Работы!$D$4:$D$672,MATCH(SUBSTITUTE(SUBSTITUTE(SUBSTITUTE(A20,"~","~~"),"*","~*"),"?","~?"),Работы!$B$4:$B$672,0)),0) | G20: 70 | H20: 1 | I20: 0.04 | J20: 0.12 | L20: оценка | N20: 2026-10-29 | O20: оценка ПВХ/ПП внутренней канализации В Петрович, Лемана ПРО и Сатурн открытой карточки нет, оставлен прежний источник. | P20: =IF(H20=1,G20/VAT_DIV,G20) | Q20: =P20*(1+I20)*(1+DELIV)*(1+GROWTH+MONEY) | R20: =IF(AND(K20<>"",Q20*(1+J20)>K20/VAT_DIV),K20/VAT_DIV,Q20*(1+J20)) | S20: =Q20*F20 | T20: =R20*F20 | U20: =IF(AND(K20<>"",Q20*(1+J20)>K20/VAT_DIV+0.01),"ДА","") | V20: =P20*F20
A21: 25. Устранение протечек в сантехническом оборудовании (включая материалы и з/части) за 1 ед. | B21: Лён, паста, прокладки | C21: Трубы и фитинги ВиК, отопления | D21: компл | E21: 1 | F21: =E21*IFERROR(INDEX(Работы!$D$4:$D$672,MATCH(SUBSTITUTE(SUBSTITUTE(SUBSTITUTE(A21,"~","~~"),"*","~*"),"?","~?"),Работы!$B$4:$B$672,0)),0) | G21: 180 | H21: 1 | I21: 0.04 | J21: 0.12 | L21: оценка | N21: 2026-10-29 | O21: оценка В Петрович, Лемана ПРО и Сатурн открытой карточки нет, оставлен прежний источник. | P21: =IF(H21=1,G21/VAT_DIV,G21) | Q21: =P21*(1+I21)*(1+DELIV)*(1+GROWTH+MONEY) | R21: =IF(AND(K21<>"",Q21*(1+J21)>K21/VAT_DIV),K21/VAT_DIV,Q21*(1+J21)) | S21: =Q21*F21 | T21: =R21*F21 | U21: =IF(AND(K21<>"",Q21*(1+J21)>K21/VAT_DIV+0.01),"ДА","") | V21: =P21*F21
A22: 26. Замена запорной арматуры трубопроводов (включая материалы и з/части) за 1 ед. | B22: Кран шаровой латунь Ду15–25 | C22: Трубы и фитинги ВиК, отопления | D22: шт | E22: 1 | F22: =E22*IFERROR(INDEX(Работы!$D$4:$D$672,MATCH(SUBSTITUTE(SUBSTITUTE(SUBSTITUTE(A22,"~","~~"),"*","~*"),"?","~?"),Работы!$B$4:$B$672,0)),0) | G22: 420 | H22: 1 | I22: 0.04 | J22: 0.12 | L22: оценка | N22: 2026-10-29 | O22: оценка В Петрович, Лемана ПРО и Сатурн открытой карточки нет, оставлен прежний источник. | P22: =IF(H22=1,G22/VAT_DIV,G22) | Q22: =P22*(1+I22)*(1+DELIV)*(1+GROWTH+MONEY) | R22: =IF(AND(K22<>"",Q22*(1+J22)>K22/VAT_DIV),K22/VAT_DIV,Q22*(1+J22)) | S22: =Q22*F22 | T22: =R22*F22 | U22: =IF(AND(K22<>"",Q22*(1+J22)>K22/VAT_DIV+0.01),"ДА","") | V22: =P22*F22
A23: 27. Подключение к системе ХВС, ГВС приборов (водонагреватель, кулер, пурифайр, стиральная машинка и т.д.) (включая материалы, комплектующие, фитинги, з/части и т.д.) за 1 ед. | B23: Кран и подводка для прибора | C23: Трубы и фитинги ВиК, отопления | D23: компл | E23: 1 | F23: =E23*IFERROR(INDEX(Работы!$D$4:$D$672,MATCH(SUBSTITUTE(SUBSTITUTE(SUBSTITUTE(A23,"~","~~"),"*","~*"),"?","~?"),Работы!$B$4:$B$672,0)),0) | G23: 650 | H23: 1 | I23: 0.04 | J23: 0.12 | L23: оценка | N23: 2026-10-29 | O23: оценка В Петрович, Лемана ПРО и Сатурн открытой карточки нет, оставлен прежний источник. | P23: =IF(H23=1,G23/VAT_DIV,G23) | Q23: =P23*(1+I23)*(1+DELIV)*(1+GROWTH+MONEY) | R23: =IF(AND(K23<>"",Q23*(1+J23)>K23/VAT_DIV),K23/VAT_DIV,Q23*(1+J23)) | S23: =Q23*F23 | T23: =R23*F23 | U23: =IF(AND(K23<>"",Q23*(1+J23)>K23/VAT_DIV+0.01),"ДА","") | V23: =P23*F23
A24: 29. Планка примыкания верхняя, нижняя 150 х 250 с полимерным покрытием по RAL по согласованию | B24: Планка 150х250, ~1,6 кг/м | C24: Металлопрокат и метизы | D24: кг | E24: 1.6 | F24: =E24*IFERROR(INDEX(Работы!$D$4:$D$672,MATCH(SUBSTITUTE(SUBSTITUTE(SUBSTITUTE(A24,"~","~~"),"*","~*"),"?","~?"),Работы!$B$4:$B$672,0)),0) | G24: 107.68 | H24: 1 | I24: 0.05 | J24: 0.1 | L24: Петрович | M24: https://moscow.petrovich.ru/product/108534/ | N24: 2026-10-29 | O24: Петрович, труба 40х40х2, 587 руб/3 м с НДС, 7,36 кг. Цена кг с НДС 79.76. Карта клуба не учитывалась. коэффициент 1.35 к чёрному — оценка, запросить КП металлобазы | P24: =IF(H24=1,G24/VAT_DIV,G24) | Q24: =P24*(1+I24)*(1+DELIV)*(1+GROWTH+MONEY) | R24: =IF(AND(K24<>"",Q24*(1+J24)>K24/VAT_DIV),K24/VAT_DIV,Q24*(1+J24)) | S24: =Q24*F24 | T24: =R24*F24 | U24: =IF(AND(K24<>"",Q24*(1+J24)>K24/VAT_DIV+0.01),"ДА","") | V24: =P24*F24
A25: 30. Монтаж профлиста С8-115 - 0,50 окрашенный | B25: Монтаж профлиста С8-115 - 0,50 окрашенный | C25: Кровельные материалы и утеплитель | D25: м2 | E25: 1.08 | F25: =E25*IFERROR(INDEX(Работы!$D$4:$D$672,MATCH(SUBSTITUTE(SUBSTITUTE(SUBSTITUTE(A25,"~","~~"),"*","~*"),"?","~?"),Работы!$B$4:$B$672,0)),0) | G25: 560 | H25: 1 | I25: 0.1 | J25: 0.12 | L25: оценка | N25: 2026-10-29 | O25: оценка профлиста С8 0,45–0,5, запросить металлобазу В Петрович, Лемана ПРО и Сатурн открытой карточки нет, оставлен прежний источник. | P25: =IF(H25=1,G25/VAT_DIV,G25) | Q25: =P25*(1+I25)*(1+DELIV)*(1+GROWTH+MONEY) | R25: =IF(AND(K25<>"",Q25*(1+J25)>K25/VAT_DIV),K25/VAT_DIV,Q25*(1+J25)) | S25: =Q25*F25 | T25: =R25*F25 | U25: =IF(AND(K25<>"",Q25*(1+J25)>K25/VAT_DIV+0.01),"ДА","") | V25: =P25*F25
A26: 31. Монтаж профлиста С8, 0,45мм | B26: Монтаж профлиста С8, 0,45мм | C26: Кровельные материалы и утеплитель | D26: м2 | E26: 1.08 | F26: =E26*IFERROR(INDEX(Работы!$D$4:$D$672,MATCH(SUBSTITUTE(SUBSTITUTE(SUBSTITUTE(A26,"~","~~"),"*","~*"),"?","~?"),Работы!$B$4:$B$672,0)),0) | G26: 560 | H26: 1 | I26: 0.1 | J26: 0.12 | L26: оценка | N26: 2026-10-29 | O26: оценка профлиста С8 0,45–0,5, запросить металлобазу В Петрович, Лемана ПРО и Сатурн открытой карточки нет, оставлен прежний источник. | P26: =IF(H26=1,G26/VAT_DIV,G26) | Q26: =P26*(1+I26)*(1+DELIV)*(1+GROWTH+MONEY) | R26: =IF(AND(K26<>"",Q26*(1+J26)>K26/VAT_DIV),K26/VAT_DIV,Q26*(1+J26)) | S26: =Q26*F26 | T26: =R26*F26 | U26: =IF(AND(K26<>"",Q26*(1+J26)>K26/VAT_DIV+0.01),"ДА","") | V26: =P26*F26
A27: 32. Монтаж профлиста С20, 0,45мм | B27: Монтаж профлиста С20, 0,45мм | C27: Кровельные материалы и утеплитель | D27: м2 | E27: 1.08 | F27: =E27*IFERROR(INDEX(Работы!$D$4:$D$672,MATCH(SUBSTITUTE(SUBSTITUTE(SUBSTITUTE(A27,"~","~~"),"*","~*"),"?","~?"),Работы!$B$4:$B$672,0)),0) | G27: 560 | H27: 1 | I27: 0.1 | J27: 0.12 | L27: оценка | N27: 2026-10-29 | O27: оценка профлиста С8 0,45–0,5, запросить металлобазу В Петрович, Лемана ПРО и Сатурн открытой карточки нет, оставлен прежний источник. | P27: =IF(H27=1,G27/VAT_DIV,G27) | Q27: =P27*(1+I27)*(1+DELIV)*(1+GROWTH+MONEY) | R27: =IF(AND(K27<>"",Q27*(1+J27)>K27/VAT_DIV),K27/VAT_DIV,Q27*(1+J27)) | S27: =Q27*F27 | T27: =R27*F27 | U27: =IF(AND(K27<>"",Q27*(1+J27)>K27/VAT_DIV+0.01),"ДА","") | V27: =P27*F27
A28: 33. Поручни из нержавеющей стали ( с 3 ригелями ) | B28: Поручни из нержавеющей стали ( с 3 ригелями ) | C28: Металлопрокат и метизы | D28: м | E28: 1 | F28: =E28*IFERROR(INDEX(Работы!$D$4:$D$672,MATCH(SUBSTITUTE(SUBSTITUTE(SUBSTITUTE(A28,"~","~~"),"*","~*"),"?","~?"),Работы!$B$4:$B$672,0)),0) | G28: 4500 | H28: 1 | I28: 0.05 | J28: 0.1 | L28: оценка | N28: 2026-10-29 | O28: оценка нержавеющего ограждения, запросить КП В Петрович, Лемана ПРО и Сатурн открытой карточки нет, оставлен прежний источник. | P28: =IF(H28=1,G28/VAT_DIV,G28) | Q28: =P28*(1+I28)*(1+DELIV)*(1+GROWTH+MONEY) | R28: =IF(AND(K28<>"",Q28*(1+J28)>K28/VAT_DIV),K28/VAT_DIV,Q28*(1+J28)) | S28: =Q28*F28 | T28: =R28*F28 | U28: =IF(AND(K28<>"",Q28*(1+J28)>K28/VAT_DIV+0.01),"ДА","") | V28: =P28*F28
A29: 34. Поручни из нержавеющей стали ( с 2 ригелями, с двойным ) | B29: Поручни из нержавеющей стали ( с 2 ригелями, с двойным ) | C29: Металлопрокат и метизы | D29: м | E29: 1 | F29: =E29*IFERROR(INDEX(Работы!$D$4:$D$672,MATCH(SUBSTITUTE(SUBSTITUTE(SUBSTITUTE(A29,"~","~~"),"*","~*"),"?","~?"),Работы!$B$4:$B$672,0)),0) | G29: 4500 | H29: 1 | I29: 0.05 | J29: 0.1 | L29: оценка | N29: 2026-10-29 | O29: оценка нержавеющего ограждения, запросить КП В Петрович, Лемана ПРО и Сатурн открытой карточки нет, оставлен прежний источник. | P29: =IF(H29=1,G29/VAT_DIV,G29) | Q29: =P29*(1+I29)*(1+DELIV)*(1+GROWTH+MONEY) | R29: =IF(AND(K29<>"",Q29*(1+J29)>K29/VAT_DIV),K29/VAT_DIV,Q29*(1+J29)) | S29: =Q29*F29 | T29: =R29*F29 | U29: =IF(AND(K29<>"",Q29*(1+J29)>K29/VAT_DIV+0.01),"ДА","") | V29: =P29*F29
A30: 35. Керамогранит 300х300х8 мм типа "Эстима" (цвет белый )RW-01 (вкл. За основу клей, грунтовку, затирку швов) | B30: Керамогранит 300х300х8 мм типа "Эстима" (цвет белый )RW-01 (вкл. За основу клей, | C30: Плитка, керамогранит | D30: м2 | E30: 1 | F30: =E30*IFERROR(INDEX(Работы!$D$4:$D$672,MATCH(SUBSTITUTE(SUBSTITUTE(SUBSTITUTE(A30,"~","~~"),"*","~*"),"?","~?"),Работы!$B$4:$B$672,0)),0) | G30: 1038.28 | H30: 1 | I30: 0.1 | J30: 0.12 | L30: Лемана ПРО | M30: https://lemanapro.ru/product/keramogranit-grani-taganaya-seryy-600h600-mm-91358213/ | N30: 2026-10-29 | O30: Якорь 600х600: Лемана ПРО 923 руб/м2, Петрович Grasaro 1007 руб/м2. Взят минимум. Прежний коэффициент размера сохранён. Сатурн не использован: цена карточки не сходится с м2. | P30: =IF(H30=1,G30/VAT_DIV,G30) | Q30: =P30*(1+I30)*(1+DELIV)*(1+GROWTH+MONEY) | R30: =IF(AND(K30<>"",Q30*(1+J30)>K30/VAT_DIV),K30/VAT_DIV,Q30*(1+J30)) | S30: =Q30*F30 | T30: =R30*F30 | U30: =IF(AND(K30<>"",Q30*(1+J30)>K30/VAT_DIV+0.01),"ДА","") | V30: =P30*F30
A31: 35. Керамогранит 300х300х8 мм типа "Эстима" (цвет белый )RW-01 (вкл. За основу клей, грунтовку, затирку швов) | B31: Клей плиточный | C31: Сухие смеси, штукатурки, шпаклёвки | D31: кг | E31: 5.5 | F31: =E31*IFERROR(INDEX(Работы!$D$4:$D$672,MATCH(SUBSTITUTE(SUBSTITUTE(SUBSTITUTE(A31,"~","~~"),"*","~*"),"?","~?"),Работы!$B$4:$B$672,0)),0) | G31: 22.68 | H31: 1 | I31: 0.05 | J31: 0.12 | L31: Лемана ПРО | M31: https://lemanapro.ru/product/kley-plitochnyy-ceresit-cm-11-pro-25-kg-89340445/ | N31: 2026-10-29 | O31: Минимум из трёх: Лемана ПРО Ceresit CM 11 PRO 25 кг = 22,68 руб/кг. Петрович 24,76, Сатурн 27. | P31: =IF(H31=1,G31/VAT_DIV,G31) | Q31: =P31*(1+I31)*(1+DELIV)*(1+GROWTH+MONEY) | R31: =IF(AND(K31<>"",Q31*(1+J31)>K31/VAT_DIV),K31/VAT_DIV,Q31*(1+J31)) | S31: =Q31*F31 | T31: =R31*F31 | U31: =IF(AND(K31<>"",Q31*(1+J31)>K31/VAT_DIV+0.01),"ДА","") | V31: =P31*F31
A32: 35. Керамогранит 300х300х8 мм типа "Эстима" (цвет белый )RW-01 (вкл. За основу клей, грунтовку, затирку швов) | B32: Затирка | C32: Сухие смеси, штукатурки, шпаклёвки | D32: кг | E32: 0.4 | F32: =E32*IFERROR(INDEX(Работы!$D$4:$D$672,MATCH(SUBSTITUTE(SUBSTITUTE(SUBSTITUTE(A32,"~","~~"),"*","~*"),"?","~?"),Работы!$B$4:$B$672,0)),0) | G32: 155 | H32: 1 | I32: 0.05 | J32: 0.12 | L32: Петрович | M32: https://moscow.petrovich.ru/product/102834/ | N32: 2026-10-29 | O32: Петрович, Ceresit CE 33, 2 кг = 310 руб (155 руб/кг). Лемана ПРО 173, Сатурн 181,5 руб/кг. | P32: =IF(H32=1,G32/VAT_DIV,G32) | Q32: =P32*(1+I32)*(1+DELIV)*(1+GROWTH+MONEY) | R32: =IF(AND(K32<>"",Q32*(1+J32)>K32/VAT_DIV),K32/VAT_DIV,Q32*(1+J32)) | S32: =Q32*F32 | T32: =R32*F32 | U32: =IF(AND(K32<>"",Q32*(1+J32)>K32/VAT_DIV+0.01),"ДА","") | V32: =P32*F32
A33: 35. Керамогранит 300х300х8 мм типа "Эстима" (цвет белый )RW-01 (вкл. За основу клей, грунтовку, затирку швов) | B33: Грунт | C33: Краски, грунты, ЛКМ | D33: л | E33: 0.15 | F33: =E33*IFERROR(INDEX(Работы!$D$4:$D$672,MATCH(SUBSTITUTE(SUBSTITUTE(SUBSTITUTE(A33,"~","~~"),"*","~*"),"?","~?"),Работы!$B$4:$B$672,0)),0) | G33: 136.7 | H33: 1 | I33: 0.05 | J33: 0.12 | L33: Лемана ПРО | M33: https://lemanapro.ru/product/grunt-ceresit-ct-17-transparent-glubokogo-proniknoveniya-10-l-89398668/ | N33: 2026-10-29 | O33: Минимум из трёх: Лемана ПРО Ceresit CT 17, 10 л = 136,7 руб/л. Петрович CT 17 PRO 143,8, Сатурн 145,9. | P33: =IF(H33=1,G33/VAT_DIV,G33) | Q33: =P33*(1+I33)*(1+DELIV)*(1+GROWTH+MONEY) | R33: =IF(AND(K33<>"",Q33*(1+J33)>K33/VAT_DIV),K33/VAT_DIV,Q33*(1+J33)) | S33: =Q33*F33 | T33: =R33*F33 | U33: =IF(AND(K33<>"",Q33*(1+J33)>K33/VAT_DIV+0.01),"ДА","") | V33: =P33*F33
A34: 36. Керамогранит 400х400х9 мм типа "Эстима" (цвет белый))RW-01 (вкл. За основу клей, грунтовку, затирку швов) | B34: Керамогранит 400х400х9 мм типа "Эстима" (цвет белый))RW-01 (вкл. За основу клей, | C34: Плитка, керамогранит | D34: м2 | E34: 1 | F34: =E34*IFERROR(INDEX(Работы!$D$4:$D$672,MATCH(SUBSTITUTE(SUBSTITUTE(SUBSTITUTE(A34,"~","~~"),"*","~*"),"?","~?"),Работы!$B$4:$B$672,0)),0) | G34: 1153.65 | H34: 1 | I34: 0.1 | J34: 0.12 | L34: Лемана ПРО | M34: https://lemanapro.ru/product/keramogranit-grani-taganaya-seryy-600h600-mm-91358213/ | N34: 2026-10-29 | O34: Якорь 600х600: Лемана ПРО 923 руб/м2, Петрович Grasaro 1007 руб/м2. Взят минимум. Прежний коэффициент размера сохранён. Сатурн не использован: цена карточки не сходится с м2. | P34: =IF(H34=1,G34/VAT_DIV,G34) | Q34: =P34*(1+I34)*(1+DELIV)*(1+GROWTH+MONEY) | R34: =IF(AND(K34<>"",Q34*(1+J34)>K34/VAT_DIV),K34/VAT_DIV,Q34*(1+J34)) | S34: =Q34*F34 | T34: =R34*F34 | U34: =IF(AND(K34<>"",Q34*(1+J34)>K34/VAT_DIV+0.01),"ДА","") | V34: =P34*F34
A35: 36. Керамогранит 400х400х9 мм типа "Эстима" (цвет белый))RW-01 (вкл. За основу клей, грунтовку, затирку швов) | B35: Клей плиточный | C35: Сухие смеси, штукатурки, шпаклёвки | D35: кг | E35: 5.5 | F35: =E35*IFERROR(INDEX(Работы!$D$4:$D$672,MATCH(SUBSTITUTE(SUBSTITUTE(SUBSTITUTE(A35,"~","~~"),"*","~*"),"?","~?"),Работы!$B$4:$B$672,0)),0) | G35: 22.68 | H35: 1 | I35: 0.05 | J35: 0.12 | L35: Лемана ПРО | M35: https://lemanapro.ru/product/kley-plitochnyy-ceresit-cm-11-pro-25-kg-89340445/ | N35: 2026-10-29 | O35: Минимум из трёх: Лемана ПРО Ceresit CM 11 PRO 25 кг = 22,68 руб/кг. Петрович 24,76, Сатурн 27. | P35: =IF(H35=1,G35/VAT_DIV,G35) | Q35: =P35*(1+I35)*(1+DELIV)*(1+GROWTH+MONEY) | R35: =IF(AND(K35<>"",Q35*(1+J35)>K35/VAT_DIV),K35/VAT_DIV,Q35*(1+J35)) | S35: =Q35*F35 | T35: =R35*F35 | U35: =IF(AND(K35<>"",Q35*(1+J35)>K35/VAT_DIV+0.01),"ДА","") | V35: =P35*F35
A36: 36. Керамогранит 400х400х9 мм типа "Эстима" (цвет белый))RW-01 (вкл. За основу клей, грунтовку, затирку швов) | B36: Затирка | C36: Сухие смеси, штукатурки, шпаклёвки | D36: кг | E36: 0.4 | F36: =E36*IFERROR(INDEX(Работы!$D$4:$D$672,MATCH(SUBSTITUTE(SUBSTITUTE(SUBSTITUTE(A36,"~","~~"),"*","~*"),"?","~?"),Работы!$B$4:$B$672,0)),0) | G36: 155 | H36: 1 | I36: 0.05 | J36: 0.12 | L36: Петрович | M36: https://moscow.petrovich.ru/product/102834/ | N36: 2026-10-29 | O36: Петрович, Ceresit CE 33, 2 кг = 310 руб (155 руб/кг). Лемана ПРО 173, Сатурн 181,5 руб/кг. | P36: =IF(H36=1,G36/VAT_DIV,G36) | Q36: =P36*(1+I36)*(1+DELIV)*(1+GROWTH+MONEY) | R36: =IF(AND(K36<>"",Q36*(1+J36)>K36/VAT_DIV),K36/VAT_DIV,Q36*(1+J36)) | S36: =Q36*F36 | T36: =R36*F36 | U36: =IF(AND(K36<>"",Q36*(1+J36)>K36/VAT_DIV+0.01),"ДА","") | V36: =P36*F36
A37: 36. Керамогранит 400х400х9 мм типа "Эстима" (цвет белый))RW-01 (вкл. За основу клей, грунтовку, затирку швов) | B37: Грунт | C37: Краски, грунты, ЛКМ | D37: л | E37: 0.15 | F37: =E37*IFERROR(INDEX(Работы!$D$4:$D$672,MATCH(SUBSTITUTE(SUBSTITUTE(SUBSTITUTE(A37,"~","~~"),"*","~*"),"?","~?"),Работы!$B$4:$B$672,0)),0) | G37: 136.7 | H37: 1 | I37: 0.05 | J37: 0.12 | L37: Лемана ПРО | M37: https://lemanapro.ru/product/grunt-ceresit-ct-17-transparent-glubokogo-proniknoveniya-10-l-89398668/ | N37: 2026-10-29 | O37: Минимум из трёх: Лемана ПРО Ceresit CT 17, 10 л = 136,7 руб/л. Петрович CT 17 PRO 143,8, Сатурн 145,9. | P37: =IF(H37=1,G37/VAT_DIV,G37) | Q37: =P37*(1+I37)*(1+DELIV)*(1+GROWTH+MONEY) | R37: =IF(AND(K37<>"",Q37*(1+J37)>K37/VAT_DIV),K37/VAT_DIV,Q37*(1+J37)) | S37: =Q37*F37 | T37: =R37*F37 | U37: =IF(AND(K37<>"",Q37*(1+J37)>K37/VAT_DIV+0.01),"ДА","") | V37: =P37*F37
