Workbook

Sheet Как считать
B1: МАТЕРИАЛЫ: КАК СЧИТАТЬ СЕБЕСТОИМОСТЬ И ЦЕНУ В КП
B2: Версия 23.10.2026. Внутренний документ НЕОСТРОЙ. Работы — по файлу «Расценки НЕОСТРОЙ — для сотрудников», материалы и расходники — по этому файлу.
B3: 1. МАТЕРИАЛЫ РАСЦЕНКИ — ВЕСЬ КОМПЛЕКТ
B4: • Цена работы в тарификаторе — только работа. Материалы расценки считаются комплектом: всё, что по технологии уходит в работу. Пример — укладка керамогранита: керамогранит, клей, затирка, грунт, СВП/крестики, демпферная лента.
B5: • Расход на единицу работы — по технологическим картам и нормам производителей (лист «Комплекты материалов» — типовые комплекты; пополняется). Отходы добавляются по категории.
B6: 2. СЕБЕСТОИМОСТЬ МАТЕРИАЛА
B7: С/с за единицу = закупка б/НДС × (1 + отходы) × (1 + доставка) × (1 + резерв роста цен + стоимость денег).
B8: • Закупка. Позиции дороже 5 % суммы материалов — минимум 2–3 КП поставщиков (берём лучшую). Остальное — прайсы дистрибьюторов для юрлиц с нашей скидкой. Оборудование — только по КП поставщика. Источник цены записывается в калькулятор — без него с/с не принимается.
B9: • Отходы и запас — по категории (лист «Категории и наценки»): заказчик платит за объём по проекту, а покупаем мы больше на величину отходов.
B10: • Доставка, разгрузка, подъём — % к закупке по региону (лист «Параметры»: СПб/Москва 3 %, области 5 %, регионы — по расчёту).
B11: • Резерв роста цен — если закупка позже чем через 2 месяца после КП и цену у поставщика не зафиксировали: 1,25 % за каждый месяц сверх двух.
B12: • Стоимость денег — если материалы покупаем не из аванса: 2 % за каждый месяц от закупки до оплаты заказчиком.
... B30: 4) В таблице 1 появится цена под ключ за единицу и маржа по каждой работе; внизу — итог, наценка, маржа и проверка по типу тендера.

Sheet Калькулятор
A1: КАЛЬКУЛЯТОР: РАБОТЫ ИЗ ТАРИФИКАТОРА + КОМПЛЕКТЫ МАТЕРИАЛОВ → СЕБЕСТОИМОСТЬ И КП
A3: Объект / тендер | J3: Доставка, % | M3: =IFERROR(INDEX(Параметры!$B$4:$B$8,MATCH($D$4,Параметры!$E$4:$E$8,0)),0) -> 0.03
A4: Регион | D4: СПб | J4: Резерв роста цен, % | M4: =MAX(0,$D$7-Параметры!$B$10)*Параметры!$B$9 -> 0
A5: Форма КП | D5: Раздельная | J5: Стоимость денег, % | M5: =IF($D$8="нет",$D$9*Параметры!$B$11,0) -> 0
A6: Тип тендера | D6: Крупные сети и девелоперы — конкурентный тендер | J6: Целевая наценка от | M6: =INDEX('Тип тендера'!$B$5:$B$9,MATCH($D$6,'Тип тендера'!$A$5:$A$9,0)) -> 0.3
A7: Месяцев от КП до закупки | D7: 1 | J7: Целевая наценка до | M7: =INDEX('Тип тендера'!$C$5:$C$9,MATCH($D$6,'Тип тендера'!$A$5:$A$9,0)) -> 0.4
A8: Материалы покупаем из аванса? | D8: да | J8: Цены тарификатора (по региону) | M8: =IF(OR($D$4="Москва",$D$4="Подмосковье"),"Мск","СПб") -> СПб
A9: Мес. от закупки до оплаты (если не из аванса) | D9: 2
A11: 1. РАБОТЫ (введите артикул тарификатора и объём — остальное подставится)
A12: № | B12: Артикул | C12: Работа (из тарификатора) | D12: Ед. | E12: Объём | F12: Код | G12: Цена работы в КП за ед. | H12: Подтянута выше рынка | I12: Работа в КП, сумма = цена × объём | J12: Оплата бригаде за ед. | K12: Оплата бригаде, сумма | L12: Расходники, % (по коду) | M12: Расходники, руб = оплата × % | N12: Материалы по работе — с/с (из таблицы 2) | O12: Материалы по работе — КП (из таблицы 2) | P12: ЦЕНА ПОД КЛЮЧ за ед. = (работа + материалы) ÷ объём | Q12: С/с строки = бригада + расходники + материалы | R12: Маржа строки
A13: 1 | B13: 7.2.25 | C13: =IF(B13="","",IFERROR(INDEX(Тарификатор!$B$5:$B$2356,MATCH(B13,Тарификатор!$A$5:$A$2356,0)),"НЕТ ТАКОГО АРТИКУЛА")) -> Устройство покрытий пола из плит керамической плитки/керамогранита с огрунтовкой основания и затиркой швов на клее из цементных сухих смесей | D13: =IF(B13="","",IFERROR(INDEX(Тарификатор!$C$5:$C$2356,MATCH(B13,Тарификатор!$A$5:$A$2356,0)),"")) -> м2 | E13: 250 | F13: =IF(B13="","",IFERROR(INDEX(Тарификатор!$D$5:$D$2356,MATCH(B13,Тарификатор!$A$5:$A$2356,0)),"")) -> PLI | G13: =IF(B13="","",IFERROR(IF($M$8="Мск",INDEX(Тарификатор!$F$5:$F$2356,MATCH(B13,Тарификатор!$A$5:$A$2356,0)),INDEX(Тарификатор!$E$5:$E$2356,MATCH(B13,Тарификатор!$A$5:$A$2356,0))),0)) -> 1800 | H13: =IF(B13="","",IFERROR(IF($M$8="Мск",INDEX(Тарификатор!$J$5:$J$2356,MATCH(B13,Тарификатор!$A$5:$A$2356,0)),INDEX(Тарификатор!$I$5:$I$2356,MATCH(B13,Тарификатор!$A$5:$A$2356,0))),0)) -> 0.125 | I13: =IF(OR(G13="",E13=""),"",ROUND(G13*E13,2)) -> 450000 | J13: =IF(B13="","",IFERROR(IF($M$8="Мск",INDEX(Тарификатор!$H$5:$H$2356,MATCH(B13,Тарификатор!$A$5:$A$2356,0)),INDEX(Тарификатор!$G$5:$G$2356,MATCH(B13,Тарификатор!$A$5:$A$2356,0))),0)) -> 1000 | K13: =IF(OR(J13="",E13=""),"",ROUND(J13*E13,2)) -> 250000 | L13: =IF(F13="","",IFERROR(INDEX('Расходники к работам'!$C$5:$C$24,MATCH(F13,'Расходники к работам'!$A$5:$A$24,0)),0)) -> 0.02 | M13: =IF(K13="","",ROUND(K13*L13,2)) -> 5000 | N13: =IF(B13="","",SUMIF($B$58:$B$177,B13,$L$58:$L$177)) -> 389143.88 | O13: =IF(B13="","",SUMIF($B$58:$B$177,B13,$O$58:$O$177)) -> 436031.75 | P13: =IF(OR(I13="",E13="",E13=0),"",ROUND((I13+O13)/E13,2)) -> 3544.13 | Q13: =IF(K13="","",K13+M13+N13) -> 644143.88 | R13: =IF(Q13="","",IF(N(I13)+N(O13)=0,"",1-Q13/(N(I13)+N(O13)))) -> 0.27300136
A14: 2 | B14: 10.2.N3 | C14: =IF(B14="","",IFERROR(INDEX(Тарификатор!$B$5:$B$2356,MATCH(B14,Тарификатор!$A$5:$A$2356,0)),"НЕТ ТАКОГО АРТИКУЛА")) -> Прокладка кабеля до 16 мм² открыто по стенам/потолку с креплением скобами/клипсами | D14: =IF(B14="","",IFERROR(INDEX(Тарификатор!$C$5:$C$2356,MATCH(B14,Тарификатор!$A$5:$A$2356,0)),"")) -> мп | E14: 1200 | F14: =IF(B14="","",IFERROR(INDEX(Тарификатор!$D$5:$D$2356,MATCH(B14,Тарификатор!$A$5:$A$2356,0)),"")) -> ELM | G14: =IF(B14="","",IFERROR(IF($M$8="Мск",INDEX(Тарификатор!$F$5:$F$2356,MATCH(B14,Тарификатор!$A$5:$A$2356,0)),INDEX(Тарификатор!$E$5:$E$2356,MATCH(B14,Тарификатор!$A$5:$A$2356,0))),0)) -> 220 | H14: =IF(B14="","",IFERROR(IF($M$8="Мск",INDEX(Тарификатор!$J$5:$J$2356,MATCH(B14,Тарификатор!$A$5:$A$2356,0)),INDEX(Тарификатор!$I$5:$I$2356,MATCH(B14,Тарификатор!$A$5:$A$2356,0))),0)) -> 0 | I14: =IF(OR(G14="",E14=""),"",ROUND(G14*E14,2)) -> 264000 | J14: =IF(B14="","",IFERROR(IF($M$8="Мск",INDEX(Тарификатор!$H$5:$H$2356,MATCH(B14,Тарификатор!$A$5:$A$2356,0)),INDEX(Тарификатор!$G$5:$G$2356,MATCH(B14,Тарификатор!$A$5:$A$2356,0))),0)) -> 135 | K14: =IF(OR(J14="",E14=""),"",ROUND(J14*E14,2)) -> 162000 | L14: =IF(F14="","",IFERROR(INDEX('Расходники к работам'!$C$5:$C$24,MATCH(F14,'Расходники к работам'!$A$5:$A$24,0)),0)) -> 0.02 | M14: =IF(K14="","",ROUND(K14*L14,2)) -> 3240 | N14: =IF(B14="","",SUMIF($B$58:$B$177,B14,$L$58:$L$177)) -> 140724 | O14: =IF(B14="","",SUMIF($B$58:$B$177,B14,$O$58:$O$177)) -> 157620 | P14: =IF(OR(I14="",E14="",E14=0),"",ROUND((I14+O14)/E14,2)) -> 351.35 | Q14: =IF(K14="","",K14+M14+N14) -> 305964 | R14: =IF(Q14="","",IF(N(I14)+N(O14)=0,"",1-Q14/(N(I14)+N(O14)))) -> 0.27431336
A15: 3 | C15: =IF(B15="","",IFERROR(INDEX(Тарификатор!$B$5:$B$2356,MATCH(B15,Тарификатор!$A$5:$A$2356,0)),"НЕТ ТАКОГО АРТИКУЛА")) | D15: =IF(B15="","",IFERROR(INDEX(Тарификатор!$C$5:$C$2356,MATCH(B15,Тарификатор!$A$5:$A$2356,0)),"")) | F15: =IF(B15="","",IFERROR(INDEX(Тарификатор!$D$5:$D$2356,MATCH(B15,Тарификатор!$A$5:$A$2356,0)),"")) | G15: =IF(B15="","",IFERROR(IF($M$8="Мск",INDEX(Тарификатор!$F$5:$F$2356,MATCH(B15,Тарификатор!$A$5:$A$2356,0)),INDEX(Тарификатор!$E$5:$E$2356,MATCH(B15,Тарификатор!$A$5:$A$2356,0))),0)) | H15: =IF(B15="","",IFERROR(IF($M$8="Мск",INDEX(Тарификатор!$J$5:$J$2356,MATCH(B15,Тарификатор!$A$5:$A$2356,0)),INDEX(Тарификатор!$I$5:$I$2356,MATCH(B15,Тарификатор!$A$5:$A$2356,0))),0)) | I15: =IF(OR(G15="",E15=""),"",ROUND(G15*E15,2)) | J15: =IF(B15="","",IFERROR(IF($M$8="Мск",INDEX(Тарификатор!$H$5:$H$2356,MATCH(B15,Тарификатор!$A$5:$A$2356,0)),INDEX(Тарификатор!$G$5:$G$2356,MATCH(B15,Тарификатор!$A$5:$A$2356,0))),0)) | K15: =IF(OR(J15="",E15=""),"",ROUND(J15*E15,2)) | L15: =IF(F15="","",IFERROR(INDEX('Расходники к работам'!$C$5:$C$24,MATCH(F15,'Расходники к работам'!$A$5:$A$24,0)),0)) | M15: =IF(K15="","",ROUND(K15*L15,2)) | N15: =IF(B15="","",SUMIF($B$58:$B$177,B15,$L$58:$L$177)) | O15: =IF(B15="","",SUMIF($B$58:$B$177,B15,$O$58:$O$177)) | P15: =IF(OR(I15="",E15="",E15=0),"",ROUND((I15+O15)/E15,2)) | Q15: =IF(K15="","",K15+M15+N15) | R15: =IF(Q15="","",IF(N(I15)+N(O15)=0,"",1-Q15/(N(I15)+N(O15))))
A16: 4 | C16: =IF(B16="","",IFERROR(INDEX(Тарификатор!$B$5:$B$2356,MATCH(B16,Тарификатор!$A$5:$A$2356,0)),"НЕТ ТАКОГО АРТИКУЛА")) | D16: =IF(B16="","",IFERROR(INDEX(Тарификатор!$C$5:$C$2356,MATCH(B16,Тарификатор!$A$5:$A$2356,0)),"")) | F16: =IF(B16="","",IFERROR(INDEX(Тарификатор!$D$5:$D$2356,MATCH(B16,Тарификатор!$A$5:$A$2356,0)),"")) | G16: =IF(B16="","",IFERROR(IF($M$8="Мск",INDEX(Тарификатор!$F$5:$F$2356,MATCH(B16,Тарификатор!$A$5:$A$2356,0)),INDEX(Тарификатор!$E$5:$E$2356,MATCH(B16,Тарификатор!$A$5:$A$2356,0))),0)) | H16: =IF(B16="","",IFERROR(IF($M$8="Мск",INDEX(Тарификатор!$J$5:$J$2356,MATCH(B16,Тарификатор!$A$5:$A$2356,0)),INDEX(Тарификатор!$I$5:$I$2356,MATCH(B16,Тарификатор!$A$5:$A$2356,0))),0)) | I16: =IF(OR(G16="",E16=""),"",ROUND(G16*E16,2)) | J16: =IF(B16="","",IFERROR(IF($M$8="Мск",INDEX(Тарификатор!$H$5:$H$2356,MATCH(B16,Тарификатор!$A$5:$A$2356,0)),INDEX(Тарификатор!$G$5:$G$2356,MATCH(B16,Тарификатор!$A$5:$A$2356,0))),0)) | K16: =IF(OR(J16="",E16=""),"",ROUND(J16*E16,2)) | L16: =IF(F16="","",IFERROR(INDEX('Расходники к работам'!$C$5:$C$24,MATCH(F16,'Расходники к работам'!$A$5:$A$24,0)),0)) | M16: =IF(K16="","",ROUND(K16*L16,2)) | N16: =IF(B16="","",SUMIF($B$58:$B$177,B16,$L$58:$L$177)) | O16: =IF(B16="","",SUMIF($B$58:$B$177,B16,$O$58:$O$177)) | P16: =IF(OR(I16="",E16="",E16=0),"",ROUND((I16+O16)/E16,2)) | Q16: =IF(K16="","",K16+M16+N16) | R16: =IF(Q16="","",IF(N(I16)+N(O16)=0,"",1-Q16/(N(I16)+N(O16))))
A17: 5 | C17: =IF(B17="","",IFERROR(INDEX(Тарификатор!$B$5:$B$2356,MATCH(B17,Тарификатор!$A$5:$A$2356,0)),"НЕТ ТАКОГО АРТИКУЛА")) | D17: =IF(B17="","",IFERROR(INDEX(Тарификатор!$C$5:$C$2356,MATCH(B17,Тарификатор!$A$5:$A$2356,0)),"")) | F17: =IF(B17="","",IFERROR(INDEX(Тарификатор!$D$5:$D$2356,MATCH(B17,Тарификатор!$A$5:$A$2356,0)),"")) | G17: =IF(B17="","",IFERROR(IF($M$8="Мск",INDEX(Тарификатор!$F$5:$F$2356,MATCH(B17,Тарификатор!$A$5:$A$2356,0)),INDEX(Тарификатор!$E$5:$E$2356,MATCH(B17,Тарификатор!$A$5:$A$2356,0))),0)) | H17: =IF(B17="","",IFERROR(IF($M$8="Мск",INDEX(Тарификатор!$J$5:$J$2356,MATCH(B17,Тарификатор!$A$5:$A$2356,0)),INDEX(Тарификатор!$I$5:$I$2356,MATCH(B17,Тарификатор!$A$5:$A$2356,0))),0)) | I17: =IF(OR(G17="",E17=""),"",ROUND(G17*E17,2)) | J17: =IF(B17="","",IFERROR(IF($M$8="Мск",INDEX(Тарификатор!$H$5:$H$2356,MATCH(B17,Тарификатор!$A$5:$A$2356,0)),INDEX(Тарификатор!$G$5:$G$2356,MATCH(B17,Тарификатор!$A$5:$A$2356,0))),0)) | K17: =IF(OR(J17="",E17=""),"",ROUND(J17*E17,2)) | L17: =IF(F17="","",IFERROR(INDEX('Расходники к работам'!$C$5:$C$24,MATCH(F17,'Расходники к работам'!$A$5:$A$24,0)),0)) | M17: =IF(K17="","",ROUND(K17*L17,2)) | N17: =IF(B17="","",SUMIF($B$58:$B$177,B17,$L$58:$L$177)) | O17: =IF(B17="","",SUMIF($B$58:$B$177,B17,$O$58:$O$177)) | P17: =IF(OR(I17="",E17="",E17=0),"",ROUND((I17+O17)/E17,2)) | Q17: =IF(K17="","",K17+M17+N17) | R17: =IF(Q17="","",IF(N(I17)+N(O17)=0,"",1-Q17/(N(I17)+N(O17))))
A18: 6 | C18: =IF(B18="","",IFERROR(INDEX(Тарификатор!$B$5:$B$2356,MATCH(B18,Тарификатор!$A$5:$A$2356,0)),"НЕТ ТАКОГО АРТИКУЛА")) | D18: =IF(B18="","",IFERROR(INDEX(Тарификатор!$C$5:$C$2356,MATCH(B18,Тарификатор!$A$5:$A$2356,0)),"")) | F18: =IF(B18="","",IFERROR(INDEX(Тарификатор!$D$5:$D$2356,MATCH(B18,Тарификатор!$A$5:$A$2356,0)),"")) | G18: =IF(B18="","",IFERROR(IF($M$8="Мск",INDEX(Тарификатор!$F$5:$F$2356,MATCH(B18,Тарификатор!$A$5:$A$2356,0)),INDEX(Тарификатор!$E$5:$E$2356,MATCH(B18,Тарификатор!$A$5:$A$2356,0))),0)) | H18: =IF(B18="","",IFERROR(IF($M$8="Мск",INDEX(Тарификатор!$J$5:$J$2356,MATCH(B18,Тарификатор!$A$5:$A$2356,0)),INDEX(Тарификатор!$I$5:$I$2356,MATCH(B18,Тарификатор!$A$5:$A$2356,0))),0)) | I18: =IF(OR(G18="",E18=""),"",ROUND(G18*E18,2)) | J18: =IF(B18="","",IFERROR(IF($M$8="Мск",INDEX(Тарификатор!$H$5:$H$2356,MATCH(B18,Тарификатор!$A$5:$A$2356,0)),INDEX(Тарификатор!$G$5:$G$2356,MATCH(B18,Тарификатор!$A$5:$A$2356,0))),0)) | K18: =IF(OR(J18="",E18=""),"",ROUND(J18*E18,2)) | L18: =IF(F18="","",IFERROR(INDEX('Расходники к работам'!$C$5:$C$24,MATCH(F18,'Расходники к работам'!$A$5:$A$24,0)),0)) | M18: =IF(K18="","",ROUND(K18*L18,2)) | N18: =IF(B18="","",SUMIF($B$58:$B$177,B18,$L$58:$L$177)) | O18: =IF(B18="","",SUMIF($B$58:$B$177,B18,$O$58:$O$177)) | P18: =IF(OR(I18="",E18="",E18=0),"",ROUND((I18+O18)/E18,2)) | Q18: =IF(K18="","",K18+M18+N18) | R18: =IF(Q18="","",IF(N(I18)+N(O18)=0,"",1-Q18/(N(I18)+N(O18))))
A19: 7 | C19: =IF(B19="","",IFERROR(INDEX(Тарификатор!$B$5:$B$2356,MATCH(B19,Тарификатор!$A$5:$A$2356,0)),"НЕТ ТАКОГО АРТИКУЛА")) | D19: =IF(B19="","",IFERROR(INDEX(Тарификатор!$C$5:$C$2356,MATCH(B19,Тарификатор!$A$5:$A$2356,0)),"")) | F19: =IF(B19="","",IFERROR(INDEX(Тарификатор!$D$5:$D$2356,MATCH(B19,Тарификатор!$A$5:$A$2356,0)),"")) | G19: =IF(B19="","",IFERROR(IF($M$8="Мск",INDEX(Тарификатор!$F$5:$F$2356,MATCH(B19,Тарификатор!$A$5:$A$2356,0)),INDEX(Тарификатор!$E$5:$E$2356,MATCH(B19,Тарификатор!$A$5:$A$2356,0))),0)) | H19: =IF(B19="","",IFERROR(IF($M$8="Мск",INDEX(Тарификатор!$J$5:$J$2356,MATCH(B19,Тарификатор!$A$5:$A$2356,0)),INDEX(Тарификатор!$I$5:$I$2356,MATCH(B19,Тарификатор!$A$5:$A$2356,0))),0)) | I19: =IF(OR(G19="",E19=""),"",ROUND(G19*E19,2)) | J19: =IF(B19="","",IFERROR(IF($M$8="Мск",INDEX(Тарификатор!$H$5:$H$2356,MATCH(B19,Тарификатор!$A$5:$A$2356,0)),INDEX(Тарификатор!$G$5:$G$2356,MATCH(B19,Тарификатор!$A$5:$A$2356,0))),0)) | K19: =IF(OR(J19="",E19=""),"",ROUND(J19*E19,2)) | L19: =IF(F19="","",IFERROR(INDEX('Расходники к работам'!$C$5:$C$24,MATCH(F19,'Расходники к работам'!$A$5:$A$24,0)),0)) | M19: =IF(K19="","",ROUND(K19*L19,2)) | N19: =IF(B19="","",SUMIF($B$58:$B$177,B19,$L$58:$L$177)) | O19: =IF(B19="","",SUMIF($B$58:$B$177,B19,$O$58:$O$177)) | P19: =IF(OR(I19="",E19="",E19=0),"",ROUND((I19+O19)/E19,2)) | Q19: =IF(K19="","",K19+M19+N19) | R19: =IF(Q19="","",IF(N(I19)+N(O19)=0,"",1-Q19/(N(I19)+N(O19))))
A20: 8 | C20: =IF(B20="","",IFERROR(INDEX(Тарификатор!$B$5:$B$2356,MATCH(B20,Тарификатор!$A$5:$A$2356,0)),"НЕТ ТАКОГО АРТИКУЛА")) | D20: =IF(B20="","",IFERROR(INDEX(Тарификатор!$C$5:$C$2356,MATCH(B20,Тарификатор!$A$5:$A$2356,0)),"")) | F20: =IF(B20="","",IFERROR(INDEX(Тарификатор!$D$5:$D$2356,MATCH(B20,Тарификатор!$A$5:$A$2356,0)),"")) | G20: =IF(B20="","",IFERROR(IF($M$8="Мск",INDEX(Тарификатор!$F$5:$F$2356,MATCH(B20,Тарификатор!$A$5:$A$2356,0)),INDEX(Тарификатор!$E$5:$E$2356,MATCH(B20,Тарификатор!$A$5:$A$2356,0))),0)) | H20: =IF(B20="","",IFERROR(IF($M$8="Мск",INDEX(Тарификатор!$J$5:$J$2356,MATCH(B20,Тарификатор!$A$5:$A$2356,0)),INDEX(Тарификатор!$I$5:$I$2356,MATCH(B20,Тарификатор!$A$5:$A$2356,0))),0)) | I20: =IF(OR(G20="",E20=""),"",ROUND(G20*E20,2)) | J20: =IF(B20="","",IFERROR(IF($M$8="Мск",INDEX(Тарификатор!$H$5:$H$2356,MATCH(B20,Тарификатор!$A$5:$A$2356,0)),INDEX(Тарификатор!$G$5:$G$2356,MATCH(B20,Тарификатор!$A$5:$A$2356,0))),0)) | K20: =IF(OR(J20="",E20=""),"",ROUND(J20*E20,2)) | L20: =IF(F20="","",IFERROR(INDEX('Расходники к работам'!$C$5:$C$24,MATCH(F20,'Расходники к работам'!$A$5:$A$24,0)),0)) | M20: =IF(K20="","",ROUND(K20*L20,2)) | N20: =IF(B20="","",SUMIF($B$58:$B$177,B20,$L$58:$L$177)) | O20: =IF(B20="","",SUMIF($B$58:$B$177,B20,$O$58:$O$177)) | P20: =IF(OR(I20="",E20="",E20=0),"",ROUND((I20+O20)/E20,2)) | Q20: =IF(K20="","",K20+M20+N20) | R20: =IF(Q20="","",IF(N(I20)+N(O20)=0,"",1-Q20/(N(I20)+N(O20))))
A21: 9 | C21: =IF(B21="","",IFERROR(INDEX(Тарификатор!$B$5:$B$2356,MATCH(B21,Тарификатор!$A$5:$A$2356,0)),"НЕТ ТАКОГО АРТИКУЛА")) | D21: =IF(B21="","",IFERROR(INDEX(Тарификатор!$C$5:$C$2356,MATCH(B21,Тарификатор!$A$5:$A$2356,0)),"")) | F21: =IF(B21="","",IFERROR(INDEX(Тарификатор!$D$5:$D$2356,MATCH(B21,Тарификатор!$A$5:$A$2356,0)),"")) | G21: =IF(B21="","",IFERROR(IF($M$8="Мск",INDEX(Тарификатор!$F$5:$F$2356,MATCH(B21,Тарификатор!$A$5:$A$2356,0)),INDEX(Тарификатор!$E$5:$E$2356,MATCH(B21,Тарификатор!$A$5:$A$2356,0))),0)) | H21: =IF(B21="","",IFERROR(IF($M$8="Мск",INDEX(Тарификатор!$J$5:$J$2356,MATCH(B21,Тарификатор!$A$5:$A$2356,0)),INDEX(Тарификатор!$I$5:$I$2356,MATCH(B21,Тарификатор!$A$5:$A$2356,0))),0)) | I21: =IF(OR(G21="",E21=""),"",ROUND(G21*E21,2)) | J21: =IF(B21="","",IFERROR(IF($M$8="Мск",INDEX(Тарификатор!$H$5:$H$2356,MATCH(B21,Тарификатор!$A$5:$A$2356,0)),INDEX(Тарификатор!$G$5:$G$2356,MATCH(B21,Тарификатор!$A$5:$A$2356,0))),0)) | K21: =IF(OR(J21="",E21=""),"",ROUND(J21*E21,2)) | L21: =IF(F21="","",IFERROR(INDEX('Расходники к работам'!$C$5:$C$24,MATCH(F21,'Расходники к работам'!$A$5:$A$24,0)),0)) | M21: =IF(K21="","",ROUND(K21*L21,2)) | N21: =IF(B21="","",SUMIF($B$58:$B$177,B21,$L$58:$L$177)) | O21: =IF(B21="","",SUMIF($B$58:$B$177,B21,$O$58:$O$177)) | P21: =IF(OR(I21="",E21="",E21=0),"",ROUND((I21+O21)/E21,2)) | Q21: =IF(K21="","",K21+M21+N21) | R21: =IF(Q21="","",IF(N(I21)+N(O21)=0,"",1-Q21/(N(I21)+N(O21))))
A22: 10 | C22: =IF(B22="","",IFERROR(INDEX(Тарификатор!$B$5:$B$2356,MATCH(B22,Тарификатор!$A$5:$A$2356,0)),"НЕТ ТАКОГО АРТИКУЛА")) | D22: =IF(B22="","",IFERROR(INDEX(Тарификатор!$C$5:$C$2356,MATCH(B22,Тарификатор!$A$5:$A$2356,0)),"")) | F22: =IF(B22="","",IFERROR(INDEX(Тарификатор!$D$5:$D$2356,MATCH(B22,Тарификатор!$A$5:$A$2356,0)),"")) | G22: =IF(B22="","",IFERROR(IF($M$8="Мск",INDEX(Тарификатор!$F$5:$F$2356,MATCH(B22,Тарификатор!$A$5:$A$2356,0)),INDEX(Тарификатор!$E$5:$E$2356,MATCH(B22,Тарификатор!$A$5:$A$2356,0))),0)) | H22: =IF(B22="","",IFERROR(IF($M$8="Мск",INDEX(Тарификатор!$J$5:$J$2356,MATCH(B22,Тарификатор!$A$5:$A$2356,0)),INDEX(Тарификатор!$I$5:$I$2356,MATCH(B22,Тарификатор!$A$5:$A$2356,0))),0)) | I22: =IF(OR(G22="",E22=""),"",ROUND(G22*E22,2)) | J22: =IF(B22="","",IFERROR(IF($M$8="Мск",INDEX(Тарификатор!$H$5:$H$2356,MATCH(B22,Тарификатор!$A$5:$A$2356,0)),INDEX(Тарификатор!$G$5:$G$2356,MATCH(B22,Тарификатор!$A$5:$A$2356,0))),0)) | K22: =IF(OR(J22="",E22=""),"",ROUND(J22*E22,2)) | L22: =IF(F22="","",IFERROR(INDEX('Расходники к работам'!$C$5:$C$24,MATCH(F22,'Расходники к работам'!$A$5:$A$24,0)),0)) | M22: =IF(K22="","",ROUND(K22*L22,2)) | N22: =IF(B22="","",SUMIF($B$58:$B$177,B22,$L$58:$L$177)) | O22: =IF(B22="","",SUMIF($B$58:$B$177,B22,$O$58:$O$177)) | P22: =IF(OR(I22="",E22="",E22=0),"",ROUND((I22+O22)/E22,2)) | Q22: =IF(K22="","",K22+M22+N22) | R22: =IF(Q22="","",IF(N(I22)+N(O22)=0,"",1-Q22/(N(I22)+N(O22))))
A23: 11 | C23: =IF(B23="","",IFERROR(INDEX(Тарификатор!$B$5:$B$2356,MATCH(B23,Тарификатор!$A$5:$A$2356,0)),"НЕТ ТАКОГО АРТИКУЛА")) | D23: =IF(B23="","",IFERROR(INDEX(Тарификатор!$C$5:$C$2356,MATCH(B23,Тарификатор!$A$5:$A$2356,0)),"")) | F23: =IF(B23="","",IFERROR(INDEX(Тарификатор!$D$5:$D$2356,MATCH(B23,Тарификатор!$A$5:$A$2356,0)),"")) | G23: =IF(B23="","",IFERROR(IF($M$8="Мск",INDEX(Тарификатор!$F$5:$F$2356,MATCH(B23,Тарификатор!$A$5:$A$2356,0)),INDEX(Тарификатор!$E$5:$E$2356,MATCH(B23,Тарификатор!$A$5:$A$2356,0))),0)) | H23: =IF(B23="","",IFERROR(IF($M$8="Мск",INDEX(Тарификатор!$J$5:$J$2356,MATCH(B23,Тарификатор!$A$5:$A$2356,0)),INDEX(Тарификатор!$I$5:$I$2356,MATCH(B23,Тарификатор!$A$5:$A$2356,0))),0)) | I23: =IF(OR(G23="",E23=""),"",ROUND(G23*E23,2)) | J23: =IF(B23="","",IFERROR(IF($M$8="Мск",INDEX(Тарификатор!$H$5:$H$2356,MATCH(B23,Тарификатор!$A$5:$A$2356,0)),INDEX(Тарификатор!$G$5:$G$2356,MATCH(B23,Тарификатор!$A$5:$A$2356,0))),0)) | K23: =IF(OR(J23="",E23=""),"",ROUND(J23*E23,2)) | L23: =IF(F23="","",IFERROR(INDEX('Расходники к работам'!$C$5:$C$24,MATCH(F23,'Расходники к работам'!$A$5:$A$24,0)),0)) | M23: =IF(K23="","",ROUND(K23*L23,2)) | N23: =IF(B23="","",SUMIF($B$58:$B$177,B23,$L$58:$L$177)) | O23: =IF(B23="","",SUMIF($B$58:$B$177,B23,$O$58:$O$177)) | P23: =IF(OR(I23="",E23="",E23=0),"",ROUND((I23+O23)/E23,2)) | Q23: =IF(K23="","",K23+M23+N23) | R23: =IF(Q23="","",IF(N(I23)+N(O23)=0,"",1-Q23/(N(I23)+N(O23))))
A24: 12 | C24: =IF(B24="","",IFERROR(INDEX(Тарификатор!$B$5:$B$2356,MATCH(B24,Тарификатор!$A$5:$A$2356,0)),"НЕТ ТАКОГО АРТИКУЛА")) | D24: =IF(B24="","",IFERROR(INDEX(Тарификатор!$C$5:$C$2356,MATCH(B24,Тарификатор!$A$5:$A$2356,0)),"")) | F24: =IF(B24="","",IFERROR(INDEX(Тарификатор!$D$5:$D$2356,MATCH(B24,Тарификатор!$A$5:$A$2356,0)),"")) | G24: =IF(B24="","",IFERROR(IF($M$8="Мск",INDEX(Тарификатор!$F$5:$F$2356,MATCH(B24,Тарификатор!$A$5:$A$2356,0)),INDEX(Тарификатор!$E$5:$E$2356,MATCH(B24,Тарификатор!$A$5:$A$2356,0))),0)) | H24: =IF(B24="","",IFERROR(IF($M$8="Мск",INDEX(Тарификатор!$J$5:$J$2356,MATCH(B24,Тарификатор!$A$5:$A$2356,0)),INDEX(Тарификатор!$I$5:$I$2356,MATCH(B24,Тарификатор!$A$5:$A$2356,0))),0)) | I24: =IF(OR(G24="",E24=""),"",ROUND(G24*E24,2)) | J24: =IF(B24="","",IFERROR(IF($M$8="Мск",INDEX(Тарификатор!$H$5:$H$2356,MATCH(B24,Тарификатор!$A$5:$A$2356,0)),INDEX(Тарификатор!$G$5:$G$2356,MATCH(B24,Тарификатор!$A$5:$A$2356,0))),0)) | K24: =IF(OR(J24="",E24=""),"",ROUND(J24*E24,2)) | L24: =IF(F24="","",IFERROR(INDEX('Расходники к работам'!$C$5:$C$24,MATCH(F24,'Расходники к работам'!$A$5:$A$24,0)),0)) | M24: =IF(K24="","",ROUND(K24*L24,2)) | N24: =IF(B24="","",SUMIF($B$58:$B$177,B24,$L$58:$L$177)) | O24: =IF(B24="","",SUMIF($B$58:$B$177,B24,$O$58:$O$177)) | P24: =IF(OR(I24="",E24="",E24=0),"",ROUND((I24+O24)/E24,2)) | Q24: =IF(K24="","",K24+M24+N24) | R24: =IF(Q24="","",IF(N(I24)+N(O24)=0,"",1-Q24/(N(I24)+N(O24))))
A25: 13 | C25: =IF(B25="","",IFERROR(INDEX(Тарификатор!$B$5:$B$2356,MATCH(B25,Тарификатор!$A$5:$A$2356,0)),"НЕТ ТАКОГО АРТИКУЛА")) | D25: =IF(B25="","",IFERROR(INDEX(Тарификатор!$C$5:$C$2356,MATCH(B25,Тарификатор!$A$5:$A$2356,0)),"")) | F25: =IF(B25="","",IFERROR(INDEX(Тарификатор!$D$5:$D$2356,MATCH(B25,Тарификатор!$A$5:$A$2356,0)),"")) | G25: =IF(B25="","",IFERROR(IF($M$8="Мск",INDEX(Тарификатор!$F$5:$F$2356,MATCH(B25,Тарификатор!$A$5:$A$2356,0)),INDEX(Тарификатор!$E$5:$E$2356,MATCH(B25,Тарификатор!$A$5:$A$2356,0))),0)) | H25: =IF(B25="","",IFERROR(IF($M$8="Мск",INDEX(Тарификатор!$J$5:$J$2356,MATCH(B25,Тарификатор!$A$5:$A$2356,0)),INDEX(Тарификатор!$I$5:$I$2356,MATCH(B25,Тарификатор!$A$5:$A$2356,0))),0)) | I25: =IF(OR(G25="",E25=""),"",ROUND(G25*E25,2)) | J25: =IF(B25="","",IFERROR(IF($M$8="Мск",INDEX(Тарификатор!$H$5:$H$2356,MATCH(B25,Тарификатор!$A$5:$A$2356,0)),INDEX(Тарификатор!$G$5:$G$2356,MATCH(B25,Тарификатор!$A$5:$A$2356,0))),0)) | K25: =IF(OR(J25="",E25=""),"",ROUND(J25*E25,2)) | L25: =IF(F25="","",IFERROR(INDEX('Расходники к работам'!$C$5:$C$24,MATCH(F25,'Расходники к работам'!$A$5:$A$24,0)),0)) | M25: =IF(K25="","",ROUND(K25*L25,2)) | N25: =IF(B25="","",SUMIF($B$58:$B$177,B25,$L$58:$L$177)) | O25: =IF(B25="","",SUMIF($B$58:$B$177,B25,$O$58:$O$177)) | P25: =IF(OR(I25="",E25="",E25=0),"",ROUND((I25+O25)/E25,2)) | Q25: =IF(K25="","",K25+M25+N25) | R25: =IF(Q25="","",IF(N(I25)+N(O25)=0,"",1-Q25/(N(I25)+N(O25))))
A26: 14 | C26: =IF(B26="","",IFERROR(INDEX(Тарификатор!$B$5:$B$2356,MATCH(B26,Тарификатор!$A$5:$A$2356,0)),"НЕТ ТАКОГО АРТИКУЛА")) | D26: =IF(B26="","",IFERROR(INDEX(Тарификатор!$C$5:$C$2356,MATCH(B26,Тарификатор!$A$5:$A$2356,0)),"")) | F26: =IF(B26="","",IFERROR(INDEX(Тарификатор!$D$5:$D$2356,MATCH(B26,Тарификатор!$A$5:$A$2356,0)),"")) | G26: =IF(B26="","",IFERROR(IF($M$8="Мск",INDEX(Тарификатор!$F$5:$F$2356,MATCH(B26,Тарификатор!$A$5:$A$2356,0)),INDEX(Тарификатор!$E$5:$E$2356,MATCH(B26,Тарификатор!$A$5:$A$2356,0))),0)) | H26: =IF(B26="","",IFERROR(IF($M$8="Мск",INDEX(Тарификатор!$J$5:$J$2356,MATCH(B26,Тарификатор!$A$5:$A$2356,0)),INDEX(Тарификатор!$I$5:$I$2356,MATCH(B26,Тарификатор!$A$5:$A$2356,0))),0)) | I26: =IF(OR(G26="",E26=""),"",ROUND(G26*E26,2)) | J26: =IF(B26="","",IFERROR(IF($M$8="Мск",INDEX(Тарификатор!$H$5:$H$2356,MATCH(B26,Тарификатор!$A$5:$A$2356,0)),INDEX(Тарификатор!$G$5:$G$2356,MATCH(B26,Тарификатор!$A$5:$A$2356,0))),0)) | K26: =IF(OR(J26="",E26=""),"",ROUND(J26*E26,2)) | L26: =IF(F26="","",IFERROR(INDEX('Расходники к работам'!$C$5:$C$24,MATCH(F26,'Расходники к работам'!$A$5:$A$24,0)),0)) | M26: =IF(K26="","",ROUND(K26*L26,2)) | N26: =IF(B26="","",SUMIF($B$58:$B$177,B26,$L$58:$L$177)) | O26: =IF(B26="","",SUMIF($B$58:$B$177,B26,$O$58:$O$177)) | P26: =IF(OR(I26="",E26="",E26=0),"",ROUND((I26+O26)/E26,2)) | Q26: =IF(K26="","",K26+M26+N26) | R26: =IF(Q26="","",IF(N(I26)+N(O26)=0,"",1-Q26/(N(I26)+N(O26))))
... A52: 40 | C52: =IF(B52="","",IFERROR(INDEX(Тарификатор!$B$5:$B$2356,MATCH(B52,Тарификатор!$A$5:$A$2356,0)),"НЕТ ТАКОГО АРТИКУЛА")) | D52: =IF(B52="","",IFERROR(INDEX(Тарификатор!$C$5:$C$2356,MATCH(B52,Тарификатор!$A$5:$A$2356,0)),"")) | F52: =IF(B52="","",IFERROR(INDEX(Тарификатор!$D$5:$D$2356,MATCH(B52,Тарификатор!$A$5:$A$2356,0)),"")) | G52: =IF(B52="","",IFERROR(IF($M$8="Мск",INDEX(Тарификатор!$F$5:$F$2356,MATCH(B52,Тарификатор!$A$5:$A$2356,0)),INDEX(Тарификатор!$E$5:$E$2356,MATCH(B52,Тарификатор!$A$5:$A$2356,0))),0)) | H52: =IF(B52="","",IFERROR(IF($M$8="Мск",INDEX(Тарификатор!$J$5:$J$2356,MATCH(B52,Тарификатор!$A$5:$A$2356,0)),INDEX(Тарификатор!$I$5:$I$2356,MATCH(B52,Тарификатор!$A$5:$A$2356,0))),0)) | I52: =IF(OR(G52="",E52=""),"",ROUND(G52*E52,2)) | J52: =IF(B52="","",IFERROR(IF($M$8="Мск",INDEX(Тарификатор!$H$5:$H$2356,MATCH(B52,Тарификатор!$A$5:$A$2356,0)),INDEX(Тарификатор!$G$5:$G$2356,MATCH(B52,Тарификатор!$A$5:$A$2356,0))),0)) | K52: =IF(OR(J52="",E52=""),"",ROUND(J52*E52,2)) | L52: =IF(F52="","",IFERROR(INDEX('Расходники к работам'!$C$5:$C$24,MATCH(F52,'Расходники к работам'!$A$5:$A$24,0)),0)) | M52: =IF(K52="","",ROUND(K52*L52,2)) | N52: =IF(B52="","",SUMIF($B$58:$B$177,B52,$L$58:$L$177)) | O52: =IF(B52="","",SUMIF($B$58:$B$177,B52,$O$58:$O$177)) | P52: =IF(OR(I52="",E52="",E52=0),"",ROUND((I52+O52)/E52,2)) | Q52: =IF(K52="","",K52+M52+N52) | R52: =IF(Q52="","",IF(N(I52)+N(O52)=0,"",1-Q52/(N(I52)+N(O52))))
C53: ИТОГО работы | I53: =SUM(I13:I52) -> 714000 | K53: =SUM(K13:K52) -> 412000 | M53: =SUM(M13:M52) -> 8240 | N53: =SUM(N13:N52) -> 529867.88 | O53: =SUM(O13:O52) -> 593651.75 | Q53: =SUM(Q13:Q52) -> 950107.88
C54: Строки 1–2 — пример, замените своими. Работы, которых нет в тарификаторе, — запрос сметчику.
A56: 2. МАТЕРИАЛЫ — комплект к каждой работе (артикул работы + расход на её единицу) или отдельно (артикул пустой, расход = количество)
A57: № | B57: Артикул работы (пусто — отдельно) | C57: Материал | D57: Категория (список) | E57: Ед. | F57: Расход на ед. работы (или кол-во, если без работы) | G57: Кол-во по КП = расход × объём работы | H57: Закупка за ед. б/НДС | I57: Поставщик / источник цены | J57: Отходы, % | K57: С/с за ед. = закупка × (1+отходы) × (1+доставка) × (1+резерв+деньги) | L57: С/с итого | M57: Наценка, % (категория, форма КП; для подтянутых работ — как раздельная) | N57: Цена в КП за ед. = с/с × (1 + наценка) | O57: Сумма в КП | P57: Розница для юрлица на сайте, за ед. (ввод) | Q57: Проверка
A58: 1 | B58: 7.2.25 | C58: Керамогранит 600×600 технический | D58: Плитка, керамогранит | E58: м2 | F58: 1 | G58: =IF(F58="","",IF(B58="",F58,IFERROR(F58*INDEX($E$13:$E$52,MATCH(B58,$B$13:$B$52,0)),"нет работы"))) -> 250 | H58: 1150 | I58: Керама Марацци, КП №… | J58: =IF(D58="","",IFERROR(INDEX('Категории и наценки'!$B$5:$B$26,MATCH(D58,'Категории и наценки'!$A$5:$A$26,0)),0)) -> 0.1 | K58: =IF(OR(H58="",D58=""),"",ROUND(H58*(1+J58)*(1+$M$3)*(1+$M$4+$M$5),2)) -> 1302.95 | L58: =IF(OR(K58="",NOT(ISNUMBER(G58))),"",ROUND(K58*G58,2)) -> 325737.5 | M58: =IF(D58="","",IFERROR(IF($D$5="Под ключ",IF(AND(B58<>"",IFERROR(INDEX($H$13:$H$52,MATCH(B58,$B$13:$B$52,0)),0)>0),INDEX('Категории и наценки'!$C$5:$C$26,MATCH(D58,'Категории и наценки'!$A$5:$A$26,0)),INDEX('Категории и наценки'!$D$5:$D$26,MATCH(D58,'Категории и наценки'!$A$5:$A$26,0))),INDEX('Категории и наценки'!$C$5:$C$26,MATCH(D58,'Категории и наценки'!$A$5:$A$26,0))),0)) -> 0.12 | N58: =IF(K58="","",ROUND(K58*(1+M58),2)) -> 1459.3 | O58: =IF(OR(N58="",NOT(ISNUMBER(G58))),"",ROUND(N58*G58,2)) -> 364825 | Q58: =IF(OR(P58="",N58=""),"—",IF(N58>P58,"ВЫШЕ РОЗНИЦЫ","ок")) -> —
A59: 2 | B59: 7.2.25 | C59: Клей плиточный C2 | D59: Сухие смеси, штукатурки, шпаклёвки | E59: кг | F59: 5.5 | G59: =IF(F59="","",IF(B59="",F59,IFERROR(F59*INDEX($E$13:$E$52,MATCH(B59,$B$13:$B$52,0)),"нет работы"))) -> 1375 | H59: 28 | I59: Петрович | J59: =IF(D59="","",IFERROR(INDEX('Категории и наценки'!$B$5:$B$26,MATCH(D59,'Категории и наценки'!$A$5:$A$26,0)),0)) -> 0.05 | K59: =IF(OR(H59="",D59=""),"",ROUND(H59*(1+J59)*(1+$M$3)*(1+$M$4+$M$5),2)) -> 30.28 | L59: =IF(OR(K59="",NOT(ISNUMBER(G59))),"",ROUND(K59*G59,2)) -> 41635 | M59: =IF(D59="","",IFERROR(IF($D$5="Под ключ",IF(AND(B59<>"",IFERROR(INDEX($H$13:$H$52,MATCH(B59,$B$13:$B$52,0)),0)>0),INDEX('Категории и наценки'!$C$5:$C$26,MATCH(D59,'Категории и наценки'!$A$5:$A$26,0)),INDEX('Категории и наценки'!$D$5:$D$26,MATCH(D59,'Категории и наценки'!$A$5:$A$26,0))),INDEX('Категории и наценки'!$C$5:$C$26,MATCH(D59,'Категории и наценки'!$A$5:$A$26,0))),0)) -> 0.12 | N59: =IF(K59="","",ROUND(K59*(1+M59),2)) -> 33.91 | O59: =IF(OR(N59="",NOT(ISNUMBER(G59))),"",ROUND(N59*G59,2)) -> 46626.25 | Q59: =IF(OR(P59="",N59=""),"—",IF(N59>P59,"ВЫШЕ РОЗНИЦЫ","ок")) -> —
A60: 3 | B60: 7.2.25 | C60: Затирка цементная | D60: Сухие смеси, штукатурки, шпаклёвки | E60: кг | F60: 0.4 | G60: =IF(F60="","",IF(B60="",F60,IFERROR(F60*INDEX($E$13:$E$52,MATCH(B60,$B$13:$B$52,0)),"нет работы"))) -> 100 | H60: 120 | I60: Петрович | J60: =IF(D60="","",IFERROR(INDEX('Категории и наценки'!$B$5:$B$26,MATCH(D60,'Категории и наценки'!$A$5:$A$26,0)),0)) -> 0.05 | K60: =IF(OR(H60="",D60=""),"",ROUND(H60*(1+J60)*(1+$M$3)*(1+$M$4+$M$5),2)) -> 129.78 | L60: =IF(OR(K60="",NOT(ISNUMBER(G60))),"",ROUND(K60*G60,2)) -> 12978 | M60: =IF(D60="","",IFERROR(IF($D$5="Под ключ",IF(AND(B60<>"",IFERROR(INDEX($H$13:$H$52,MATCH(B60,$B$13:$B$52,0)),0)>0),INDEX('Категории и наценки'!$C$5:$C$26,MATCH(D60,'Категории и наценки'!$A$5:$A$26,0)),INDEX('Категории и наценки'!$D$5:$D$26,MATCH(D60,'Категории и наценки'!$A$5:$A$26,0))),INDEX('Категории и наценки'!$C$5:$C$26,MATCH(D60,'Категории и наценки'!$A$5:$A$26,0))),0)) -> 0.12 | N60: =IF(K60="","",ROUND(K60*(1+M60),2)) -> 145.35 | O60: =IF(OR(N60="",NOT(ISNUMBER(G60))),"",ROUND(N60*G60,2)) -> 14535 | Q60: =IF(OR(P60="",N60=""),"—",IF(N60>P60,"ВЫШЕ РОЗНИЦЫ","ок")) -> —
A61: 4 | B61: 7.2.25 | C61: Грунт глубокого проникновения | D61: Краски, грунты, ЛКМ | E61: л | F61: 0.15 | G61: =IF(F61="","",IF(B61="",F61,IFERROR(F61*INDEX($E$13:$E$52,MATCH(B61,$B$13:$B$52,0)),"нет работы"))) -> 37.5 | H61: 60 | I61: Петрович | J61: =IF(D61="","",IFERROR(INDEX('Категории и наценки'!$B$5:$B$26,MATCH(D61,'Категории и наценки'!$A$5:$A$26,0)),0)) -> 0.05 | K61: =IF(OR(H61="",D61=""),"",ROUND(H61*(1+J61)*(1+$M$3)*(1+$M$4+$M$5),2)) -> 64.89 | L61: =IF(OR(K61="",NOT(ISNUMBER(G61))),"",ROUND(K61*G61,2)) -> 2433.38 | M61: =IF(D61="","",IFERROR(IF($D$5="Под ключ",IF(AND(B61<>"",IFERROR(INDEX($H$13:$H$52,MATCH(B61,$B$13:$B$52,0)),0)>0),INDEX('Категории и наценки'!$C$5:$C$26,MATCH(D61,'Категории и наценки'!$A$5:$A$26,0)),INDEX('Категории и наценки'!$D$5:$D$26,MATCH(D61,'Категории и наценки'!$A$5:$A$26,0))),INDEX('Категории и наценки'!$C$5:$C$26,MATCH(D61,'Категории и наценки'!$A$5:$A$26,0))),0)) -> 0.12 | N61: =IF(K61="","",ROUND(K61*(1+M61),2)) -> 72.68 | O61: =IF(OR(N61="",NOT(ISNUMBER(G61))),"",ROUND(N61*G61,2)) -> 2725.5 | Q61: =IF(OR(P61="",N61=""),"—",IF(N61>P61,"ВЫШЕ РОЗНИЦЫ","ок")) -> —
A62: 5 | B62: 7.2.25 | C62: СВП клипсы 1,5 мм | D62: Прочее | E62: шт | F62: 8 | G62: =IF(F62="","",IF(B62="",F62,IFERROR(F62*INDEX($E$13:$E$52,MATCH(B62,$B$13:$B$52,0)),"нет работы"))) -> 2000 | H62: 3 | I62: Лемана ПРО | J62: =IF(D62="","",IFERROR(INDEX('Категории и наценки'!$B$5:$B$26,MATCH(D62,'Категории и наценки'!$A$5:$A$26,0)),0)) -> 0.03 | K62: =IF(OR(H62="",D62=""),"",ROUND(H62*(1+J62)*(1+$M$3)*(1+$M$4+$M$5),2)) -> 3.18 | L62: =IF(OR(K62="",NOT(ISNUMBER(G62))),"",ROUND(K62*G62,2)) -> 6360 | M62: =IF(D62="","",IFERROR(IF($D$5="Под ключ",IF(AND(B62<>"",IFERROR(INDEX($H$13:$H$52,MATCH(B62,$B$13:$B$52,0)),0)>0),INDEX('Категории и наценки'!$C$5:$C$26,MATCH(D62,'Категории и наценки'!$A$5:$A$26,0)),INDEX('Категории и наценки'!$D$5:$D$26,MATCH(D62,'Категории и наценки'!$A$5:$A$26,0))),INDEX('Категории и наценки'!$C$5:$C$26,MATCH(D62,'Категории и наценки'!$A$5:$A$26,0))),0)) -> 0.15 | N62: =IF(K62="","",ROUND(K62*(1+M62),2)) -> 3.66 | O62: =IF(OR(N62="",NOT(ISNUMBER(G62))),"",ROUND(N62*G62,2)) -> 7320 | Q62: =IF(OR(P62="",N62=""),"—",IF(N62>P62,"ВЫШЕ РОЗНИЦЫ","ок")) -> —
A63: 6 | B63: 10.2.N3 | C63: Кабель ВВГнг(А)-LS 3×2,5 | D63: Кабель и провод | E63: м | F63: 1 | G63: =IF(F63="","",IF(B63="",F63,IFERROR(F63*INDEX($E$13:$E$52,MATCH(B63,$B$13:$B$52,0)),"нет работы"))) -> 1200 | H63: 92 | I63: ЭТМ, счёт №… | J63: =IF(D63="","",IFERROR(INDEX('Категории и наценки'!$B$5:$B$26,MATCH(D63,'Категории и наценки'!$A$5:$A$26,0)),0)) -> 0.04 | K63: =IF(OR(H63="",D63=""),"",ROUND(H63*(1+J63)*(1+$M$3)*(1+$M$4+$M$5),2)) -> 98.55 | L63: =IF(OR(K63="",NOT(ISNUMBER(G63))),"",ROUND(K63*G63,2)) -> 118260 | M63: =IF(D63="","",IFERROR(IF($D$5="Под ключ",IF(AND(B63<>"",IFERROR(INDEX($H$13:$H$52,MATCH(B63,$B$13:$B$52,0)),0)>0),INDEX('Категории и наценки'!$C$5:$C$26,MATCH(D63,'Категории и наценки'!$A$5:$A$26,0)),INDEX('Категории и наценки'!$D$5:$D$26,MATCH(D63,'Категории и наценки'!$A$5:$A$26,0))),INDEX('Категории и наценки'!$C$5:$C$26,MATCH(D63,'Категории и наценки'!$A$5:$A$26,0))),0)) -> 0.12 | N63: =IF(K63="","",ROUND(K63*(1+M63),2)) -> 110.38 | O63: =IF(OR(N63="",NOT(ISNUMBER(G63))),"",ROUND(N63*G63,2)) -> 132456 | Q63: =IF(OR(P63="",N63=""),"—",IF(N63>P63,"ВЫШЕ РОЗНИЦЫ","ок")) -> —
A64: 7 | B64: 10.2.N3 | C64: Клипса для кабеля | D64: Электроустановочные изделия, щиты, автоматы | E64: шт | F64: 3 | G64: =IF(F64="","",IF(B64="",F64,IFERROR(F64*INDEX($E$13:$E$52,MATCH(B64,$B$13:$B$52,0)),"нет работы"))) -> 3600 | H64: 4 | I64: ЭТМ | J64: =IF(D64="","",IFERROR(INDEX('Категории и наценки'!$B$5:$B$26,MATCH(D64,'Категории и наценки'!$A$5:$A$26,0)),0)) -> 0.01 | K64: =IF(OR(H64="",D64=""),"",ROUND(H64*(1+J64)*(1+$M$3)*(1+$M$4+$M$5),2)) -> 4.16 | L64: =IF(OR(K64="",NOT(ISNUMBER(G64))),"",ROUND(K64*G64,2)) -> 14976 | M64: =IF(D64="","",IFERROR(IF($D$5="Под ключ",IF(AND(B64<>"",IFERROR(INDEX($H$13:$H$52,MATCH(B64,$B$13:$B$52,0)),0)>0),INDEX('Категории и наценки'!$C$5:$C$26,MATCH(D64,'Категории и наценки'!$A$5:$A$26,0)),INDEX('Категории и наценки'!$D$5:$D$26,MATCH(D64,'Категории и наценки'!$A$5:$A$26,0))),INDEX('Категории и наценки'!$C$5:$C$26,MATCH(D64,'Категории и наценки'!$A$5:$A$26,0))),0)) -> 0.12 | N64: =IF(K64="","",ROUND(K64*(1+M64),2)) -> 4.66 | O64: =IF(OR(N64="",NOT(ISNUMBER(G64))),"",ROUND(N64*G64,2)) -> 16776 | Q64: =IF(OR(P64="",N64=""),"—",IF(N64>P64,"ВЫШЕ РОЗНИЦЫ","ок")) -> —
A65: 8 | B65: 10.2.N3 | C65: Дюбель-гвоздь 6×40 | D65: Электроустановочные изделия, щиты, автоматы | E65: шт | F65: 3 | G65: =IF(F65="","",IF(B65="",F65,IFERROR(F65*INDEX($E$13:$E$52,MATCH(B65,$B$13:$B$52,0)),"нет работы"))) -> 3600 | H65: 2 | I65: ЭТМ | J65: =IF(D65="","",IFERROR(INDEX('Категории и наценки'!$B$5:$B$26,MATCH(D65,'Категории и наценки'!$A$5:$A$26,0)),0)) -> 0.01 | K65: =IF(OR(H65="",D65=""),"",ROUND(H65*(1+J65)*(1+$M$3)*(1+$M$4+$M$5),2)) -> 2.08 | L65: =IF(OR(K65="",NOT(ISNUMBER(G65))),"",ROUND(K65*G65,2)) -> 7488 | M65: =IF(D65="","",IFERROR(IF($D$5="Под ключ",IF(AND(B65<>"",IFERROR(INDEX($H$13:$H$52,MATCH(B65,$B$13:$B$52,0)),0)>0),INDEX('Категории и наценки'!$C$5:$C$26,MATCH(D65,'Категории и наценки'!$A$5:$A$26,0)),INDEX('Категории и наценки'!$D$5:$D$26,MATCH(D65,'Категории и наценки'!$A$5:$A$26,0))),INDEX('Категории и наценки'!$C$5:$C$26,MATCH(D65,'Категории и наценки'!$A$5:$A$26,0))),0)) -> 0.12 | N65: =IF(K65="","",ROUND(K65*(1+M65),2)) -> 2.33 | O65: =IF(OR(N65="",NOT(ISNUMBER(G65))),"",ROUND(N65*G65,2)) -> 8388 | Q65: =IF(OR(P65="",N65=""),"—",IF(N65>P65,"ВЫШЕ РОЗНИЦЫ","ок")) -> —
A66: 9 | C66: Приточная установка 3 000 м³/ч | D66: ОБОРУДОВАНИЕ (вентустановки, кондиционеры, насосы, щиты под заказ) | E66: шт | F66: 1 | G66: =IF(F66="","",IF(B66="",F66,IFERROR(F66*INDEX($E$13:$E$52,MATCH(B66,$B$13:$B$52,0)),"нет работы"))) -> 1 | H66: 640000 | I66: КП поставщика | J66: =IF(D66="","",IFERROR(INDEX('Категории и наценки'!$B$5:$B$26,MATCH(D66,'Категории и наценки'!$A$5:$A$26,0)),0)) -> 0 | K66: =IF(OR(H66="",D66=""),"",ROUND(H66*(1+J66)*(1+$M$3)*(1+$M$4+$M$5),2)) -> 659200 | L66: =IF(OR(K66="",NOT(ISNUMBER(G66))),"",ROUND(K66*G66,2)) -> 659200 | M66: =IF(D66="","",IFERROR(IF($D$5="Под ключ",IF(AND(B66<>"",IFERROR(INDEX($H$13:$H$52,MATCH(B66,$B$13:$B$52,0)),0)>0),INDEX('Категории и наценки'!$C$5:$C$26,MATCH(D66,'Категории и наценки'!$A$5:$A$26,0)),INDEX('Категории и наценки'!$D$5:$D$26,MATCH(D66,'Категории и наценки'!$A$5:$A$26,0))),INDEX('Категории и наценки'!$C$5:$C$26,MATCH(D66,'Категории и наценки'!$A$5:$A$26,0))),0)) -> 0.1 | N66: =IF(K66="","",ROUND(K66*(1+M66),2)) -> 725120 | O66: =IF(OR(N66="",NOT(ISNUMBER(G66))),"",ROUND(N66*G66,2)) -> 725120 | Q66: =IF(OR(P66="",N66=""),"—",IF(N66>P66,"ВЫШЕ РОЗНИЦЫ","ок")) -> —
A67: 10 | G67: =IF(F67="","",IF(B67="",F67,IFERROR(F67*INDEX($E$13:$E$52,MATCH(B67,$B$13:$B$52,0)),"нет работы"))) | J67: =IF(D67="","",IFERROR(INDEX('Категории и наценки'!$B$5:$B$26,MATCH(D67,'Категории и наценки'!$A$5:$A$26,0)),0)) | K67: =IF(OR(H67="",D67=""),"",ROUND(H67*(1+J67)*(1+$M$3)*(1+$M$4+$M$5),2)) | L67: =IF(OR(K67="",NOT(ISNUMBER(G67))),"",ROUND(K67*G67,2)) | M67: =IF(D67="","",IFERROR(IF($D$5="Под ключ",IF(AND(B67<>"",IFERROR(INDEX($H$13:$H$52,MATCH(B67,$B$13:$B$52,0)),0)>0),INDEX('Категории и наценки'!$C$5:$C$26,MATCH(D67,'Категории и наценки'!$A$5:$A$26,0)),INDEX('Категории и наценки'!$D$5:$D$26,MATCH(D67,'Категории и наценки'!$A$5:$A$26,0))),INDEX('Категории и наценки'!$C$5:$C$26,MATCH(D67,'Категории и наценки'!$A$5:$A$26,0))),0)) | N67: =IF(K67="","",ROUND(K67*(1+M67),2)) | O67: =IF(OR(N67="",NOT(ISNUMBER(G67))),"",ROUND(N67*G67,2)) | Q67: =IF(OR(P67="",N67=""),"—",IF(N67>P67,"ВЫШЕ РОЗНИЦЫ","ок")) -> —
A68: 11 | G68: =IF(F68="","",IF(B68="",F68,IFERROR(F68*INDEX($E$13:$E$52,MATCH(B68,$B$13:$B$52,0)),"нет работы"))) | J68: =IF(D68="","",IFERROR(INDEX('Категории и наценки'!$B$5:$B$26,MATCH(D68,'Категории и наценки'!$A$5:$A$26,0)),0)) | K68: =IF(OR(H68="",D68=""),"",ROUND(H68*(1+J68)*(1+$M$3)*(1+$M$4+$M$5),2)) | L68: =IF(OR(K68="",NOT(ISNUMBER(G68))),"",ROUND(K68*G68,2)) | M68: =IF(D68="","",IFERROR(IF($D$5="Под ключ",IF(AND(B68<>"",IFERROR(INDEX($H$13:$H$52,MATCH(B68,$B$13:$B$52,0)),0)>0),INDEX('Категории и наценки'!$C$5:$C$26,MATCH(D68,'Категории и наценки'!$A$5:$A$26,0)),INDEX('Категории и наценки'!$D$5:$D$26,MATCH(D68,'Категории и наценки'!$A$5:$A$26,0))),INDEX('Категории и наценки'!$C$5:$C$26,MATCH(D68,'Категории и наценки'!$A$5:$A$26,0))),0)) | N68: =IF(K68="","",ROUND(K68*(1+M68),2)) | O68: =IF(OR(N68="",NOT(ISNUMBER(G68))),"",ROUND(N68*G68,2)) | Q68: =IF(OR(P68="",N68=""),"—",IF(N68>P68,"ВЫШЕ РОЗНИЦЫ","ок")) -> —
...

Sheet Комплекты материалов
A1: КОМПЛЕКТЫ МАТЕРИАЛОВ К РАСЦЕНКАМ — РАСХОД НА ЕДИНИЦУ РАБОТЫ
A2: В материалы расценки входит ВСЁ, что по технологии уходит в работу: для укладки плитки — плитка, клей, затирка, грунт, крестики/СВП, демпферная лента. Расход — по технологическим картам и нормам производителей (Knauf, Ceresit, ТехноНИКОЛЬ и т. п.), без отходов: отходы добавляются по категории в калькуляторе. Как пользоваться: скопировать строки комплекта в калькулятор (таблица «Материалы»), указать артикул работы и цену закупки. Список пополняется по мере работы.
A4: Артикул работы | B4: Работа | C4: Ед. работы | D4: Материал | E4: Категория | F4: Ед. материала | G4: Расход на ед. работы | H4: Основание / комментарий
A5: 7.2.25 | B5: Пол из керамогранита на клее, грунт, затирка | C5: м2 | D5: Керамогранит | E5: Плитка, керамогранит | F5: м2 | G5: 1 | H5: отходы 10 % — в категории
A6: 7.2.25 | D6: Клей плиточный цементный C1/C2 | E6: Сухие смеси, штукатурки, шпаклёвки | F6: кг | G6: 5.5 | H6: 60×60, гребёнка 10 мм (Ceresit CM 11/CM 17)
A7: 7.2.25 | D7: Затирка цементная | E7: Сухие смеси, штукатурки, шпаклёвки | F7: кг | G7: 0.4 | H7: шов 2–3 мм
A8: 7.2.25 | D8: Грунт глубокого проникновения | E8: Краски, грунты, ЛКМ | F8: л | G8: 0.15
A9: 7.2.25 | D9: СВП (клипсы + клинья) / крестики | E9: Прочее | F9: шт | G9: 8 | H9: клипсы одноразовые, клинья многоразовые
A10: 7.2.25 | D10: Демпферная лента | E10: Прочее | F10: м | G10: 0.4 | H10: по периметру помещения — уточнить
A11: 8.2.22 | B11: Облицовка стен керамической плиткой на клее | C11: м2 | D11: Плитка керамическая настенная | E11: Плитка, керамогранит | F11: м2 | G11: 1
A12: 8.2.22 | D12: Клей плиточный C1 | E12: Сухие смеси, штукатурки, шпаклёвки | F12: кг | G12: 4 | H12: гребёнка 8 мм
A13: 8.2.22 | D13: Затирка цементная | E13: Сухие смеси, штукатурки, шпаклёвки | F13: кг | G13: 0.3
A14: 8.2.22 | D14: Грунт глубокого проникновения | E14: Краски, грунты, ЛКМ | F14: л | G14: 0.15
A15: 8.2.22 | D15: Крестики / СВП | E15: Прочее | F15: шт | G15: 10
A16: 8.2.22 | D16: Уголок/раскладка для плитки | E16: Прочее | F16: м | G16: 0.3 | H16: по проекту
A17: 8.1.22 | B17: Перегородка ГКЛ С111 (одинарный каркас, 1 слой с двух сторон) | C17: м2 | D17: ГКЛ 12,5 мм | E17: ГКЛ, профиль, комплектующие | F17: м2 | G17: 2 | H17: Knauf С111
A18: 8.1.22 | D18: Профиль стоечный ПС 50/50 | E18: ГКЛ, профиль, комплектующие | F18: м | G18: 2
A19: 8.1.22 | D19: Профиль направляющий ПН 50/40 | E19: ГКЛ, профиль, комплектующие | F19: м | G19: 0.7
A20: 8.1.22 | D20: Саморез TN 25 | E20: ГКЛ, профиль, комплектующие | F20: шт | G20: 29
A21: 8.1.22 | D21: Дюбель 6×40 | E21: ГКЛ, профиль, комплектующие | F21: шт | G21: 1.6
A22: 8.1.22 | D22: Лента уплотнительная | E22: ГКЛ, профиль, комплектующие | F22: м | G22: 1.2
A23: 8.1.22 | D23: Шпаклёвка для швов (Фугенфюллер) | E23: Сухие смеси, штукатурки, шпаклёвки | F23: кг | G23: 0.6
A24: 8.1.22 | D24: Лента армирующая (серпянка/бумажная) | E24: ГКЛ, профиль, комплектующие | F24: м | G24: 1.5
A25: 8.1.22 | D25: Грунт | E25: Краски, грунты, ЛКМ | F25: л | G25: 0.2
A26: 8.3.12 | B26: Подвесной потолок ГКЛ П113 одноуровневый | C26: м2 | D26: ГКЛ 12,5 мм | E26: ГКЛ, профиль, комплектующие | F26: м2 | G26: 1 | H26: Knauf П113
A27: 8.3.12 | D27: Профиль потолочный ПП 60/27 | E27: ГКЛ, профиль, комплектующие | F27: м | G27: 3.2
A28: 8.3.12 | D28: Профиль направляющий ПН 28/27 | E28: ГКЛ, профиль, комплектующие | F28: м | G28: 0.4 | H28: зависит от периметра
A29: 8.3.12 | D29: Подвес прямой / с тягой | E29: ГКЛ, профиль, комплектующие | F29: шт | G29: 0.7
A30: 8.3.12 | D30: Соединитель одноуровневый «краб» | E30: ГКЛ, профиль, комплектующие | F30: шт | G30: 1.7
A31: 8.3.12 | D31: Анкер-клин / дюбель потолочный | E31: ГКЛ, профиль, комплектующие | F31: шт | G31: 1.3
A32: 8.3.12 | D32: Саморез LN 9 | E32: ГКЛ, профиль, комплектующие | F32: шт | G32: 7
A33: 8.3.12 | D33: Саморез TN 25 | E33: ГКЛ, профиль, комплектующие | F33: шт | G33: 23
A34: 8.3.12 | D34: Шпаклёвка для швов | E34: Сухие смеси, штукатурки, шпаклёвки | F34: кг | G34: 0.5
A35: 8.3.12 | D35: Лента армирующая | E35: ГКЛ, профиль, комплектующие | F35: м | G35: 1.2
A36: 8.3.13 | B36: Подвесной потолок «Армстронг» 600×600 | C36: м2 | D36: Плита потолочная 600×600 | E36: ГКЛ, профиль, комплектующие | F36: м2 | G36: 1
A37: 8.3.13 | D37: Профиль несущий 3,7 м | E37: ГКЛ, профиль, комплектующие | F37: м | G37: 0.84
A38: 8.3.13 | D38: Профиль поперечный 1,2 м | E38: ГКЛ, профиль, комплектующие | F38: м | G38: 1.67
A39: 8.3.13 | D39: Профиль поперечный 0,6 м | E39: ГКЛ, профиль, комплектующие | F39: м | G39: 0.84
A40: 8.3.13 | D40: Уголок пристенный | E40: ГКЛ, профиль, комплектующие | F40: м | G40: 0.6 | H40: по периметру — уточнить
A41: 8.3.13 | D41: Подвес с тягой | E41: ГКЛ, профиль, комплектующие | F41: шт | G41: 0.7
...

Sheet Категории и наценки
A1: КАТЕГОРИИ МАТЕРИАЛОВ: ОТХОДЫ, НАЦЕНКА В КП, ГДЕ ПРОВЕРЯТЬ ЦЕНУ
A2: Наценка — к себестоимости материала (закупка + отходы + доставка + резервы). «Раздельная форма» — КП, где материалы и работы в разных колонках (заказчик сверяет материалы с прайсами — наценка минимальная). «Под ключ» — одна цена за единицу работы с материалом. Главное ограничение: цена материала в КП не выше розничной цены для юрлица на сайтах дистрибьюторов (колонка «Где проверять»).
A4: Категория | B4: Отходы и запас, % | C4: Наценка: раздельная форма | D4: Наценка: под ключ | E4: Где заказчик проверит цену (и где брать закупку) | F4: Примеры | G4: Комментарий
A5: Сухие смеси, штукатурки, шпаклёвки | B5: 0.05 | C5: 0.12 | D5: 0.25 | E5: Петрович, Лемана ПРО, сайты производителей (Knauf, Ceresit, Волма) | F5: Штукатурка гипсовая, шпаклёвка, клей плиточный, ровнитель
A6: Краски, грунты, ЛКМ | B6: 0.05 | C6: 0.12 | D6: 0.25 | E6: Петрович, Лемана ПРО, Tikkurila/Dulux/Текс | F6: Краска ВД, грунт, эмаль, огнезащита (кроме спец.)
A7: ГКЛ, профиль, комплектующие | B7: 0.07 | C7: 0.12 | D7: 0.25 | E7: Петрович, Knauf, Гипсополимер | F7: ГКЛ, ГВЛ, профиль ПП/ПН, подвесы
A8: Плитка, керамогранит | B8: 0.1 | C8: 0.12 | D8: 0.25 | E8: Лемана, Керама Марацци, сайты дилеров | F8: Керамогранит 60×60, плитка настенная | G8: Отходы выше при диагональной раскладке (до 15 %)
A9: Напольные покрытия (линолеум, ПВХ, ковролин) | B9: 0.08 | C9: 0.15 | D9: 0.25 | E9: Tarkett, Forbo, дилеры | F9: Коммерческий линолеум, кварцвинил, ковровая плитка
A10: Наливные и промышленные полы (эпоксид, ПУ, топпинг) | B10: 0.05 | C10: 0.15 | D10: 0.3 | E10: Дилеры производителей, цены по запросу | F10: Эпоксидное покрытие, полиуретан, упрочнитель | G10: Прайсы закрыты — можно выше
A11: Кровельные материалы и утеплитель | B11: 0.1 | C11: 0.12 | D11: 0.25 | E11: ТехноНИКОЛЬ (прайс), Петрович, Лемана | F11: Наплавляемые, ПВХ-мембрана, минвата, XPS
A12: Металлопрокат и метизы | B12: 0.05 | C12: 0.1 | D12: 0.2 | E12: Металлобазы, Металлсервис, ПКМ | F12: Швеллер, уголок, лист, труба профильная | G12: Цена по биржевым котировкам — легко проверяется
A13: Бетон и раствор товарный | B13: 0.02 | C13: 0.08 | D13: 0.15 | E13: Сайты БСУ, агрегаторы | F13: Бетон В25, раствор М150 | G13: Легко проверяется
A14: Арматура | B14: 0.05 | C14: 0.1 | D14: 0.2 | E14: Металлобазы | F14: А500С, вязальная проволока
A15: Кирпич, блоки, ЖБИ | B15: 0.05 | C15: 0.12 | D15: 0.25 | E15: Петрович, заводы ЖБИ | F15: Кирпич, газобетон, лотки, кольца
A16: Кабель и провод | B16: 0.04 | C16: 0.12 | D16: 0.25 | E16: ЭТМ, Русский Свет, Элком, Кабель.рф | F16: ВВГнг-LS, NYM, КПСЭ, UTP | G16: Цена меняется с медью — фиксировать у поставщика
A17: Электроустановочные изделия, щиты, автоматы | B17: 0.01 | C17: 0.12 | D17: 0.25 | E17: ЭТМ, Русский Свет, IEK/EKF/ABB | F17: Автоматы, щиты, розетки, кабель-каналы, лотки
A18: Светильники | B18: 0.01 | C18: 0.1 | D18: 0.2 | E18: Дилеры, сайты производителей | F18: LED-панели, промышленные, уличные | G18: Часто дают КП с ценой — проверяется
A19: Трубы и фитинги ВиК, отопления | B19: 0.04 | C19: 0.12 | D19: 0.25 | E19: Сантехкомплект, Valtec, Rehau, Петрович | F19: ПП, PE, сталь, чугун, PEX, фитинги, краны
A20: Сантехприборы | B20: 0 | C20: 0.12 | D20: 0.2 | E20: Сантехкомплект, Лемана | F20: Унитазы, раковины, смесители, трапы
A21: Воздуховоды, фасонные изделия, изоляция | B21: 0.05 | C21: 0.15 | D21: 0.3 | E21: Производители воздуховодов (цены по запросу) | F21: Оцинк. воздуховоды, фасонка, решётки, клапаны | G21: Под заказ, прайсов мало
A22: ОБОРУДОВАНИЕ (вентустановки, кондиционеры, насосы, щиты под заказ) | B22: 0 | C22: 0.1 | D22: 0.15 | E22: КП поставщика; заказчик часто сам запрашивает цену | F22: ПВУ, ККБ, сплит-системы, насосные станции | G22: Самое проверяемое — наценка минимальная
A23: Изделия под заказ (ворота, двери, окна, перегородки) | B23: 0 | C23: 0.12 | D23: 0.2 | E23: КП производителя (DoorHan, Alutech и т. п.) | F23: Секционные ворота, противопожарные двери, витражи
A24: Нерудные и дорожные (щебень, песок, асфальт) | B24: 0.05 | C24: 0.08 | D24: 0.15 | E24: Карьеры, АБЗ, агрегаторы | F24: Щебень гранитный, песок, асфальтобетон | G24: Легко проверяется, большие объёмы
A25: Специальные материалы (нет в открытых прайсах) | B25: 0.03 | C25: 0.2 | D25: 0.3 | E25: Только КП поставщиков | F25: Огнезащита спец., антистатика, химия для промполов | G25: Можно выше — заказчику не с чем сравнить
A26: Прочее | B26: 0.03 | C26: 0.15 | D26: 0.25 | E26: —

Sheet Расходники к работам
A1: РАСХОДНЫЕ МАТЕРИАЛЫ К РАБОТАМ — ЗА СЧЁТ НЕОСТРОЙ
A2: Расходники в цену бригады и в ставку часа НЕ входят — их покупаем и выдаём мы. Расходник — только то, что изнашивается или выбрасывается (диски, свёрла, коронки, валики, плёнка, мешки). Всё, что по технологии уходит в работу (клей, затирка, крестики, крепёж, пена, электроды, газ…), — МАТЕРИАЛ в комплекте расценки (лист «Комплекты материалов»). Норматив — % к оплате бригаде по специальности. Это себестоимость работ: в КП отдельной строкой не выделяется, покрывается ценой работ. Нормативы — экспертная оценка; уточнить по фактическим закупкам за 2–3 месяца (сумма расходников ÷ сумма выплат бригадам по объектам).
A4: Код | B4: Специальность | C4: Расходники, % к оплате бригаде | D4: Расходники: износ оснастки и укрывные | E4: НЕ расходник — материал в составе работы (комплект материалов расценки)
A5: RAZ | B5: Разнорабочий / демонтажник | C5: 0.04 | D5: Отрезные диски, свёрла и коронки, мешки для мусора, плёнка укрывная, скотч | E5: Контейнер и вывоз мусора — отдельная услуга
A6: ZEM | B6: Землекоп | C6: 0.01 | D6: Мешки, сигнальная лента, колышки | E6: Песок, щебень, геотекстиль
A7: BLG | B7: Благоустройство | C7: 0.02 | D7: Диски по камню, шнур разбивочный | E7: Плитка, бордюр, ЦПС, щебень
A8: BET | B8: Бетонщик / арматурщик | C8: 0.02 | D8: Диски, свёрла, плёнка для ухода за бетоном | E8: Бетон, арматура, вязальная проволока, фиксаторы, смазка опалубки
A9: KAM | B9: Каменщик | C9: 0.02 | D9: Диски, свёрла, плёнка | E9: Кирпич, блоки, раствор/клей, сетка, гибкие связи
A10: OTD | B10: Отделочник | C10: 0.03 | D10: Валики, кисти, шпатели, абразив, малярная лента, плёнка, биты | E10: Смеси, грунт, краска, ГКЛ, профиль, саморезы, дюбели, серпянка
A11: PLI | B11: Плиточник / полы | C11: 0.02 | D11: Диски и коронки алмазные, губки, малярная лента, плёнка | E11: Плитка, клей, затирка, грунт, крестики/СВП, демпферная лента
A12: KRO | B12: Кровельщик | C12: 0.02 | D12: Диски, ножи, насадки, валики прикаточные | E12: Рулонные материалы, мембрана, праймер, газ, крепёж, герметик, утеплитель
A13: FAS | B13: Фасадчик / промальп | C13: 0.02 | D13: Свёрла, биты, диски, расходники верёвочного доступа | E13: Кассеты, подсистема, утеплитель, заклёпки, анкеры, герметик
A14: SVA | B14: Сварщик / монтажник МК | C14: 0.03 | D14: Отрезные и зачистные диски, щётки, наконечники и сопла горелок | E14: Металл, электроды, проволока, газ, грунт и краска, болты
A15: SAN | B15: Сантехник | C15: 0.02 | D15: Свёрла, коронки, полотна, биты | E15: Трубы, фитинги, арматура, приборы, хомуты, лён/паста/ФУМ, герметик
A16: VEN | B16: Монтажник вентиляции | C16: 0.02 | D16: Свёрла, биты, ножницы/полотна по металлу | E16: Воздуховоды, фасонка, шпилька, анкеры, траверсы, алюм. скотч, герметик
... A24: DER | B24: Дезинфектор (ОЗДС) | C24: 0.02 | D24: Перчатки одноразовые, ветошь | E24: Препараты, приманки, ловушки, станции — материал по нормам расхода
A26: СИЗ, инструмент, оснастка, бытовки — не расходники, они в накладных расходах НЕОСТРОЙ (25 % к ставке бригады в тарификаторе).
A27: Как выдавать: прораб получает расходники под объект по нормативу (оплата бригадам × %); перерасход больше 20 % — объяснение прораба.

Sheet Тип тендера
A1: ИТОГОВАЯ НАЦЕНКА НА ВСЮ СЕБЕСТОИМОСТЬ ПО ТИПУ ТЕНДЕРА
A2: Наценка = КП ÷ полная себестоимость − 1; маржа = 1 − себестоимость ÷ КП. Ориентиры — по КП НЕОСТРОЙ август–октябрь 2026; результаты торгов (выиграли / нет) не собраны, поэтому диапазоны нужно калибровать по реестру тендеров.
A4: Тип тендера | B4: Наценка от | C4: Наценка до | D4: Маржа от | E4: Маржа до | F4: Примеры НЕОСТРОЙ
A5: Крупные сети и девелоперы — конкурентный тендер | B5: 0.3 | C5: 0.4 | D5: =1-1/(1+B5) -> 0.23076923 | E5: =1-1/(1+C5) -> 0.28571429 | F5: АГМ Р71 +30 %, ФСК лот 141 +30 %, Сегежа +40 %, АГМ Р-7 +40 %, Перекрёсток 1 тур маржа 21,9 %
A6: Переторжка / 2 тур / вход к новому заказчику | B6: 0.15 | C6: 0.25 | D6: =1-1/(1+B6) -> 0.13043478 | E6: =1-1/(1+C6) -> 0.2 | F6: ФСК лот 126 +17 %, переторжки АГМ лот 28
A7: Fit-out, частный бизнес, малые объёмы | B7: 0.45 | C7: 0.6 | D7: =1-1/(1+B7) -> 0.31034483 | E7: =1-1/(1+C7) -> 0.375 | F7: Партия Еды +50 %, Космос Невский ~+45 %, СанЛайт работы ×1,7
A8: ТО и абонентское обслуживание | B8: 0.3 | C8: 0.4 | D8: =1-1/(1+B8) -> 0.23076923 | E8: =1-1/(1+C8) -> 0.28571429 | F8: Биотек +35 %, Лемана 4 ГМ +50 %, СПАР +30 %
A9: Госзакупки 44-ФЗ / 223-ФЗ | B9: 0.15 | C9: 0.3 | D9: =1-1/(1+B9) -> 0.13043478 | E9: =1-1/(1+C9) -> 0.23076923 | F9: Считать от НМЦК: допустимое снижение = НМЦК − с/с × 1,15
A11: Нижняя граница без согласования генерального директора: | B11: 0.15

Sheet Параметры
A1: ПАРАМЕТРЫ (жёлтые ячейки можно менять — калькулятор пересчитается)
A3: Параметр | B3: Значение | C3: Пояснение
A4: Доставка: СПб | B4: 0.03 | C4: Доставка, разгрузка, подъём на этаж — % к закупке | E4: СПб
A5: Доставка: Москва | B5: 0.03 | E5: Москва
A6: Доставка: Ленобласть | B6: 0.05 | E6: Ленобласть
A7: Доставка: Подмосковье | B7: 0.05 | E7: Подмосковье
A8: Доставка: Регион | B8: 0.1 | C8: Для регионов посчитать доставку фактически (машины × тариф) и вписать % сюда (АМК Наб. Челны — 12,7 %) | E8: Регион
A9: Рост цен поставщиков, % в месяц | B9: 0.0125 | C9: Применяется, если закупка позже чем через «льготный» срок после КП и цену у поставщика не зафиксировали
A10: Льготный срок без резерва роста, мес. | B10: 2 | C10: КП поставщиков обычно держат цену 1–2 месяца
A11: Стоимость денег, % в месяц | B11: 0.02 | C11: Если материалы покупаем не из аванса — за каждый месяц от закупки до оплаты заказчиком

Sheet Тарификатор
A1: ТАРИФИКАТОР НЕОСТРОЙ — РАБОТЫ (справочно, для подстановки в калькулятор по артикулу)
A2: Значения из основного тарификатора v2. Цена работы в КП и оплата бригаде — только работа, без материалов и расходников. «Выше рынка» > 0 — цена подтянута над рынком (почасовая маржа была < 25 %).
A4: Артикул | B4: Работа | C4: Ед. | D4: Код | E4: Цена в КП СПб | F4: Цена в КП Мск | G4: Оплата бригаде СПб | H4: Оплата бригаде Мск | I4: Выше рынка СПб | J4: Выше рынка Мск
A5: 1.1.1 | B5: Разборка покрытий и оснований асфальтобетонных | C5: м3 | D5: BLG | E5: 3500 | F5: 4025 | G5: 2100 | H5: 2415 | I5: 0 | J5: 0
A6: 1.1.2 | B6: Демонтаж деревянных зданий и строений без сохранения годного материала | C6: м3 здания | D6: RAZ | E6: 1000 | F6: 1300 | G6: 600 | H6: 768 | I6: 0 | J6: 0
A7: 1.1.3 | B7: Демонтаж зданий и строений из металлоконструкций без сохранения годного материала | C7: т | D7: SVA | E7: 12000 | F7: 14400 | G7: 3900 | H7: 4485 | I7: 0.84615385 | J7: 0.9264214
A8: 1.1.4 | B8: Демонтаж каменных зданий и строений (кирпич, бетон, железобетон) комплексная работа с сохранением годного материала | C8: м3 | D8: RAZ | E8: 4767 | F8: 5720 | G8: 2500 | H8: 2875 | I8: 0.135 | J8: 0.18426501
A9: 1.1.5 | B9: Разборка бортовых камней с сохранением камня пригодного для дальнейшего использования | C9: мп | D9: BLG | E9: 350 | F9: 402 | G9: 200 | H9: 230 | I9: 0 | J9: 0
A10: 1.1.6 | B10: Разборка тротуаров и дорожек из плит бетонных, брусчатки с сохранением пригодных для дальнейшего использования | C10: м2 | D10: BLG | E10: 260 | F10: 312 | G10: 150 | H10: 172 | I10: 0.04 | J10: 0.083333333
A11: 1.1.N1 | B11: Разборка асфальтобетонного покрытия толщиной до 5 см отбойными молотками | C11: м2 | D11: BLG | E11: 200 | F11: 230 | G11: 120 | H11: 138 | I11: 0 | J11: 0
A12: 1.1.N2 | B12: Демонтаж бетонных дорожных плит (ПАГ, 2П) с погрузкой | C12: м2 | D12: BLG | E12: 460 | F12: 529 | G12: 280 | H12: 322 | I12: 0 | J12: 0
A13: 1.1.N3 | B13: Демонтаж ограждения из сетки/профлиста со стойками | C13: мп | D13: SVA | E13: 480 | F13: 576 | G13: 180 | H13: 207 | I13: 0.6 | J13: 0.66956522
A14: 1.2.1 | B14: Отбивка штукатурки с поверхностей стен | C14: м2 | D14: RAZ | E14: 300 | F14: 345 | G14: 180 | H14: 207 | I14: 0 | J14: 0
A15: 1.2.2 | B15: Демонтаж облицовки из профилированного листа без разборки каркаса | C15: м2 | D15: RAZ | E15: 250 | F15: 288 | G15: 150 | H15: 172 | I15: 0 | J15: 0
A16: 1.2.3 | B16: Демонтаж облицовки из профилированного листа с разборкой каркаса | C16: м2 | D16: RAZ | E16: 380 | F16: 437 | G16: 230 | H16: 264 | I16: 0 | J16: 0
... A2356: 19.2.N13 | B2356: Замена фотоэлементов безопасности ворот (пара) | C2356: пара | D2356: VOR | E2356: 5000 | F2356: 6000 | G2356: 2650 | H2356: 3100 | I2356: 0 | J2356: 0
