Workbook

Sheet Как пользоваться
B1: РАСЦЕНКИ НЕОСТРОЙ — ПРАВИЛА РАБОТЫ ДЛЯ СОТРУДНИКОВ
B2: Версия от 23.10.2026. Все цены — только работа (без материалов и оборудования), руб. без НДС. Документ внутренний, заказчикам и бригадам не передаётся.
B3: 1. СМЕТЧИКИ И МЕНЕДЖЕРЫ: ЦЕНЫ В КП
B4: • В КП ставим «Цену в КП» с листа «Расценки» (голубые колонки) — СПб или Мск по месту объекта. Это наша базовая цена; ниже — только с согласования руководителя.
B5: • Материалы считаются отдельно, по счетам поставщиков.
B6: • Если заказчик просит ставку нормо-часа (ТО, аварийные и нерегламентные работы) — берём «Нормо-час для заказчика» с листа «Почасовка — ставки и план».
B7: • Позиции, подсвеченные оранжевым/красным в колонке «Цена в КП», стоят выше рынка (на 10–30 % и больше 30 %): мы их подняли, потому что на почасовке они убыточны. Если заказчик торгуется именно по ним — снижать можно только при условии, что работу берёт бригада в сделку по целевой цене.
B8: • Работы, которой нет в списке, — не придумывать цену: запрос сметчику.
B9: 2. ПРОРАБЫ И РУКОВОДИТЕЛИ ПРОЕКТОВ: СДЕЛКА С БРИГАДОЙ
B10: • «Сделка — цель» — цена за единицу, которую предлагаем бригаде (ИП или самозанятый), уже включая их налог 6 %. С неё начинаем переговоры.
B11: • «Сделка — потолок» (цель +15 %) — максимум, который можно согласовать самостоятельно. Выше потолка — только с письменного согласования руководителя.
B12: • Платим за принятый объём по акту (м², м, шт, т…), а не за выходы. Мусор, уборка и вынос в пределах рабочей зоны входят в цену.
... B29: Периодичность выплат бригадам/почасовикам: ____________________ · Форма договора: ИП / самозанятый, договор подряда · Кто подписывает акты: ____________________

Sheet Расценки
A1: РАСЦЕНКИ НЕОСТРОЙ: ЦЕНА В КП, СДЕЛКА С БРИГАДОЙ, ПОЧАСОВАЯ ОПЛАТА И ПЛАН
A2: Только работа, руб. без НДС. Колонки F, G, H, J, L — исходные данные из основного тарификатора (цена КП, цель сделки, норма); остальное считается формулами (подсказка формулы — в заголовке), параметры — лист «Параметры», ставки часа — лист «Почасовка — ставки и план».
F3: ЦЕНА В КП | H3: СДЕЛКА С БРИГАДОЙ (за единицу) | L3: ПОЧАСОВАЯ ОПЛАТА И ПЛАН (1 человек)
A4: Артикул | B4: Вид работ | C4: Ед. изм. | D4: Код | E4: Специальность (по коду) | F4: Цена в КП СПб (тарификатор) | G4: Цена в КП Мск (тарификатор) | H4: Сделка — цель СПб (тарификатор) | I4: Сделка — потолок СПб = цель × 1,15, не выше цены КП × 0,75 | J4: Сделка — цель Мск (тарификатор) | K4: Сделка — потолок Мск = цель × 1,15, не выше цены КП × 0,75 | L4: Норма, чел.-ч на ед. (тарификатор) | M4: План за 1 час, ед. = 1 ÷ норма | N4: План на смену, ед. = часы смены ÷ норма | O4: Ставка часа СПб, руб/ч (лист «Почасовка») | P4: Ставка часа Мск, руб/ч (лист «Почасовка») | Q4: Оплата за ед. по часам СПб = норма × ставка | R4: Как выгоднее отдать (СПб) оплата по часам vs цель сделки, ±10 %
A5: 1.1 Демонтаж зданий, строений, сооружений
A6: 1.1.1 | B6: Разборка покрытий и оснований асфальтобетонных | C6: м3 | D6: BLG | E6: =IFERROR(INDEX('Почасовка — ставки и план'!$B$5:$B$24,MATCH(D6,'Почасовка — ставки и план'!$A$5:$A$24,0)),"Аренда техники / механизмы") -> Дорожный рабочий / благоустройство | F6: 3500 | G6: 4025 | H6: 2100 | I6: =IF(OR(H6="",F6=""),"",MAX(H6,MIN(ROUND(H6*(1+Параметры!$B$5),IF(H6*(1+Параметры!$B$5)>=1000,-1,0)),ROUND(F6*Параметры!$B$6,IF(F6*Параметры!$B$6>=1000,-1,0))))) -> 2420 | J6: 2415 | K6: =IF(OR(J6="",G6=""),"",MAX(J6,MIN(ROUND(J6*(1+Параметры!$B$5),IF(J6*(1+Параметры!$B$5)>=1000,-1,0)),ROUND(G6*Параметры!$B$6,IF(G6*Параметры!$B$6>=1000,-1,0))))) -> 2780 | L6: 3.5 | M6: =IF(OR(L6="",L6=0),"",1/L6) -> 0.28571429 | N6: =IF(OR(L6="",L6=0),"",Параметры!$B$3/L6) -> 2.2857143 | O6: =IF(L6="","",IFERROR(INDEX('Почасовка — ставки и план'!$D$5:$D$24,MATCH($D6,'Почасовка — ставки и план'!$A$5:$A$24,0)),"")) -> 650 | P6: =IF(L6="","",IFERROR(INDEX('Почасовка — ставки и план'!$E$5:$E$24,MATCH($D6,'Почасовка — ставки и план'!$A$5:$A$24,0)),"")) -> 780 | Q6: =IF(OR(L6="",O6=""),"",ROUND(L6*O6,0)) -> 2275 | R6: =IF(D6="TEX","аренда техники — сделка/счёт",IF(OR(Q6="",H6="",H6=0),"—",IF(Q6<H6*(1-Параметры!$B$7),"почасовка",IF(Q6>H6*(1+Параметры!$B$7),"сделка","любой способ")))) -> любой способ | S6: 0 | T6: 0
A7: 1.1.2 | B7: Демонтаж деревянных зданий и строений без сохранения годного материала | C7: м3 здания | D7: RAZ | E7: =IFERROR(INDEX('Почасовка — ставки и план'!$B$5:$B$24,MATCH(D7,'Почасовка — ставки и план'!$A$5:$A$24,0)),"Аренда техники / механизмы") -> Разнорабочий / демонтажник | F7: 1000 | G7: 1300 | H7: 600 | I7: =IF(OR(H7="",F7=""),"",MAX(H7,MIN(ROUND(H7*(1+Параметры!$B$5),IF(H7*(1+Параметры!$B$5)>=1000,-1,0)),ROUND(F7*Параметры!$B$6,IF(F7*Параметры!$B$6>=1000,-1,0))))) -> 690 | J7: 768 | K7: =IF(OR(J7="",G7=""),"",MAX(J7,MIN(ROUND(J7*(1+Параметры!$B$5),IF(J7*(1+Параметры!$B$5)>=1000,-1,0)),ROUND(G7*Параметры!$B$6,IF(G7*Параметры!$B$6>=1000,-1,0))))) -> 883 | L7: 1.2 | M7: =IF(OR(L7="",L7=0),"",1/L7) -> 0.83333333 | N7: =IF(OR(L7="",L7=0),"",Параметры!$B$3/L7) -> 6.6666667 | O7: =IF(L7="","",IFERROR(INDEX('Почасовка — ставки и план'!$D$5:$D$24,MATCH($D7,'Почасовка — ставки и план'!$A$5:$A$24,0)),"")) -> 550 | P7: =IF(L7="","",IFERROR(INDEX('Почасовка — ставки и план'!$E$5:$E$24,MATCH($D7,'Почасовка — ставки и план'!$A$5:$A$24,0)),"")) -> 660 | Q7: =IF(OR(L7="",O7=""),"",ROUND(L7*O7,0)) -> 660 | R7: =IF(D7="TEX","аренда техники — сделка/счёт",IF(OR(Q7="",H7="",H7=0),"—",IF(Q7<H7*(1-Параметры!$B$7),"почасовка",IF(Q7>H7*(1+Параметры!$B$7),"сделка","любой способ")))) -> любой способ | S7: 0 | T7: 0
A8: 1.1.3 | B8: Демонтаж зданий и строений из металлоконструкций без сохранения годного материала | C8: т | D8: SVA | E8: =IFERROR(INDEX('Почасовка — ставки и план'!$B$5:$B$24,MATCH(D8,'Почасовка — ставки и план'!$A$5:$A$24,0)),"Аренда техники / механизмы") -> Сварщик / монтажник МК | F8: 12000 | G8: 14400 | H8: 3900 | I8: =IF(OR(H8="",F8=""),"",MAX(H8,MIN(ROUND(H8*(1+Параметры!$B$5),IF(H8*(1+Параметры!$B$5)>=1000,-1,0)),ROUND(F8*Параметры!$B$6,IF(F8*Параметры!$B$6>=1000,-1,0))))) -> 4490 | J8: 4485 | K8: =IF(OR(J8="",G8=""),"",MAX(J8,MIN(ROUND(J8*(1+Параметры!$B$5),IF(J8*(1+Параметры!$B$5)>=1000,-1,0)),ROUND(G8*Параметры!$B$6,IF(G8*Параметры!$B$6>=1000,-1,0))))) -> 5160 | L8: 10 | M8: =IF(OR(L8="",L8=0),"",1/L8) -> 0.1 | N8: =IF(OR(L8="",L8=0),"",Параметры!$B$3/L8) -> 0.8 | O8: =IF(L8="","",IFERROR(INDEX('Почасовка — ставки и план'!$D$5:$D$24,MATCH($D8,'Почасовка — ставки и план'!$A$5:$A$24,0)),"")) -> 900 | P8: =IF(L8="","",IFERROR(INDEX('Почасовка — ставки и план'!$E$5:$E$24,MATCH($D8,'Почасовка — ставки и план'!$A$5:$A$24,0)),"")) -> 1080 | Q8: =IF(OR(L8="",O8=""),"",ROUND(L8*O8,0)) -> 9000 | R8: =IF(D8="TEX","аренда техники — сделка/счёт",IF(OR(Q8="",H8="",H8=0),"—",IF(Q8<H8*(1-Параметры!$B$7),"почасовка",IF(Q8>H8*(1+Параметры!$B$7),"сделка","любой способ")))) -> сделка | S8: 0.84615385 | T8: 0.9264214
A9: 1.1.4 | B9: Демонтаж каменных зданий и строений (кирпич, бетон, железобетон) комплексная работа с сохранением годного материала | C9: м3 | D9: RAZ | E9: =IFERROR(INDEX('Почасовка — ставки и план'!$B$5:$B$24,MATCH(D9,'Почасовка — ставки и план'!$A$5:$A$24,0)),"Аренда техники / механизмы") -> Разнорабочий / демонтажник | F9: 4767 | G9: 5720 | H9: 2500 | I9: =IF(OR(H9="",F9=""),"",MAX(H9,MIN(ROUND(H9*(1+Параметры!$B$5),IF(H9*(1+Параметры!$B$5)>=1000,-1,0)),ROUND(F9*Параметры!$B$6,IF(F9*Параметры!$B$6>=1000,-1,0))))) -> 2880 | J9: 2875 | K9: =IF(OR(J9="",G9=""),"",MAX(J9,MIN(ROUND(J9*(1+Параметры!$B$5),IF(J9*(1+Параметры!$B$5)>=1000,-1,0)),ROUND(G9*Параметры!$B$6,IF(G9*Параметры!$B$6>=1000,-1,0))))) -> 3310 | L9: 6.5 | M9: =IF(OR(L9="",L9=0),"",1/L9) -> 0.15384615 | N9: =IF(OR(L9="",L9=0),"",Параметры!$B$3/L9) -> 1.2307692 | O9: =IF(L9="","",IFERROR(INDEX('Почасовка — ставки и план'!$D$5:$D$24,MATCH($D9,'Почасовка — ставки и план'!$A$5:$A$24,0)),"")) -> 550 | P9: =IF(L9="","",IFERROR(INDEX('Почасовка — ставки и план'!$E$5:$E$24,MATCH($D9,'Почасовка — ставки и план'!$A$5:$A$24,0)),"")) -> 660 | Q9: =IF(OR(L9="",O9=""),"",ROUND(L9*O9,0)) -> 3575 | R9: =IF(D9="TEX","аренда техники — сделка/счёт",IF(OR(Q9="",H9="",H9=0),"—",IF(Q9<H9*(1-Параметры!$B$7),"почасовка",IF(Q9>H9*(1+Параметры!$B$7),"сделка","любой способ")))) -> сделка | S9: 0.135 | T9: 0.18426501
A10: 1.1.5 | B10: Разборка бортовых камней с сохранением камня пригодного для дальнейшего использования | C10: мп | D10: BLG | E10: =IFERROR(INDEX('Почасовка — ставки и план'!$B$5:$B$24,MATCH(D10,'Почасовка — ставки и план'!$A$5:$A$24,0)),"Аренда техники / механизмы") -> Дорожный рабочий / благоустройство | F10: 350 | G10: 402 | H10: 200 | I10: =IF(OR(H10="",F10=""),"",MAX(H10,MIN(ROUND(H10*(1+Параметры!$B$5),IF(H10*(1+Параметры!$B$5)>=1000,-1,0)),ROUND(F10*Параметры!$B$6,IF(F10*Параметры!$B$6>=1000,-1,0))))) -> 230 | J10: 230 | K10: =IF(OR(J10="",G10=""),"",MAX(J10,MIN(ROUND(J10*(1+Параметры!$B$5),IF(J10*(1+Параметры!$B$5)>=1000,-1,0)),ROUND(G10*Параметры!$B$6,IF(G10*Параметры!$B$6>=1000,-1,0))))) -> 265 | L10: 0.35 | M10: =IF(OR(L10="",L10=0),"",1/L10) -> 2.8571429 | N10: =IF(OR(L10="",L10=0),"",Параметры!$B$3/L10) -> 22.857143 | O10: =IF(L10="","",IFERROR(INDEX('Почасовка — ставки и план'!$D$5:$D$24,MATCH($D10,'Почасовка — ставки и план'!$A$5:$A$24,0)),"")) -> 650 | P10: =IF(L10="","",IFERROR(INDEX('Почасовка — ставки и план'!$E$5:$E$24,MATCH($D10,'Почасовка — ставки и план'!$A$5:$A$24,0)),"")) -> 780 | Q10: =IF(OR(L10="",O10=""),"",ROUND(L10*O10,0)) -> 228 | R10: =IF(D10="TEX","аренда техники — сделка/счёт",IF(OR(Q10="",H10="",H10=0),"—",IF(Q10<H10*(1-Параметры!$B$7),"почасовка",IF(Q10>H10*(1+Параметры!$B$7),"сделка","любой способ")))) -> сделка | S10: 0 | T10: 0
A11: 1.1.6 | B11: Разборка тротуаров и дорожек из плит бетонных, брусчатки с сохранением пригодных для дальнейшего использования | C11: м2 | D11: BLG | E11: =IFERROR(INDEX('Почасовка — ставки и план'!$B$5:$B$24,MATCH(D11,'Почасовка — ставки и план'!$A$5:$A$24,0)),"Аренда техники / механизмы") -> Дорожный рабочий / благоустройство | F11: 260 | G11: 312 | H11: 150 | I11: =IF(OR(H11="",F11=""),"",MAX(H11,MIN(ROUND(H11*(1+Параметры!$B$5),IF(H11*(1+Параметры!$B$5)>=1000,-1,0)),ROUND(F11*Параметры!$B$6,IF(F11*Параметры!$B$6>=1000,-1,0))))) -> 173 | J11: 172 | K11: =IF(OR(J11="",G11=""),"",MAX(J11,MIN(ROUND(J11*(1+Параметры!$B$5),IF(J11*(1+Параметры!$B$5)>=1000,-1,0)),ROUND(G11*Параметры!$B$6,IF(G11*Параметры!$B$6>=1000,-1,0))))) -> 198 | L11: 0.3 | M11: =IF(OR(L11="",L11=0),"",1/L11) -> 3.3333333 | N11: =IF(OR(L11="",L11=0),"",Параметры!$B$3/L11) -> 26.666667 | O11: =IF(L11="","",IFERROR(INDEX('Почасовка — ставки и план'!$D$5:$D$24,MATCH($D11,'Почасовка — ставки и план'!$A$5:$A$24,0)),"")) -> 650 | P11: =IF(L11="","",IFERROR(INDEX('Почасовка — ставки и план'!$E$5:$E$24,MATCH($D11,'Почасовка — ставки и план'!$A$5:$A$24,0)),"")) -> 780 | Q11: =IF(OR(L11="",O11=""),"",ROUND(L11*O11,0)) -> 195 | R11: =IF(D11="TEX","аренда техники — сделка/счёт",IF(OR(Q11="",H11="",H11=0),"—",IF(Q11<H11*(1-Параметры!$B$7),"почасовка",IF(Q11>H11*(1+Параметры!$B$7),"сделка","любой способ")))) -> сделка | S11: 0.04 | T11: 0.083333333
A12: 1.1.N1 | B12: Разборка асфальтобетонного покрытия толщиной до 5 см отбойными молотками | C12: м2 | D12: BLG | E12: =IFERROR(INDEX('Почасовка — ставки и план'!$B$5:$B$24,MATCH(D12,'Почасовка — ставки и план'!$A$5:$A$24,0)),"Аренда техники / механизмы") -> Дорожный рабочий / благоустройство | F12: 200 | G12: 230 | H12: 120 | I12: =IF(OR(H12="",F12=""),"",MAX(H12,MIN(ROUND(H12*(1+Параметры!$B$5),IF(H12*(1+Параметры!$B$5)>=1000,-1,0)),ROUND(F12*Параметры!$B$6,IF(F12*Параметры!$B$6>=1000,-1,0))))) -> 138 | J12: 138 | K12: =IF(OR(J12="",G12=""),"",MAX(J12,MIN(ROUND(J12*(1+Параметры!$B$5),IF(J12*(1+Параметры!$B$5)>=1000,-1,0)),ROUND(G12*Параметры!$B$6,IF(G12*Параметры!$B$6>=1000,-1,0))))) -> 159 | L12: 0.2 | M12: =IF(OR(L12="",L12=0),"",1/L12) -> 5 | N12: =IF(OR(L12="",L12=0),"",Параметры!$B$3/L12) -> 40 | O12: =IF(L12="","",IFERROR(INDEX('Почасовка — ставки и план'!$D$5:$D$24,MATCH($D12,'Почасовка — ставки и план'!$A$5:$A$24,0)),"")) -> 650 | P12: =IF(L12="","",IFERROR(INDEX('Почасовка — ставки и план'!$E$5:$E$24,MATCH($D12,'Почасовка — ставки и план'!$A$5:$A$24,0)),"")) -> 780 | Q12: =IF(OR(L12="",O12=""),"",ROUND(L12*O12,0)) -> 130 | R12: =IF(D12="TEX","аренда техники — сделка/счёт",IF(OR(Q12="",H12="",H12=0),"—",IF(Q12<H12*(1-Параметры!$B$7),"почасовка",IF(Q12>H12*(1+Параметры!$B$7),"сделка","любой способ")))) -> любой способ | S12: 0 | T12: 0
A13: 1.1.N2 | B13: Демонтаж бетонных дорожных плит (ПАГ, 2П) с погрузкой | C13: м2 | D13: BLG | E13: =IFERROR(INDEX('Почасовка — ставки и план'!$B$5:$B$24,MATCH(D13,'Почасовка — ставки и план'!$A$5:$A$24,0)),"Аренда техники / механизмы") -> Дорожный рабочий / благоустройство | F13: 460 | G13: 529 | H13: 280 | I13: =IF(OR(H13="",F13=""),"",MAX(H13,MIN(ROUND(H13*(1+Параметры!$B$5),IF(H13*(1+Параметры!$B$5)>=1000,-1,0)),ROUND(F13*Параметры!$B$6,IF(F13*Параметры!$B$6>=1000,-1,0))))) -> 322 | J13: 322 | K13: =IF(OR(J13="",G13=""),"",MAX(J13,MIN(ROUND(J13*(1+Параметры!$B$5),IF(J13*(1+Параметры!$B$5)>=1000,-1,0)),ROUND(G13*Параметры!$B$6,IF(G13*Параметры!$B$6>=1000,-1,0))))) -> 370 | L13: 0.25 | M13: =IF(OR(L13="",L13=0),"",1/L13) -> 4 | N13: =IF(OR(L13="",L13=0),"",Параметры!$B$3/L13) -> 32 | O13: =IF(L13="","",IFERROR(INDEX('Почасовка — ставки и план'!$D$5:$D$24,MATCH($D13,'Почасовка — ставки и план'!$A$5:$A$24,0)),"")) -> 650 | P13: =IF(L13="","",IFERROR(INDEX('Почасовка — ставки и план'!$E$5:$E$24,MATCH($D13,'Почасовка — ставки и план'!$A$5:$A$24,0)),"")) -> 780 | Q13: =IF(OR(L13="",O13=""),"",ROUND(L13*O13,0)) -> 163 | R13: =IF(D13="TEX","аренда техники — сделка/счёт",IF(OR(Q13="",H13="",H13=0),"—",IF(Q13<H13*(1-Параметры!$B$7),"почасовка",IF(Q13>H13*(1+Параметры!$B$7),"сделка","любой способ")))) -> почасовка | S13: 0 | T13: 0
A14: 1.1.N3 | B14: Демонтаж ограждения из сетки/профлиста со стойками | C14: мп | D14: SVA | E14: =IFERROR(INDEX('Почасовка — ставки и план'!$B$5:$B$24,MATCH(D14,'Почасовка — ставки и план'!$A$5:$A$24,0)),"Аренда техники / механизмы") -> Сварщик / монтажник МК | F14: 480 | G14: 576 | H14: 180 | I14: =IF(OR(H14="",F14=""),"",MAX(H14,MIN(ROUND(H14*(1+Параметры!$B$5),IF(H14*(1+Параметры!$B$5)>=1000,-1,0)),ROUND(F14*Параметры!$B$6,IF(F14*Параметры!$B$6>=1000,-1,0))))) -> 207 | J14: 207 | K14: =IF(OR(J14="",G14=""),"",MAX(J14,MIN(ROUND(J14*(1+Параметры!$B$5),IF(J14*(1+Параметры!$B$5)>=1000,-1,0)),ROUND(G14*Параметры!$B$6,IF(G14*Параметры!$B$6>=1000,-1,0))))) -> 238 | L14: 0.4 | M14: =IF(OR(L14="",L14=0),"",1/L14) -> 2.5 | N14: =IF(OR(L14="",L14=0),"",Параметры!$B$3/L14) -> 20 | O14: =IF(L14="","",IFERROR(INDEX('Почасовка — ставки и план'!$D$5:$D$24,MATCH($D14,'Почасовка — ставки и план'!$A$5:$A$24,0)),"")) -> 900 | P14: =IF(L14="","",IFERROR(INDEX('Почасовка — ставки и план'!$E$5:$E$24,MATCH($D14,'Почасовка — ставки и план'!$A$5:$A$24,0)),"")) -> 1080 | Q14: =IF(OR(L14="",O14=""),"",ROUND(L14*O14,0)) -> 360 | R14: =IF(D14="TEX","аренда техники — сделка/счёт",IF(OR(Q14="",H14="",H14=0),"—",IF(Q14<H14*(1-Параметры!$B$7),"почасовка",IF(Q14>H14*(1+Параметры!$B$7),"сделка","любой способ")))) -> сделка | S14: 0.6 | T14: 0.66956522
A15: 1.2 Демонтажные работы по фасаду
A16: 1.2.1 | B16: Отбивка штукатурки с поверхностей стен | C16: м2 | D16: RAZ | E16: =IFERROR(INDEX('Почасовка — ставки и план'!$B$5:$B$24,MATCH(D16,'Почасовка — ставки и план'!$A$5:$A$24,0)),"Аренда техники / механизмы") -> Разнорабочий / демонтажник | F16: 300 | G16: 345 | H16: 180 | I16: =IF(OR(H16="",F16=""),"",MAX(H16,MIN(ROUND(H16*(1+Параметры!$B$5),IF(H16*(1+Параметры!$B$5)>=1000,-1,0)),ROUND(F16*Параметры!$B$6,IF(F16*Параметры!$B$6>=1000,-1,0))))) -> 207 | J16: 207 | K16: =IF(OR(J16="",G16=""),"",MAX(J16,MIN(ROUND(J16*(1+Параметры!$B$5),IF(J16*(1+Параметры!$B$5)>=1000,-1,0)),ROUND(G16*Параметры!$B$6,IF(G16*Параметры!$B$6>=1000,-1,0))))) -> 238 | L16: 0.35 | M16: =IF(OR(L16="",L16=0),"",1/L16) -> 2.8571429 | N16: =IF(OR(L16="",L16=0),"",Параметры!$B$3/L16) -> 22.857143 | O16: =IF(L16="","",IFERROR(INDEX('Почасовка — ставки и план'!$D$5:$D$24,MATCH($D16,'Почасовка — ставки и план'!$A$5:$A$24,0)),"")) -> 550 | P16: =IF(L16="","",IFERROR(INDEX('Почасовка — ставки и план'!$E$5:$E$24,MATCH($D16,'Почасовка — ставки и план'!$A$5:$A$24,0)),"")) -> 660 | Q16: =IF(OR(L16="",O16=""),"",ROUND(L16*O16,0)) -> 193 | R16: =IF(D16="TEX","аренда техники — сделка/счёт",IF(OR(Q16="",H16="",H16=0),"—",IF(Q16<H16*(1-Параметры!$B$7),"почасовка",IF(Q16>H16*(1+Параметры!$B$7),"сделка","любой способ")))) -> любой способ | S16: 0 | T16: 0
A17: 1.2.2 | B17: Демонтаж облицовки из профилированного листа без разборки каркаса | C17: м2 | D17: RAZ | E17: =IFERROR(INDEX('Почасовка — ставки и план'!$B$5:$B$24,MATCH(D17,'Почасовка — ставки и план'!$A$5:$A$24,0)),"Аренда техники / механизмы") -> Разнорабочий / демонтажник | F17: 250 | G17: 288 | H17: 150 | I17: =IF(OR(H17="",F17=""),"",MAX(H17,MIN(ROUND(H17*(1+Параметры!$B$5),IF(H17*(1+Параметры!$B$5)>=1000,-1,0)),ROUND(F17*Параметры!$B$6,IF(F17*Параметры!$B$6>=1000,-1,0))))) -> 173 | J17: 172 | K17: =IF(OR(J17="",G17=""),"",MAX(J17,MIN(ROUND(J17*(1+Параметры!$B$5),IF(J17*(1+Параметры!$B$5)>=1000,-1,0)),ROUND(G17*Параметры!$B$6,IF(G17*Параметры!$B$6>=1000,-1,0))))) -> 198 | L17: 0.25 | M17: =IF(OR(L17="",L17=0),"",1/L17) -> 4 | N17: =IF(OR(L17="",L17=0),"",Параметры!$B$3/L17) -> 32 | O17: =IF(L17="","",IFERROR(INDEX('Почасовка — ставки и план'!$D$5:$D$24,MATCH($D17,'Почасовка — ставки и план'!$A$5:$A$24,0)),"")) -> 550 | P17: =IF(L17="","",IFERROR(INDEX('Почасовка — ставки и план'!$E$5:$E$24,MATCH($D17,'Почасовка — ставки и план'!$A$5:$A$24,0)),"")) -> 660 | Q17: =IF(OR(L17="",O17=""),"",ROUND(L17*O17,0)) -> 138 | R17: =IF(D17="TEX","аренда техники — сделка/счёт",IF(OR(Q17="",H17="",H17=0),"—",IF(Q17<H17*(1-Параметры!$B$7),"почасовка",IF(Q17>H17*(1+Параметры!$B$7),"сделка","любой способ")))) -> любой способ | S17: 0 | T17: 0
A18: 1.2.3 | B18: Демонтаж облицовки из профилированного листа с разборкой каркаса | C18: м2 | D18: RAZ | E18: =IFERROR(INDEX('Почасовка — ставки и план'!$B$5:$B$24,MATCH(D18,'Почасовка — ставки и план'!$A$5:$A$24,0)),"Аренда техники / механизмы") -> Разнорабочий / демонтажник | F18: 380 | G18: 437 | H18: 230 | I18: =IF(OR(H18="",F18=""),"",MAX(H18,MIN(ROUND(H18*(1+Параметры!$B$5),IF(H18*(1+Параметры!$B$5)>=1000,-1,0)),ROUND(F18*Параметры!$B$6,IF(F18*Параметры!$B$6>=1000,-1,0))))) -> 265 | J18: 264 | K18: =IF(OR(J18="",G18=""),"",MAX(J18,MIN(ROUND(J18*(1+Параметры!$B$5),IF(J18*(1+Параметры!$B$5)>=1000,-1,0)),ROUND(G18*Параметры!$B$6,IF(G18*Параметры!$B$6>=1000,-1,0))))) -> 304 | L18: 0.4 | M18: =IF(OR(L18="",L18=0),"",1/L18) -> 2.5 | N18: =IF(OR(L18="",L18=0),"",Параметры!$B$3/L18) -> 20 | O18: =IF(L18="","",IFERROR(INDEX('Почасовка — ставки и план'!$D$5:$D$24,MATCH($D18,'Почасовка — ставки и план'!$A$5:$A$24,0)),"")) -> 550 | P18: =IF(L18="","",IFERROR(INDEX('Почасовка — ставки и план'!$E$5:$E$24,MATCH($D18,'Почасовка — ставки и план'!$A$5:$A$24,0)),"")) -> 660 | Q18: =IF(OR(L18="",O18=""),"",ROUND(L18*O18,0)) -> 220 | R18: =IF(D18="TEX","аренда техники — сделка/счёт",IF(OR(Q18="",H18="",H18=0),"—",IF(Q18<H18*(1-Параметры!$B$7),"почасовка",IF(Q18>H18*(1+Параметры!$B$7),"сделка","любой способ")))) -> любой способ | S18: 0 | T18: 0
A19: 1.2.4 | B19: Демонтаж ограждающих конструкций стен из многослойных панелей (сэндвич-панели) | C19: м2 | D19: KRO | E19: =IFERROR(INDEX('Почасовка — ставки и план'!$B$5:$B$24,MATCH(D19,'Почасовка — ставки и план'!$A$5:$A$24,0)),"Аренда техники / механизмы") -> Кровельщик | F19: 480 | G19: 571 | H19: 230 | I19: =IF(OR(H19="",F19=""),"",MAX(H19,MIN(ROUND(H19*(1+Параметры!$B$5),IF(H19*(1+Параметры!$B$5)>=1000,-1,0)),ROUND(F19*Параметры!$B$6,IF(F19*Параметры!$B$6>=1000,-1,0))))) -> 265 | J19: 264 | K19: =IF(OR(J19="",G19=""),"",MAX(J19,MIN(ROUND(J19*(1+Параметры!$B$5),IF(J19*(1+Параметры!$B$5)>=1000,-1,0)),ROUND(G19*Параметры!$B$6,IF(G19*Параметры!$B$6>=1000,-1,0))))) -> 304 | L19: 0.45 | M19: =IF(OR(L19="",L19=0),"",1/L19) -> 2.2222222 | N19: =IF(OR(L19="",L19=0),"",Параметры!$B$3/L19) -> 17.777778 | O19: =IF(L19="","",IFERROR(INDEX('Почасовка — ставки и план'!$D$5:$D$24,MATCH($D19,'Почасовка — ставки и план'!$A$5:$A$24,0)),"")) -> 800 | P19: =IF(L19="","",IFERROR(INDEX('Почасовка — ставки и план'!$E$5:$E$24,MATCH($D19,'Почасовка — ставки и план'!$A$5:$A$24,0)),"")) -> 950 | Q19: =IF(OR(L19="",O19=""),"",ROUND(L19*O19,0)) -> 360 | R19: =IF(D19="TEX","аренда техники — сделка/счёт",IF(OR(Q19="",H19="",H19=0),"—",IF(Q19<H19*(1-Параметры!$B$7),"почасовка",IF(Q19>H19*(1+Параметры!$B$7),"сделка","любой способ")))) -> сделка | S19: 0.26315789 | T19: 0.30663616
A20: 1.2.5 | B20: Демонтаж ограждающих конструкций стен из панелей "Алюкобонд" и металлического каркаса | C20: м2 | D20: FAS | E20: =IFERROR(INDEX('Почасовка — ставки и план'!$B$5:$B$24,MATCH(D20,'Почасовка — ставки и план'!$A$5:$A$24,0)),"Аренда техники / механизмы") -> Фасадчик / промальпинист | F20: 1320 | G20: 1560 | H20: 650 | I20: =IF(OR(H20="",F20=""),"",MAX(H20,MIN(ROUND(H20*(1+Параметры!$B$5),IF(H20*(1+Параметры!$B$5)>=1000,-1,0)),ROUND(F20*Параметры!$B$6,IF(F20*Параметры!$B$6>=1000,-1,0))))) -> 748 | J20: 747 | K20: =IF(OR(J20="",G20=""),"",MAX(J20,MIN(ROUND(J20*(1+Параметры!$B$5),IF(J20*(1+Параметры!$B$5)>=1000,-1,0)),ROUND(G20*Параметры!$B$6,IF(G20*Параметры!$B$6>=1000,-1,0))))) -> 859 | L20: 0.9 | M20: =IF(OR(L20="",L20=0),"",1/L20) -> 1.1111111 | N20: =IF(OR(L20="",L20=0),"",Параметры!$B$3/L20) -> 8.8888889 | O20: =IF(L20="","",IFERROR(INDEX('Почасовка — ставки и план'!$D$5:$D$24,MATCH($D20,'Почасовка — ставки и план'!$A$5:$A$24,0)),"")) -> 1100 | P20: =IF(L20="","",IFERROR(INDEX('Почасовка — ставки и план'!$E$5:$E$24,MATCH($D20,'Почасовка — ставки и план'!$A$5:$A$24,0)),"")) -> 1300 | Q20: =IF(OR(L20="",O20=""),"",ROUND(L20*O20,0)) -> 990 | R20: =IF(D20="TEX","аренда техники — сделка/счёт",IF(OR(Q20="",H20="",H20=0),"—",IF(Q20<H20*(1-Параметры!$B$7),"почасовка",IF(Q20>H20*(1+Параметры!$B$7),"сделка","любой способ")))) -> сделка | S20: 0.2 | T20: 0.23320158
A21: 1.2.6 | B21: Демонтаж теплоизоляционного слоя стен | C21: м2 | D21: RAZ | E21: =IFERROR(INDEX('Почасовка — ставки и план'!$B$5:$B$24,MATCH(D21,'Почасовка — ставки и план'!$A$5:$A$24,0)),"Аренда техники / механизмы") -> Разнорабочий / демонтажник | F21: 200 | G21: 230 | H21: 120 | I21: =IF(OR(H21="",F21=""),"",MAX(H21,MIN(ROUND(H21*(1+Параметры!$B$5),IF(H21*(1+Параметры!$B$5)>=1000,-1,0)),ROUND(F21*Параметры!$B$6,IF(F21*Параметры!$B$6>=1000,-1,0))))) -> 138 | J21: 138 | K21: =IF(OR(J21="",G21=""),"",MAX(J21,MIN(ROUND(J21*(1+Параметры!$B$5),IF(J21*(1+Параметры!$B$5)>=1000,-1,0)),ROUND(G21*Параметры!$B$6,IF(G21*Параметры!$B$6>=1000,-1,0))))) -> 159 | L21: 0.2 | M21: =IF(OR(L21="",L21=0),"",1/L21) -> 5 | N21: =IF(OR(L21="",L21=0),"",Параметры!$B$3/L21) -> 40 | O21: =IF(L21="","",IFERROR(INDEX('Почасовка — ставки и план'!$D$5:$D$24,MATCH($D21,'Почасовка — ставки и план'!$A$5:$A$24,0)),"")) -> 550 | P21: =IF(L21="","",IFERROR(INDEX('Почасовка — ставки и план'!$E$5:$E$24,MATCH($D21,'Почасовка — ставки и план'!$A$5:$A$24,0)),"")) -> 660 | Q21: =IF(OR(L21="",O21=""),"",ROUND(L21*O21,0)) -> 110 | R21: =IF(D21="TEX","аренда техники — сделка/счёт",IF(OR(Q21="",H21="",H21=0),"—",IF(Q21<H21*(1-Параметры!$B$7),"почасовка",IF(Q21>H21*(1+Параметры!$B$7),"сделка","любой способ")))) -> любой способ | S21: 0 | T21: 0
A22: 1.2.7 | B22: Разборка систем вентилируемых фасадов из плит "Керамогранит" с сохранением каркаса | C22: м2 | D22: FAS | E22: =IFERROR(INDEX('Почасовка — ставки и план'!$B$5:$B$24,MATCH(D22,'Почасовка — ставки и план'!$A$5:$A$24,0)),"Аренда техники / механизмы") -> Фасадчик / промальпинист | F22: 880 | G22: 1040 | H22: 400 | I22: =IF(OR(H22="",F22=""),"",MAX(H22,MIN(ROUND(H22*(1+Параметры!$B$5),IF(H22*(1+Параметры!$B$5)>=1000,-1,0)),ROUND(F22*Параметры!$B$6,IF(F22*Параметры!$B$6>=1000,-1,0))))) -> 460 | J22: 460 | K22: =IF(OR(J22="",G22=""),"",MAX(J22,MIN(ROUND(J22*(1+Параметры!$B$5),IF(J22*(1+Параметры!$B$5)>=1000,-1,0)),ROUND(G22*Параметры!$B$6,IF(G22*Параметры!$B$6>=1000,-1,0))))) -> 529 | L22: 0.6 | M22: =IF(OR(L22="",L22=0),"",1/L22) -> 1.6666667 | N22: =IF(OR(L22="",L22=0),"",Параметры!$B$3/L22) -> 13.333333 | O22: =IF(L22="","",IFERROR(INDEX('Почасовка — ставки и план'!$D$5:$D$24,MATCH($D22,'Почасовка — ставки и план'!$A$5:$A$24,0)),"")) -> 1100 | P22: =IF(L22="","",IFERROR(INDEX('Почасовка — ставки и план'!$E$5:$E$24,MATCH($D22,'Почасовка — ставки и план'!$A$5:$A$24,0)),"")) -> 1300 | Q22: =IF(OR(L22="",O22=""),"",ROUND(L22*O22,0)) -> 660 | R22: =IF(D22="TEX","аренда техники — сделка/счёт",IF(OR(Q22="",H22="",H22=0),"—",IF(Q22<H22*(1-Параметры!$B$7),"почасовка",IF(Q22>H22*(1+Параметры!$B$7),"сделка","любой способ")))) -> сделка | S22: 0.35384615 | T22: 0.39223561
A23: 1.2.8 | B23: Разборка систем вентилируемых фасадов из плит "Керамогранит" с учетом каркаса | C23: м2 | D23: FAS | E23: =IFERROR(INDEX('Почасовка — ставки и план'!$B$5:$B$24,MATCH(D23,'Почасовка — ставки и план'!$A$5:$A$24,0)),"Аренда техники / механизмы") -> Фасадчик / промальпинист | F23: 1467 | G23: 1734 | H23: 650 | I23: =IF(OR(H23="",F23=""),"",MAX(H23,MIN(ROUND(H23*(1+Параметры!$B$5),IF(H23*(1+Параметры!$B$5)>=1000,-1,0)),ROUND(F23*Параметры!$B$6,IF(F23*Параметры!$B$6>=1000,-1,0))))) -> 748 | J23: 747 | K23: =IF(OR(J23="",G23=""),"",MAX(J23,MIN(ROUND(J23*(1+Параметры!$B$5),IF(J23*(1+Параметры!$B$5)>=1000,-1,0)),ROUND(G23*Параметры!$B$6,IF(G23*Параметры!$B$6>=1000,-1,0))))) -> 859 | L23: 1 | M23: =IF(OR(L23="",L23=0),"",1/L23) -> 1 | N23: =IF(OR(L23="",L23=0),"",Параметры!$B$3/L23) -> 8 | O23: =IF(L23="","",IFERROR(INDEX('Почасовка — ставки и план'!$D$5:$D$24,MATCH($D23,'Почасовка — ставки и план'!$A$5:$A$24,0)),"")) -> 1100 | P23: =IF(L23="","",IFERROR(INDEX('Почасовка — ставки и план'!$E$5:$E$24,MATCH($D23,'Почасовка — ставки и план'!$A$5:$A$24,0)),"")) -> 1300 | Q23: =IF(OR(L23="",O23=""),"",ROUND(L23*O23,0)) -> 1100 | R23: =IF(D23="TEX","аренда техники — сделка/счёт",IF(OR(Q23="",H23="",H23=0),"—",IF(Q23<H23*(1-Параметры!$B$7),"почасовка",IF(Q23>H23*(1+Параметры!$B$7),"сделка","любой способ")))) -> сделка | S23: 0.33363636 | T23: 0.37075099
A24: 1.2.N1 | B24: Демонтаж металлического козырька/навеса над входом | C24: м2 | D24: SVA | E24: =IFERROR(INDEX('Почасовка — ставки и план'!$B$5:$B$24,MATCH(D24,'Почасовка — ставки и план'!$A$5:$A$24,0)),"Аренда техники / механизмы") -> Сварщик / монтажник МК | F24: 1200 | G24: 1440 | H24: 720 | I24: =IF(OR(H24="",F24=""),"",MAX(H24,MIN(ROUND(H24*(1+Параметры!$B$5),IF(H24*(1+Параметры!$B$5)>=1000,-1,0)),ROUND(F24*Параметры!$B$6,IF(F24*Параметры!$B$6>=1000,-1,0))))) -> 828 | J24: 828 | K24: =IF(OR(J24="",G24=""),"",MAX(J24,MIN(ROUND(J24*(1+Параметры!$B$5),IF(J24*(1+Параметры!$B$5)>=1000,-1,0)),ROUND(G24*Параметры!$B$6,IF(G24*Параметры!$B$6>=1000,-1,0))))) -> 952 | L24: 1 | M24: =IF(OR(L24="",L24=0),"",1/L24) -> 1 | N24: =IF(OR(L24="",L24=0),"",Параметры!$B$3/L24) -> 8 | O24: =IF(L24="","",IFERROR(INDEX('Почасовка — ставки и план'!$D$5:$D$24,MATCH($D24,'Почасовка — ставки и план'!$A$5:$A$24,0)),"")) -> 900 | P24: =IF(L24="","",IFERROR(INDEX('Почасовка — ставки и план'!$E$5:$E$24,MATCH($D24,'Почасовка — ставки и план'!$A$5:$A$24,0)),"")) -> 1080 | Q24: =IF(OR(L24="",O24=""),"",ROUND(L24*O24,0)) -> 900 | R24: =IF(D24="TEX","аренда техники — сделка/счёт",IF(OR(Q24="",H24="",H24=0),"—",IF(Q24<H24*(1-Параметры!$B$7),"почасовка",IF(Q24>H24*(1+Параметры!$B$7),"сделка","любой способ")))) -> сделка | S24: 0 | T24: 0.043478261
A25: 1.3 Демонтажные работы по фундаменту
A26: 1.3.1 | B26: Разборка бутовых фундаментов | C26: м3 | D26: RAZ | E26: =IFERROR(INDEX('Почасовка — ставки и план'!$B$5:$B$24,MATCH(D26,'Почасовка — ставки и план'!$A$5:$A$24,0)),"Аренда техники / механизмы") -> Разнорабочий / демонтажник | F26: 5500 | G26: 6600 | H26: 2400 | I26: =IF(OR(H26="",F26=""),"",MAX(H26,MIN(ROUND(H26*(1+Параметры!$B$5),IF(H26*(1+Параметры!$B$5)>=1000,-1,0)),ROUND(F26*Параметры!$B$6,IF(F26*Параметры!$B$6>=1000,-1,0))))) -> 2760 | J26: 2760 | K26: =IF(OR(J26="",G26=""),"",MAX(J26,MIN(ROUND(J26*(1+Параметры!$B$5),IF(J26*(1+Параметры!$B$5)>=1000,-1,0)),ROUND(G26*Параметры!$B$6,IF(G26*Параметры!$B$6>=1000,-1,0))))) -> 3170 | L26: 7.5 | M26: =IF(OR(L26="",L26=0),"",1/L26) -> 0.13333333 | N26: =IF(OR(L26="",L26=0),"",Параметры!$B$3/L26) -> 1.0666667 | O26: =IF(L26="","",IFERROR(INDEX('Почасовка — ставки и план'!$D$5:$D$24,MATCH($D26,'Почасовка — ставки и план'!$A$5:$A$24,0)),"")) -> 550 | P26: =IF(L26="","",IFERROR(INDEX('Почасовка — ставки и план'!$E$5:$E$24,MATCH($D26,'Почасовка — ставки и план'!$A$5:$A$24,0)),"")) -> 660 | Q26: =IF(OR(L26="",O26=""),"",ROUND(L26*O26,0)) -> 4125 | R26: =IF(D26="TEX","аренда техники — сделка/счёт",IF(OR(Q26="",H26="",H26=0),"—",IF(Q26<H26*(1-Параметры!$B$7),"почасовка",IF(Q26>H26*(1+Параметры!$B$7),"сделка","любой способ")))) -> сделка | S26: 0.375 | T26: 0.43478261
A27: 1.3.2 | B27: Разборка бетонных фундаментов | C27: м3 | D27: RAZ | E27: =IFERROR(INDEX('Почасовка — ставки и план'!$B$5:$B$24,MATCH(D27,'Почасовка — ставки и план'!$A$5:$A$24,0)),"Аренда техники / механизмы") -> Разнорабочий / демонтажник | F27: 8067 | G27: 9680 | H27: 4500 | I27: =IF(OR(H27="",F27=""),"",MAX(H27,MIN(ROUND(H27*(1+Параметры!$B$5),IF(H27*(1+Параметры!$B$5)>=1000,-1,0)),ROUND(F27*Параметры!$B$6,IF(F27*Параметры!$B$6>=1000,-1,0))))) -> 5180 | J27: 5310 | K27: =IF(OR(J27="",G27=""),"",MAX(J27,MIN(ROUND(J27*(1+Параметры!$B$5),IF(J27*(1+Параметры!$B$5)>=1000,-1,0)),ROUND(G27*Параметры!$B$6,IF(G27*Параметры!$B$6>=1000,-1,0))))) -> 6110 | L27: 11 | M27: =IF(OR(L27="",L27=0),"",1/L27) -> 0.090909091 | N27: =IF(OR(L27="",L27=0),"",Параметры!$B$3/L27) -> 0.72727273 | O27: =IF(L27="","",IFERROR(INDEX('Почасовка — ставки и план'!$D$5:$D$24,MATCH($D27,'Почасовка — ставки и план'!$A$5:$A$24,0)),"")) -> 550 | P27: =IF(L27="","",IFERROR(INDEX('Почасовка — ставки и план'!$E$5:$E$24,MATCH($D27,'Почасовка — ставки и план'!$A$5:$A$24,0)),"")) -> 660 | Q27: =IF(OR(L27="",O27=""),"",ROUND(L27*O27,0)) -> 6050 | R27: =IF(D27="TEX","аренда техники — сделка/счёт",IF(OR(Q27="",H27="",H27=0),"—",IF(Q27<H27*(1-Параметры!$B$7),"почасовка",IF(Q27>H27*(1+Параметры!$B$7),"сделка","любой способ")))) -> сделка | S27: 0.0756 | T27: 0.075555556
A28: 1.3.3 | B28: Разборка железобетонных фундаментов | C28: м3 | D28: RAZ | E28: =IFERROR(INDEX('Почасовка — ставки и план'!$B$5:$B$24,MATCH(D28,'Почасовка — ставки и план'!$A$5:$A$24,0)),"Аренда техники / механизмы") -> Разнорабочий / демонтажник | F28: 11000 | G28: 13200 | H28: 6000 | I28: =IF(OR(H28="",F28=""),"",MAX(H28,MIN(ROUND(H28*(1+Параметры!$B$5),IF(H28*(1+Параметры!$B$5)>=1000,-1,0)),ROUND(F28*Параметры!$B$6,IF(F28*Параметры!$B$6>=1000,-1,0))))) -> 6900 | J28: 7080 | K28: =IF(OR(J28="",G28=""),"",MAX(J28,MIN(ROUND(J28*(1+Параметры!$B$5),IF(J28*(1+Параметры!$B$5)>=1000,-1,0)),ROUND(G28*Параметры!$B$6,IF(G28*Параметры!$B$6>=1000,-1,0))))) -> 8140 | L28: 15 | M28: =IF(OR(L28="",L28=0),"",1/L28) -> 0.066666667 | N28: =IF(OR(L28="",L28=0),"",Параметры!$B$3/L28) -> 0.53333333 | O28: =IF(L28="","",IFERROR(INDEX('Почасовка — ставки и план'!$D$5:$D$24,MATCH($D28,'Почасовка — ставки и план'!$A$5:$A$24,0)),"")) -> 550 | P28: =IF(L28="","",IFERROR(INDEX('Почасовка — ставки и план'!$E$5:$E$24,MATCH($D28,'Почасовка — ставки и план'!$A$5:$A$24,0)),"")) -> 660 | Q28: =IF(OR(L28="",O28=""),"",ROUND(L28*O28,0)) -> 8250 | R28: =IF(D28="TEX","аренда техники — сделка/счёт",IF(OR(Q28="",H28="",H28=0),"—",IF(Q28<H28*(1-Параметры!$B$7),"почасовка",IF(Q28>H28*(1+Параметры!$B$7),"сделка","любой способ")))) -> сделка | S28: 0.1 | T28: 0.1
A29: 1.4 Демонтажные работы кровли
A30: 1.4.1 | B30: Очистка кровли от листвы и мусора | C30: м2 | D30: RAZ | E30: =IFERROR(INDEX('Почасовка — ставки и план'!$B$5:$B$24,MATCH(D30,'Почасовка — ставки и план'!$A$5:$A$24,0)),"Аренда техники / механизмы") -> Разнорабочий / демонтажник | F30: 35 | G30: 40 | H30: 20 | I30: =IF(OR(H30="",F30=""),"",MAX(H30,MIN(ROUND(H30*(1+Параметры!$B$5),IF(H30*(1+Параметры!$B$5)>=1000,-1,0)),ROUND(F30*Параметры!$B$6,IF(F30*Параметры!$B$6>=1000,-1,0))))) -> 23 | J30: 23 | K30: =IF(OR(J30="",G30=""),"",MAX(J30,MIN(ROUND(J30*(1+Параметры!$B$5),IF(J30*(1+Параметры!$B$5)>=1000,-1,0)),ROUND(G30*Параметры!$B$6,IF(G30*Параметры!$B$6>=1000,-1,0))))) -> 26 | L30: 0.04 | M30: =IF(OR(L30="",L30=0),"",1/L30) -> 25 | N30: =IF(OR(L30="",L30=0),"",Параметры!$B$3/L30) -> 200 | O30: =IF(L30="","",IFERROR(INDEX('Почасовка — ставки и план'!$D$5:$D$24,MATCH($D30,'Почасовка — ставки и план'!$A$5:$A$24,0)),"")) -> 550 | P30: =IF(L30="","",IFERROR(INDEX('Почасовка — ставки и план'!$E$5:$E$24,MATCH($D30,'Почасовка — ставки и план'!$A$5:$A$24,0)),"")) -> 660 | Q30: =IF(OR(L30="",O30=""),"",ROUND(L30*O30,0)) -> 22 | R30: =IF(D30="TEX","аренда техники — сделка/счёт",IF(OR(Q30="",H30="",H30=0),"—",IF(Q30<H30*(1-Параметры!$B$7),"почасовка",IF(Q30>H30*(1+Параметры!$B$7),"сделка","любой способ")))) -> любой способ | S30: 0 | T30: 0
A31: 1.4.2 | B31: Очистка снега с крыш при толщине слоя до 20 см | C31: м2 | D31: RAZ | E31: =IFERROR(INDEX('Почасовка — ставки и план'!$B$5:$B$24,MATCH(D31,'Почасовка — ставки и план'!$A$5:$A$24,0)),"Аренда техники / механизмы") -> Разнорабочий / демонтажник | F31: 30 | G31: 35 | H31: 18 | I31: =IF(OR(H31="",F31=""),"",MAX(H31,MIN(ROUND(H31*(1+Параметры!$B$5),IF(H31*(1+Параметры!$B$5)>=1000,-1,0)),ROUND(F31*Параметры!$B$6,IF(F31*Параметры!$B$6>=1000,-1,0))))) -> 21 | J31: 20.5 | K31: =IF(OR(J31="",G31=""),"",MAX(J31,MIN(ROUND(J31*(1+Параметры!$B$5),IF(J31*(1+Параметры!$B$5)>=1000,-1,0)),ROUND(G31*Параметры!$B$6,IF(G31*Параметры!$B$6>=1000,-1,0))))) -> 24 | L31: 0.04 | M31: =IF(OR(L31="",L31=0),"",1/L31) -> 25 | N31: =IF(OR(L31="",L31=0),"",Параметры!$B$3/L31) -> 200 | O31: =IF(L31="","",IFERROR(INDEX('Почасовка — ставки и план'!$D$5:$D$24,MATCH($D31,'Почасовка — ставки и план'!$A$5:$A$24,0)),"")) -> 550 | P31: =IF(L31="","",IFERROR(INDEX('Почасовка — ставки и план'!$E$5:$E$24,MATCH($D31,'Почасовка — ставки и план'!$A$5:$A$24,0)),"")) -> 660 | Q31: =IF(OR(L31="",O31=""),"",ROUND(L31*O31,0)) -> 22 | R31: =IF(D31="TEX","аренда техники — сделка/счёт",IF(OR(Q31="",H31="",H31=0),"—",IF(Q31<H31*(1-Параметры!$B$7),"почасовка",IF(Q31>H31*(1+Параметры!$B$7),"сделка","любой способ")))) -> сделка | S31: 0 | T31: 0.014492754
A32: 1.4.3 | B32: Очистка снега с крыш, добавлять на каждые следующие 10 см увеличения толщины слоя | C32: м2 | D32: RAZ | E32: =IFERROR(INDEX('Почасовка — ставки и план'!$B$5:$B$24,MATCH(D32,'Почасовка — ставки и план'!$A$5:$A$24,0)),"Аренда техники / механизмы") -> Разнорабочий / демонтажник | F32: 10 | G32: 11 | H32: 5 | I32: =IF(OR(H32="",F32=""),"",MAX(H32,MIN(ROUND(H32*(1+Параметры!$B$5),IF(H32*(1+Параметры!$B$5)>=1000,-1,0)),ROUND(F32*Параметры!$B$6,IF(F32*Параметры!$B$6>=1000,-1,0))))) -> 6 | J32: 6 | K32: =IF(OR(J32="",G32=""),"",MAX(J32,MIN(ROUND(J32*(1+Параметры!$B$5),IF(J32*(1+Параметры!$B$5)>=1000,-1,0)),ROUND(G32*Параметры!$B$6,IF(G32*Параметры!$B$6>=1000,-1,0))))) -> 7 | L32: 0.012 | M32: =IF(OR(L32="",L32=0),"",1/L32) -> 83.333333 | N32: =IF(OR(L32="",L32=0),"",Параметры!$B$3/L32) -> 666.66667 | O32: =IF(L32="","",IFERROR(INDEX('Почасовка — ставки и план'!$D$5:$D$24,MATCH($D32,'Почасовка — ставки и план'!$A$5:$A$24,0)),"")) -> 550 | P32: =IF(L32="","",IFERROR(INDEX('Почасовка — ставки и план'!$E$5:$E$24,MATCH($D32,'Почасовка — ставки и план'!$A$5:$A$24,0)),"")) -> 660 | Q32: =IF(OR(L32="",O32=""),"",ROUND(L32*O32,0)) -> 7 | R32: =IF(D32="TEX","аренда техники — сделка/счёт",IF(OR(Q32="",H32="",H32=0),"—",IF(Q32<H32*(1-Параметры!$B$7),"почасовка",IF(Q32>H32*(1+Параметры!$B$7),"сделка","любой способ")))) -> сделка | S32: 0.25 | T32: 0.22222222
A33: 1.4.4 | B33: Разборка водосточных ПВХ труб | C33: мп | D33: KRO | E33: =IFERROR(INDEX('Почасовка — ставки и план'!$B$5:$B$24,MATCH(D33,'Почасовка — ставки и план'!$A$5:$A$24,0)),"Аренда техники / механизмы") -> Кровельщик | F33: 160 | G33: 191 | H33: 70 | I33: =IF(OR(H33="",F33=""),"",MAX(H33,MIN(ROUND(H33*(1+Параметры!$B$5),IF(H33*(1+Параметры!$B$5)>=1000,-1,0)),ROUND(F33*Параметры!$B$6,IF(F33*Параметры!$B$6>=1000,-1,0))))) -> 81 | J33: 80.5 | K33: =IF(OR(J33="",G33=""),"",MAX(J33,MIN(ROUND(J33*(1+Параметры!$B$5),IF(J33*(1+Параметры!$B$5)>=1000,-1,0)),ROUND(G33*Параметры!$B$6,IF(G33*Параметры!$B$6>=1000,-1,0))))) -> 93 | L33: 0.15 | M33: =IF(OR(L33="",L33=0),"",1/L33) -> 6.6666667 | N33: =IF(OR(L33="",L33=0),"",Параметры!$B$3/L33) -> 53.333333 | O33: =IF(L33="","",IFERROR(INDEX('Почасовка — ставки и план'!$D$5:$D$24,MATCH($D33,'Почасовка — ставки и план'!$A$5:$A$24,0)),"")) -> 800 | P33: =IF(L33="","",IFERROR(INDEX('Почасовка — ставки и план'!$E$5:$E$24,MATCH($D33,'Почасовка — ставки и план'!$A$5:$A$24,0)),"")) -> 950 | Q33: =IF(OR(L33="",O33=""),"",ROUND(L33*O33,0)) -> 120 | R33: =IF(D33="TEX","аренда техники — сделка/счёт",IF(OR(Q33="",H33="",H33=0),"—",IF(Q33<H33*(1-Параметры!$B$7),"почасовка",IF(Q33>H33*(1+Параметры!$B$7),"сделка","любой способ")))) -> сделка | S33: 0.33333333 | T33: 0.38405797
A34: 1.4.5 | B34: Разборка водосточных труб металлических | C34: мп | D34: KRO | E34: =IFERROR(INDEX('Почасовка — ставки и план'!$B$5:$B$24,MATCH(D34,'Почасовка — ставки и план'!$A$5:$A$24,0)),"Аренда техники / механизмы") -> Кровельщик | F34: 214 | G34: 254 | H34: 90 | I34: =IF(OR(H34="",F34=""),"",MAX(H34,MIN(ROUND(H34*(1+Параметры!$B$5),IF(H34*(1+Параметры!$B$5)>=1000,-1,0)),ROUND(F34*Параметры!$B$6,IF(F34*Параметры!$B$6>=1000,-1,0))))) -> 104 | J34: 103 | K34: =IF(OR(J34="",G34=""),"",MAX(J34,MIN(ROUND(J34*(1+Параметры!$B$5),IF(J34*(1+Параметры!$B$5)>=1000,-1,0)),ROUND(G34*Параметры!$B$6,IF(G34*Параметры!$B$6>=1000,-1,0))))) -> 118 | L34: 0.2 | M34: =IF(OR(L34="",L34=0),"",1/L34) -> 5 | N34: =IF(OR(L34="",L34=0),"",Параметры!$B$3/L34) -> 40 | O34: =IF(L34="","",IFERROR(INDEX('Почасовка — ставки и план'!$D$5:$D$24,MATCH($D34,'Почасовка — ставки и план'!$A$5:$A$24,0)),"")) -> 800 | P34: =IF(L34="","",IFERROR(INDEX('Почасовка — ставки и план'!$E$5:$E$24,MATCH($D34,'Почасовка — ставки и план'!$A$5:$A$24,0)),"")) -> 950 | Q34: =IF(OR(L34="",O34=""),"",ROUND(L34*O34,0)) -> 160 | R34: =IF(D34="TEX","аренда техники — сделка/счёт",IF(OR(Q34="",H34="",H34=0),"—",IF(Q34<H34*(1-Параметры!$B$7),"почасовка",IF(Q34>H34*(1+Параметры!$B$7),"сделка","любой способ")))) -> сделка | S34: 0.42666667 | T34: 0.47674419
A35: 1.4.6 | B35: Разборка выравнивающих стяжек цементно-песчаных на кровле | C35: м3 | D35: KRO | E35: =IFERROR(INDEX('Почасовка — ставки и план'!$B$5:$B$24,MATCH(D35,'Почасовка — ставки и план'!$A$5:$A$24,0)),"Аренда техники / механизмы") -> Кровельщик | F35: 10134 | G35: 12034 | H35: 3600 | I35: =IF(OR(H35="",F35=""),"",MAX(H35,MIN(ROUND(H35*(1+Параметры!$B$5),IF(H35*(1+Параметры!$B$5)>=1000,-1,0)),ROUND(F35*Параметры!$B$6,IF(F35*Параметры!$B$6>=1000,-1,0))))) -> 4140 | J35: 4140 | K35: =IF(OR(J35="",G35=""),"",MAX(J35,MIN(ROUND(J35*(1+Параметры!$B$5),IF(J35*(1+Параметры!$B$5)>=1000,-1,0)),ROUND(G35*Параметры!$B$6,IF(G35*Параметры!$B$6>=1000,-1,0))))) -> 4760 | L35: 9.5 | M35: =IF(OR(L35="",L35=0),"",1/L35) -> 0.10526316 | N35: =IF(OR(L35="",L35=0),"",Параметры!$B$3/L35) -> 0.84210526 | O35: =IF(L35="","",IFERROR(INDEX('Почасовка — ставки и план'!$D$5:$D$24,MATCH($D35,'Почасовка — ставки и план'!$A$5:$A$24,0)),"")) -> 800 | P35: =IF(L35="","",IFERROR(INDEX('Почасовка — ставки и план'!$E$5:$E$24,MATCH($D35,'Почасовка — ставки и план'!$A$5:$A$24,0)),"")) -> 950 | Q35: =IF(OR(L35="",O35=""),"",ROUND(L35*O35,0)) -> 7600 | R35: =IF(D35="TEX","аренда техники — сделка/счёт",IF(OR(Q35="",H35="",H35=0),"—",IF(Q35<H35*(1-Параметры!$B$7),"почасовка",IF(Q35>H35*(1+Параметры!$B$7),"сделка","любой способ")))) -> сделка | S35: 0.689 | T35: 0.74405797
A36: 1.4.7 | B36: Разборка монолитных перекрытий бетонных | C36: м3 | D36: RAZ | E36: =IFERROR(INDEX('Почасовка — ставки и план'!$B$5:$B$24,MATCH(D36,'Почасовка — ставки и план'!$A$5:$A$24,0)),"Аренда техники / механизмы") -> Разнорабочий / демонтажник | F36: 9534 | G36: 11440 | H36: 5100 | I36: =IF(OR(H36="",F36=""),"",MAX(H36,MIN(ROUND(H36*(1+Параметры!$B$5),IF(H36*(1+Параметры!$B$5)>=1000,-1,0)),ROUND(F36*Параметры!$B$6,IF(F36*Параметры!$B$6>=1000,-1,0))))) -> 5870 | J36: 5865 | K36: =IF(OR(J36="",G36=""),"",MAX(J36,MIN(ROUND(J36*(1+Параметры!$B$5),IF(J36*(1+Параметры!$B$5)>=1000,-1,0)),ROUND(G36*Параметры!$B$6,IF(G36*Параметры!$B$6>=1000,-1,0))))) -> 6740 | L36: 13 | M36: =IF(OR(L36="",L36=0),"",1/L36) -> 0.076923077 | N36: =IF(OR(L36="",L36=0),"",Параметры!$B$3/L36) -> 0.61538462 | O36: =IF(L36="","",IFERROR(INDEX('Почасовка — ставки и план'!$D$5:$D$24,MATCH($D36,'Почасовка — ставки и план'!$A$5:$A$24,0)),"")) -> 550 | P36: =IF(L36="","",IFERROR(INDEX('Почасовка — ставки и план'!$E$5:$E$24,MATCH($D36,'Почасовка — ставки и план'!$A$5:$A$24,0)),"")) -> 660 | Q36: =IF(OR(L36="",O36=""),"",ROUND(L36*O36,0)) -> 7150 | R36: =IF(D36="TEX","аренда техники — сделка/счёт",IF(OR(Q36="",H36="",H36=0),"—",IF(Q36<H36*(1-Параметры!$B$7),"почасовка",IF(Q36>H36*(1+Параметры!$B$7),"сделка","любой способ")))) -> сделка | S36: 0.12164706 | T36: 0.17033248
A37: 1.4.8 | B37: Разборка монолитных перекрытий железобетонных | C37: м3 | D37: RAZ | E37: =IFERROR(INDEX('Почасовка — ставки и план'!$B$5:$B$24,MATCH(D37,'Почасовка — ставки и план'!$A$5:$A$24,0)),"Аренда техники / механизмы") -> Разнорабочий / демонтажник | F37: 12467 | G37: 14960 | H37: 6600 | I37: =IF(OR(H37="",F37=""),"",MAX(H37,MIN(ROUND(H37*(1+Параметры!$B$5),IF(H37*(1+Параметры!$B$5)>=1000,-1,0)),ROUND(F37*Параметры!$B$6,IF(F37*Параметры!$B$6>=1000,-1,0))))) -> 7590 | J37: 7788 | K37: =IF(OR(J37="",G37=""),"",MAX(J37,MIN(ROUND(J37*(1+Параметры!$B$5),IF(J37*(1+Параметры!$B$5)>=1000,-1,0)),ROUND(G37*Параметры!$B$6,IF(G37*Параметры!$B$6>=1000,-1,0))))) -> 8960 | L37: 17 | M37: =IF(OR(L37="",L37=0),"",1/L37) -> 0.058823529 | N37: =IF(OR(L37="",L37=0),"",Параметры!$B$3/L37) -> 0.47058824 | O37: =IF(L37="","",IFERROR(INDEX('Почасовка — ставки и план'!$D$5:$D$24,MATCH($D37,'Почасовка — ставки и план'!$A$5:$A$24,0)),"")) -> 550 | P37: =IF(L37="","",IFERROR(INDEX('Почасовка — ставки и план'!$E$5:$E$24,MATCH($D37,'Почасовка — ставки и план'!$A$5:$A$24,0)),"")) -> 660 | Q37: =IF(OR(L37="",O37=""),"",ROUND(L37*O37,0)) -> 9350 | R37: =IF(D37="TEX","аренда техники — сделка/счёт",IF(OR(Q37="",H37="",H37=0),"—",IF(Q37<H37*(1-Параметры!$B$7),"почасовка",IF(Q37>H37*(1+Параметры!$B$7),"сделка","любой способ")))) -> сделка | S37: 0.13336364 | T37: 0.13333333
A38: 1.4.9 | B38: Разборка парапетных решеток | C38: мп | D38: KRO | E38: =IFERROR(INDEX('Почасовка — ставки и план'!$B$5:$B$24,MATCH(D38,'Почасовка — ставки и план'!$A$5:$A$24,0)),"Аренда техники / механизмы") -> Кровельщик | F38: 427 | G38: 507 | H38: 150 | I38: =IF(OR(H38="",F38=""),"",MAX(H38,MIN(ROUND(H38*(1+Параметры!$B$5),IF(H38*(1+Параметры!$B$5)>=1000,-1,0)),ROUND(F38*Параметры!$B$6,IF(F38*Параметры!$B$6>=1000,-1,0))))) -> 173 | J38: 172 | K38: =IF(OR(J38="",G38=""),"",MAX(J38,MIN(ROUND(J38*(1+Параметры!$B$5),IF(J38*(1+Параметры!$B$5)>=1000,-1,0)),ROUND(G38*Параметры!$B$6,IF(G38*Параметры!$B$6>=1000,-1,0))))) -> 198 | L38: 0.4 | M38: =IF(OR(L38="",L38=0),"",1/L38) -> 2.5 | N38: =IF(OR(L38="",L38=0),"",Параметры!$B$3/L38) -> 20 | O38: =IF(L38="","",IFERROR(INDEX('Почасовка — ставки и план'!$D$5:$D$24,MATCH($D38,'Почасовка — ставки и план'!$A$5:$A$24,0)),"")) -> 800 | P38: =IF(L38="","",IFERROR(INDEX('Почасовка — ставки и план'!$E$5:$E$24,MATCH($D38,'Почасовка — ставки и план'!$A$5:$A$24,0)),"")) -> 950 | Q38: =IF(OR(L38="",O38=""),"",ROUND(L38*O38,0)) -> 320 | R38: =IF(D38="TEX","аренда техники — сделка/счёт",IF(OR(Q38="",H38="",H38=0),"—",IF(Q38<H38*(1-Параметры!$B$7),"почасовка",IF(Q38>H38*(1+Параметры!$B$7),"сделка","любой способ")))) -> сделка | S38: 0.708 | T38: 0.76041667
A39: 1.4.10 | B39: Разборка покрытий кровель из волнистых и полуволнистых асбестоцементных листов | C39: м2 | D39: KRO | E39: =IFERROR(INDEX('Почасовка — ставки и план'!$B$5:$B$24,MATCH(D39,'Почасовка — ставки и план'!$A$5:$A$24,0)),"Аренда техники / механизмы") -> Кровельщик | F39: 267 | G39: 318 | H39: 130 | I39: =IF(OR(H39="",F39=""),"",MAX(H39,MIN(ROUND(H39*(1+Параметры!$B$5),IF(H39*(1+Параметры!$B$5)>=1000,-1,0)),ROUND(F39*Параметры!$B$6,IF(F39*Параметры!$B$6>=1000,-1,0))))) -> 150 | J39: 150 | K39: =IF(OR(J39="",G39=""),"",MAX(J39,MIN(ROUND(J39*(1+Параметры!$B$5),IF(J39*(1+Параметры!$B$5)>=1000,-1,0)),ROUND(G39*Параметры!$B$6,IF(G39*Параметры!$B$6>=1000,-1,0))))) -> 173 | L39: 0.25 | M39: =IF(OR(L39="",L39=0),"",1/L39) -> 4 | N39: =IF(OR(L39="",L39=0),"",Параметры!$B$3/L39) -> 32 | O39: =IF(L39="","",IFERROR(INDEX('Почасовка — ставки и план'!$D$5:$D$24,MATCH($D39,'Почасовка — ставки и план'!$A$5:$A$24,0)),"")) -> 800 | P39: =IF(L39="","",IFERROR(INDEX('Почасовка — ставки и план'!$E$5:$E$24,MATCH($D39,'Почасовка — ставки и план'!$A$5:$A$24,0)),"")) -> 950 | Q39: =IF(OR(L39="",O39=""),"",ROUND(L39*O39,0)) -> 200 | R39: =IF(D39="TEX","аренда техники — сделка/счёт",IF(OR(Q39="",H39="",H39=0),"—",IF(Q39<H39*(1-Параметры!$B$7),"почасовка",IF(Q39>H39*(1+Параметры!$B$7),"сделка","любой способ")))) -> сделка | S39: 0.21363636 | T39: 0.256917
A40: 1.4.11 | B40: Разборка покрытий кровель из листовой стали | C40: м2 | D40: KRO | E40: =IFERROR(INDEX('Почасовка — ставки и план'!$B$5:$B$24,MATCH(D40,'Почасовка — ставки и план'!$A$5:$A$24,0)),"Аренда техники / механизмы") -> Кровельщик | F40: 192 | G40: 228 | H40: 90 | I40: =IF(OR(H40="",F40=""),"",MAX(H40,MIN(ROUND(H40*(1+Параметры!$B$5),IF(H40*(1+Параметры!$B$5)>=1000,-1,0)),ROUND(F40*Параметры!$B$6,IF(F40*Параметры!$B$6>=1000,-1,0))))) -> 104 | J40: 103 | K40: =IF(OR(J40="",G40=""),"",MAX(J40,MIN(ROUND(J40*(1+Параметры!$B$5),IF(J40*(1+Параметры!$B$5)>=1000,-1,0)),ROUND(G40*Параметры!$B$6,IF(G40*Параметры!$B$6>=1000,-1,0))))) -> 118 | L40: 0.18 | M40: =IF(OR(L40="",L40=0),"",1/L40) -> 5.5555556 | N40: =IF(OR(L40="",L40=0),"",Параметры!$B$3/L40) -> 44.444444 | O40: =IF(L40="","",IFERROR(INDEX('Почасовка — ставки и план'!$D$5:$D$24,MATCH($D40,'Почасовка — ставки и план'!$A$5:$A$24,0)),"")) -> 800 | P40: =IF(L40="","",IFERROR(INDEX('Почасовка — ставки и план'!$E$5:$E$24,MATCH($D40,'Почасовка — ставки и план'!$A$5:$A$24,0)),"")) -> 950 | Q40: =IF(OR(L40="",O40=""),"",ROUND(L40*O40,0)) -> 144 | R40: =IF(D40="TEX","аренда техники — сделка/счёт",IF(OR(Q40="",H40="",H40=0),"—",IF(Q40<H40*(1-Параметры!$B$7),"почасовка",IF(Q40>H40*(1+Параметры!$B$7),"сделка","любой способ")))) -> сделка | S40: 0.28 | T40: 0.3255814
...

Sheet Почасовка — ставки и план
A1: ПОЧАСОВАЯ ОПЛАТА ПО СПЕЦИАЛЬНОСТЯМ
A2: Жёлтые ячейки — вводные (ставка бригаде ИП/СЗ вкл. налог 6 % и рынок нормо-часа подрядчика): при изменении пересчитываются листы «Расценки» и «Для HR». Цена в КП на листе «Расценки» не пересчитывается — она из основного тарификатора.
A4: Код | B4: Специальность | C4: Что делает | D4: Ставка часа СПб, руб/ч (вводная) | E4: Ставка часа Мск, руб/ч (вводная) | F4: Смена СПб, руб = ставка × часы смены | G4: Смена Мск, руб = ставка × часы смены | H4: Месяц СПб, руб = смена × смен в месяц | I4: Месяц Мск, руб = смена × смен в месяц | J4: Рынок нормо-часа подрядчика СПб, б/НДС (вводная) | K4: Рынок нормо-часа Мск (вводная) | L4: Нормо-час для заказчика СПб, б/НДС = ставка × 1,25 × 1,35, не ниже 95 % рынка | M4: Нормо-час для заказчика Мск, б/НДС = то же | N4: Работ в тарификаторе
A5: RAZ | B5: Разнорабочий / демонтажник | C5: Демонтаж, разборка, вынос мусора, такелаж вручную, уборка | D5: 550 | E5: 660 | F5: =D5*Параметры!$B$3 -> 4400 | G5: =E5*Параметры!$B$3 -> 5280 | H5: =F5*Параметры!$B$4 -> 92400 | I5: =G5*Параметры!$B$4 -> 110880 | J5: 1000 | K5: 1200 | L5: =IF(J5=0,ROUND(ROUND(D5*(1+Параметры!$B$9),0)*(1+Параметры!$B$10),-1),IF(ROUND(ROUND(D5*(1+Параметры!$B$9),0)*(1+Параметры!$B$10),-1)<=J5,ROUND(MAX(ROUND(ROUND(D5*(1+Параметры!$B$9),0)*(1+Параметры!$B$10),-1),J5*Параметры!$B$11),-1),ROUND(ROUND(D5*(1+Параметры!$B$9),0)*(1+Параметры!$B$10),-1))) -> 950 | M5: =IF(K5=0,ROUND(ROUND(E5*(1+Параметры!$B$9),0)*(1+Параметры!$B$10),-1),IF(ROUND(ROUND(E5*(1+Параметры!$B$9),0)*(1+Параметры!$B$10),-1)<=K5,ROUND(MAX(ROUND(ROUND(E5*(1+Параметры!$B$9),0)*(1+Параметры!$B$10),-1),K5*Параметры!$B$11),-1),ROUND(ROUND(E5*(1+Параметры!$B$9),0)*(1+Параметры!$B$10),-1))) -> 1140 | N5: =COUNTIF(Расценки!$D$5:$D$2419,A5) -> 111
A6: ZEM | B6: Землекоп / рабочий земляных работ | C6: Ручная разработка и обратная засыпка грунта, планировка | D6: 550 | E6: 660 | F6: =D6*Параметры!$B$3 -> 4400 | G6: =E6*Параметры!$B$3 -> 5280 | H6: =F6*Параметры!$B$4 -> 92400 | I6: =G6*Параметры!$B$4 -> 110880 | J6: 1000 | K6: 1200 | L6: =IF(J6=0,ROUND(ROUND(D6*(1+Параметры!$B$9),0)*(1+Параметры!$B$10),-1),IF(ROUND(ROUND(D6*(1+Параметры!$B$9),0)*(1+Параметры!$B$10),-1)<=J6,ROUND(MAX(ROUND(ROUND(D6*(1+Параметры!$B$9),0)*(1+Параметры!$B$10),-1),J6*Параметры!$B$11),-1),ROUND(ROUND(D6*(1+Параметры!$B$9),0)*(1+Параметры!$B$10),-1))) -> 950 | M6: =IF(K6=0,ROUND(ROUND(E6*(1+Параметры!$B$9),0)*(1+Параметры!$B$10),-1),IF(ROUND(ROUND(E6*(1+Параметры!$B$9),0)*(1+Параметры!$B$10),-1)<=K6,ROUND(MAX(ROUND(ROUND(E6*(1+Параметры!$B$9),0)*(1+Параметры!$B$10),-1),K6*Параметры!$B$11),-1),ROUND(ROUND(E6*(1+Параметры!$B$9),0)*(1+Параметры!$B$10),-1))) -> 1140 | N6: =COUNTIF(Расценки!$D$5:$D$2419,A6) -> 18
A7: BLG | B7: Дорожный рабочий / благоустройство | C7: Бортовой камень, плитка, газоны, ограждения, ручные дорожные работы | D7: 650 | E7: 780 | F7: =D7*Параметры!$B$3 -> 5200 | G7: =E7*Параметры!$B$3 -> 6240 | H7: =F7*Параметры!$B$4 -> 109200 | I7: =G7*Параметры!$B$4 -> 131040 | J7: 1300 | K7: 1500 | L7: =IF(J7=0,ROUND(ROUND(D7*(1+Параметры!$B$9),0)*(1+Параметры!$B$10),-1),IF(ROUND(ROUND(D7*(1+Параметры!$B$9),0)*(1+Параметры!$B$10),-1)<=J7,ROUND(MAX(ROUND(ROUND(D7*(1+Параметры!$B$9),0)*(1+Параметры!$B$10),-1),J7*Параметры!$B$11),-1),ROUND(ROUND(D7*(1+Параметры!$B$9),0)*(1+Параметры!$B$10),-1))) -> 1240 | M7: =IF(K7=0,ROUND(ROUND(E7*(1+Параметры!$B$9),0)*(1+Параметры!$B$10),-1),IF(ROUND(ROUND(E7*(1+Параметры!$B$9),0)*(1+Параметры!$B$10),-1)<=K7,ROUND(MAX(ROUND(ROUND(E7*(1+Параметры!$B$9),0)*(1+Параметры!$B$10),-1),K7*Параметры!$B$11),-1),ROUND(ROUND(E7*(1+Параметры!$B$9),0)*(1+Параметры!$B$10),-1))) -> 1430 | N7: =COUNTIF(Расценки!$D$5:$D$2419,A7) -> 84
A8: BET | B8: Бетонщик / арматурщик | C8: Опалубка, армирование, бетонирование, стяжки, основания | D8: 800 | E8: 950 | F8: =D8*Параметры!$B$3 -> 6400 | G8: =E8*Параметры!$B$3 -> 7600 | H8: =F8*Параметры!$B$4 -> 134400 | I8: =G8*Параметры!$B$4 -> 159600 | J8: 1500 | K8: 1800 | L8: =IF(J8=0,ROUND(ROUND(D8*(1+Параметры!$B$9),0)*(1+Параметры!$B$10),-1),IF(ROUND(ROUND(D8*(1+Параметры!$B$9),0)*(1+Параметры!$B$10),-1)<=J8,ROUND(MAX(ROUND(ROUND(D8*(1+Параметры!$B$9),0)*(1+Параметры!$B$10),-1),J8*Параметры!$B$11),-1),ROUND(ROUND(D8*(1+Параметры!$B$9),0)*(1+Параметры!$B$10),-1))) -> 1430 | M8: =IF(K8=0,ROUND(ROUND(E8*(1+Параметры!$B$9),0)*(1+Параметры!$B$10),-1),IF(ROUND(ROUND(E8*(1+Параметры!$B$9),0)*(1+Параметры!$B$10),-1)<=K8,ROUND(MAX(ROUND(ROUND(E8*(1+Параметры!$B$9),0)*(1+Параметры!$B$10),-1),K8*Параметры!$B$11),-1),ROUND(ROUND(E8*(1+Параметры!$B$9),0)*(1+Параметры!$B$10),-1))) -> 1710 | N8: =COUNTIF(Расценки!$D$5:$D$2419,A8) -> 61
A9: KAM | B9: Каменщик | C9: Кладка кирпича и блоков, перегородки, ремонт кладки | D9: 800 | E9: 950 | F9: =D9*Параметры!$B$3 -> 6400 | G9: =E9*Параметры!$B$3 -> 7600 | H9: =F9*Параметры!$B$4 -> 134400 | I9: =G9*Параметры!$B$4 -> 159600 | J9: 1600 | K9: 1900 | L9: =IF(J9=0,ROUND(ROUND(D9*(1+Параметры!$B$9),0)*(1+Параметры!$B$10),-1),IF(ROUND(ROUND(D9*(1+Параметры!$B$9),0)*(1+Параметры!$B$10),-1)<=J9,ROUND(MAX(ROUND(ROUND(D9*(1+Параметры!$B$9),0)*(1+Параметры!$B$10),-1),J9*Параметры!$B$11),-1),ROUND(ROUND(D9*(1+Параметры!$B$9),0)*(1+Параметры!$B$10),-1))) -> 1520 | M9: =IF(K9=0,ROUND(ROUND(E9*(1+Параметры!$B$9),0)*(1+Параметры!$B$10),-1),IF(ROUND(ROUND(E9*(1+Параметры!$B$9),0)*(1+Параметры!$B$10),-1)<=K9,ROUND(MAX(ROUND(ROUND(E9*(1+Параметры!$B$9),0)*(1+Параметры!$B$10),-1),K9*Параметры!$B$11),-1),ROUND(ROUND(E9*(1+Параметры!$B$9),0)*(1+Параметры!$B$10),-1))) -> 1810 | N9: =COUNTIF(Расценки!$D$5:$D$2419,A9) -> 29
A10: OTD | B10: Отделочник (штукатур, маляр, ГКЛ) | C10: Штукатурка, шпаклёвка, окраска, перегородки и потолки ГКЛ, подвесные потолки | D10: 750 | E10: 900 | F10: =D10*Параметры!$B$3 -> 6000 | G10: =E10*Параметры!$B$3 -> 7200 | H10: =F10*Параметры!$B$4 -> 126000 | I10: =G10*Параметры!$B$4 -> 151200 | J10: 1500 | K10: 1800 | L10: =IF(J10=0,ROUND(ROUND(D10*(1+Параметры!$B$9),0)*(1+Параметры!$B$10),-1),IF(ROUND(ROUND(D10*(1+Параметры!$B$9),0)*(1+Параметры!$B$10),-1)<=J10,ROUND(MAX(ROUND(ROUND(D10*(1+Параметры!$B$9),0)*(1+Параметры!$B$10),-1),J10*Параметры!$B$11),-1),ROUND(ROUND(D10*(1+Параметры!$B$9),0)*(1+Параметры!$B$10),-1))) -> 1430 | M10: =IF(K10=0,ROUND(ROUND(E10*(1+Параметры!$B$9),0)*(1+Параметры!$B$10),-1),IF(ROUND(ROUND(E10*(1+Параметры!$B$9),0)*(1+Параметры!$B$10),-1)<=K10,ROUND(MAX(ROUND(ROUND(E10*(1+Параметры!$B$9),0)*(1+Параметры!$B$10),-1),K10*Параметры!$B$11),-1),ROUND(ROUND(E10*(1+Параметры!$B$9),0)*(1+Параметры!$B$10),-1))) -> 1710 | N10: =COUNTIF(Расценки!$D$5:$D$2419,A10) -> 141
A11: PLI | B11: Плиточник / укладчик полов | C11: Плитка, керамогранит, наливные полы, линолеум, ПВХ, плинтус | D11: 900 | E11: 1080 | F11: =D11*Параметры!$B$3 -> 7200 | G11: =E11*Параметры!$B$3 -> 8640 | H11: =F11*Параметры!$B$4 -> 151200 | I11: =G11*Параметры!$B$4 -> 181440 | J11: 1700 | K11: 2000 | L11: =IF(J11=0,ROUND(ROUND(D11*(1+Параметры!$B$9),0)*(1+Параметры!$B$10),-1),IF(ROUND(ROUND(D11*(1+Параметры!$B$9),0)*(1+Параметры!$B$10),-1)<=J11,ROUND(MAX(ROUND(ROUND(D11*(1+Параметры!$B$9),0)*(1+Параметры!$B$10),-1),J11*Параметры!$B$11),-1),ROUND(ROUND(D11*(1+Параметры!$B$9),0)*(1+Параметры!$B$10),-1))) -> 1620 | M11: =IF(K11=0,ROUND(ROUND(E11*(1+Параметры!$B$9),0)*(1+Параметры!$B$10),-1),IF(ROUND(ROUND(E11*(1+Параметры!$B$9),0)*(1+Параметры!$B$10),-1)<=K11,ROUND(MAX(ROUND(ROUND(E11*(1+Параметры!$B$9),0)*(1+Параметры!$B$10),-1),K11*Параметры!$B$11),-1),ROUND(ROUND(E11*(1+Параметры!$B$9),0)*(1+Параметры!$B$10),-1))) -> 1900 | N11: =COUNTIF(Расценки!$D$5:$D$2419,A11) -> 62
A12: KRO | B12: Кровельщик | C12: Наплавляемые и мембранные кровли, металлокровля, водосток, примыкания | D12: 800 | E12: 950 | F12: =D12*Параметры!$B$3 -> 6400 | G12: =E12*Параметры!$B$3 -> 7600 | H12: =F12*Параметры!$B$4 -> 134400 | I12: =G12*Параметры!$B$4 -> 159600 | J12: 1600 | K12: 1900 | L12: =IF(J12=0,ROUND(ROUND(D12*(1+Параметры!$B$9),0)*(1+Параметры!$B$10),-1),IF(ROUND(ROUND(D12*(1+Параметры!$B$9),0)*(1+Параметры!$B$10),-1)<=J12,ROUND(MAX(ROUND(ROUND(D12*(1+Параметры!$B$9),0)*(1+Параметры!$B$10),-1),J12*Параметры!$B$11),-1),ROUND(ROUND(D12*(1+Параметры!$B$9),0)*(1+Параметры!$B$10),-1))) -> 1520 | M12: =IF(K12=0,ROUND(ROUND(E12*(1+Параметры!$B$9),0)*(1+Параметры!$B$10),-1),IF(ROUND(ROUND(E12*(1+Параметры!$B$9),0)*(1+Параметры!$B$10),-1)<=K12,ROUND(MAX(ROUND(ROUND(E12*(1+Параметры!$B$9),0)*(1+Параметры!$B$10),-1),K12*Параметры!$B$11),-1),ROUND(ROUND(E12*(1+Параметры!$B$9),0)*(1+Параметры!$B$10),-1))) -> 1810 | N12: =COUNTIF(Расценки!$D$5:$D$2419,A12) -> 66
A13: FAS | B13: Фасадчик / промальпинист | C13: Вентфасады, сэндвич-панели, работы на высоте с люльки и верёвки | D13: 1100 | E13: 1300 | F13: =D13*Параметры!$B$3 -> 8800 | G13: =E13*Параметры!$B$3 -> 10400 | H13: =F13*Параметры!$B$4 -> 184800 | I13: =G13*Параметры!$B$4 -> 218400 | J13: 2400 | K13: 2800 | L13: =IF(J13=0,ROUND(ROUND(D13*(1+Параметры!$B$9),0)*(1+Параметры!$B$10),-1),IF(ROUND(ROUND(D13*(1+Параметры!$B$9),0)*(1+Параметры!$B$10),-1)<=J13,ROUND(MAX(ROUND(ROUND(D13*(1+Параметры!$B$9),0)*(1+Параметры!$B$10),-1),J13*Параметры!$B$11),-1),ROUND(ROUND(D13*(1+Параметры!$B$9),0)*(1+Параметры!$B$10),-1))) -> 2280 | M13: =IF(K13=0,ROUND(ROUND(E13*(1+Параметры!$B$9),0)*(1+Параметры!$B$10),-1),IF(ROUND(ROUND(E13*(1+Параметры!$B$9),0)*(1+Параметры!$B$10),-1)<=K13,ROUND(MAX(ROUND(ROUND(E13*(1+Параметры!$B$9),0)*(1+Параметры!$B$10),-1),K13*Параметры!$B$11),-1),ROUND(ROUND(E13*(1+Параметры!$B$9),0)*(1+Параметры!$B$10),-1))) -> 2660 | N13: =COUNTIF(Расценки!$D$5:$D$2419,A13) -> 32
A14: SVA | B14: Сварщик / монтажник МК | C14: Сварка, монтаж и ремонт металлоконструкций, ограждений, ворот | D14: 900 | E14: 1080 | F14: =D14*Параметры!$B$3 -> 7200 | G14: =E14*Параметры!$B$3 -> 8640 | H14: =F14*Параметры!$B$4 -> 151200 | I14: =G14*Параметры!$B$4 -> 181440 | J14: 2000 | K14: 2400 | L14: =IF(J14=0,ROUND(ROUND(D14*(1+Параметры!$B$9),0)*(1+Параметры!$B$10),-1),IF(ROUND(ROUND(D14*(1+Параметры!$B$9),0)*(1+Параметры!$B$10),-1)<=J14,ROUND(MAX(ROUND(ROUND(D14*(1+Параметры!$B$9),0)*(1+Параметры!$B$10),-1),J14*Параметры!$B$11),-1),ROUND(ROUND(D14*(1+Параметры!$B$9),0)*(1+Параметры!$B$10),-1))) -> 1900 | M14: =IF(K14=0,ROUND(ROUND(E14*(1+Параметры!$B$9),0)*(1+Параметры!$B$10),-1),IF(ROUND(ROUND(E14*(1+Параметры!$B$9),0)*(1+Параметры!$B$10),-1)<=K14,ROUND(MAX(ROUND(ROUND(E14*(1+Параметры!$B$9),0)*(1+Параметры!$B$10),-1),K14*Параметры!$B$11),-1),ROUND(ROUND(E14*(1+Параметры!$B$9),0)*(1+Параметры!$B$10),-1))) -> 2280 | N14: =COUNTIF(Расценки!$D$5:$D$2419,A14) -> 132
A15: SAN | B15: Сантехник | C15: Водопровод, канализация, отопление, сантехприборы, насосы | D15: 850 | E15: 1020 | F15: =D15*Параметры!$B$3 -> 6800 | G15: =E15*Параметры!$B$3 -> 8160 | H15: =F15*Параметры!$B$4 -> 142800 | I15: =G15*Параметры!$B$4 -> 171360 | J15: 1900 | K15: 2200 | L15: =IF(J15=0,ROUND(ROUND(D15*(1+Параметры!$B$9),0)*(1+Параметры!$B$10),-1),IF(ROUND(ROUND(D15*(1+Параметры!$B$9),0)*(1+Параметры!$B$10),-1)<=J15,ROUND(MAX(ROUND(ROUND(D15*(1+Параметры!$B$9),0)*(1+Параметры!$B$10),-1),J15*Параметры!$B$11),-1),ROUND(ROUND(D15*(1+Параметры!$B$9),0)*(1+Параметры!$B$10),-1))) -> 1810 | M15: =IF(K15=0,ROUND(ROUND(E15*(1+Параметры!$B$9),0)*(1+Параметры!$B$10),-1),IF(ROUND(ROUND(E15*(1+Параметры!$B$9),0)*(1+Параметры!$B$10),-1)<=K15,ROUND(MAX(ROUND(ROUND(E15*(1+Параметры!$B$9),0)*(1+Параметры!$B$10),-1),K15*Параметры!$B$11),-1),ROUND(ROUND(E15*(1+Параметры!$B$9),0)*(1+Параметры!$B$10),-1))) -> 2090 | N15: =COUNTIF(Расценки!$D$5:$D$2419,A15) -> 342
A16: VEN | B16: Монтажник вентиляции | C16: Воздуховоды, вентиляторы, решётки, клапаны, ТО вентустановок | D16: 850 | E16: 1020 | F16: =D16*Параметры!$B$3 -> 6800 | G16: =E16*Параметры!$B$3 -> 8160 | H16: =F16*Параметры!$B$4 -> 142800 | I16: =G16*Параметры!$B$4 -> 171360 | J16: 2200 | K16: 2600 | L16: =IF(J16=0,ROUND(ROUND(D16*(1+Параметры!$B$9),0)*(1+Параметры!$B$10),-1),IF(ROUND(ROUND(D16*(1+Параметры!$B$9),0)*(1+Параметры!$B$10),-1)<=J16,ROUND(MAX(ROUND(ROUND(D16*(1+Параметры!$B$9),0)*(1+Параметры!$B$10),-1),J16*Параметры!$B$11),-1),ROUND(ROUND(D16*(1+Параметры!$B$9),0)*(1+Параметры!$B$10),-1))) -> 2090 | M16: =IF(K16=0,ROUND(ROUND(E16*(1+Параметры!$B$9),0)*(1+Параметры!$B$10),-1),IF(ROUND(ROUND(E16*(1+Параметры!$B$9),0)*(1+Параметры!$B$10),-1)<=K16,ROUND(MAX(ROUND(ROUND(E16*(1+Параметры!$B$9),0)*(1+Параметры!$B$10),-1),K16*Параметры!$B$11),-1),ROUND(ROUND(E16*(1+Параметры!$B$9),0)*(1+Параметры!$B$10),-1))) -> 2470 | N16: =COUNTIF(Расценки!$D$5:$D$2419,A16) -> 124
... A24: DER | B24: Дезинфектор (ОЗДС) | C24: Дератизация, дезинсекция, обслуживание ОЗДС — лицензируемая | D24: 850 | E24: 1020 | F24: =D24*Параметры!$B$3 -> 6800 | G24: =E24*Параметры!$B$3 -> 8160 | H24: =F24*Параметры!$B$4 -> 142800 | I24: =G24*Параметры!$B$4 -> 171360 | J24: 1800 | K24: 2100 | L24: =IF(J24=0,ROUND(ROUND(D24*(1+Параметры!$B$9),0)*(1+Параметры!$B$10),-1),IF(ROUND(ROUND(D24*(1+Параметры!$B$9),0)*(1+Параметры!$B$10),-1)<=J24,ROUND(MAX(ROUND(ROUND(D24*(1+Параметры!$B$9),0)*(1+Параметры!$B$10),-1),J24*Параметры!$B$11),-1),ROUND(ROUND(D24*(1+Параметры!$B$9),0)*(1+Параметры!$B$10),-1))) -> 1710 | M24: =IF(K24=0,ROUND(ROUND(E24*(1+Параметры!$B$9),0)*(1+Параметры!$B$10),-1),IF(ROUND(ROUND(E24*(1+Параметры!$B$9),0)*(1+Параметры!$B$10),-1)<=K24,ROUND(MAX(ROUND(ROUND(E24*(1+Параметры!$B$9),0)*(1+Параметры!$B$10),-1),K24*Параметры!$B$11),-1),ROUND(ROUND(E24*(1+Параметры!$B$9),0)*(1+Параметры!$B$10),-1))) -> 2000 | N24: =COUNTIF(Расценки!$D$5:$D$2419,A24) -> 6
A26: Как ставить план строителю:
A27: 1. Найдите работу на листе «Расценки» → колонка «План на смену» — это объём для ОДНОГО человека за смену. Для звена умножьте на число людей.
