Workbook

Sheet Реестр
A1: РЕЕСТР ТЕНДЕРОВ НЕОСТРОЙ
A2: Синие колонки — расчёт (заполнено по расчётам с июля 2026). Жёлтые колонки — РЕЗУЛЬТАТ, заполняет отдел тендеров после подведения итогов. Наценка и маржа считаются формулами из с/с и КП. Цифры — руб. без НДС за период из колонки «Период». Аналитика — на листе «Аналитика».
A3: РАСЧЁТ | U3: ИТОГИ ТЕНДЕРА (заполнять)
A4: № | B4: Дата расчёта | C4: Заказчик | D4: Объект | E4: Предмет | F4: Регион | G4: Вид работ | H4: Тип тендера | I4: Период цены | J4: НМЦК б/НДС | K4: С/с б/НДС | L4: КП б/НДС | M4: КП с НДС | N4: Наценка = КП ÷ с/с − 1 | O4: Маржа = 1 − с/с ÷ КП | P4: КП к НМЦК | Q4: Наценка мат. | R4: Наценка раб. | S4: Решение по расчёту | T4: Переторжки (история) | U4: Подано, дата | V4: Наша финальная цена б/НДС | W4: РЕЗУЛЬТАТ | X4: Место | Y4: Цена победителя б/НДС | Z4: Наша цена к победителю = наша ÷ победитель − 1 | AA4: Участников | AB4: Причина / комментарий по итогам | AC4: Папка | AD4: Источник расчёта (память) | AE4: Примечания
A5: 1 | B5: 46212 | C5: ООО «Пулково Аэропорт Отель СПб» | D5: СПб, Пулковское ш. 41 лит. ЗД, 109 ед. оборудования | E5: ТО кухонного и холодильного оборудования точек питания | F5: СПб | G5: КТО / ТО | H5: ТО и абонентское обслуживание | I5: в месяц | K5: 241132 | L5: 361698 | M5: 441263 | N5: =IF(AND(ISNUMBER(K5),ISNUMBER(L5),K5>0),L5/K5-1,0.5) -> 0.5 | O5: =IF(AND(ISNUMBER(K5),ISNUMBER(L5),L5>0),1-K5/L5,0.3333) -> 0.33333333 | P5: =IF(AND(ISNUMBER(J5),ISNUMBER(L5),J5>0),L5/J5-1,"") | S5: рассчитано | Z5: =IF(AND(ISNUMBER(V5),ISNUMBER(Y5),Y5>0),V5/Y5-1,"") | AD5: project_pulkovo_hotel.md | AE5: Форма с НДС 5 %, по решению пользователя НДС 22 %. Кол-во ед. 109 vs 103 в ТЗ.
A6: 2 | B6: 46213 | C6: ООО «Лента» | D6: ТК-6 | E6: Ремонт асфальтовой парковки ТК-6 | F6: СПб | G6: СМР / ремонт | H6: Крупные сети и девелоперы — конкурентный тендер | I6: разово | K6: 2710000 | L6: 4073770.5 | M6: 4970000 | N6: =IF(AND(ISNUMBER(K6),ISNUMBER(L6),K6>0),L6/K6-1,0.5) -> 0.50323634 | O6: =IF(AND(ISNUMBER(K6),ISNUMBER(L6),L6>0),1-K6/L6,0.3348) -> 0.33476861 | P6: =IF(AND(ISNUMBER(J6),ISNUMBER(L6),J6>0),L6/J6-1,"") | S6: рассчитано | Z6: =IF(AND(ISNUMBER(V6),ISNUMBER(Y6),Y6>0),V6/Y6-1,"") | AD6: project_lenta_parkovki.md | AE6: Портфель 3 ТК: с/с 10,08 млн, КП 18,46 млн с НДС. ТЗ ТК-6 путаница (объём 85 vs 985 м²).
A7: 3 | B7: 46213 | C7: ООО «Лента» | D7: ТК-48, Кудрово | E7: Ремонт асфальтовой парковки ТК-48 | F7: ЛО | G7: СМР / ремонт | H7: Крупные сети и девелоперы — конкурентный тендер | I7: разово | K7: 3870000 | L7: 5811475.4 | M7: 7090000 | N7: =IF(AND(ISNUMBER(K7),ISNUMBER(L7),K7>0),L7/K7-1,0.5) -> 0.50167323 | O7: =IF(AND(ISNUMBER(K7),ISNUMBER(L7),L7>0),1-K7/L7,0.3341) -> 0.33407616 | P7: =IF(AND(ISNUMBER(J7),ISNUMBER(L7),J7>0),L7/J7-1,"") | S7: рассчитано | Z7: =IF(AND(ISNUMBER(V7),ISNUMBER(Y7),Y7>0),V7/Y7-1,"") | AD7: project_lenta_parkovki.md | AE7: Портфель 3 ТК: с/с 10,08 млн, КП 18,46 млн с НДС.
A8: 4 | B8: 46213 | C8: ООО «Лента» | D8: ТК-270, Сосновый Бор | E8: Ремонт асфальтовой парковки ТК-270 | F8: ЛО | G8: СМР / ремонт | H8: Крупные сети и девелоперы — конкурентный тендер | I8: разово | K8: 3500000 | L8: 5245901.6 | M8: 6400000 | N8: =IF(AND(ISNUMBER(K8),ISNUMBER(L8),K8>0),L8/K8-1,0.5) -> 0.49882904 | O8: =IF(AND(ISNUMBER(K8),ISNUMBER(L8),L8>0),1-K8/L8,0.3328) -> 0.3328125 | P8: =IF(AND(ISNUMBER(J8),ISNUMBER(L8),J8>0),L8/J8-1,"") | S8: рассчитано | Z8: =IF(AND(ISNUMBER(V8),ISNUMBER(Y8),Y8>0),V8/Y8-1,"") | AD8: project_lenta_parkovki.md | AE8: Портфель 3 ТК: с/с 10,08 млн, КП 18,46 млн с НДС.
A9: 5 | B9: 46216 | C9: ООО «Лента» | D9: Столовая Центрального офиса Ленты | E9: ТОиР кухонного/пекарного оборудования столовой ЦО, 63 ед., 2026 г. | F9: СПб | G9: КТО / ТО | H9: ТО и абонентское обслуживание | I9: в месяц | K9: 63242 | L9: 94795.08 | M9: 115650 | N9: =IF(AND(ISNUMBER(K9),ISNUMBER(L9),K9>0),L9/K9-1,0.5) -> 0.49892603 | O9: =IF(AND(ISNUMBER(K9),ISNUMBER(L9),L9>0),1-K9/L9,0.3329) -> 0.33285567 | P9: =IF(AND(ISNUMBER(J9),ISNUMBER(L9),J9>0),L9/J9-1,"") | S9: рассчитано | Z9: =IF(AND(ISNUMBER(V9),ISNUMBER(Y9),Y9>0),V9/Y9-1,"") | AD9: project_lenta_stolovaya_co.md | AE9: КП 115 650/мес с НДС (б/НДС = /1,22); нерегламент 3 100 руб/ч с НДС; запчасти отдельно; SL ≥ 96 %
A10: 6 | B10: 46220 | C10: ОАО «КАРАВАЙ» | D10: ПП2 СПб, Политехническая 11 + ПП3 СПб, пр. Стачек 39 | E10: Ремонт асфальтобетонного покрытия двух площадок | F10: СПб | G10: СМР / ремонт | H10: Крупные сети и девелоперы — конкурентный тендер | I10: разово | K10: 3909760 | L10: 7504410 | M10: 9155380.2 | N10: =IF(AND(ISNUMBER(K10),ISNUMBER(L10),K10>0),L10/K10-1,0.9194) -> 0.91940426 | O10: =IF(AND(ISNUMBER(K10),ISNUMBER(L10),L10>0),1-K10/L10,0.479) -> 0.47900501 | P10: =IF(AND(ISNUMBER(J10),ISNUMBER(L10),J10>0),L10/J10-1,"") | S10: рассчитано | Z10: =IF(AND(ISNUMBER(V10),ISNUMBER(Y10),Y10>0),V10/Y10-1,"") | AD10: project_karavay_asfalt.md | AE10: B2B №4518138; ПП2 с/с 2 999 790 / КП 5 758 080, ПП3 909 970 / 1 746 330; первоначально КП 6 253 745 (+60 %), поднято +20 % до подачи
A11: 7 | B11: 46223 | C11: ООО «ФЕНИКС-ОТЕЛЬ» | D11: Cosmos SPb Nevsky, Гончарная 4А, конференц-зал 115,6 м² | E11: Реновация конференц-зала с оснащением (мебель, АВ) | F11: СПб | G11: Fit-out | H11: Fit-out, частный бизнес, малые объёмы | I11: разово | K11: 6966150 | L11: 10125740 | N11: =IF(AND(ISNUMBER(K11),ISNUMBER(L11),K11>0),L11/K11-1,0.4536) -> 0.4535633 | O11: =IF(AND(ISNUMBER(K11),ISNUMBER(L11),L11>0),1-K11/L11,0.312) -> 0.31203547 | P11: =IF(AND(ISNUMBER(J11),ISNUMBER(L11),J11>0),L11/J11-1,"") | Q11: 0.2 | R11: 1 | S11: рассчитано | Z11: =IF(AND(ISNUMBER(V11),ISNUMBER(Y11),Y11>0),V11/Y11-1,"") | AC11: Космос. Невский | AD11: project_cosmos_nevsky.md | AE11: Расхождения формы КП и РД: панели 36 vs 107 м² (~330К), ковролин, рейка. Срок до 01.09.2026.
A12: 8 | B12: 46225 | C12: ООО «ГИПЕРГЛОБУС» (Глобус) | D12: ГМ «Глобус» Тверь, Октябрьский пр-т 101 | E12: Полное ТО ГМ: электро, ОВиК, мех., холод, дежурство 24/7, Купава | F12: Тверь | G12: КТО / ТО | H12: ТО и абонентское обслуживание | I12: в год | K12: 22965000 | L12: 27999000 | N12: =IF(AND(ISNUMBER(K12),ISNUMBER(L12),K12>0),L12/K12-1,0.2192) -> 0.21920314 | O12: =IF(AND(ISNUMBER(K12),ISNUMBER(L12),L12>0),1-K12/L12,0.1798) -> 0.17979214 | P12: =IF(AND(ISNUMBER(J12),ISNUMBER(L12),J12>0),L12/J12-1,"") | S12: рассчитано | Z12: =IF(AND(ISNUMBER(V12),ISNUMBER(Y12),Y12>0),V12/Y12-1,"") | AC12: Сметы (корень, подпапки Встройка, ЦХМ) | AD12: project_globus_to.md | AE12: Финал v2 по ценам Митино; первый вариант 33,54 млн. Р1–Р3 по уровню Митино, Р4–Р6 с/с×1,3. Ремонты до 200 тыс/мес в цене, фиксация цены 1–3 года
A13: 9 | B13: 46225 | C13: ООО «ГИПЕРГЛОБУС» (Глобус) | D13: ГМ «Глобус» Тула 2, ул. Октябрьская 215 | E13: Полное ТО ГМ: электро, ОВиК, механические системы | F13: Тула | G13: КТО / ТО | H13: ТО и абонентское обслуживание | I13: в год | K13: 11765000 | L13: 13673000 | N13: =IF(AND(ISNUMBER(K13),ISNUMBER(L13),K13>0),L13/K13-1,0.1622) -> 0.16217595 | O13: =IF(AND(ISNUMBER(K13),ISNUMBER(L13),L13>0),1-K13/L13,0.1395) -> 0.13954509 | P13: =IF(AND(ISNUMBER(J13),ISNUMBER(L13),J13>0),L13/J13-1,"") | S13: рассчитано | Z13: =IF(AND(ISNUMBER(V13),ISNUMBER(Y13),Y13>0),V13/Y13-1,"") | AC13: Сметы (корень) | AD13: project_globus_to.md | AE13: Финал v2 по ценам Митино; первый вариант 17,34 млн. По файлу итог двух ГМ 41,67 млн, «маржа 20,0 %» = фактически наценка (маржа 16,7 %)
A14: 10 | B14: 46226 | C14: X5 (Агроторг) | D14: РЦ Калининград | E14: КТО РЦ, оптимизированный штат 8 чел. (вар. А) | F14: Калининград | G14: КТО / ТО | H14: ТО и абонентское обслуживание | I14: в месяц | J14: 2600000 | K14: 2111750 | L14: 2600000 | N14: =IF(AND(ISNUMBER(K14),ISNUMBER(L14),K14>0),L14/K14-1,0.231) -> 0.23120635 | O14: =IF(AND(ISNUMBER(K14),ISNUMBER(L14),L14>0),1-K14/L14,0.188) -> 0.18778846 | P14: =IF(AND(ISNUMBER(J14),ISNUMBER(L14),J14>0),L14/J14-1,"") -> 0 | S14: рассчитано | Z14: =IF(AND(ISNUMBER(V14),ISNUMBER(Y14),Y14>0),V14/Y14-1,"") | AC14: РЦ Калининград | AD14: project_kaliningrad_budget.md | AE14: Полный штат 17 чел. — с/с 4,74 млн/мес (убыток). Фикс 70 % (1,82 млн) с/с не покрывает; вар. Б 7 чел. маржа 24,2 %. Штраф 100 % мес.
A15: 11 | B15: 46226 | C15: X5 / Агроторг («Пятёрочка») | D15: РЦ «Пятёрочка» Ярославль | E15: Комплексное ТО распределительного центра, 24 мес (B2B 4507641) | F15: Ярославль | G15: КТО / ТО | H15: ТО и абонентское обслуживание | I15: в месяц | L15: 1300000 | N15: =IF(AND(ISNUMBER(K15),ISNUMBER(L15),K15>0),L15/K15-1,"") | O15: =IF(AND(ISNUMBER(K15),ISNUMBER(L15),L15>0),1-K15/L15,"") | P15: =IF(AND(ISNUMBER(J15),ISNUMBER(L15),J15>0),L15/J15-1,"") | S15: подано | V15: 1300000 | W15: проиграли | Z15: =IF(AND(ISNUMBER(V15),ISNUMBER(Y15),Y15>0),V15/Y15-1,"") | AB15: По цене 1-е место в 5 лотах из 9; проиграли на квалификации (оборот 20–50 млн в анкете). Итог 12.08.2026. | AC15: РЦ … (9 подпапок) | AD15: project_pyaterochka_rc.md | AE15: Итог 12.08.2026: проиграли все 9 лотов (по 5 лотам были 1-ми по цене). Слабая квал. анкета (оборот 20–50 млн). Плюс нормочасы РСР отдельно
A16: 12 | B16: 46226 | C16: X5 / Агроторг («Пятёрочка») | D16: РЦ «Пятёрочка» Вятка | E16: Комплексное ТО распределительного центра, 24 мес (B2B 4507641) | F16: Киров | G16: КТО / ТО | H16: ТО и абонентское обслуживание | I16: в месяц | L16: 1200000 | N16: =IF(AND(ISNUMBER(K16),ISNUMBER(L16),K16>0),L16/K16-1,"") | O16: =IF(AND(ISNUMBER(K16),ISNUMBER(L16),L16>0),1-K16/L16,"") | P16: =IF(AND(ISNUMBER(J16),ISNUMBER(L16),J16>0),L16/J16-1,"") | S16: подано | V16: 1200000 | W16: проиграли | Z16: =IF(AND(ISNUMBER(V16),ISNUMBER(Y16),Y16>0),V16/Y16-1,"") | AB16: По цене 1-е место в 5 лотах из 9; проиграли на квалификации (оборот 20–50 млн в анкете). Итог 12.08.2026. | AC16: РЦ … (9 подпапок) | AD16: project_pyaterochka_rc.md | AE16: Итог 12.08.2026: проиграли все 9 лотов (по 5 лотам были 1-ми по цене). Слабая квал. анкета (оборот 20–50 млн). Плюс нормочасы РСР отдельно
A17: 13 | B17: 46226 | C17: X5 / Агроторг («Пятёрочка») | D17: РЦ «Пятёрочка» В.Новгород | E17: Комплексное ТО распределительного центра, 24 мес (B2B 4507641) | F17: Новгородская обл. | G17: КТО / ТО | H17: ТО и абонентское обслуживание | I17: в месяц | L17: 1200000 | N17: =IF(AND(ISNUMBER(K17),ISNUMBER(L17),K17>0),L17/K17-1,"") | O17: =IF(AND(ISNUMBER(K17),ISNUMBER(L17),L17>0),1-K17/L17,"") | P17: =IF(AND(ISNUMBER(J17),ISNUMBER(L17),J17>0),L17/J17-1,"") | S17: подано | V17: 1200000 | W17: проиграли | Z17: =IF(AND(ISNUMBER(V17),ISNUMBER(Y17),Y17>0),V17/Y17-1,"") | AB17: По цене 1-е место в 5 лотах из 9; проиграли на квалификации (оборот 20–50 млн в анкете). Итог 12.08.2026. | AC17: РЦ … (9 подпапок) | AD17: project_pyaterochka_rc.md | AE17: Итог 12.08.2026: проиграли все 9 лотов (по 5 лотам были 1-ми по цене). Слабая квал. анкета (оборот 20–50 млн). Плюс нормочасы РСР отдельно
A18: 14 | B18: 46226 | C18: X5 / Агроторг («Пятёрочка») | D18: РЦ «Пятёрочка» Калининград | E18: Комплексное ТО распределительного центра, 24 мес (B2B 4507641) | F18: Калининград | G18: КТО / ТО | H18: ТО и абонентское обслуживание | I18: в месяц | L18: 2600000 | N18: =IF(AND(ISNUMBER(K18),ISNUMBER(L18),K18>0),L18/K18-1,"") | O18: =IF(AND(ISNUMBER(K18),ISNUMBER(L18),L18>0),1-K18/L18,"") | P18: =IF(AND(ISNUMBER(J18),ISNUMBER(L18),J18>0),L18/J18-1,"") | S18: подано | V18: 2600000 | W18: проиграли | Z18: =IF(AND(ISNUMBER(V18),ISNUMBER(Y18),Y18>0),V18/Y18-1,"") | AB18: По цене 1-е место в 5 лотах из 9; проиграли на квалификации (оборот 20–50 млн в анкете). Итог 12.08.2026. | AC18: РЦ … (9 подпапок) | AD18: project_pyaterochka_rc.md | AE18: Итог 12.08.2026: проиграли все 9 лотов (по 5 лотам были 1-ми по цене). Слабая квал. анкета (оборот 20–50 млн). Плюс нормочасы РСР отдельно
A19: 15 | B19: 46226 | C19: X5 / Агроторг («Пятёрочка») | D19: РЦ «Пятёрочка» Адамант | E19: Комплексное ТО распределительного центра, 24 мес (B2B 4507641) | G19: КТО / ТО | H19: ТО и абонентское обслуживание | I19: в месяц | L19: 1550000 | N19: =IF(AND(ISNUMBER(K19),ISNUMBER(L19),K19>0),L19/K19-1,"") | O19: =IF(AND(ISNUMBER(K19),ISNUMBER(L19),L19>0),1-K19/L19,"") | P19: =IF(AND(ISNUMBER(J19),ISNUMBER(L19),J19>0),L19/J19-1,"") | S19: подано | V19: 1550000 | W19: проиграли | Z19: =IF(AND(ISNUMBER(V19),ISNUMBER(Y19),Y19>0),V19/Y19-1,"") | AB19: По цене 1-е место в 5 лотах из 9; проиграли на квалификации (оборот 20–50 млн в анкете). Итог 12.08.2026. | AC19: РЦ … (9 подпапок) | AD19: project_pyaterochka_rc.md | AE19: Итог 12.08.2026: проиграли все 9 лотов (по 5 лотам были 1-ми по цене). Слабая квал. анкета (оборот 20–50 млн). Плюс нормочасы РСР отдельно
A20: 16 | B20: 46226 | C20: X5 / Агроторг («Пятёрочка») | D20: РЦ «Пятёрочка» ЗТЛ лот 1 | E20: Комплексное ТО распределительного центра, 24 мес (B2B 4507641) | G20: КТО / ТО | H20: ТО и абонентское обслуживание | I20: в месяц | L20: 1050000 | N20: =IF(AND(ISNUMBER(K20),ISNUMBER(L20),K20>0),L20/K20-1,"") | O20: =IF(AND(ISNUMBER(K20),ISNUMBER(L20),L20>0),1-K20/L20,"") | P20: =IF(AND(ISNUMBER(J20),ISNUMBER(L20),J20>0),L20/J20-1,"") | S20: подано | V20: 1050000 | W20: проиграли | Z20: =IF(AND(ISNUMBER(V20),ISNUMBER(Y20),Y20>0),V20/Y20-1,"") | AB20: По цене 1-е место в 5 лотах из 9; проиграли на квалификации (оборот 20–50 млн в анкете). Итог 12.08.2026. | AC20: РЦ … (9 подпапок) | AD20: project_pyaterochka_rc.md | AE20: Итог 12.08.2026: проиграли все 9 лотов (по 5 лотам были 1-ми по цене). Слабая квал. анкета (оборот 20–50 млн). Плюс нормочасы РСР отдельно
A21: 17 | B21: 46226 | C21: X5 / Агроторг («Пятёрочка») | D21: РЦ «Пятёрочка» ЗТЛ лот 2 | E21: Комплексное ТО распределительного центра, 24 мес (B2B 4507641) | G21: КТО / ТО | H21: ТО и абонентское обслуживание | I21: в месяц | L21: 1235000 | N21: =IF(AND(ISNUMBER(K21),ISNUMBER(L21),K21>0),L21/K21-1,"") | O21: =IF(AND(ISNUMBER(K21),ISNUMBER(L21),L21>0),1-K21/L21,"") | P21: =IF(AND(ISNUMBER(J21),ISNUMBER(L21),J21>0),L21/J21-1,"") | S21: подано | V21: 1235000 | W21: проиграли | Z21: =IF(AND(ISNUMBER(V21),ISNUMBER(Y21),Y21>0),V21/Y21-1,"") | AB21: По цене 1-е место в 5 лотах из 9; проиграли на квалификации (оборот 20–50 млн в анкете). Итог 12.08.2026. | AC21: РЦ … (9 подпапок) | AD21: project_pyaterochka_rc.md | AE21: Итог 12.08.2026: проиграли все 9 лотов (по 5 лотам были 1-ми по цене). Слабая квал. анкета (оборот 20–50 млн). Плюс нормочасы РСР отдельно
A22: 18 | B22: 46226 | C22: X5 / Агроторг («Пятёрочка») | D22: РЦ «Пятёрочка» Уткина Заводь (УТЗ) | E22: Комплексное ТО распределительного центра, 24 мес (B2B 4507641) | F22: ЛО | G22: КТО / ТО | H22: ТО и абонентское обслуживание | I22: в месяц | L22: 1100000 | N22: =IF(AND(ISNUMBER(K22),ISNUMBER(L22),K22>0),L22/K22-1,"") | O22: =IF(AND(ISNUMBER(K22),ISNUMBER(L22),L22>0),1-K22/L22,"") | P22: =IF(AND(ISNUMBER(J22),ISNUMBER(L22),J22>0),L22/J22-1,"") | S22: переторжка | T22: 1 150 000 → 1 100 000/мес (повторная переторжка 23.07.2026) | V22: 1100000 | W22: проиграли | Z22: =IF(AND(ISNUMBER(V22),ISNUMBER(Y22),Y22>0),V22/Y22-1,"") | AB22: По цене 1-е место в 5 лотах из 9; проиграли на квалификации (оборот 20–50 млн в анкете). Итог 12.08.2026. | AC22: РЦ … (9 подпапок) | AD22: project_pyaterochka_rc.md | AE22: Итог 12.08.2026: проиграли все 9 лотов (по 5 лотам были 1-ми по цене). Слабая квал. анкета (оборот 20–50 млн). Плюс нормочасы РСР отдельно
A23: 19 | B23: 46226 | C23: X5 / Агроторг («Пятёрочка») | D23: РЦ «Пятёрочка» Петрозаводск | E23: Комплексное ТО распределительного центра, 24 мес (B2B 4507641) | F23: Карелия | G23: КТО / ТО | H23: ТО и абонентское обслуживание | I23: в месяц | L23: 1140000 | N23: =IF(AND(ISNUMBER(K23),ISNUMBER(L23),K23>0),L23/K23-1,"") | O23: =IF(AND(ISNUMBER(K23),ISNUMBER(L23),L23>0),1-K23/L23,"") | P23: =IF(AND(ISNUMBER(J23),ISNUMBER(L23),J23>0),L23/J23-1,"") | S23: переторжка | T23: 1 200 000 → 1 140 000/мес (повторная переторжка 23.07.2026) | V23: 1140000 | W23: проиграли | Z23: =IF(AND(ISNUMBER(V23),ISNUMBER(Y23),Y23>0),V23/Y23-1,"") | AB23: По цене 1-е место в 5 лотах из 9; проиграли на квалификации (оборот 20–50 млн в анкете). Итог 12.08.2026. | AC23: РЦ … (9 подпапок) | AD23: project_pyaterochka_rc.md | AE23: Итог 12.08.2026: проиграли все 9 лотов (по 5 лотам были 1-ми по цене). Слабая квал. анкета (оборот 20–50 млн). Плюс нормочасы РСР отдельно
A24: 20 | B24: 46227 | C24: X5 Group | D24: РЦ «Троицкий», СПб, пр. Обуховской Обороны 295БД, 16 742 м² | E24: КТОиР инж. сетей, зданий и РСР, 1 200 н-ч/мес (B2B-Center 4491892) | F24: СПб | G24: КТО / ТО | H24: ТО и абонентское обслуживание | I24: в месяц | K24: 1876875 | L24: 2436000 | N24: =IF(AND(ISNUMBER(K24),ISNUMBER(L24),K24>0),L24/K24-1,0.2979) -> 0.2979021 | O24: =IF(AND(ISNUMBER(K24),ISNUMBER(L24),L24>0),1-K24/L24,0.2295) -> 0.22952586 | P24: =IF(AND(ISNUMBER(J24),ISNUMBER(L24),J24>0),L24/J24-1,"") | S24: рассчитано | Z24: =IF(AND(ISNUMBER(V24),ISNUMBER(Y24),Y24>0),V24/Y24-1,"") | AC24: РЦ БЕ ОКОЛО | AD24: project_x5_troitsky.md | AE24: Цена 2 030 руб/н-ч × 14 400 = 29 232 000/год; наценка 30 %. Пост 24/7, реакция 60 мин. Материалы по тарификатору ×1,3.
A25: 21 | B25: 46227 | C25: АО «Балтийский берег» | D25: ЛО, Ломоносовский р-н, д. Пеники, Центральная 2Г — 3 цеха | E25: Ремонтно-отделочные работы 3 объектов (полы, лотки, трапы, покраска, освещение) | F25: ЛО | G25: СМР / ремонт | H25: Крупные сети и девелоперы — конкурентный тендер | I25: разово | K25: 13010000 | L25: 19524000 | N25: =IF(AND(ISNUMBER(K25),ISNUMBER(L25),K25>0),L25/K25-1,0.5) -> 0.50069178 | O25: =IF(AND(ISNUMBER(K25),ISNUMBER(L25),L25>0),1-K25/L25,0.3336) -> 0.33364065 | P25: =IF(AND(ISNUMBER(J25),ISNUMBER(L25),J25>0),L25/J25-1,"") | S25: рассчитано | Z25: =IF(AND(ISNUMBER(V25),ISNUMBER(Y25),Y25>0),V25/Y25-1,"") | AC25: Балтийский берег | AD25: project_baltbereg_remont.md | AE25: Объекты: КП 7,167 / 7,777 / 4,58 млн. Действующее производство; площади уточнить обмером
A26: 22 | B26: 46230 | C26: X5 (АО «ТД «ПЕРЕКРЕСТОК») | D26: РЦ «Троицкий», СПб, пр. Обуховской Обороны 295БД | E26: Лот 1: ТО и ремонт ХО/КО/ВО, full service | F26: СПб | G26: КТО / ТО | H26: ТО и абонентское обслуживание | I26: в год | K26: 8520600 | L26: 11159000 | N26: =IF(AND(ISNUMBER(K26),ISNUMBER(L26),K26>0),L26/K26-1,0.3096) -> 0.30964956 | O26: =IF(AND(ISNUMBER(K26),ISNUMBER(L26),L26>0),1-K26/L26,0.2364) -> 0.23643696 | P26: =IF(AND(ISNUMBER(J26),ISNUMBER(L26),J26>0),L26/J26-1,"") | S26: рассчитано | Z26: =IF(AND(ISNUMBER(V26),ISNUMBER(Y26),Y26>0),V26/Y26-1,"") | AC26: РЦ БЕ ОКОЛО ХО | AD26: project_x5_ho_troitsky_ufa.md | AE26: с/с 710 050/мес ×12; ТО ХО 900 000/мес, н-ч 2 300; тарификатор ЗИП 3 174 поз. рынок ×1,30 (модельные цены); оффер на ЭТП заполнен
A27: 23 | B27: 46230 | C27: X5 (АО «ТД «ПЕРЕКРЕСТОК») | D27: РЦ Уфа, ул. Цветочная 36 | E27: Лот 2: ТО и ремонт ХО/КО/ВО, full service | F27: Башкортостан (Уфа) | G27: КТО / ТО | H27: ТО и абонентское обслуживание | I27: в год | K27: 4167900 | L27: 5465500 | N27: =IF(AND(ISNUMBER(K27),ISNUMBER(L27),K27>0),L27/K27-1,0.3113) -> 0.31133185 | O27: =IF(AND(ISNUMBER(K27),ISNUMBER(L27),L27>0),1-K27/L27,0.2374) -> 0.23741652 | P27: =IF(AND(ISNUMBER(J27),ISNUMBER(L27),J27>0),L27/J27-1,"") | S27: рассчитано | Z27: =IF(AND(ISNUMBER(V27),ISNUMBER(Y27),Y27>0),V27/Y27-1,"") | AC27: РЦ БЕ ОКОЛО ХО | AD27: project_x5_ho_troitsky_ufa.md | AE27: с/с 347 325/мес ×12; уфимская ставка — допущение (альтернатива субподряд 350–400К/мес); риск неоплаты месяца при потере товара
A28: 24 | B28: 46230 | C28: ООО «Гротекс» (Solopharm) | D28: Завод ЖЛФ, СПб, Индустриальный пр. 71 к.2 лит. А | E28: Ремонт плоской кровли ~350 м² (ПВХ-мембрана), Bidzaar 352-421 | F28: СПб | G28: СМР / ремонт | H28: Fit-out, частный бизнес, малые объёмы | I28: разово | K28: 914947 | N28: =IF(AND(ISNUMBER(K28),ISNUMBER(L28),K28>0),L28/K28-1,"") | O28: =IF(AND(ISNUMBER(K28),ISNUMBER(L28),L28>0),1-K28/L28,"") | P28: =IF(AND(ISNUMBER(J28),ISNUMBER(L28),J28>0),L28/J28-1,"") | S28: рассчитано | Z28: =IF(AND(ISNUMBER(V28),ISNUMBER(Y28),Y28>0),V28/Y28-1,"") | AC28: Сметы (корень) | AD28: project_grotex_krovlya.md | AE28: С/с 1 116 235 с НДС /1,22. ВОР нет — объёмы по 2 фото; КП не делали. Демонтаж старого ковра не заложен
A29: 25 | B29: 46230 | C29: ООО «Ладожская Форель» | D29: Склад-навес 18×24 м, пос. Хийденсельга, Питкярантский р-н | E29: Строительство склада-навеса (МК ~15 т, профнастил, фундаменты) с ПИР | F29: Карелия | G29: ПИР+СМР | H29: Fit-out, частный бизнес, малые объёмы | I29: разово | K29: 7541230 | L29: 15081967 | M29: 18400000 | N29: =IF(AND(ISNUMBER(K29),ISNUMBER(L29),K29>0),L29/K29-1,1) -> 0.99993465 | O29: =IF(AND(ISNUMBER(K29),ISNUMBER(L29),L29>0),1-K29/L29,0.5) -> 0.49998366 | P29: =IF(AND(ISNUMBER(J29),ISNUMBER(L29),J29>0),L29/J29-1,"") | S29: рассчитано | Z29: =IF(AND(ISNUMBER(V29),ISNUMBER(Y29),Y29>0),V29/Y29-1,"") | AC29: Сметы (корень) | AD29: project_ladoga_sklad.md | AE29: С/с 9 200 300 с НДС /1,22. КП б/НДС = 18,4 млн − НДС 3 318 032,79. Расхождения ТЗ/чертежей; полы, сети, электрика не включены
A30: 26 | B30: 46231 | C30: SUNLIGHT / ООО «МЦЗ-Ритейл» | D30: Магазин МЦЗ, СПб, Балканская пл. 5, ТРК «Балканский-3», пом. 21-16 (153,2 м²) | E30: СМР магазина ювелирных украшений + монтаж ТО | F30: СПб | G30: Fit-out | H30: Fit-out, частный бизнес, малые объёмы | I30: разово | K30: 4376359 | L30: 5224768 | M30: 6374217 | N30: =IF(AND(ISNUMBER(K30),ISNUMBER(L30),K30>0),L30/K30-1,"") -> 0.19386184 | O30: =IF(AND(ISNUMBER(K30),ISNUMBER(L30),L30>0),1-K30/L30,"") -> 0.16238214 | P30: =IF(AND(ISNUMBER(J30),ISNUMBER(L30),J30>0),L30/J30-1,"") | Q30: 0.2 | R30: 0.7 | S30: рассчитано | Z30: =IF(AND(ISNUMBER(V30),ISNUMBER(Y30),Y30>0),V30/Y30-1,"") | AC30: СанЛайт | AD30: project_sunlight_balkansky.md | AE30: КП 6 374 217 в т.ч. НДС (б/НДС = /1,22); с/с смешанная (работы без НДС, материалы с НДС) — наценка не считалась
A31: 27 | B31: 46232 | C31: СПбГИКиТ | D31: Съёмочный павильон УЛК №3, СПб, Бухарестская 22 лит. А | E31: Текущий ремонт съёмочного павильона (ЛСР 02-17-01, 138 позиций) | F31: СПб | G31: СМР / ремонт | H31: Госзакупки 44-ФЗ / 223-ФЗ | I31: разово | J31: 2146695.5 | K31: 1332034 | N31: =IF(AND(ISNUMBER(K31),ISNUMBER(L31),K31>0),L31/K31-1,"") | O31: =IF(AND(ISNUMBER(K31),ISNUMBER(L31),L31>0),1-K31/L31,"") | P31: =IF(AND(ISNUMBER(J31),ISNUMBER(L31),J31>0),L31/J31-1,"") | S31: рассчитано | Z31: =IF(AND(ISNUMBER(V31),ISNUMBER(Y31),Y31>0),V31/Y31-1,"") | AD31: project_gikit_pavilion.md | AE31: НМЦ 2 618 968,53 с НДС; рыночный бюджет на 37,9 % ниже сметы
A32: 28 | B32: 46232 | C32: СПбГУ | D32: СПб шоссе 109 (Петергоф) | E32: Ремонт ограждений: сварка, антикор, окраска 1 227 м² | F32: СПб | G32: СМР / ремонт | H32: Госзакупки 44-ФЗ / 223-ФЗ | I32: разово | J32: 944874.04 | K32: 641998 | N32: =IF(AND(ISNUMBER(K32),ISNUMBER(L32),K32>0),L32/K32-1,"") | O32: =IF(AND(ISNUMBER(K32),ISNUMBER(L32),L32>0),1-K32/L32,"") | P32: =IF(AND(ISNUMBER(J32),ISNUMBER(L32),J32>0),L32/J32-1,"") | S32: рассчитано | Z32: =IF(AND(ISNUMBER(V32),ISNUMBER(Y32),Y32>0),V32/Y32-1,"") | AC32: Сметы (корень) | AD32: project_spbgu_ograzhdeniya.md | AE32: Книга проекта по ЛСР 480-26/03-06-10; рыночный бюджет на 32,1 % ниже НМЦ. Доска для настила моста без стоимости
A33: 29 | B33: 46233 | C33: АО «СЗ Ланселот» | D33: ОКН «Мастеровой двор» (CHEVAL COURT), СПб, Конюшенная пл. 2 | E33: Отделочные и инженерные работы МОП, полная ВОР (463 поз.) | F33: СПб | G33: СМР / ремонт | H33: Крупные сети и девелоперы — конкурентный тендер | I33: разово | K33: 25900000 | L33: 48331148 | M33: 58964000 | N33: =IF(AND(ISNUMBER(K33),ISNUMBER(L33),K33>0),L33/K33-1,0.8661) -> 0.86606749 | O33: =IF(AND(ISNUMBER(K33),ISNUMBER(L33),L33>0),1-K33/L33,0.465) -> 0.4641137 | P33: =IF(AND(ISNUMBER(J33),ISNUMBER(L33),J33>0),L33/J33-1,"") | S33: рассчитано | Z33: =IF(AND(ISNUMBER(V33),ISNUMBER(Y33),Y33>0),V33/Y33-1,"") | AC33: Конюшня 2 | AD33: project_cheval_court_mop.md | AE33: На 2,2 % ниже конкурента (60,26 млн с НДС). Первый вариант 54 560 000. Люкс-отделка, много давальческих, ГУ 5 %.
A34: 30 | B34: 46233 | C34: ООО «СТД «Петрович» | D34: СПб, Южное ш. 39, лит. П, пом. 3.7 ~100 м² | E34: Косметический ремонт видеостудии (ЗА-523) | F34: СПб | G34: Fit-out | H34: Fit-out, частный бизнес, малые объёмы | I34: разово | K34: 1258232 | N34: =IF(AND(ISNUMBER(K34),ISNUMBER(L34),K34>0),L34/K34-1,"") | O34: =IF(AND(ISNUMBER(K34),ISNUMBER(L34),L34>0),1-K34/L34,"") | P34: =IF(AND(ISNUMBER(J34),ISNUMBER(L34),J34>0),L34/J34-1,"") | S34: рассчитано | Z34: =IF(AND(ISNUMBER(V34),ISNUMBER(Y34),Y34>0),V34/Y34-1,"") | AD34: project_petrovich_videostudia.md | AE34: КП не сделано. Без аванса, оплата 15 к.д. после КС с ИД; выезд обязателен. НДС в с/с не уточнён.
A35: 31 | B35: 46233 | C35: ООО «СТРОЙКОМПЛЕКС» | D35: Москва, ЦЗ №169, 1 и 4 этажи | E35: Отделка помещений 1 и 4 этажей (~133 поз.) | F35: Москва | G35: СМР / ремонт | H35: Крупные сети и девелоперы — конкурентный тендер | I35: разово | K35: 86803279 | L35: 1.7364619e+08 | M35: 211848347 | N35: =IF(AND(ISNUMBER(K35),ISNUMBER(L35),K35>0),L35/K35-1,1) -> 1.0004565 | O35: =IF(AND(ISNUMBER(K35),ISNUMBER(L35),L35>0),1-K35/L35,0.5001) -> 0.50011411 | P35: =IF(AND(ISNUMBER(J35),ISNUMBER(L35),J35>0),L35/J35-1,"") | S35: рассчитано | Z35: =IF(AND(ISNUMBER(V35),ISNUMBER(Y35),Y35>0),V35/Y35-1,"") | AD35: project_stroykompleks_otdelka_14.md | AE35: С/с 105,9 млн принята с НДС (маржа = КП − с/с), ÷1,22. Km 1,37 / Kw 3,50. В заметке противоречие «КП не сделано».
A36: 32 | B36: 46233 | C36: ООО «СТРОЙКОМПЛЕКС» | D36: Объект ЦЗ №165, Москва, 2–3 этаж (фарма, ЧПП) | E36: Отделка помещений 2–3 этажа с ЧПП, ~150 позиций | F36: Москва | G36: СМР / ремонт | H36: Крупные сети и девелоперы — конкурентный тендер | I36: разово | K36: 125100000 | M36: 250261091 | N36: =IF(AND(ISNUMBER(K36),ISNUMBER(L36),K36>0),L36/K36-1,1) -> 1 | O36: =IF(AND(ISNUMBER(K36),ISNUMBER(L36),L36>0),1-K36/L36,0.5) -> 0.5 | P36: =IF(AND(ISNUMBER(J36),ISNUMBER(L36),J36>0),L36/J36-1,"") | Q36: 0.36 | R36: 2.43 | S36: рассчитано | Z36: =IF(AND(ISNUMBER(V36),ISNUMBER(Y36),Y36>0),V36/Y36-1,"") | AD36: project_stroykompleks_otdelka.md | AE36: КП 250,26 млн указан «с НДС», но = с/с×2 (мат 94,5 + раб 155,8) — вероятно без НДС; уточнить. Давальческие материалы, аванс 30 %, 240 к.д.
A37: 33 | B37: 46233 | C37: ФСО (44-ФЗ) | D37: 11 режимных объектов ФСО в СПб, 462 ед. | E37: ТОиР кухонного оборудования, 12 мес | F37: СПб | G37: КТО / ТО | H37: Госзакупки 44-ФЗ / 223-ФЗ | I37: в год | J37: 4657400 | K37: 5214744 | N37: =IF(AND(ISNUMBER(K37),ISNUMBER(L37),K37>0),L37/K37-1,"") | O37: =IF(AND(ISNUMBER(K37),ISNUMBER(L37),L37>0),1-K37/L37,-0.12) -> -0.12 | P37: =IF(AND(ISNUMBER(J37),ISNUMBER(L37),J37>0),L37/J37-1,"") | S37: не участвовать | W37: не подавали | Z37: =IF(AND(ISNUMBER(V37),ISNUMBER(Y37),Y37>0),V37/Y37-1,"") | AD37: project_to_fso.md | AE37: С/с — сценарий Б (434 562/мес ×12); сценарий А −52,8 %. НМЦК под действующего исполнителя; участие только по НМЦК как вход.
A38: 34 | B38: 46234 | D38: 3 площадки: СПб Софийская 8; Сестрорецк, Воскова 2; Пушкин, Тиньков пер. 7 | E38: Абонентский хендимен-сервис офисных и производственных помещений (355-604 Bidzaar) | F38: СПб | G38: КТО / ТО | H38: ТО и абонентское обслуживание | I38: в месяц | K38: 93000 | L38: 195000 | M38: 237900 | N38: =IF(AND(ISNUMBER(K38),ISNUMBER(L38),K38>0),L38/K38-1,1.0968) -> 1.0967742 | O38: =IF(AND(ISNUMBER(K38),ISNUMBER(L38),L38>0),1-K38/L38,0.5231) -> 0.52307692 | P38: =IF(AND(ISNUMBER(J38),ISNUMBER(L38),J38>0),L38/J38-1,"") | S38: рассчитано | Z38: =IF(AND(ISNUMBER(V38),ISNUMBER(Y38),Y38>0),V38/Y38-1,"") | AC38: Сметы (корень) | AD38: project_handyman_3ploshchadki.md | AE38: С/с ≈93К при присоединении к бригадам (отдельным мастером ≈143К). Пол торга 150К. Лимит 60 н-ч/мес, сверх 3 000/н-ч
A39: 35 | B39: 46234 | C39: modi | D39: ТЦ «Экопарк», Мурино, Охтинская аллея 9, 112,5 м² | E39: Fit-out магазина modi | F39: ЛО | G39: Fit-out | H39: Fit-out, частный бизнес, малые объёмы | I39: разово | K39: 2230201 | L39: 3345301 | M39: 4081267 | N39: =IF(AND(ISNUMBER(K39),ISNUMBER(L39),K39>0),L39/K39-1,0.5) -> 0.49999978 | O39: =IF(AND(ISNUMBER(K39),ISNUMBER(L39),L39>0),1-K39/L39,0.3333) -> 0.33333323 | P39: =IF(AND(ISNUMBER(J39),ISNUMBER(L39),J39>0),L39/J39-1,"") | S39: рассчитано | Z39: =IF(AND(ISNUMBER(V39),ISNUMBER(Y39),Y39>0),V39/Y39-1,"") | AC39: Моди | AD39: project_modi_ekopark.md | AE39: Опция вывеска +330К; минус за сохранение треков −787 894 б/НДС. Вопросы: треки, готовый щит, вывеска.
A40: 36 | B40: 46234 | C40: Отель Sofitel 5* | D40: Отель Sofitel, СПб, 16 сплит-систем | E40: Абонентское ТО 16 кондиционеров (Bidzaar 351-654) | F40: СПб | G40: КТО / ТО | H40: ТО и абонентское обслуживание | I40: в месяц | K40: 55272 | L40: 98000 | M40: 119560 | N40: =IF(AND(ISNUMBER(K40),ISNUMBER(L40),K40>0),L40/K40-1,0.773) -> 0.77304965 | O40: =IF(AND(ISNUMBER(K40),ISNUMBER(L40),L40>0),1-K40/L40,0.436) -> 0.436 | P40: =IF(AND(ISNUMBER(J40),ISNUMBER(L40),J40>0),L40/J40-1,"") | S40: рассчитано | Z40: =IF(AND(ISNUMBER(V40),ISNUMBER(Y40),Y40>0),V40/Y40-1,"") | AC40: Софитель | AD40: project_sofitel_kondicionery.md | AE40: В форме: 96 000 за цикл раз в 2 мес (576К/год), выезд 6 000, н-ч 3 500. Пол торга ~80К/мес.
...

Sheet Аналитика
A1: АНАЛИТИКА: ПРИ КАКОЙ НАЦЕНКЕ МЫ ВЫИГРЫВАЕМ
A2: Считается формулами по листу «Реестр». Колонки результата заполнятся, когда в реестре будут проставлены итоги (РЕЗУЛЬТАТ, цена победителя). Цель — через 15–20 закрытых тендеров откалибровать диапазоны наценки на листе «Тип тендера» файла материалов.
A4: По типу тендера
A5: Тип тендера | B5: Расчётов | C5: Не участвовали | D5: Средняя наценка (все) | E5: Средняя маржа (все) | F5: Ждём итогов | G5: Выиграли | H5: Проиграли | I5: Доля побед | J5: Средняя наценка — выигранные | K5: Средняя наценка — проигранные | L5: Наша цена к победителю (проигранные), среднее
A6: Крупные сети и девелоперы — конкурентный тендер | B6: =COUNTIF(Реестр!$H$5:$H$318,$A6) -> 130 | C6: =COUNTIFS(Реестр!$H$5:$H$318,$A6,Реестр!$S$5:$S$318,"не участвовать") -> 1 | D6: =IFERROR(AVERAGEIFS(Реестр!$N$5:$N$318,Реестр!$H$5:$H$318,$A6,Реестр!$S$5:$S$318,"<>не участвовать"),"") -> 0.39120221 | E6: =IFERROR(AVERAGEIFS(Реестр!$O$5:$O$318,Реестр!$H$5:$H$318,$A6,Реестр!$S$5:$S$318,"<>не участвовать"),"") -> 0.22722002 | F6: =COUNTIFS(Реестр!$H$5:$H$318,$A6,Реестр!$W$5:$W$318,"ждём итогов") -> 5 | G6: =COUNTIFS(Реестр!$H$5:$H$318,$A6,Реестр!$W$5:$W$318,"выиграли") -> 0 | H6: =COUNTIFS(Реестр!$H$5:$H$318,$A6,Реестр!$W$5:$W$318,"проиграли") -> 0 | I6: =IF(G6+H6=0,"",G6/(G6+H6)) | J6: =IFERROR(AVERAGEIFS(Реестр!$N$5:$N$318,Реестр!$H$5:$H$318,$A6,Реестр!$W$5:$W$318,"выиграли"),"") | K6: =IFERROR(AVERAGEIFS(Реестр!$N$5:$N$318,Реестр!$H$5:$H$318,$A6,Реестр!$W$5:$W$318,"проиграли"),"") | L6: =IFERROR(AVERAGEIFS(Реестр!$Z$5:$Z$318,Реестр!$H$5:$H$318,$A6,Реестр!$W$5:$W$318,"проиграли"),"")
A7: Переторжка / 2 тур / вход к новому заказчику | B7: =COUNTIF(Реестр!$H$5:$H$318,$A7) -> 8 | C7: =COUNTIFS(Реестр!$H$5:$H$318,$A7,Реестр!$S$5:$S$318,"не участвовать") -> 0 | D7: =IFERROR(AVERAGEIFS(Реестр!$N$5:$N$318,Реестр!$H$5:$H$318,$A7,Реестр!$S$5:$S$318,"<>не участвовать"),"") -> 0.31983688 | E7: =IFERROR(AVERAGEIFS(Реестр!$O$5:$O$318,Реестр!$H$5:$H$318,$A7,Реестр!$S$5:$S$318,"<>не участвовать"),"") -> 0.22243298 | F7: =COUNTIFS(Реестр!$H$5:$H$318,$A7,Реестр!$W$5:$W$318,"ждём итогов") -> 2 | G7: =COUNTIFS(Реестр!$H$5:$H$318,$A7,Реестр!$W$5:$W$318,"выиграли") -> 0 | H7: =COUNTIFS(Реестр!$H$5:$H$318,$A7,Реестр!$W$5:$W$318,"проиграли") -> 0 | I7: =IF(G7+H7=0,"",G7/(G7+H7)) | J7: =IFERROR(AVERAGEIFS(Реестр!$N$5:$N$318,Реестр!$H$5:$H$318,$A7,Реестр!$W$5:$W$318,"выиграли"),"") | K7: =IFERROR(AVERAGEIFS(Реестр!$N$5:$N$318,Реестр!$H$5:$H$318,$A7,Реестр!$W$5:$W$318,"проиграли"),"") | L7: =IFERROR(AVERAGEIFS(Реестр!$Z$5:$Z$318,Реестр!$H$5:$H$318,$A7,Реестр!$W$5:$W$318,"проиграли"),"")
A8: Fit-out, частный бизнес, малые объёмы | B8: =COUNTIF(Реестр!$H$5:$H$318,$A8) -> 25 | C8: =COUNTIFS(Реестр!$H$5:$H$318,$A8,Реестр!$S$5:$S$318,"не участвовать") -> 0 | D8: =IFERROR(AVERAGEIFS(Реестр!$N$5:$N$318,Реестр!$H$5:$H$318,$A8,Реестр!$S$5:$S$318,"<>не участвовать"),"") -> 0.65207654 | E8: =IFERROR(AVERAGEIFS(Реестр!$O$5:$O$318,Реестр!$H$5:$H$318,$A8,Реестр!$S$5:$S$318,"<>не участвовать"),"") -> 0.35423362 | F8: =COUNTIFS(Реестр!$H$5:$H$318,$A8,Реестр!$W$5:$W$318,"ждём итогов") -> 1 | G8: =COUNTIFS(Реестр!$H$5:$H$318,$A8,Реестр!$W$5:$W$318,"выиграли") -> 0 | H8: =COUNTIFS(Реестр!$H$5:$H$318,$A8,Реестр!$W$5:$W$318,"проиграли") -> 0 | I8: =IF(G8+H8=0,"",G8/(G8+H8)) | J8: =IFERROR(AVERAGEIFS(Реестр!$N$5:$N$318,Реестр!$H$5:$H$318,$A8,Реестр!$W$5:$W$318,"выиграли"),"") | K8: =IFERROR(AVERAGEIFS(Реестр!$N$5:$N$318,Реестр!$H$5:$H$318,$A8,Реестр!$W$5:$W$318,"проиграли"),"") | L8: =IFERROR(AVERAGEIFS(Реестр!$Z$5:$Z$318,Реестр!$H$5:$H$318,$A8,Реестр!$W$5:$W$318,"проиграли"),"")
A9: ТО и абонентское обслуживание | B9: =COUNTIF(Реестр!$H$5:$H$318,$A9) -> 75 | C9: =COUNTIFS(Реестр!$H$5:$H$318,$A9,Реестр!$S$5:$S$318,"не участвовать") -> 1 | D9: =IFERROR(AVERAGEIFS(Реестр!$N$5:$N$318,Реестр!$H$5:$H$318,$A9,Реестр!$S$5:$S$318,"<>не участвовать"),"") -> 0.35019268 | E9: =IFERROR(AVERAGEIFS(Реестр!$O$5:$O$318,Реестр!$H$5:$H$318,$A9,Реестр!$S$5:$S$318,"<>не участвовать"),"") -> 0.2251106 | F9: =COUNTIFS(Реестр!$H$5:$H$318,$A9,Реестр!$W$5:$W$318,"ждём итогов") -> 10 | G9: =COUNTIFS(Реестр!$H$5:$H$318,$A9,Реестр!$W$5:$W$318,"выиграли") -> 0 | H9: =COUNTIFS(Реестр!$H$5:$H$318,$A9,Реестр!$W$5:$W$318,"проиграли") -> 9 | I9: =IF(G9+H9=0,"",G9/(G9+H9)) -> 0 | J9: =IFERROR(AVERAGEIFS(Реестр!$N$5:$N$318,Реестр!$H$5:$H$318,$A9,Реестр!$W$5:$W$318,"выиграли"),"") | K9: =IFERROR(AVERAGEIFS(Реестр!$N$5:$N$318,Реестр!$H$5:$H$318,$A9,Реестр!$W$5:$W$318,"проиграли"),"") | L9: =IFERROR(AVERAGEIFS(Реестр!$Z$5:$Z$318,Реестр!$H$5:$H$318,$A9,Реестр!$W$5:$W$318,"проиграли"),"")
A10: Госзакупки 44-ФЗ / 223-ФЗ | B10: =COUNTIF(Реестр!$H$5:$H$318,$A10) -> 62 | C10: =COUNTIFS(Реестр!$H$5:$H$318,$A10,Реестр!$S$5:$S$318,"не участвовать") -> 17 | D10: =IFERROR(AVERAGEIFS(Реестр!$N$5:$N$318,Реестр!$H$5:$H$318,$A10,Реестр!$S$5:$S$318,"<>не участвовать"),"") -> 0.32657362 | E10: =IFERROR(AVERAGEIFS(Реестр!$O$5:$O$318,Реестр!$H$5:$H$318,$A10,Реестр!$S$5:$S$318,"<>не участвовать"),"") -> 0.23911797 | F10: =COUNTIFS(Реестр!$H$5:$H$318,$A10,Реестр!$W$5:$W$318,"ждём итогов") -> 0 | G10: =COUNTIFS(Реестр!$H$5:$H$318,$A10,Реестр!$W$5:$W$318,"выиграли") -> 0 | H10: =COUNTIFS(Реестр!$H$5:$H$318,$A10,Реестр!$W$5:$W$318,"проиграли") -> 0 | I10: =IF(G10+H10=0,"",G10/(G10+H10)) | J10: =IFERROR(AVERAGEIFS(Реестр!$N$5:$N$318,Реестр!$H$5:$H$318,$A10,Реестр!$W$5:$W$318,"выиграли"),"") | K10: =IFERROR(AVERAGEIFS(Реестр!$N$5:$N$318,Реестр!$H$5:$H$318,$A10,Реестр!$W$5:$W$318,"проиграли"),"") | L10: =IFERROR(AVERAGEIFS(Реестр!$Z$5:$Z$318,Реестр!$H$5:$H$318,$A10,Реестр!$W$5:$W$318,"проиграли"),"")
A11: ИТОГО | B11: =SUM(B6:B10) -> 300 | C11: =SUM(C6:C10) -> 19 | F11: =SUM(F6:F10) -> 18 | G11: =SUM(G6:G10) -> 0 | H11: =SUM(H6:H10) -> 9
A14: По виду работ
A15: Вид работ | B15: Расчётов | C15: Не участвовали | D15: Средняя наценка (все) | E15: Средняя маржа (все) | F15: Ждём итогов | G15: Выиграли | H15: Проиграли | I15: Доля побед | J15: Средняя наценка — выигранные | K15: Средняя наценка — проигранные | L15: Наша цена к победителю (проигранные), среднее
A16: СМР / ремонт | B16: =COUNTIF(Реестр!$G$5:$G$318,$A16) -> 131 | C16: =COUNTIFS(Реестр!$G$5:$G$318,$A16,Реестр!$S$5:$S$318,"не участвовать") -> 6 | D16: =IFERROR(AVERAGEIFS(Реестр!$N$5:$N$318,Реестр!$G$5:$G$318,$A16,Реестр!$S$5:$S$318,"<>не участвовать"),"") -> 0.41650876 | E16: =IFERROR(AVERAGEIFS(Реестр!$O$5:$O$318,Реестр!$G$5:$G$318,$A16,Реестр!$S$5:$S$318,"<>не участвовать"),"") -> 0.28370905 | F16: =COUNTIFS(Реестр!$G$5:$G$318,$A16,Реестр!$W$5:$W$318,"ждём итогов") -> 6 | G16: =COUNTIFS(Реестр!$G$5:$G$318,$A16,Реестр!$W$5:$W$318,"выиграли") -> 0 | H16: =COUNTIFS(Реестр!$G$5:$G$318,$A16,Реестр!$W$5:$W$318,"проиграли") -> 0 | I16: =IF(G16+H16=0,"",G16/(G16+H16)) | J16: =IFERROR(AVERAGEIFS(Реестр!$N$5:$N$318,Реестр!$G$5:$G$318,$A16,Реестр!$W$5:$W$318,"выиграли"),"") | K16: =IFERROR(AVERAGEIFS(Реестр!$N$5:$N$318,Реестр!$G$5:$G$318,$A16,Реестр!$W$5:$W$318,"проиграли"),"") | L16: =IFERROR(AVERAGEIFS(Реестр!$Z$5:$Z$318,Реестр!$G$5:$G$318,$A16,Реестр!$W$5:$W$318,"проиграли"),"")
A17: Fit-out | B17: =COUNTIF(Реестр!$G$5:$G$318,$A17) -> 12 | C17: =COUNTIFS(Реестр!$G$5:$G$318,$A17,Реестр!$S$5:$S$318,"не участвовать") -> 0 | D17: =IFERROR(AVERAGEIFS(Реестр!$N$5:$N$318,Реестр!$G$5:$G$318,$A17,Реестр!$S$5:$S$318,"<>не участвовать"),"") -> 0.6740113 | E17: =IFERROR(AVERAGEIFS(Реестр!$O$5:$O$318,Реестр!$G$5:$G$318,$A17,Реестр!$S$5:$S$318,"<>не участвовать"),"") -> 0.34156961 | F17: =COUNTIFS(Реестр!$G$5:$G$318,$A17,Реестр!$W$5:$W$318,"ждём итогов") -> 0 | G17: =COUNTIFS(Реестр!$G$5:$G$318,$A17,Реестр!$W$5:$W$318,"выиграли") -> 0 | H17: =COUNTIFS(Реестр!$G$5:$G$318,$A17,Реестр!$W$5:$W$318,"проиграли") -> 0 | I17: =IF(G17+H17=0,"",G17/(G17+H17)) | J17: =IFERROR(AVERAGEIFS(Реестр!$N$5:$N$318,Реестр!$G$5:$G$318,$A17,Реестр!$W$5:$W$318,"выиграли"),"") | K17: =IFERROR(AVERAGEIFS(Реестр!$N$5:$N$318,Реестр!$G$5:$G$318,$A17,Реестр!$W$5:$W$318,"проиграли"),"") | L17: =IFERROR(AVERAGEIFS(Реестр!$Z$5:$Z$318,Реестр!$G$5:$G$318,$A17,Реестр!$W$5:$W$318,"проиграли"),"")
A18: КТО / ТО | B18: =COUNTIF(Реестр!$G$5:$G$318,$A18) -> 107 | C18: =COUNTIFS(Реестр!$G$5:$G$318,$A18,Реестр!$S$5:$S$318,"не участвовать") -> 11 | D18: =IFERROR(AVERAGEIFS(Реестр!$N$5:$N$318,Реестр!$G$5:$G$318,$A18,Реестр!$S$5:$S$318,"<>не участвовать"),"") -> 0.34870728 | E18: =IFERROR(AVERAGEIFS(Реестр!$O$5:$O$318,Реестр!$G$5:$G$318,$A18,Реестр!$S$5:$S$318,"<>не участвовать"),"") -> 0.1611856 | F18: =COUNTIFS(Реестр!$G$5:$G$318,$A18,Реестр!$W$5:$W$318,"ждём итогов") -> 10 | G18: =COUNTIFS(Реестр!$G$5:$G$318,$A18,Реестр!$W$5:$W$318,"выиграли") -> 0 | H18: =COUNTIFS(Реестр!$G$5:$G$318,$A18,Реестр!$W$5:$W$318,"проиграли") -> 9 | I18: =IF(G18+H18=0,"",G18/(G18+H18)) -> 0 | J18: =IFERROR(AVERAGEIFS(Реестр!$N$5:$N$318,Реестр!$G$5:$G$318,$A18,Реестр!$W$5:$W$318,"выиграли"),"") | K18: =IFERROR(AVERAGEIFS(Реестр!$N$5:$N$318,Реестр!$G$5:$G$318,$A18,Реестр!$W$5:$W$318,"проиграли"),"") | L18: =IFERROR(AVERAGEIFS(Реестр!$Z$5:$Z$318,Реестр!$G$5:$G$318,$A18,Реестр!$W$5:$W$318,"проиграли"),"")
A19: Рамочные расценки | B19: =COUNTIF(Реестр!$G$5:$G$318,$A19) -> 11 | C19: =COUNTIFS(Реестр!$G$5:$G$318,$A19,Реестр!$S$5:$S$318,"не участвовать") -> 0 | D19: =IFERROR(AVERAGEIFS(Реестр!$N$5:$N$318,Реестр!$G$5:$G$318,$A19,Реестр!$S$5:$S$318,"<>не участвовать"),"") -> 0.35819824 | E19: =IFERROR(AVERAGEIFS(Реестр!$O$5:$O$318,Реестр!$G$5:$G$318,$A19,Реестр!$S$5:$S$318,"<>не участвовать"),"") -> 0.24813785 | F19: =COUNTIFS(Реестр!$G$5:$G$318,$A19,Реестр!$W$5:$W$318,"ждём итогов") -> 1 | G19: =COUNTIFS(Реестр!$G$5:$G$318,$A19,Реестр!$W$5:$W$318,"выиграли") -> 0 | H19: =COUNTIFS(Реестр!$G$5:$G$318,$A19,Реестр!$W$5:$W$318,"проиграли") -> 0 | I19: =IF(G19+H19=0,"",G19/(G19+H19)) | J19: =IFERROR(AVERAGEIFS(Реестр!$N$5:$N$318,Реестр!$G$5:$G$318,$A19,Реестр!$W$5:$W$318,"выиграли"),"") | K19: =IFERROR(AVERAGEIFS(Реестр!$N$5:$N$318,Реестр!$G$5:$G$318,$A19,Реестр!$W$5:$W$318,"проиграли"),"") | L19: =IFERROR(AVERAGEIFS(Реестр!$Z$5:$Z$318,Реестр!$G$5:$G$318,$A19,Реестр!$W$5:$W$318,"проиграли"),"")
A20: Поставка и монтаж | B20: =COUNTIF(Реестр!$G$5:$G$318,$A20) -> 13 | C20: =COUNTIFS(Реестр!$G$5:$G$318,$A20,Реестр!$S$5:$S$318,"не участвовать") -> 0 | D20: =IFERROR(AVERAGEIFS(Реестр!$N$5:$N$318,Реестр!$G$5:$G$318,$A20,Реестр!$S$5:$S$318,"<>не участвовать"),"") -> 0.36143126 | E20: =IFERROR(AVERAGEIFS(Реестр!$O$5:$O$318,Реестр!$G$5:$G$318,$A20,Реестр!$S$5:$S$318,"<>не участвовать"),"") -> 0.26381181 | F20: =COUNTIFS(Реестр!$G$5:$G$318,$A20,Реестр!$W$5:$W$318,"ждём итогов") -> 1 | G20: =COUNTIFS(Реестр!$G$5:$G$318,$A20,Реестр!$W$5:$W$318,"выиграли") -> 0 | H20: =COUNTIFS(Реестр!$G$5:$G$318,$A20,Реестр!$W$5:$W$318,"проиграли") -> 0 | I20: =IF(G20+H20=0,"",G20/(G20+H20)) | J20: =IFERROR(AVERAGEIFS(Реестр!$N$5:$N$318,Реестр!$G$5:$G$318,$A20,Реестр!$W$5:$W$318,"выиграли"),"") | K20: =IFERROR(AVERAGEIFS(Реестр!$N$5:$N$318,Реестр!$G$5:$G$318,$A20,Реестр!$W$5:$W$318,"проиграли"),"") | L20: =IFERROR(AVERAGEIFS(Реестр!$Z$5:$Z$318,Реестр!$G$5:$G$318,$A20,Реестр!$W$5:$W$318,"проиграли"),"")
A21: ПИР+СМР | B21: =COUNTIF(Реестр!$G$5:$G$318,$A21) -> 11 | C21: =COUNTIFS(Реестр!$G$5:$G$318,$A21,Реестр!$S$5:$S$318,"не участвовать") -> 0 | D21: =IFERROR(AVERAGEIFS(Реестр!$N$5:$N$318,Реестр!$G$5:$G$318,$A21,Реестр!$S$5:$S$318,"<>не участвовать"),"") -> 0.41889296 | E21: =IFERROR(AVERAGEIFS(Реестр!$O$5:$O$318,Реестр!$G$5:$G$318,$A21,Реестр!$S$5:$S$318,"<>не участвовать"),"") -> 0.28410036 | F21: =COUNTIFS(Реестр!$G$5:$G$318,$A21,Реестр!$W$5:$W$318,"ждём итогов") -> 0 | G21: =COUNTIFS(Реестр!$G$5:$G$318,$A21,Реестр!$W$5:$W$318,"выиграли") -> 0 | H21: =COUNTIFS(Реестр!$G$5:$G$318,$A21,Реестр!$W$5:$W$318,"проиграли") -> 0 | I21: =IF(G21+H21=0,"",G21/(G21+H21)) | J21: =IFERROR(AVERAGEIFS(Реестр!$N$5:$N$318,Реестр!$G$5:$G$318,$A21,Реестр!$W$5:$W$318,"выиграли"),"") | K21: =IFERROR(AVERAGEIFS(Реестр!$N$5:$N$318,Реестр!$G$5:$G$318,$A21,Реестр!$W$5:$W$318,"проиграли"),"") | L21: =IFERROR(AVERAGEIFS(Реестр!$Z$5:$Z$318,Реестр!$G$5:$G$318,$A21,Реестр!$W$5:$W$318,"проиграли"),"")
A22: Другое | B22: =COUNTIF(Реестр!$G$5:$G$318,$A22) -> 4 | C22: =COUNTIFS(Реестр!$G$5:$G$318,$A22,Реестр!$S$5:$S$318,"не участвовать") -> 0 | D22: =IFERROR(AVERAGEIFS(Реестр!$N$5:$N$318,Реестр!$G$5:$G$318,$A22,Реестр!$S$5:$S$318,"<>не участвовать"),"") -> 0.36910972 | E22: =IFERROR(AVERAGEIFS(Реестр!$O$5:$O$318,Реестр!$G$5:$G$318,$A22,Реестр!$S$5:$S$318,"<>не участвовать"),"") -> 0.28582623 | F22: =COUNTIFS(Реестр!$G$5:$G$318,$A22,Реестр!$W$5:$W$318,"ждём итогов") -> 0 | G22: =COUNTIFS(Реестр!$G$5:$G$318,$A22,Реестр!$W$5:$W$318,"выиграли") -> 0 | H22: =COUNTIFS(Реестр!$G$5:$G$318,$A22,Реестр!$W$5:$W$318,"проиграли") -> 0 | I22: =IF(G22+H22=0,"",G22/(G22+H22)) | J22: =IFERROR(AVERAGEIFS(Реестр!$N$5:$N$318,Реестр!$G$5:$G$318,$A22,Реестр!$W$5:$W$318,"выиграли"),"") | K22: =IFERROR(AVERAGEIFS(Реестр!$N$5:$N$318,Реестр!$G$5:$G$318,$A22,Реестр!$W$5:$W$318,"проиграли"),"") | L22: =IFERROR(AVERAGEIFS(Реестр!$Z$5:$Z$318,Реестр!$G$5:$G$318,$A22,Реестр!$W$5:$W$318,"проиграли"),"")
A23: ИТОГО | B23: =SUM(B16:B22) -> 289 | C23: =SUM(C16:C22) -> 17 | F23: =SUM(F16:F22) -> 18 | G23: =SUM(G16:G22) -> 0 | H23: =SUM(H16:H22) -> 9
A26: Как читать: если «средняя наценка — выигранные» стабильно ниже целевого диапазона — диапазон завышен; если проигрываем с ценой выше победителя на 5–10 % — снижать наценку на работы в этом типе тендеров.

Sheet Как вести
A1: КАК ВЕСТИ РЕЕСТР
A2: 1. Новый тендер добавляется в реестр после каждого расчёта (шаг 12 промта «Расчёт тендера и КП»): дата, заказчик, объект, тип, с/с, КП, наценка, решение.
A3: 2. После подачи — отдел тендеров ставит дату подачи и нашу финальную цену (после переторжки — последнюю).
A4: 3. После итогов — РЕЗУЛЬТАТ (выиграли / проиграли / отменён), место, цену победителя и число участников, причину проигрыша (цена, квалификация, сроки, отказ заказчика).
A5: 4. Цену победителя спрашивать у организатора или смотреть в протоколе (на ЭТП она обычно публикуется). Без неё нельзя понять, насколько мы дороже рынка.
A6: 5. Раз в месяц смотреть лист «Аналитика»: доля побед и наценка выигранных тендеров по типам — по ним корректируем целевые диапазоны наценки.
A7: Синие колонки заполнены по расчётам в памяти Claude (июль–октябрь 2026). Решение «подано» стоит только там, где подача была явно зафиксирована; РЕЗУЛЬТАТ пуст, если неизвестно, подавали ли; по остальным «рассчитано» — проверьте и поправьте статус.
A8: Наценка/маржа: формула из с/с и КП; если какой-то из сумм нет — подставлено значение из расчёта. Периоды разные (разово / в месяц / в год) — суммы между строками не складывать.

Sheet Списки
A1: Крупные сети и девелоперы — конкурентный тендер
A2: Переторжка / 2 тур / вход к новому заказчику
A3: Fit-out, частный бизнес, малые объёмы
A4: ТО и абонентское обслуживание
A5: Госзакупки 44-ФЗ / 223-ФЗ
