Workbook

Sheet Расценки
A1: ТАРИФИКАТОР НЕОСТРОЙ v2 — рыночные расценки, оплата бригадам и маржа
A2: Только работа, без материалов и оборудования · руб. без НДС · октябрь 2026. Бригада = выплата ИП/самозанятому за единицу, включая их налог 6 %. Цена НЕОСТРОЙ = рыночная цена; если при оплате бригаде по нормо-часам (норма × ставка часа) маржа ниже порога в F3 — цена поднята выше рынка до этого порога (подсвечено: светло — до +10 % к рынку, оранжевый — +10…30 %, красный — больше +30 %). Маржа = (цена НЕОСТРОЙ − оплата бригаде) ÷ цена НЕОСТРОЙ. Зелёные артикулы — новые работы.
B3: Минимальная маржа при оплате бригаде по нормо-часам (ниже — цена НЕОСТРОЙ поднимается над рынком): | F3: 0.25
A4: Артикул | B4: Вид работ | C4: Ед. изм. | D4: Новая | E4: Специальность (код) | F4: Рынок СПб, руб/ед. | G4: Рынок Мск, руб/ед. | H4: ЦЕНА НЕОСТРОЙ СПб, руб/ед. | I4: ЦЕНА НЕОСТРОЙ Мск, руб/ед. | J4: Цена НЕОСТРОЙ выше рынка СПб, % | K4: Цена НЕОСТРОЙ выше рынка Мск, % | L4: Оплата бригаде СПб (ИП/СЗ, вкл. 6 %) | M4: Оплата бригаде Мск (ИП/СЗ, вкл. 6 %) | N4: Маржа СПб, % | O4: Маржа Мск, % | P4: Маржа СПб, руб/ед. | Q4: Маржа Мск, руб/ед. | R4: Старый тарификатор: оплата бригаде | S4: Старый тарификатор: цена (+35 %) | T4: Старая цена ÷ рынок СПб | U4: Источник цены | V4: Примечание
A5: 1.1 Демонтаж зданий, строений, сооружений
A6: 1.1.1 | B6: Разборка покрытий и оснований асфальтобетонных | C6: м3 | E6: BLG | F6: 3500 | G6: 4025 | H6: =IF(OR(F6="",F6=0),"",MAX(F6,IF(ISNUMBER('Нормы и нормо-часы'!K7),ROUNDUP('Нормы и нормо-часы'!K7/(1-$F$3),0),0))) -> 3500 | I6: =IF(OR(G6="",G6=0),"",MAX(G6,IF(ISNUMBER('Нормы и нормо-часы'!L7),ROUNDUP('Нормы и нормо-часы'!L7/(1-$F$3),0),0))) -> 4025 | J6: =IF(OR(F6="",F6=0),"",H6/F6-1) -> 0 | K6: =IF(OR(G6="",G6=0),"",I6/G6-1) -> 0 | L6: 2100 | M6: 2415 | N6: =IF(OR(H6="",H6=0),"",(H6-L6)/H6) -> 0.4 | O6: =IF(OR(I6="",I6=0),"",(I6-M6)/I6) -> 0.4 | P6: =IF(H6="","",H6-L6) -> 1400 | Q6: =IF(I6="","",I6-M6) -> 1610 | R6: 5162.06 | S6: 6968.78 | T6: =IF(OR(S6="",F6="",F6=0),"",S6/F6) -> 1.99108 | U6: аналог zakazstroy.ru 120 руб/м2 при 5 см (мех.), ручная ×1,4 | V6: Наш тариф ~2× рынка; при площадях >100 м2 выгоднее фрезерование/экскаватор с гидромолотом (100–200 руб/м2)
A7: 1.1.2 | B7: Демонтаж деревянных зданий и строений без сохранения годного материала | C7: м3 здания | E7: RAZ | F7: 1000 | G7: 1300 | H7: =IF(OR(F7="",F7=0),"",MAX(F7,IF(ISNUMBER('Нормы и нормо-часы'!K8),ROUNDUP('Нормы и нормо-часы'!K8/(1-$F$3),0),0))) -> 1000 | I7: =IF(OR(G7="",G7=0),"",MAX(G7,IF(ISNUMBER('Нормы и нормо-часы'!L8),ROUNDUP('Нормы и нормо-часы'!L8/(1-$F$3),0),0))) -> 1300 | J7: =IF(OR(F7="",F7=0),"",H7/F7-1) -> 0 | K7: =IF(OR(G7="",G7=0),"",I7/G7-1) -> 0 | L7: 600 | M7: 768 | N7: =IF(OR(H7="",H7=0),"",(H7-L7)/H7) -> 0.4 | O7: =IF(OR(I7="",I7=0),"",(I7-M7)/I7) -> 0.40923077 | P7: =IF(H7="","",H7-L7) -> 400 | Q7: =IF(I7="","",I7-M7) -> 532 | R7: 1479.19 | S7: 1996.91 | T7: =IF(OR(S7="",F7="",F7=0),"",S7/F7) -> 1.99691 | U7: прайс moskva-demontazh.ru (дер. дом от 1300/м3, МСК) | V7: Ед. — м3 строительного объёма здания; вывоз не входит
A8: 1.1.3 | B8: Демонтаж зданий и строений из металлоконструкций без сохранения годного материала | C8: т | E8: SVA | F8: 6500 | G8: 7475 | H8: =IF(OR(F8="",F8=0),"",MAX(F8,IF(ISNUMBER('Нормы и нормо-часы'!K9),ROUNDUP('Нормы и нормо-часы'!K9/(1-$F$3),0),0))) -> 12000 | I8: =IF(OR(G8="",G8=0),"",MAX(G8,IF(ISNUMBER('Нормы и нормо-часы'!L9),ROUNDUP('Нормы и нормо-часы'!L9/(1-$F$3),0),0))) -> 14400 | J8: =IF(OR(F8="",F8=0),"",H8/F8-1) -> 0.84615385 | K8: =IF(OR(G8="",G8=0),"",I8/G8-1) -> 0.9264214 | L8: 3900 | M8: 4485 | N8: =IF(OR(H8="",H8=0),"",(H8-L8)/H8) -> 0.675 | O8: =IF(OR(I8="",I8=0),"",(I8-M8)/I8) -> 0.68854167 | P8: =IF(H8="","",H8-L8) -> 8100 | Q8: =IF(I8="","",I8-M8) -> 9915 | R8: 8588.95 | S8: 11595.08 | T8: =IF(OR(S8="",F8="",F8=0),"",S8/F8) -> 1.7838585 | U8: аналог moskva-demontazh.ru (МК от 4000 руб/т МСК, мех.) | V8: Газорезка без сохранения; кран/автовышка оплачиваются отдельно
A9: 1.1.4 | B9: Демонтаж каменных зданий и строений (кирпич, бетон, железобетон) комплексная работа с сохранением годного материала | C9: м3 | E9: RAZ | F9: 4200 | G9: 4830 | H9: =IF(OR(F9="",F9=0),"",MAX(F9,IF(ISNUMBER('Нормы и нормо-часы'!K10),ROUNDUP('Нормы и нормо-часы'!K10/(1-$F$3),0),0))) -> 4767 | I9: =IF(OR(G9="",G9=0),"",MAX(G9,IF(ISNUMBER('Нормы и нормо-часы'!L10),ROUNDUP('Нормы и нормо-часы'!L10/(1-$F$3),0),0))) -> 5720 | J9: =IF(OR(F9="",F9=0),"",H9/F9-1) -> 0.135 | K9: =IF(OR(G9="",G9=0),"",I9/G9-1) -> 0.18426501 | L9: 2500 | M9: 2875 | N9: =IF(OR(H9="",H9=0),"",(H9-L9)/H9) -> 0.47556115 | O9: =IF(OR(I9="",I9=0),"",(I9-M9)/I9) -> 0.49737762 | P9: =IF(H9="","",H9-L9) -> 2267 | Q9: =IF(I9="","",I9-M9) -> 2845 | R9: 2294.25 | S9: 3097.24 | T9: =IF(OR(S9="",F9="",F9=0),"",S9/F9) -> 0.7374381 | U9: аналог zakazstroy.ru (кирп. стены от 1800/м3 мех.), ручная с сохранением ×2,3 | V9: Неясно м3 конструкций или строит. объёма; цена дана на м3 кладки/конструкций
A10: 1.1.5 | B10: Разборка бортовых камней с сохранением камня пригодного для дальнейшего использования | C10: мп | E10: BLG | F10: 350 | G10: 402 | H10: =IF(OR(F10="",F10=0),"",MAX(F10,IF(ISNUMBER('Нормы и нормо-часы'!K11),ROUNDUP('Нормы и нормо-часы'!K11/(1-$F$3),0),0))) -> 350 | I10: =IF(OR(G10="",G10=0),"",MAX(G10,IF(ISNUMBER('Нормы и нормо-часы'!L11),ROUNDUP('Нормы и нормо-часы'!L11/(1-$F$3),0),0))) -> 402 | J10: =IF(OR(F10="",F10=0),"",H10/F10-1) -> 0 | K10: =IF(OR(G10="",G10=0),"",I10/G10-1) -> 0 | L10: 200 | M10: 230 | N10: =IF(OR(H10="",H10=0),"",(H10-L10)/H10) -> 0.42857143 | O10: =IF(OR(I10="",I10=0),"",(I10-M10)/I10) -> 0.4278607 | P10: =IF(H10="","",H10-L10) -> 150 | Q10: =IF(I10="","",I10-M10) -> 172 | R10: 543.38 | S10: 733.56 | T10: =IF(OR(S10="",F10="",F10=0),"",S10/F10) -> 2.0958857 | U10: аналог zakazstroy.ru 160–200 руб/мп с вывозом (крупные объёмы)
A11: 1.1.6 | B11: Разборка тротуаров и дорожек из плит бетонных, брусчатки с сохранением пригодных для дальнейшего использования | C11: м2 | E11: BLG | F11: 250 | G11: 288 | H11: =IF(OR(F11="",F11=0),"",MAX(F11,IF(ISNUMBER('Нормы и нормо-часы'!K12),ROUNDUP('Нормы и нормо-часы'!K12/(1-$F$3),0),0))) -> 260 | I11: =IF(OR(G11="",G11=0),"",MAX(G11,IF(ISNUMBER('Нормы и нормо-часы'!L12),ROUNDUP('Нормы и нормо-часы'!L12/(1-$F$3),0),0))) -> 312 | J11: =IF(OR(F11="",F11=0),"",H11/F11-1) -> 0.04 | K11: =IF(OR(G11="",G11=0),"",I11/G11-1) -> 0.083333333 | L11: 150 | M11: 172 | N11: =IF(OR(H11="",H11=0),"",(H11-L11)/H11) -> 0.42307692 | O11: =IF(OR(I11="",I11=0),"",(I11-M11)/I11) -> 0.44871795 | P11: =IF(H11="","",H11-L11) -> 110 | Q11: =IF(I11="","",I11-M11) -> 140 | R11: 256.8 | S11: 346.68 | T11: =IF(OR(S11="",F11="",F11=0),"",S11/F11) -> 1.38672 | U11: аналог zakazstroy.ru 100 руб/м2 (без сохранения)
A12: 1.1.N1 | B12: Разборка асфальтобетонного покрытия толщиной до 5 см отбойными молотками | C12: м2 | D12: да | E12: BLG | F12: 200 | G12: 230 | H12: =IF(OR(F12="",F12=0),"",MAX(F12,IF(ISNUMBER('Нормы и нормо-часы'!K13),ROUNDUP('Нормы и нормо-часы'!K13/(1-$F$3),0),0))) -> 200 | I12: =IF(OR(G12="",G12=0),"",MAX(G12,IF(ISNUMBER('Нормы и нормо-часы'!L13),ROUNDUP('Нормы и нормо-часы'!L13/(1-$F$3),0),0))) -> 230 | J12: =IF(OR(F12="",F12=0),"",H12/F12-1) -> 0 | K12: =IF(OR(G12="",G12=0),"",I12/G12-1) -> 0 | L12: 120 | M12: 138 | N12: =IF(OR(H12="",H12=0),"",(H12-L12)/H12) -> 0.4 | O12: =IF(OR(I12="",I12=0),"",(I12-M12)/I12) -> 0.4 | P12: =IF(H12="","",H12-L12) -> 80 | Q12: =IF(I12="","",I12-M12) -> 92 | T12: =IF(OR(S12="",F12="",F12=0),"",S12/F12) | U12: аналог zakazstroy.ru 120 руб/м2 (мех.)
A13: 1.1.N2 | B13: Демонтаж бетонных дорожных плит (ПАГ, 2П) с погрузкой | C13: м2 | D13: да | E13: BLG | F13: 460 | G13: 529 | H13: =IF(OR(F13="",F13=0),"",MAX(F13,IF(ISNUMBER('Нормы и нормо-часы'!K14),ROUNDUP('Нормы и нормо-часы'!K14/(1-$F$3),0),0))) -> 460 | I13: =IF(OR(G13="",G13=0),"",MAX(G13,IF(ISNUMBER('Нормы и нормо-часы'!L14),ROUNDUP('Нормы и нормо-часы'!L14/(1-$F$3),0),0))) -> 529 | J13: =IF(OR(F13="",F13=0),"",H13/F13-1) -> 0 | K13: =IF(OR(G13="",G13=0),"",I13/G13-1) -> 0 | L13: 280 | M13: 322 | N13: =IF(OR(H13="",H13=0),"",(H13-L13)/H13) -> 0.39130435 | O13: =IF(OR(I13="",I13=0),"",(I13-M13)/I13) -> 0.39130435 | P13: =IF(H13="","",H13-L13) -> 180 | Q13: =IF(I13="","",I13-M13) -> 207 | T13: =IF(OR(S13="",F13="",F13=0),"",S13/F13) | U13: прайс zakazstroy.ru 460 руб/м2 | V13: Кран/манипулятор отдельно
A14: 1.1.N3 | B14: Демонтаж ограждения из сетки/профлиста со стойками | C14: мп | D14: да | E14: SVA | F14: 300 | G14: 345 | H14: =IF(OR(F14="",F14=0),"",MAX(F14,IF(ISNUMBER('Нормы и нормо-часы'!K15),ROUNDUP('Нормы и нормо-часы'!K15/(1-$F$3),0),0))) -> 480 | I14: =IF(OR(G14="",G14=0),"",MAX(G14,IF(ISNUMBER('Нормы и нормо-часы'!L15),ROUNDUP('Нормы и нормо-часы'!L15/(1-$F$3),0),0))) -> 576 | J14: =IF(OR(F14="",F14=0),"",H14/F14-1) -> 0.6 | K14: =IF(OR(G14="",G14=0),"",I14/G14-1) -> 0.66956522 | L14: 180 | M14: 207 | N14: =IF(OR(H14="",H14=0),"",(H14-L14)/H14) -> 0.625 | O14: =IF(OR(I14="",I14=0),"",(I14-M14)/I14) -> 0.640625 | P14: =IF(H14="","",H14-L14) -> 300 | Q14: =IF(I14="","",I14-M14) -> 369 | T14: =IF(OR(S14="",F14="",F14=0),"",S14/F14) | U14: аналог zakazstroy.ru (ж/б заборы 800 руб/мп)
A15: 1.2 Демонтажные работы по фасаду
A16: 1.2.1 | B16: Отбивка штукатурки с поверхностей стен | C16: м2 | E16: RAZ | F16: 300 | G16: 345 | H16: =IF(OR(F16="",F16=0),"",MAX(F16,IF(ISNUMBER('Нормы и нормо-часы'!K17),ROUNDUP('Нормы и нормо-часы'!K17/(1-$F$3),0),0))) -> 300 | I16: =IF(OR(G16="",G16=0),"",MAX(G16,IF(ISNUMBER('Нормы и нормо-часы'!L17),ROUNDUP('Нормы и нормо-часы'!L17/(1-$F$3),0),0))) -> 345 | J16: =IF(OR(F16="",F16=0),"",H16/F16-1) -> 0 | K16: =IF(OR(G16="",G16=0),"",I16/G16-1) -> 0 | L16: 180 | M16: 207 | N16: =IF(OR(H16="",H16=0),"",(H16-L16)/H16) -> 0.4 | O16: =IF(OR(I16="",I16=0),"",(I16-M16)/I16) -> 0.4 | P16: =IF(H16="","",H16-L16) -> 120 | Q16: =IF(I16="","",I16-M16) -> 138 | R16: 217.35 | S16: 293.42 | T16: =IF(OR(S16="",F16="",F16=0),"",S16/F16) -> 0.97806667 | U16: прайс remontvspb.ru 200–500, stroygarant78.ru 220 руб/м2
A17: 1.2.2 | B17: Демонтаж облицовки из профилированного листа без разборки каркаса | C17: м2 | E17: RAZ | F17: 250 | G17: 288 | H17: =IF(OR(F17="",F17=0),"",MAX(F17,IF(ISNUMBER('Нормы и нормо-часы'!K18),ROUNDUP('Нормы и нормо-часы'!K18/(1-$F$3),0),0))) -> 250 | I17: =IF(OR(G17="",G17=0),"",MAX(G17,IF(ISNUMBER('Нормы и нормо-часы'!L18),ROUNDUP('Нормы и нормо-часы'!L18/(1-$F$3),0),0))) -> 288 | J17: =IF(OR(F17="",F17=0),"",H17/F17-1) -> 0 | K17: =IF(OR(G17="",G17=0),"",I17/G17-1) -> 0 | L17: 150 | M17: 172 | N17: =IF(OR(H17="",H17=0),"",(H17-L17)/H17) -> 0.4 | O17: =IF(OR(I17="",I17=0),"",(I17-M17)/I17) -> 0.40277778 | P17: =IF(H17="","",H17-L17) -> 100 | Q17: =IF(I17="","",I17-M17) -> 116 | R17: 244.52 | S17: 330.1 | T17: =IF(OR(S17="",F17="",F17=0),"",S17/F17) -> 1.3204 | U17: аналог spb.rsk-uteplitel.ru (профлист кровли 60–240 руб/м2) | V17: Работа с вышки/подъёмника — техника отдельно
A18: 1.2.3 | B18: Демонтаж облицовки из профилированного листа с разборкой каркаса | C18: м2 | E18: RAZ | F18: 380 | G18: 437 | H18: =IF(OR(F18="",F18=0),"",MAX(F18,IF(ISNUMBER('Нормы и нормо-часы'!K19),ROUNDUP('Нормы и нормо-часы'!K19/(1-$F$3),0),0))) -> 380 | I18: =IF(OR(G18="",G18=0),"",MAX(G18,IF(ISNUMBER('Нормы и нормо-часы'!L19),ROUNDUP('Нормы и нормо-часы'!L19/(1-$F$3),0),0))) -> 437 | J18: =IF(OR(F18="",F18=0),"",H18/F18-1) -> 0 | K18: =IF(OR(G18="",G18=0),"",I18/G18-1) -> 0 | L18: 230 | M18: 264 | N18: =IF(OR(H18="",H18=0),"",(H18-L18)/H18) -> 0.39473684 | O18: =IF(OR(I18="",I18=0),"",(I18-M18)/I18) -> 0.39588101 | P18: =IF(H18="","",H18-L18) -> 150 | Q18: =IF(I18="","",I18-M18) -> 173 | R18: 304.83 | S18: 411.52 | T18: =IF(OR(S18="",F18="",F18=0),"",S18/F18) -> 1.0829474 | U18: аналог 1.2.2 + разборка каркаса (spb.innstroy.ru подсистема 632)
A19: 1.2.4 | B19: Демонтаж ограждающих конструкций стен из многослойных панелей (сэндвич-панели) | C19: м2 | E19: KRO | F19: 380 | G19: 437 | H19: =IF(OR(F19="",F19=0),"",MAX(F19,IF(ISNUMBER('Нормы и нормо-часы'!K20),ROUNDUP('Нормы и нормо-часы'!K20/(1-$F$3),0),0))) -> 480 | I19: =IF(OR(G19="",G19=0),"",MAX(G19,IF(ISNUMBER('Нормы и нормо-часы'!L20),ROUNDUP('Нормы и нормо-часы'!L20/(1-$F$3),0),0))) -> 571 | J19: =IF(OR(F19="",F19=0),"",H19/F19-1) -> 0.26315789 | K19: =IF(OR(G19="",G19=0),"",I19/G19-1) -> 0.30663616 | L19: 230 | M19: 264 | N19: =IF(OR(H19="",H19=0),"",(H19-L19)/H19) -> 0.52083333 | O19: =IF(OR(I19="",I19=0),"",(I19-M19)/I19) -> 0.53765324 | P19: =IF(H19="","",H19-L19) -> 250 | Q19: =IF(I19="","",I19-M19) -> 307 | R19: 547.3 | S19: 738.86 | T19: =IF(OR(S19="",F19="",F19=0),"",S19/F19) -> 1.9443684 | U19: прайс spb.rsk-uteplitel.ru 316–380 руб/м2 (СПб, 50–100 мм) | V19: Наш тариф ~1,9× рынка; техника (вышка/кран) отдельно
A20: 1.2.5 | B20: Демонтаж ограждающих конструкций стен из панелей "Алюкобонд" и металлического каркаса | C20: м2 | E20: FAS | F20: 1100 | G20: 1265 | H20: =IF(OR(F20="",F20=0),"",MAX(F20,IF(ISNUMBER('Нормы и нормо-часы'!K21),ROUNDUP('Нормы и нормо-часы'!K21/(1-$F$3),0),0))) -> 1320 | I20: =IF(OR(G20="",G20=0),"",MAX(G20,IF(ISNUMBER('Нормы и нормо-часы'!L21),ROUNDUP('Нормы и нормо-часы'!L21/(1-$F$3),0),0))) -> 1560 | J20: =IF(OR(F20="",F20=0),"",H20/F20-1) -> 0.2 | K20: =IF(OR(G20="",G20=0),"",I20/G20-1) -> 0.23320158 | L20: 650 | M20: 747 | N20: =IF(OR(H20="",H20=0),"",(H20-L20)/H20) -> 0.50757576 | O20: =IF(OR(I20="",I20=0),"",(I20-M20)/I20) -> 0.52115385 | P20: =IF(H20="","",H20-L20) -> 670 | Q20: =IF(I20="","",I20-M20) -> 813 | R20: 962.99 | S20: 1300.04 | T20: =IF(OR(S20="",F20="",F20=0),"",S20/F20) -> 1.1818545 | U20: прайс spb.innstroy.ru облицовка 738 + подсистема 632 руб/м2
A21: 1.2.6 | B21: Демонтаж теплоизоляционного слоя стен | C21: м2 | E21: RAZ | F21: 200 | G21: 230 | H21: =IF(OR(F21="",F21=0),"",MAX(F21,IF(ISNUMBER('Нормы и нормо-часы'!K22),ROUNDUP('Нормы и нормо-часы'!K22/(1-$F$3),0),0))) -> 200 | I21: =IF(OR(G21="",G21=0),"",MAX(G21,IF(ISNUMBER('Нормы и нормо-часы'!L22),ROUNDUP('Нормы и нормо-часы'!L22/(1-$F$3),0),0))) -> 230 | J21: =IF(OR(F21="",F21=0),"",H21/F21-1) -> 0 | K21: =IF(OR(G21="",G21=0),"",I21/G21-1) -> 0 | L21: 120 | M21: 138 | N21: =IF(OR(H21="",H21=0),"",(H21-L21)/H21) -> 0.4 | O21: =IF(OR(I21="",I21=0),"",(I21-M21)/I21) -> 0.4 | P21: =IF(H21="","",H21-L21) -> 80 | Q21: =IF(I21="","",I21-M21) -> 92 | R21: 171.47 | S21: 231.48 | T21: =IF(OR(S21="",F21="",F21=0),"",S21/F21) -> 1.1574 | U21: аналог spb.innstroy.ru (утеплитель фасада 527, внутри помещений 120–150)
A22: 1.2.7 | B22: Разборка систем вентилируемых фасадов из плит "Керамогранит" с сохранением каркаса | C22: м2 | E22: FAS | F22: 650 | G22: 747 | H22: =IF(OR(F22="",F22=0),"",MAX(F22,IF(ISNUMBER('Нормы и нормо-часы'!K23),ROUNDUP('Нормы и нормо-часы'!K23/(1-$F$3),0),0))) -> 880 | I22: =IF(OR(G22="",G22=0),"",MAX(G22,IF(ISNUMBER('Нормы и нормо-часы'!L23),ROUNDUP('Нормы и нормо-часы'!L23/(1-$F$3),0),0))) -> 1040 | J22: =IF(OR(F22="",F22=0),"",H22/F22-1) -> 0.35384615 | K22: =IF(OR(G22="",G22=0),"",I22/G22-1) -> 0.39223561 | L22: 400 | M22: 460 | N22: =IF(OR(H22="",H22=0),"",(H22-L22)/H22) -> 0.54545455 | O22: =IF(OR(I22="",I22=0),"",(I22-M22)/I22) -> 0.55769231 | P22: =IF(H22="","",H22-L22) -> 480 | Q22: =IF(I22="","",I22-M22) -> 580 | R22: 929.78 | S22: 1255.2 | T22: =IF(OR(S22="",F22="",F22=0),"",S22/F22) -> 1.9310769 | U22: прайс spb.innstroy.ru снятие облицовки 738 руб/м2 | V22: С сохранением каркаса — только снятие плит
A23: 1.2.8 | B23: Разборка систем вентилируемых фасадов из плит "Керамогранит" с учетом каркаса | C23: м2 | E23: FAS | F23: 1100 | G23: 1265 | H23: =IF(OR(F23="",F23=0),"",MAX(F23,IF(ISNUMBER('Нормы и нормо-часы'!K24),ROUNDUP('Нормы и нормо-часы'!K24/(1-$F$3),0),0))) -> 1467 | I23: =IF(OR(G23="",G23=0),"",MAX(G23,IF(ISNUMBER('Нормы и нормо-часы'!L24),ROUNDUP('Нормы и нормо-часы'!L24/(1-$F$3),0),0))) -> 1734 | J23: =IF(OR(F23="",F23=0),"",H23/F23-1) -> 0.33363636 | K23: =IF(OR(G23="",G23=0),"",I23/G23-1) -> 0.37075099 | L23: 650 | M23: 747 | N23: =IF(OR(H23="",H23=0),"",(H23-L23)/H23) -> 0.55691888 | O23: =IF(OR(I23="",I23=0),"",(I23-M23)/I23) -> 0.56920415 | P23: =IF(H23="","",H23-L23) -> 817 | Q23: =IF(I23="","",I23-M23) -> 987 | R23: 914.69 | S23: 1234.83 | T23: =IF(OR(S23="",F23="",F23=0),"",S23/F23) -> 1.1225727 | U23: прайс spb.innstroy.ru облицовка+подсистема 738+632 | V23: В нашем тарифе «с каркасом» дешевле, чем «без» (1.2.7) — нелогично
A24: 1.2.N1 | B24: Демонтаж металлического козырька/навеса над входом | C24: м2 | D24: да | E24: SVA | F24: 1200 | G24: 1380 | H24: =IF(OR(F24="",F24=0),"",MAX(F24,IF(ISNUMBER('Нормы и нормо-часы'!K25),ROUNDUP('Нормы и нормо-часы'!K25/(1-$F$3),0),0))) -> 1200 | I24: =IF(OR(G24="",G24=0),"",MAX(G24,IF(ISNUMBER('Нормы и нормо-часы'!L25),ROUNDUP('Нормы и нормо-часы'!L25/(1-$F$3),0),0))) -> 1440 | J24: =IF(OR(F24="",F24=0),"",H24/F24-1) -> 0 | K24: =IF(OR(G24="",G24=0),"",I24/G24-1) -> 0.043478261 | L24: 720 | M24: 828 | N24: =IF(OR(H24="",H24=0),"",(H24-L24)/H24) -> 0.4 | O24: =IF(OR(I24="",I24=0),"",(I24-M24)/I24) -> 0.425 | P24: =IF(H24="","",H24-L24) -> 480 | Q24: =IF(I24="","",I24-M24) -> 612 | T24: =IF(OR(S24="",F24="",F24=0),"",S24/F24) | U24: расчёт | V24: Техника отдельно
A25: 1.3 Демонтажные работы по фундаменту
A26: 1.3.1 | B26: Разборка бутовых фундаментов | C26: м3 | E26: RAZ | F26: 4000 | G26: 4600 | H26: =IF(OR(F26="",F26=0),"",MAX(F26,IF(ISNUMBER('Нормы и нормо-часы'!K27),ROUNDUP('Нормы и нормо-часы'!K27/(1-$F$3),0),0))) -> 5500 | I26: =IF(OR(G26="",G26=0),"",MAX(G26,IF(ISNUMBER('Нормы и нормо-часы'!L27),ROUNDUP('Нормы и нормо-часы'!L27/(1-$F$3),0),0))) -> 6600 | J26: =IF(OR(F26="",F26=0),"",H26/F26-1) -> 0.375 | K26: =IF(OR(G26="",G26=0),"",I26/G26-1) -> 0.43478261 | L26: 2400 | M26: 2760 | N26: =IF(OR(H26="",H26=0),"",(H26-L26)/H26) -> 0.56363636 | O26: =IF(OR(I26="",I26=0),"",(I26-M26)/I26) -> 0.58181818 | P26: =IF(H26="","",H26-L26) -> 3100 | Q26: =IF(I26="","",I26-M26) -> 3840 | R26: 10022.25 | S26: 13530.04 | T26: =IF(OR(S26="",F26="",F26=0),"",S26/F26) -> 3.38251 | U26: аналог rezka-prof.ru (гидроклин кирпич/бут 3000), moskva-demontazh.ru фундамент от 1900 | V26: Наш тариф 13,5 тыс. — ×3,4 к рынку
A27: 1.3.2 | B27: Разборка бетонных фундаментов | C27: м3 | E27: RAZ | F27: 7500 | G27: 9000 | H27: =IF(OR(F27="",F27=0),"",MAX(F27,IF(ISNUMBER('Нормы и нормо-часы'!K28),ROUNDUP('Нормы и нормо-часы'!K28/(1-$F$3),0),0))) -> 8067 | I27: =IF(OR(G27="",G27=0),"",MAX(G27,IF(ISNUMBER('Нормы и нормо-часы'!L28),ROUNDUP('Нормы и нормо-часы'!L28/(1-$F$3),0),0))) -> 9680 | J27: =IF(OR(F27="",F27=0),"",H27/F27-1) -> 0.0756 | K27: =IF(OR(G27="",G27=0),"",I27/G27-1) -> 0.075555556 | L27: 4500 | M27: 5310 | N27: =IF(OR(H27="",H27=0),"",(H27-L27)/H27) -> 0.44217181 | O27: =IF(OR(I27="",I27=0),"",(I27-M27)/I27) -> 0.45144628 | P27: =IF(H27="","",H27-L27) -> 3567 | Q27: =IF(I27="","",I27-M27) -> 4370 | R27: 14490 | S27: 19561.5 | T27: =IF(OR(S27="",F27="",F27=0),"",S27/F27) -> 2.6082 | U27: прайс rezka-prof.ru гидроклин бетон от 7000; moskva-demontazh.ru ручной от 9200 (МСК) | V27: Наш тариф 19,6 тыс. — ×2,6 к рынку
A28: 1.3.3 | B28: Разборка железобетонных фундаментов | C28: м3 | E28: RAZ | F28: 10000 | G28: 12000 | H28: =IF(OR(F28="",F28=0),"",MAX(F28,IF(ISNUMBER('Нормы и нормо-часы'!K29),ROUNDUP('Нормы и нормо-часы'!K29/(1-$F$3),0),0))) -> 11000 | I28: =IF(OR(G28="",G28=0),"",MAX(G28,IF(ISNUMBER('Нормы и нормо-часы'!L29),ROUNDUP('Нормы и нормо-часы'!L29/(1-$F$3),0),0))) -> 13200 | J28: =IF(OR(F28="",F28=0),"",H28/F28-1) -> 0.1 | K28: =IF(OR(G28="",G28=0),"",I28/G28-1) -> 0.1 | L28: 6000 | M28: 7080 | N28: =IF(OR(H28="",H28=0),"",(H28-L28)/H28) -> 0.45454545 | O28: =IF(OR(I28="",I28=0),"",(I28-M28)/I28) -> 0.46363636 | P28: =IF(H28="","",H28-L28) -> 5000 | Q28: =IF(I28="","",I28-M28) -> 6120 | R28: 16703.75 | S28: 22550.06 | T28: =IF(OR(S28="",F28="",F28=0),"",S28/F28) -> 2.255006 | U28: прайс rezka-prof.ru гидроклин ж/б от 13500; zakazstroy.ru ж/б от 8500 | V28: Наш тариф 22,6 тыс. — ×2,3 к рынку
A29: 1.4 Демонтажные работы кровли
A30: 1.4.1 | B30: Очистка кровли от листвы и мусора | C30: м2 | E30: RAZ | F30: 35 | G30: 40 | H30: =IF(OR(F30="",F30=0),"",MAX(F30,IF(ISNUMBER('Нормы и нормо-часы'!K31),ROUNDUP('Нормы и нормо-часы'!K31/(1-$F$3),0),0))) -> 35 | I30: =IF(OR(G30="",G30=0),"",MAX(G30,IF(ISNUMBER('Нормы и нормо-часы'!L31),ROUNDUP('Нормы и нормо-часы'!L31/(1-$F$3),0),0))) -> 40 | J30: =IF(OR(F30="",F30=0),"",H30/F30-1) -> 0 | K30: =IF(OR(G30="",G30=0),"",I30/G30-1) -> 0 | L30: 20 | M30: 23 | N30: =IF(OR(H30="",H30=0),"",(H30-L30)/H30) -> 0.42857143 | O30: =IF(OR(I30="",I30=0),"",(I30-M30)/I30) -> 0.425 | P30: =IF(H30="","",H30-L30) -> 15 | Q30: =IF(I30="","",I30-M30) -> 17 | R30: 64.96 | S30: 87.7 | T30: =IF(OR(S30="",F30="",F30=0),"",S30/F30) -> 2.5057143 | U30: аналог spb-dvigenie.ru/h2oclean.ru (снег 20–35 руб/м2) | V30: Наш тариф 88 руб — ×2,5 к рынку
A31: 1.4.2 | B31: Очистка снега с крыш при толщине слоя до 20 см | C31: м2 | E31: RAZ | F31: 30 | G31: 34.5 | H31: =IF(OR(F31="",F31=0),"",MAX(F31,IF(ISNUMBER('Нормы и нормо-часы'!K32),ROUNDUP('Нормы и нормо-часы'!K32/(1-$F$3),0),0))) -> 30 | I31: =IF(OR(G31="",G31=0),"",MAX(G31,IF(ISNUMBER('Нормы и нормо-часы'!L32),ROUNDUP('Нормы и нормо-часы'!L32/(1-$F$3),0),0))) -> 35 | J31: =IF(OR(F31="",F31=0),"",H31/F31-1) -> 0 | K31: =IF(OR(G31="",G31=0),"",I31/G31-1) -> 0.014492754 | L31: 18 | M31: 20.5 | N31: =IF(OR(H31="",H31=0),"",(H31-L31)/H31) -> 0.4 | O31: =IF(OR(I31="",I31=0),"",(I31-M31)/I31) -> 0.41428571 | P31: =IF(H31="","",H31-L31) -> 12 | Q31: =IF(I31="","",I31-M31) -> 14.5 | R31: 50.32 | S31: 67.93 | T31: =IF(OR(S31="",F31="",F31=0),"",S31/F31) -> 2.2643333 | U31: прайс spb-dvigenie.ru/h2oclean.ru юрлица 18–35 руб/м2 | V31: Наш тариф 68 руб — ×2,3 к рынку; при >1000 м2 рынок 20 руб
A32: 1.4.3 | B32: Очистка снега с крыш, добавлять на каждые следующие 10 см увеличения толщины слоя | C32: м2 | E32: RAZ | F32: 8 | G32: 9 | H32: =IF(OR(F32="",F32=0),"",MAX(F32,IF(ISNUMBER('Нормы и нормо-часы'!K33),ROUNDUP('Нормы и нормо-часы'!K33/(1-$F$3),0),0))) -> 10 | I32: =IF(OR(G32="",G32=0),"",MAX(G32,IF(ISNUMBER('Нормы и нормо-часы'!L33),ROUNDUP('Нормы и нормо-часы'!L33/(1-$F$3),0),0))) -> 11 | J32: =IF(OR(F32="",F32=0),"",H32/F32-1) -> 0.25 | K32: =IF(OR(G32="",G32=0),"",I32/G32-1) -> 0.22222222 | L32: 5 | M32: 6 | N32: =IF(OR(H32="",H32=0),"",(H32-L32)/H32) -> 0.5 | O32: =IF(OR(I32="",I32=0),"",(I32-M32)/I32) -> 0.45454545 | P32: =IF(H32="","",H32-L32) -> 5 | Q32: =IF(I32="","",I32-M32) -> 5 | R32: 11.27 | S32: 15.21 | T32: =IF(OR(S32="",F32="",F32=0),"",S32/F32) -> 1.90125 | U32: аналог 1.4.2 (+30 %/10 см)
A33: 1.4.4 | B33: Разборка водосточных ПВХ труб | C33: мп | E33: KRO | F33: 120 | G33: 138 | H33: =IF(OR(F33="",F33=0),"",MAX(F33,IF(ISNUMBER('Нормы и нормо-часы'!K34),ROUNDUP('Нормы и нормо-часы'!K34/(1-$F$3),0),0))) -> 160 | I33: =IF(OR(G33="",G33=0),"",MAX(G33,IF(ISNUMBER('Нормы и нормо-часы'!L34),ROUNDUP('Нормы и нормо-часы'!L34/(1-$F$3),0),0))) -> 191 | J33: =IF(OR(F33="",F33=0),"",H33/F33-1) -> 0.33333333 | K33: =IF(OR(G33="",G33=0),"",I33/G33-1) -> 0.38405797 | L33: 70 | M33: 80.5 | N33: =IF(OR(H33="",H33=0),"",(H33-L33)/H33) -> 0.5625 | O33: =IF(OR(I33="",I33=0),"",(I33-M33)/I33) -> 0.57853403 | P33: =IF(H33="","",H33-L33) -> 90 | Q33: =IF(I33="","",I33-M33) -> 110.5 | R33: 181.13 | S33: 244.53 | T33: =IF(OR(S33="",F33="",F33=0),"",S33/F33) -> 2.03775 | U33: аналог demontazh.spb.ru (ПВХ трубы 50 руб/мп) с учётом высоты | V33: Работа с вышки/альпинистами — отдельно
A34: 1.4.5 | B34: Разборка водосточных труб металлических | C34: мп | E34: KRO | F34: 150 | G34: 172 | H34: =IF(OR(F34="",F34=0),"",MAX(F34,IF(ISNUMBER('Нормы и нормо-часы'!K35),ROUNDUP('Нормы и нормо-часы'!K35/(1-$F$3),0),0))) -> 214 | I34: =IF(OR(G34="",G34=0),"",MAX(G34,IF(ISNUMBER('Нормы и нормо-часы'!L35),ROUNDUP('Нормы и нормо-часы'!L35/(1-$F$3),0),0))) -> 254 | J34: =IF(OR(F34="",F34=0),"",H34/F34-1) -> 0.42666667 | K34: =IF(OR(G34="",G34=0),"",I34/G34-1) -> 0.47674419 | L34: 90 | M34: 103 | N34: =IF(OR(H34="",H34=0),"",(H34-L34)/H34) -> 0.57943925 | O34: =IF(OR(I34="",I34=0),"",(I34-M34)/I34) -> 0.59448819 | P34: =IF(H34="","",H34-L34) -> 124 | Q34: =IF(I34="","",I34-M34) -> 151 | R34: 301.88 | S34: 407.54 | T34: =IF(OR(S34="",F34="",F34=0),"",S34/F34) -> 2.7169333 | U34: аналог 1.4.4
A35: 1.4.6 | B35: Разборка выравнивающих стяжек цементно-песчаных на кровле | C35: м3 | E35: KRO | F35: 6000 | G35: 6900 | H35: =IF(OR(F35="",F35=0),"",MAX(F35,IF(ISNUMBER('Нормы и нормо-часы'!K36),ROUNDUP('Нормы и нормо-часы'!K36/(1-$F$3),0),0))) -> 10134 | I35: =IF(OR(G35="",G35=0),"",MAX(G35,IF(ISNUMBER('Нормы и нормо-часы'!L36),ROUNDUP('Нормы и нормо-часы'!L36/(1-$F$3),0),0))) -> 12034 | J35: =IF(OR(F35="",F35=0),"",H35/F35-1) -> 0.689 | K35: =IF(OR(G35="",G35=0),"",I35/G35-1) -> 0.74405797 | L35: 3600 | M35: 4140 | N35: =IF(OR(H35="",H35=0),"",(H35-L35)/H35) -> 0.64476021 | O35: =IF(OR(I35="",I35=0),"",(I35-M35)/I35) -> 0.65597474 | P35: =IF(H35="","",H35-L35) -> 6534 | Q35: =IF(I35="","",I35-M35) -> 7894 | R35: 4612.65 | S35: 6227.08 | T35: =IF(OR(S35="",F35="",F35=0),"",S35/F35) -> 1.0378467 | U35: аналог stroygarant78.ru стяжка 50 мм 350 руб/м2 = 7000/м3 | V35: Включён спуск мусора с кровли вручную до 1 этажа
A36: 1.4.7 | B36: Разборка монолитных перекрытий бетонных | C36: м3 | E36: RAZ | F36: 8500 | G36: 9775 | H36: =IF(OR(F36="",F36=0),"",MAX(F36,IF(ISNUMBER('Нормы и нормо-часы'!K37),ROUNDUP('Нормы и нормо-часы'!K37/(1-$F$3),0),0))) -> 9534 | I36: =IF(OR(G36="",G36=0),"",MAX(G36,IF(ISNUMBER('Нормы и нормо-часы'!L37),ROUNDUP('Нормы и нормо-часы'!L37/(1-$F$3),0),0))) -> 11440 | J36: =IF(OR(F36="",F36=0),"",H36/F36-1) -> 0.12164706 | K36: =IF(OR(G36="",G36=0),"",I36/G36-1) -> 0.17033248 | L36: 5100 | M36: 5865 | N36: =IF(OR(H36="",H36=0),"",(H36-L36)/H36) -> 0.46507237 | O36: =IF(OR(I36="",I36=0),"",(I36-M36)/I36) -> 0.48732517 | P36: =IF(H36="","",H36-L36) -> 4434 | Q36: =IF(I36="","",I36-M36) -> 5575 | R36: 9750.56 | S36: 13163.26 | T36: =IF(OR(S36="",F36="",F36=0),"",S36/F36) -> 1.5486188 | U36: аналог zakazstroy.ru перекрытия от 1500 руб/м2; rezka-prof.ru гидроклин бетон 7000 | V36: Перекрытия в подразделе «кровля» — место позиции некорректно; ед. м3
A37: 1.4.8 | B37: Разборка монолитных перекрытий железобетонных | C37: м3 | E37: RAZ | F37: 11000 | G37: 13200 | H37: =IF(OR(F37="",F37=0),"",MAX(F37,IF(ISNUMBER('Нормы и нормо-часы'!K38),ROUNDUP('Нормы и нормо-часы'!K38/(1-$F$3),0),0))) -> 12467 | I37: =IF(OR(G37="",G37=0),"",MAX(G37,IF(ISNUMBER('Нормы и нормо-часы'!L38),ROUNDUP('Нормы и нормо-часы'!L38/(1-$F$3),0),0))) -> 14960 | J37: =IF(OR(F37="",F37=0),"",H37/F37-1) -> 0.13336364 | K37: =IF(OR(G37="",G37=0),"",I37/G37-1) -> 0.13333333 | L37: 6600 | M37: 7788 | N37: =IF(OR(H37="",H37=0),"",(H37-L37)/H37) -> 0.47060239 | O37: =IF(OR(I37="",I37=0),"",(I37-M37)/I37) -> 0.47941176 | P37: =IF(H37="","",H37-L37) -> 5867 | Q37: =IF(I37="","",I37-M37) -> 7172 | R37: 10958.06 | S37: 14793.38 | T37: =IF(OR(S37="",F37="",F37=0),"",S37/F37) -> 1.3448527 | U37: аналог rezka-prof.ru гидроклин ж/б от 13500; zakazstroy.ru ж/б 8500
A38: 1.4.9 | B38: Разборка парапетных решеток | C38: мп | E38: KRO | F38: 250 | G38: 288 | H38: =IF(OR(F38="",F38=0),"",MAX(F38,IF(ISNUMBER('Нормы и нормо-часы'!K39),ROUNDUP('Нормы и нормо-часы'!K39/(1-$F$3),0),0))) -> 427 | I38: =IF(OR(G38="",G38=0),"",MAX(G38,IF(ISNUMBER('Нормы и нормо-часы'!L39),ROUNDUP('Нормы и нормо-часы'!L39/(1-$F$3),0),0))) -> 507 | J38: =IF(OR(F38="",F38=0),"",H38/F38-1) -> 0.708 | K38: =IF(OR(G38="",G38=0),"",I38/G38-1) -> 0.76041667 | L38: 150 | M38: 172 | N38: =IF(OR(H38="",H38=0),"",(H38-L38)/H38) -> 0.64871194 | O38: =IF(OR(I38="",I38=0),"",(I38-M38)/I38) -> 0.66074951 | P38: =IF(H38="","",H38-L38) -> 277 | Q38: =IF(I38="","",I38-M38) -> 335 | R38: 181.13 | S38: 244.53 | T38: =IF(OR(S38="",F38="",F38=0),"",S38/F38) -> 0.97812 | U38: аналог (ограждения кровли)
A39: 1.4.10 | B39: Разборка покрытий кровель из волнистых и полуволнистых асбестоцементных листов | C39: м2 | E39: KRO | F39: 220 | G39: 253 | H39: =IF(OR(F39="",F39=0),"",MAX(F39,IF(ISNUMBER('Нормы и нормо-часы'!K40),ROUNDUP('Нормы и нормо-часы'!K40/(1-$F$3),0),0))) -> 267 | I39: =IF(OR(G39="",G39=0),"",MAX(G39,IF(ISNUMBER('Нормы и нормо-часы'!L40),ROUNDUP('Нормы и нормо-часы'!L40/(1-$F$3),0),0))) -> 318 | J39: =IF(OR(F39="",F39=0),"",H39/F39-1) -> 0.21363636 | K39: =IF(OR(G39="",G39=0),"",I39/G39-1) -> 0.256917 | L39: 130 | M39: 150 | N39: =IF(OR(H39="",H39=0),"",(H39-L39)/H39) -> 0.51310861 | O39: =IF(OR(I39="",I39=0),"",(I39-M39)/I39) -> 0.52830189 | P39: =IF(H39="","",H39-L39) -> 137 | Q39: =IF(I39="","",I39-M39) -> 168 | R39: 206 | S39: 278.1 | T39: =IF(OR(S39="",F39="",F39=0),"",S39/F39) -> 1.2640909 | U39: аналог profi.ru (демонтаж шифера СПб), zakazstroy.ru | V39: Асбестосодержащие отходы — утилизация с паспортом отходов отдельно
A40: 1.4.11 | B40: Разборка покрытий кровель из листовой стали | C40: м2 | E40: KRO | F40: 150 | G40: 172 | H40: =IF(OR(F40="",F40=0),"",MAX(F40,IF(ISNUMBER('Нормы и нормо-часы'!K41),ROUNDUP('Нормы и нормо-часы'!K41/(1-$F$3),0),0))) -> 192 | I40: =IF(OR(G40="",G40=0),"",MAX(G40,IF(ISNUMBER('Нормы и нормо-часы'!L41),ROUNDUP('Нормы и нормо-часы'!L41/(1-$F$3),0),0))) -> 228 | J40: =IF(OR(F40="",F40=0),"",H40/F40-1) -> 0.28 | K40: =IF(OR(G40="",G40=0),"",I40/G40-1) -> 0.3255814 | L40: 90 | M40: 103 | N40: =IF(OR(H40="",H40=0),"",(H40-L40)/H40) -> 0.53125 | O40: =IF(OR(I40="",I40=0),"",(I40-M40)/I40) -> 0.54824561 | P40: =IF(H40="","",H40-L40) -> 102 | Q40: =IF(I40="","",I40-M40) -> 125 | R40: 123.47 | S40: 166.68 | T40: =IF(OR(S40="",F40="",F40=0),"",S40/F40) -> 1.1112 | U40: аналог прайсов кровли МСК (профлист 60–240)
...

Sheet Нормы и нормо-часы
A1: НОРМЫ ВРЕМЕНИ И СРАВНЕНИЕ: СДЕЛЬНАЯ РАСЦЕНКА vs ОПЛАТА ПО НОРМО-ЧАСАМ
A2: Норма = трудоёмкость, чел.-ч на единицу (ЕНиР / ВНиР / ГЭСН ×0,85 / нормы ТО / экспертно). Почасовая расценка = норма × ставка нормо-часа бригады нужной специальности (лист «Нормо-час по специальностям», жёлтые ячейки). Разница = (почасовая − сдельная) ÷ сдельная: минус — по нормо-часам дешевле, плюс — дешевле отдавать в расценку.
A3: Порог «равно», ± | C3: 0.1 | D3: Часов чистой работы в смене | G3: 7
A5: Артикул | B5: Вид работ | C5: Ед. изм. | D5: Код | E5: Специальность | F5: Норма, чел.-ч на ед. | G5: Основание нормы | H5: Выработка 1 чел. за смену, ед. | I5: Ставка бригады СПб, руб/нормо-ч | J5: Ставка бригады Мск, руб/нормо-ч | K5: Расценка по нормо-часам СПб | L5: Расценка по нормо-часам Мск | M5: Сдельная расценка бригады СПб (лист 1) | N5: Сдельная расценка бригады Мск (лист 1) | O5: Разница СПб, % | P5: Разница Мск, % | Q5: Выгоднее СПб | R5: Выгоднее Мск | S5: Сдельно бригада получает за нормо-час СПб | T5: Сдельно за нормо-час Мск | U5: Рынок СПб, руб/ед. | V5: Рынок Мск, руб/ед. | W5: Маржа по нормо-часам при РЫНОЧНОЙ цене СПб, % | X5: Маржа по нормо-часам при рыночной цене Мск, % | Y5: ЦЕНА НЕОСТРОЙ СПб (после подтяжки), руб/ед. | Z5: ЦЕНА НЕОСТРОЙ Мск (после подтяжки), руб/ед. | AA5: Цена НЕОСТРОЙ выше рынка СПб, % | AB5: Цена НЕОСТРОЙ выше рынка Мск, % | AC5: МАРЖА при оплате бригаде по нормо-часам СПб, % | AD5: МАРЖА при оплате по нормо-часам Мск, % | AE5: Маржа при сдельной оплате СПб, % | AF5: Маржа при сдельной оплате Мск, % | AG5: Маржа по нормо-часам СПб, руб/ед. | AH5: Маржа по нормо-часам Мск, руб/ед.
A6: 1.1 Демонтаж зданий, строений, сооружений
A7: 1.1.1 | B7: Разборка покрытий и оснований асфальтобетонных | C7: м3 | D7: BLG | E7: =INDEX('Нормо-час по специальностям'!$B$6:$B$26,MATCH(D7,'Нормо-час по специальностям'!$A$6:$A$26,0)) -> Дорожный рабочий / благоустройство | F7: 3.5 | G7: ЕНиР Е20-1 / Е27 (разборка асф. покрытия отбойными молотками) | H7: =IF(OR(F7="",F7=0),"",ROUND($G$3/F7,2)) -> 2 | I7: =INDEX('Нормо-час по специальностям'!$D$6:$D$26,MATCH(D7,'Нормо-час по специальностям'!$A$6:$A$26,0)) -> 650 | J7: =INDEX('Нормо-час по специальностям'!$E$6:$E$26,MATCH(D7,'Нормо-час по специальностям'!$A$6:$A$26,0)) -> 780 | K7: =IF(OR(F7="",F7=0,I7=0),"",ROUND(F7*I7,0)) -> 2275 | L7: =IF(OR(F7="",F7=0,J7=0),"",ROUND(F7*J7,0)) -> 2730 | M7: =Расценки!L6 -> 2100 | N7: =Расценки!M6 -> 2415 | O7: =IF(OR(K7="",M7="",M7=0),"",K7/M7-1) -> 0.083333333 | P7: =IF(OR(L7="",N7="",N7=0),"",L7/N7-1) -> 0.13043478 | Q7: =IF(O7="","—",IF(O7<-$C$3,"нормо-часы",IF(O7>$C$3,"расценка","равно"))) -> равно | R7: =IF(P7="","—",IF(P7<-$C$3,"нормо-часы",IF(P7>$C$3,"расценка","равно"))) -> расценка | S7: =IF(OR(F7="",F7=0,M7=""),"",ROUND(M7/F7,0)) -> 600 | T7: =IF(OR(F7="",F7=0,N7=""),"",ROUND(N7/F7,0)) -> 690 | U7: =Расценки!F6 -> 3500 | V7: =Расценки!G6 -> 4025 | W7: =IF(OR(K7="",U7="",U7=0),"",(U7-K7)/U7) -> 0.35 | X7: =IF(OR(L7="",V7="",V7=0),"",(V7-L7)/V7) -> 0.32173913 | Y7: =Расценки!H6 -> 3500 | Z7: =Расценки!I6 -> 4025 | AA7: =Расценки!J6 -> 0 | AB7: =Расценки!K6 -> 0 | AC7: =IF(OR(K7="",Y7="",Y7=0),"",(Y7-K7)/Y7) -> 0.35 | AD7: =IF(OR(L7="",Z7="",Z7=0),"",(Z7-L7)/Z7) -> 0.32173913 | AE7: =IF(OR(Y7="",Y7=0),"",(Y7-M7)/Y7) -> 0.4 | AF7: =IF(OR(Z7="",Z7=0),"",(Z7-N7)/Z7) -> 0.4 | AG7: =IF(OR(K7="",Y7=""),"",Y7-K7) -> 1225 | AH7: =IF(OR(L7="",Z7=""),"",Z7-L7) -> 1295
A8: 1.1.2 | B8: Демонтаж деревянных зданий и строений без сохранения годного материала | C8: м3 здания | D8: RAZ | E8: =INDEX('Нормо-час по специальностям'!$B$6:$B$26,MATCH(D8,'Нормо-час по специальностям'!$A$6:$A$26,0)) -> Разнорабочий / демонтажник | F8: 1.2 | G8: ГЭСНр 46-04 (разборка конструкций) ×0,85 | H8: =IF(OR(F8="",F8=0),"",ROUND($G$3/F8,2)) -> 5.83 | I8: =INDEX('Нормо-час по специальностям'!$D$6:$D$26,MATCH(D8,'Нормо-час по специальностям'!$A$6:$A$26,0)) -> 550 | J8: =INDEX('Нормо-час по специальностям'!$E$6:$E$26,MATCH(D8,'Нормо-час по специальностям'!$A$6:$A$26,0)) -> 660 | K8: =IF(OR(F8="",F8=0,I8=0),"",ROUND(F8*I8,0)) -> 660 | L8: =IF(OR(F8="",F8=0,J8=0),"",ROUND(F8*J8,0)) -> 792 | M8: =Расценки!L7 -> 600 | N8: =Расценки!M7 -> 768 | O8: =IF(OR(K8="",M8="",M8=0),"",K8/M8-1) -> 0.1 | P8: =IF(OR(L8="",N8="",N8=0),"",L8/N8-1) -> 0.03125 | Q8: =IF(O8="","—",IF(O8<-$C$3,"нормо-часы",IF(O8>$C$3,"расценка","равно"))) -> равно | R8: =IF(P8="","—",IF(P8<-$C$3,"нормо-часы",IF(P8>$C$3,"расценка","равно"))) -> равно | S8: =IF(OR(F8="",F8=0,M8=""),"",ROUND(M8/F8,0)) -> 500 | T8: =IF(OR(F8="",F8=0,N8=""),"",ROUND(N8/F8,0)) -> 640 | U8: =Расценки!F7 -> 1000 | V8: =Расценки!G7 -> 1300 | W8: =IF(OR(K8="",U8="",U8=0),"",(U8-K8)/U8) -> 0.34 | X8: =IF(OR(L8="",V8="",V8=0),"",(V8-L8)/V8) -> 0.39076923 | Y8: =Расценки!H7 -> 1000 | Z8: =Расценки!I7 -> 1300 | AA8: =Расценки!J7 -> 0 | AB8: =Расценки!K7 -> 0 | AC8: =IF(OR(K8="",Y8="",Y8=0),"",(Y8-K8)/Y8) -> 0.34 | AD8: =IF(OR(L8="",Z8="",Z8=0),"",(Z8-L8)/Z8) -> 0.39076923 | AE8: =IF(OR(Y8="",Y8=0),"",(Y8-M8)/Y8) -> 0.4 | AF8: =IF(OR(Z8="",Z8=0),"",(Z8-N8)/Z8) -> 0.40923077 | AG8: =IF(OR(K8="",Y8=""),"",Y8-K8) -> 340 | AH8: =IF(OR(L8="",Z8=""),"",Z8-L8) -> 508
A9: 1.1.3 | B9: Демонтаж зданий и строений из металлоконструкций без сохранения годного материала | C9: т | D9: SVA | E9: =INDEX('Нормо-час по специальностям'!$B$6:$B$26,MATCH(D9,'Нормо-час по специальностям'!$A$6:$A$26,0)) -> Сварщик / монтажник МК | F9: 10 | G9: ЕНиР Е5 (демонтаж МК ≈0,6–0,7 от монтажа) | H9: =IF(OR(F9="",F9=0),"",ROUND($G$3/F9,2)) -> 0.7 | I9: =INDEX('Нормо-час по специальностям'!$D$6:$D$26,MATCH(D9,'Нормо-час по специальностям'!$A$6:$A$26,0)) -> 900 | J9: =INDEX('Нормо-час по специальностям'!$E$6:$E$26,MATCH(D9,'Нормо-час по специальностям'!$A$6:$A$26,0)) -> 1080 | K9: =IF(OR(F9="",F9=0,I9=0),"",ROUND(F9*I9,0)) -> 9000 | L9: =IF(OR(F9="",F9=0,J9=0),"",ROUND(F9*J9,0)) -> 10800 | M9: =Расценки!L8 -> 3900 | N9: =Расценки!M8 -> 4485 | O9: =IF(OR(K9="",M9="",M9=0),"",K9/M9-1) -> 1.3076923 | P9: =IF(OR(L9="",N9="",N9=0),"",L9/N9-1) -> 1.4080268 | Q9: =IF(O9="","—",IF(O9<-$C$3,"нормо-часы",IF(O9>$C$3,"расценка","равно"))) -> расценка | R9: =IF(P9="","—",IF(P9<-$C$3,"нормо-часы",IF(P9>$C$3,"расценка","равно"))) -> расценка | S9: =IF(OR(F9="",F9=0,M9=""),"",ROUND(M9/F9,0)) -> 390 | T9: =IF(OR(F9="",F9=0,N9=""),"",ROUND(N9/F9,0)) -> 449 | U9: =Расценки!F8 -> 6500 | V9: =Расценки!G8 -> 7475 | W9: =IF(OR(K9="",U9="",U9=0),"",(U9-K9)/U9) -> -0.38461538 | X9: =IF(OR(L9="",V9="",V9=0),"",(V9-L9)/V9) -> -0.44481605 | Y9: =Расценки!H8 -> 12000 | Z9: =Расценки!I8 -> 14400 | AA9: =Расценки!J8 -> 0.84615385 | AB9: =Расценки!K8 -> 0.9264214 | AC9: =IF(OR(K9="",Y9="",Y9=0),"",(Y9-K9)/Y9) -> 0.25 | AD9: =IF(OR(L9="",Z9="",Z9=0),"",(Z9-L9)/Z9) -> 0.25 | AE9: =IF(OR(Y9="",Y9=0),"",(Y9-M9)/Y9) -> 0.675 | AF9: =IF(OR(Z9="",Z9=0),"",(Z9-N9)/Z9) -> 0.68854167 | AG9: =IF(OR(K9="",Y9=""),"",Y9-K9) -> 3000 | AH9: =IF(OR(L9="",Z9=""),"",Z9-L9) -> 3600
A10: 1.1.4 | B10: Демонтаж каменных зданий и строений (кирпич, бетон, железобетон) комплексная работа с сохранением годного материала | C10: м3 | D10: RAZ | E10: =INDEX('Нормо-час по специальностям'!$B$6:$B$26,MATCH(D10,'Нормо-час по специальностям'!$A$6:$A$26,0)) -> Разнорабочий / демонтажник | F10: 6.5 | G10: ГЭСНр 46-04 (разборка конструкций) ×0,85 | H10: =IF(OR(F10="",F10=0),"",ROUND($G$3/F10,2)) -> 1.08 | I10: =INDEX('Нормо-час по специальностям'!$D$6:$D$26,MATCH(D10,'Нормо-час по специальностям'!$A$6:$A$26,0)) -> 550 | J10: =INDEX('Нормо-час по специальностям'!$E$6:$E$26,MATCH(D10,'Нормо-час по специальностям'!$A$6:$A$26,0)) -> 660 | K10: =IF(OR(F10="",F10=0,I10=0),"",ROUND(F10*I10,0)) -> 3575 | L10: =IF(OR(F10="",F10=0,J10=0),"",ROUND(F10*J10,0)) -> 4290 | M10: =Расценки!L9 -> 2500 | N10: =Расценки!M9 -> 2875 | O10: =IF(OR(K10="",M10="",M10=0),"",K10/M10-1) -> 0.43 | P10: =IF(OR(L10="",N10="",N10=0),"",L10/N10-1) -> 0.49217391 | Q10: =IF(O10="","—",IF(O10<-$C$3,"нормо-часы",IF(O10>$C$3,"расценка","равно"))) -> расценка | R10: =IF(P10="","—",IF(P10<-$C$3,"нормо-часы",IF(P10>$C$3,"расценка","равно"))) -> расценка | S10: =IF(OR(F10="",F10=0,M10=""),"",ROUND(M10/F10,0)) -> 385 | T10: =IF(OR(F10="",F10=0,N10=""),"",ROUND(N10/F10,0)) -> 442 | U10: =Расценки!F9 -> 4200 | V10: =Расценки!G9 -> 4830 | W10: =IF(OR(K10="",U10="",U10=0),"",(U10-K10)/U10) -> 0.14880952 | X10: =IF(OR(L10="",V10="",V10=0),"",(V10-L10)/V10) -> 0.11180124 | Y10: =Расценки!H9 -> 4767 | Z10: =Расценки!I9 -> 5720 | AA10: =Расценки!J9 -> 0.135 | AB10: =Расценки!K9 -> 0.18426501 | AC10: =IF(OR(K10="",Y10="",Y10=0),"",(Y10-K10)/Y10) -> 0.25005244 | AD10: =IF(OR(L10="",Z10="",Z10=0),"",(Z10-L10)/Z10) -> 0.25 | AE10: =IF(OR(Y10="",Y10=0),"",(Y10-M10)/Y10) -> 0.47556115 | AF10: =IF(OR(Z10="",Z10=0),"",(Z10-N10)/Z10) -> 0.49737762 | AG10: =IF(OR(K10="",Y10=""),"",Y10-K10) -> 1192 | AH10: =IF(OR(L10="",Z10=""),"",Z10-L10) -> 1430
A11: 1.1.5 | B11: Разборка бортовых камней с сохранением камня пригодного для дальнейшего использования | C11: мп | D11: BLG | E11: =INDEX('Нормо-час по специальностям'!$B$6:$B$26,MATCH(D11,'Нормо-час по специальностям'!$A$6:$A$26,0)) -> Дорожный рабочий / благоустройство | F11: 0.35 | G11: ЕНиР Е27 (бортовые камни, разборка) | H11: =IF(OR(F11="",F11=0),"",ROUND($G$3/F11,2)) -> 20 | I11: =INDEX('Нормо-час по специальностям'!$D$6:$D$26,MATCH(D11,'Нормо-час по специальностям'!$A$6:$A$26,0)) -> 650 | J11: =INDEX('Нормо-час по специальностям'!$E$6:$E$26,MATCH(D11,'Нормо-час по специальностям'!$A$6:$A$26,0)) -> 780 | K11: =IF(OR(F11="",F11=0,I11=0),"",ROUND(F11*I11,0)) -> 228 | L11: =IF(OR(F11="",F11=0,J11=0),"",ROUND(F11*J11,0)) -> 273 | M11: =Расценки!L10 -> 200 | N11: =Расценки!M10 -> 230 | O11: =IF(OR(K11="",M11="",M11=0),"",K11/M11-1) -> 0.14 | P11: =IF(OR(L11="",N11="",N11=0),"",L11/N11-1) -> 0.18695652 | Q11: =IF(O11="","—",IF(O11<-$C$3,"нормо-часы",IF(O11>$C$3,"расценка","равно"))) -> расценка | R11: =IF(P11="","—",IF(P11<-$C$3,"нормо-часы",IF(P11>$C$3,"расценка","равно"))) -> расценка | S11: =IF(OR(F11="",F11=0,M11=""),"",ROUND(M11/F11,0)) -> 571 | T11: =IF(OR(F11="",F11=0,N11=""),"",ROUND(N11/F11,0)) -> 657 | U11: =Расценки!F10 -> 350 | V11: =Расценки!G10 -> 402 | W11: =IF(OR(K11="",U11="",U11=0),"",(U11-K11)/U11) -> 0.34857143 | X11: =IF(OR(L11="",V11="",V11=0),"",(V11-L11)/V11) -> 0.32089552 | Y11: =Расценки!H10 -> 350 | Z11: =Расценки!I10 -> 402 | AA11: =Расценки!J10 -> 0 | AB11: =Расценки!K10 -> 0 | AC11: =IF(OR(K11="",Y11="",Y11=0),"",(Y11-K11)/Y11) -> 0.34857143 | AD11: =IF(OR(L11="",Z11="",Z11=0),"",(Z11-L11)/Z11) -> 0.32089552 | AE11: =IF(OR(Y11="",Y11=0),"",(Y11-M11)/Y11) -> 0.42857143 | AF11: =IF(OR(Z11="",Z11=0),"",(Z11-N11)/Z11) -> 0.4278607 | AG11: =IF(OR(K11="",Y11=""),"",Y11-K11) -> 122 | AH11: =IF(OR(L11="",Z11=""),"",Z11-L11) -> 129
A12: 1.1.6 | B12: Разборка тротуаров и дорожек из плит бетонных, брусчатки с сохранением пригодных для дальнейшего использования | C12: м2 | D12: BLG | E12: =INDEX('Нормо-час по специальностям'!$B$6:$B$26,MATCH(D12,'Нормо-час по специальностям'!$A$6:$A$26,0)) -> Дорожный рабочий / благоустройство | F12: 0.3 | G12: ЕНиР Е27 / Е20-1 | H12: =IF(OR(F12="",F12=0),"",ROUND($G$3/F12,2)) -> 23.33 | I12: =INDEX('Нормо-час по специальностям'!$D$6:$D$26,MATCH(D12,'Нормо-час по специальностям'!$A$6:$A$26,0)) -> 650 | J12: =INDEX('Нормо-час по специальностям'!$E$6:$E$26,MATCH(D12,'Нормо-час по специальностям'!$A$6:$A$26,0)) -> 780 | K12: =IF(OR(F12="",F12=0,I12=0),"",ROUND(F12*I12,0)) -> 195 | L12: =IF(OR(F12="",F12=0,J12=0),"",ROUND(F12*J12,0)) -> 234 | M12: =Расценки!L11 -> 150 | N12: =Расценки!M11 -> 172 | O12: =IF(OR(K12="",M12="",M12=0),"",K12/M12-1) -> 0.3 | P12: =IF(OR(L12="",N12="",N12=0),"",L12/N12-1) -> 0.36046512 | Q12: =IF(O12="","—",IF(O12<-$C$3,"нормо-часы",IF(O12>$C$3,"расценка","равно"))) -> расценка | R12: =IF(P12="","—",IF(P12<-$C$3,"нормо-часы",IF(P12>$C$3,"расценка","равно"))) -> расценка | S12: =IF(OR(F12="",F12=0,M12=""),"",ROUND(M12/F12,0)) -> 500 | T12: =IF(OR(F12="",F12=0,N12=""),"",ROUND(N12/F12,0)) -> 573 | U12: =Расценки!F11 -> 250 | V12: =Расценки!G11 -> 288 | W12: =IF(OR(K12="",U12="",U12=0),"",(U12-K12)/U12) -> 0.22 | X12: =IF(OR(L12="",V12="",V12=0),"",(V12-L12)/V12) -> 0.1875 | Y12: =Расценки!H11 -> 260 | Z12: =Расценки!I11 -> 312 | AA12: =Расценки!J11 -> 0.04 | AB12: =Расценки!K11 -> 0.083333333 | AC12: =IF(OR(K12="",Y12="",Y12=0),"",(Y12-K12)/Y12) -> 0.25 | AD12: =IF(OR(L12="",Z12="",Z12=0),"",(Z12-L12)/Z12) -> 0.25 | AE12: =IF(OR(Y12="",Y12=0),"",(Y12-M12)/Y12) -> 0.42307692 | AF12: =IF(OR(Z12="",Z12=0),"",(Z12-N12)/Z12) -> 0.44871795 | AG12: =IF(OR(K12="",Y12=""),"",Y12-K12) -> 65 | AH12: =IF(OR(L12="",Z12=""),"",Z12-L12) -> 78
A13: 1.1.N1 | B13: Разборка асфальтобетонного покрытия толщиной до 5 см отбойными молотками | C13: м2 | D13: BLG | E13: =INDEX('Нормо-час по специальностям'!$B$6:$B$26,MATCH(D13,'Нормо-час по специальностям'!$A$6:$A$26,0)) -> Дорожный рабочий / благоустройство | F13: 0.2 | G13: ЕНиР Е27 / Е20-1 | H13: =IF(OR(F13="",F13=0),"",ROUND($G$3/F13,2)) -> 35 | I13: =INDEX('Нормо-час по специальностям'!$D$6:$D$26,MATCH(D13,'Нормо-час по специальностям'!$A$6:$A$26,0)) -> 650 | J13: =INDEX('Нормо-час по специальностям'!$E$6:$E$26,MATCH(D13,'Нормо-час по специальностям'!$A$6:$A$26,0)) -> 780 | K13: =IF(OR(F13="",F13=0,I13=0),"",ROUND(F13*I13,0)) -> 130 | L13: =IF(OR(F13="",F13=0,J13=0),"",ROUND(F13*J13,0)) -> 156 | M13: =Расценки!L12 -> 120 | N13: =Расценки!M12 -> 138 | O13: =IF(OR(K13="",M13="",M13=0),"",K13/M13-1) -> 0.083333333 | P13: =IF(OR(L13="",N13="",N13=0),"",L13/N13-1) -> 0.13043478 | Q13: =IF(O13="","—",IF(O13<-$C$3,"нормо-часы",IF(O13>$C$3,"расценка","равно"))) -> равно | R13: =IF(P13="","—",IF(P13<-$C$3,"нормо-часы",IF(P13>$C$3,"расценка","равно"))) -> расценка | S13: =IF(OR(F13="",F13=0,M13=""),"",ROUND(M13/F13,0)) -> 600 | T13: =IF(OR(F13="",F13=0,N13=""),"",ROUND(N13/F13,0)) -> 690 | U13: =Расценки!F12 -> 200 | V13: =Расценки!G12 -> 230 | W13: =IF(OR(K13="",U13="",U13=0),"",(U13-K13)/U13) -> 0.35 | X13: =IF(OR(L13="",V13="",V13=0),"",(V13-L13)/V13) -> 0.32173913 | Y13: =Расценки!H12 -> 200 | Z13: =Расценки!I12 -> 230 | AA13: =Расценки!J12 -> 0 | AB13: =Расценки!K12 -> 0 | AC13: =IF(OR(K13="",Y13="",Y13=0),"",(Y13-K13)/Y13) -> 0.35 | AD13: =IF(OR(L13="",Z13="",Z13=0),"",(Z13-L13)/Z13) -> 0.32173913 | AE13: =IF(OR(Y13="",Y13=0),"",(Y13-M13)/Y13) -> 0.4 | AF13: =IF(OR(Z13="",Z13=0),"",(Z13-N13)/Z13) -> 0.4 | AG13: =IF(OR(K13="",Y13=""),"",Y13-K13) -> 70 | AH13: =IF(OR(L13="",Z13=""),"",Z13-L13) -> 74
A14: 1.1.N2 | B14: Демонтаж бетонных дорожных плит (ПАГ, 2П) с погрузкой | C14: м2 | D14: BLG | E14: =INDEX('Нормо-час по специальностям'!$B$6:$B$26,MATCH(D14,'Нормо-час по специальностям'!$A$6:$A$26,0)) -> Дорожный рабочий / благоустройство | F14: 0.25 | G14: ЕНиР Е27 | H14: =IF(OR(F14="",F14=0),"",ROUND($G$3/F14,2)) -> 28 | I14: =INDEX('Нормо-час по специальностям'!$D$6:$D$26,MATCH(D14,'Нормо-час по специальностям'!$A$6:$A$26,0)) -> 650 | J14: =INDEX('Нормо-час по специальностям'!$E$6:$E$26,MATCH(D14,'Нормо-час по специальностям'!$A$6:$A$26,0)) -> 780 | K14: =IF(OR(F14="",F14=0,I14=0),"",ROUND(F14*I14,0)) -> 163 | L14: =IF(OR(F14="",F14=0,J14=0),"",ROUND(F14*J14,0)) -> 195 | M14: =Расценки!L13 -> 280 | N14: =Расценки!M13 -> 322 | O14: =IF(OR(K14="",M14="",M14=0),"",K14/M14-1) -> -0.41785714 | P14: =IF(OR(L14="",N14="",N14=0),"",L14/N14-1) -> -0.39440994 | Q14: =IF(O14="","—",IF(O14<-$C$3,"нормо-часы",IF(O14>$C$3,"расценка","равно"))) -> нормо-часы | R14: =IF(P14="","—",IF(P14<-$C$3,"нормо-часы",IF(P14>$C$3,"расценка","равно"))) -> нормо-часы | S14: =IF(OR(F14="",F14=0,M14=""),"",ROUND(M14/F14,0)) -> 1120 | T14: =IF(OR(F14="",F14=0,N14=""),"",ROUND(N14/F14,0)) -> 1288 | U14: =Расценки!F13 -> 460 | V14: =Расценки!G13 -> 529 | W14: =IF(OR(K14="",U14="",U14=0),"",(U14-K14)/U14) -> 0.64565217 | X14: =IF(OR(L14="",V14="",V14=0),"",(V14-L14)/V14) -> 0.63137996 | Y14: =Расценки!H13 -> 460 | Z14: =Расценки!I13 -> 529 | AA14: =Расценки!J13 -> 0 | AB14: =Расценки!K13 -> 0 | AC14: =IF(OR(K14="",Y14="",Y14=0),"",(Y14-K14)/Y14) -> 0.64565217 | AD14: =IF(OR(L14="",Z14="",Z14=0),"",(Z14-L14)/Z14) -> 0.63137996 | AE14: =IF(OR(Y14="",Y14=0),"",(Y14-M14)/Y14) -> 0.39130435 | AF14: =IF(OR(Z14="",Z14=0),"",(Z14-N14)/Z14) -> 0.39130435 | AG14: =IF(OR(K14="",Y14=""),"",Y14-K14) -> 297 | AH14: =IF(OR(L14="",Z14=""),"",Z14-L14) -> 334
A15: 1.1.N3 | B15: Демонтаж ограждения из сетки/профлиста со стойками | C15: мп | D15: SVA | E15: =INDEX('Нормо-час по специальностям'!$B$6:$B$26,MATCH(D15,'Нормо-час по специальностям'!$A$6:$A$26,0)) -> Сварщик / монтажник МК | F15: 0.4 | G15: ГЭСНр 46-04 (разборка конструкций) ×0,85 | H15: =IF(OR(F15="",F15=0),"",ROUND($G$3/F15,2)) -> 17.5 | I15: =INDEX('Нормо-час по специальностям'!$D$6:$D$26,MATCH(D15,'Нормо-час по специальностям'!$A$6:$A$26,0)) -> 900 | J15: =INDEX('Нормо-час по специальностям'!$E$6:$E$26,MATCH(D15,'Нормо-час по специальностям'!$A$6:$A$26,0)) -> 1080 | K15: =IF(OR(F15="",F15=0,I15=0),"",ROUND(F15*I15,0)) -> 360 | L15: =IF(OR(F15="",F15=0,J15=0),"",ROUND(F15*J15,0)) -> 432 | M15: =Расценки!L14 -> 180 | N15: =Расценки!M14 -> 207 | O15: =IF(OR(K15="",M15="",M15=0),"",K15/M15-1) -> 1 | P15: =IF(OR(L15="",N15="",N15=0),"",L15/N15-1) -> 1.0869565 | Q15: =IF(O15="","—",IF(O15<-$C$3,"нормо-часы",IF(O15>$C$3,"расценка","равно"))) -> расценка | R15: =IF(P15="","—",IF(P15<-$C$3,"нормо-часы",IF(P15>$C$3,"расценка","равно"))) -> расценка | S15: =IF(OR(F15="",F15=0,M15=""),"",ROUND(M15/F15,0)) -> 450 | T15: =IF(OR(F15="",F15=0,N15=""),"",ROUND(N15/F15,0)) -> 518 | U15: =Расценки!F14 -> 300 | V15: =Расценки!G14 -> 345 | W15: =IF(OR(K15="",U15="",U15=0),"",(U15-K15)/U15) -> -0.2 | X15: =IF(OR(L15="",V15="",V15=0),"",(V15-L15)/V15) -> -0.25217391 | Y15: =Расценки!H14 -> 480 | Z15: =Расценки!I14 -> 576 | AA15: =Расценки!J14 -> 0.6 | AB15: =Расценки!K14 -> 0.66956522 | AC15: =IF(OR(K15="",Y15="",Y15=0),"",(Y15-K15)/Y15) -> 0.25 | AD15: =IF(OR(L15="",Z15="",Z15=0),"",(Z15-L15)/Z15) -> 0.25 | AE15: =IF(OR(Y15="",Y15=0),"",(Y15-M15)/Y15) -> 0.625 | AF15: =IF(OR(Z15="",Z15=0),"",(Z15-N15)/Z15) -> 0.640625 | AG15: =IF(OR(K15="",Y15=""),"",Y15-K15) -> 120 | AH15: =IF(OR(L15="",Z15=""),"",Z15-L15) -> 144
A16: 1.2 Демонтажные работы по фасаду
A17: 1.2.1 | B17: Отбивка штукатурки с поверхностей стен | C17: м2 | D17: RAZ | E17: =INDEX('Нормо-час по специальностям'!$B$6:$B$26,MATCH(D17,'Нормо-час по специальностям'!$A$6:$A$26,0)) -> Разнорабочий / демонтажник | F17: 0.35 | G17: ЕНиР Е20-1 (разборка конструкций при ремонте) | H17: =IF(OR(F17="",F17=0),"",ROUND($G$3/F17,2)) -> 20 | I17: =INDEX('Нормо-час по специальностям'!$D$6:$D$26,MATCH(D17,'Нормо-час по специальностям'!$A$6:$A$26,0)) -> 550 | J17: =INDEX('Нормо-час по специальностям'!$E$6:$E$26,MATCH(D17,'Нормо-час по специальностям'!$A$6:$A$26,0)) -> 660 | K17: =IF(OR(F17="",F17=0,I17=0),"",ROUND(F17*I17,0)) -> 193 | L17: =IF(OR(F17="",F17=0,J17=0),"",ROUND(F17*J17,0)) -> 231 | M17: =Расценки!L16 -> 180 | N17: =Расценки!M16 -> 207 | O17: =IF(OR(K17="",M17="",M17=0),"",K17/M17-1) -> 0.072222222 | P17: =IF(OR(L17="",N17="",N17=0),"",L17/N17-1) -> 0.11594203 | Q17: =IF(O17="","—",IF(O17<-$C$3,"нормо-часы",IF(O17>$C$3,"расценка","равно"))) -> равно | R17: =IF(P17="","—",IF(P17<-$C$3,"нормо-часы",IF(P17>$C$3,"расценка","равно"))) -> расценка | S17: =IF(OR(F17="",F17=0,M17=""),"",ROUND(M17/F17,0)) -> 514 | T17: =IF(OR(F17="",F17=0,N17=""),"",ROUND(N17/F17,0)) -> 591 | U17: =Расценки!F16 -> 300 | V17: =Расценки!G16 -> 345 | W17: =IF(OR(K17="",U17="",U17=0),"",(U17-K17)/U17) -> 0.35666667 | X17: =IF(OR(L17="",V17="",V17=0),"",(V17-L17)/V17) -> 0.33043478 | Y17: =Расценки!H16 -> 300 | Z17: =Расценки!I16 -> 345 | AA17: =Расценки!J16 -> 0 | AB17: =Расценки!K16 -> 0 | AC17: =IF(OR(K17="",Y17="",Y17=0),"",(Y17-K17)/Y17) -> 0.35666667 | AD17: =IF(OR(L17="",Z17="",Z17=0),"",(Z17-L17)/Z17) -> 0.33043478 | AE17: =IF(OR(Y17="",Y17=0),"",(Y17-M17)/Y17) -> 0.4 | AF17: =IF(OR(Z17="",Z17=0),"",(Z17-N17)/Z17) -> 0.4 | AG17: =IF(OR(K17="",Y17=""),"",Y17-K17) -> 107 | AH17: =IF(OR(L17="",Z17=""),"",Z17-L17) -> 114
A18: 1.2.2 | B18: Демонтаж облицовки из профилированного листа без разборки каркаса | C18: м2 | D18: RAZ | E18: =INDEX('Нормо-час по специальностям'!$B$6:$B$26,MATCH(D18,'Нормо-час по специальностям'!$A$6:$A$26,0)) -> Разнорабочий / демонтажник | F18: 0.25 | G18: ГЭСНр 46-04 (разборка конструкций) ×0,85 | H18: =IF(OR(F18="",F18=0),"",ROUND($G$3/F18,2)) -> 28 | I18: =INDEX('Нормо-час по специальностям'!$D$6:$D$26,MATCH(D18,'Нормо-час по специальностям'!$A$6:$A$26,0)) -> 550 | J18: =INDEX('Нормо-час по специальностям'!$E$6:$E$26,MATCH(D18,'Нормо-час по специальностям'!$A$6:$A$26,0)) -> 660 | K18: =IF(OR(F18="",F18=0,I18=0),"",ROUND(F18*I18,0)) -> 138 | L18: =IF(OR(F18="",F18=0,J18=0),"",ROUND(F18*J18,0)) -> 165 | M18: =Расценки!L17 -> 150 | N18: =Расценки!M17 -> 172 | O18: =IF(OR(K18="",M18="",M18=0),"",K18/M18-1) -> -0.08 | P18: =IF(OR(L18="",N18="",N18=0),"",L18/N18-1) -> -0.040697674 | Q18: =IF(O18="","—",IF(O18<-$C$3,"нормо-часы",IF(O18>$C$3,"расценка","равно"))) -> равно | R18: =IF(P18="","—",IF(P18<-$C$3,"нормо-часы",IF(P18>$C$3,"расценка","равно"))) -> равно | S18: =IF(OR(F18="",F18=0,M18=""),"",ROUND(M18/F18,0)) -> 600 | T18: =IF(OR(F18="",F18=0,N18=""),"",ROUND(N18/F18,0)) -> 688 | U18: =Расценки!F17 -> 250 | V18: =Расценки!G17 -> 288 | W18: =IF(OR(K18="",U18="",U18=0),"",(U18-K18)/U18) -> 0.448 | X18: =IF(OR(L18="",V18="",V18=0),"",(V18-L18)/V18) -> 0.42708333 | Y18: =Расценки!H17 -> 250 | Z18: =Расценки!I17 -> 288 | AA18: =Расценки!J17 -> 0 | AB18: =Расценки!K17 -> 0 | AC18: =IF(OR(K18="",Y18="",Y18=0),"",(Y18-K18)/Y18) -> 0.448 | AD18: =IF(OR(L18="",Z18="",Z18=0),"",(Z18-L18)/Z18) -> 0.42708333 | AE18: =IF(OR(Y18="",Y18=0),"",(Y18-M18)/Y18) -> 0.4 | AF18: =IF(OR(Z18="",Z18=0),"",(Z18-N18)/Z18) -> 0.40277778 | AG18: =IF(OR(K18="",Y18=""),"",Y18-K18) -> 112 | AH18: =IF(OR(L18="",Z18=""),"",Z18-L18) -> 123
A19: 1.2.3 | B19: Демонтаж облицовки из профилированного листа с разборкой каркаса | C19: м2 | D19: RAZ | E19: =INDEX('Нормо-час по специальностям'!$B$6:$B$26,MATCH(D19,'Нормо-час по специальностям'!$A$6:$A$26,0)) -> Разнорабочий / демонтажник | F19: 0.4 | G19: ГЭСНр 46-04 (разборка конструкций) ×0,85 | H19: =IF(OR(F19="",F19=0),"",ROUND($G$3/F19,2)) -> 17.5 | I19: =INDEX('Нормо-час по специальностям'!$D$6:$D$26,MATCH(D19,'Нормо-час по специальностям'!$A$6:$A$26,0)) -> 550 | J19: =INDEX('Нормо-час по специальностям'!$E$6:$E$26,MATCH(D19,'Нормо-час по специальностям'!$A$6:$A$26,0)) -> 660 | K19: =IF(OR(F19="",F19=0,I19=0),"",ROUND(F19*I19,0)) -> 220 | L19: =IF(OR(F19="",F19=0,J19=0),"",ROUND(F19*J19,0)) -> 264 | M19: =Расценки!L18 -> 230 | N19: =Расценки!M18 -> 264 | O19: =IF(OR(K19="",M19="",M19=0),"",K19/M19-1) -> -0.043478261 | P19: =IF(OR(L19="",N19="",N19=0),"",L19/N19-1) -> 0 | Q19: =IF(O19="","—",IF(O19<-$C$3,"нормо-часы",IF(O19>$C$3,"расценка","равно"))) -> равно | R19: =IF(P19="","—",IF(P19<-$C$3,"нормо-часы",IF(P19>$C$3,"расценка","равно"))) -> равно | S19: =IF(OR(F19="",F19=0,M19=""),"",ROUND(M19/F19,0)) -> 575 | T19: =IF(OR(F19="",F19=0,N19=""),"",ROUND(N19/F19,0)) -> 660 | U19: =Расценки!F18 -> 380 | V19: =Расценки!G18 -> 437 | W19: =IF(OR(K19="",U19="",U19=0),"",(U19-K19)/U19) -> 0.42105263 | X19: =IF(OR(L19="",V19="",V19=0),"",(V19-L19)/V19) -> 0.39588101 | Y19: =Расценки!H18 -> 380 | Z19: =Расценки!I18 -> 437 | AA19: =Расценки!J18 -> 0 | AB19: =Расценки!K18 -> 0 | AC19: =IF(OR(K19="",Y19="",Y19=0),"",(Y19-K19)/Y19) -> 0.42105263 | AD19: =IF(OR(L19="",Z19="",Z19=0),"",(Z19-L19)/Z19) -> 0.39588101 | AE19: =IF(OR(Y19="",Y19=0),"",(Y19-M19)/Y19) -> 0.39473684 | AF19: =IF(OR(Z19="",Z19=0),"",(Z19-N19)/Z19) -> 0.39588101 | AG19: =IF(OR(K19="",Y19=""),"",Y19-K19) -> 160 | AH19: =IF(OR(L19="",Z19=""),"",Z19-L19) -> 173
A20: 1.2.4 | B20: Демонтаж ограждающих конструкций стен из многослойных панелей (сэндвич-панели) | C20: м2 | D20: KRO | E20: =INDEX('Нормо-час по специальностям'!$B$6:$B$26,MATCH(D20,'Нормо-час по специальностям'!$A$6:$A$26,0)) -> Кровельщик | F20: 0.45 | G20: ГЭСНр 46-04 (разборка конструкций) ×0,85 | H20: =IF(OR(F20="",F20=0),"",ROUND($G$3/F20,2)) -> 15.56 | I20: =INDEX('Нормо-час по специальностям'!$D$6:$D$26,MATCH(D20,'Нормо-час по специальностям'!$A$6:$A$26,0)) -> 800 | J20: =INDEX('Нормо-час по специальностям'!$E$6:$E$26,MATCH(D20,'Нормо-час по специальностям'!$A$6:$A$26,0)) -> 950 | K20: =IF(OR(F20="",F20=0,I20=0),"",ROUND(F20*I20,0)) -> 360 | L20: =IF(OR(F20="",F20=0,J20=0),"",ROUND(F20*J20,0)) -> 428 | M20: =Расценки!L19 -> 230 | N20: =Расценки!M19 -> 264 | O20: =IF(OR(K20="",M20="",M20=0),"",K20/M20-1) -> 0.56521739 | P20: =IF(OR(L20="",N20="",N20=0),"",L20/N20-1) -> 0.62121212 | Q20: =IF(O20="","—",IF(O20<-$C$3,"нормо-часы",IF(O20>$C$3,"расценка","равно"))) -> расценка | R20: =IF(P20="","—",IF(P20<-$C$3,"нормо-часы",IF(P20>$C$3,"расценка","равно"))) -> расценка | S20: =IF(OR(F20="",F20=0,M20=""),"",ROUND(M20/F20,0)) -> 511 | T20: =IF(OR(F20="",F20=0,N20=""),"",ROUND(N20/F20,0)) -> 587 | U20: =Расценки!F19 -> 380 | V20: =Расценки!G19 -> 437 | W20: =IF(OR(K20="",U20="",U20=0),"",(U20-K20)/U20) -> 0.052631579 | X20: =IF(OR(L20="",V20="",V20=0),"",(V20-L20)/V20) -> 0.020594966 | Y20: =Расценки!H19 -> 480 | Z20: =Расценки!I19 -> 571 | AA20: =Расценки!J19 -> 0.26315789 | AB20: =Расценки!K19 -> 0.30663616 | AC20: =IF(OR(K20="",Y20="",Y20=0),"",(Y20-K20)/Y20) -> 0.25 | AD20: =IF(OR(L20="",Z20="",Z20=0),"",(Z20-L20)/Z20) -> 0.25043783 | AE20: =IF(OR(Y20="",Y20=0),"",(Y20-M20)/Y20) -> 0.52083333 | AF20: =IF(OR(Z20="",Z20=0),"",(Z20-N20)/Z20) -> 0.53765324 | AG20: =IF(OR(K20="",Y20=""),"",Y20-K20) -> 120 | AH20: =IF(OR(L20="",Z20=""),"",Z20-L20) -> 143
A21: 1.2.5 | B21: Демонтаж ограждающих конструкций стен из панелей "Алюкобонд" и металлического каркаса | C21: м2 | D21: FAS | E21: =INDEX('Нормо-час по специальностям'!$B$6:$B$26,MATCH(D21,'Нормо-час по специальностям'!$A$6:$A$26,0)) -> Фасадчик / промальпинист | F21: 0.9 | G21: ГЭСНр 46-04 (разборка конструкций) ×0,85 | H21: =IF(OR(F21="",F21=0),"",ROUND($G$3/F21,2)) -> 7.78 | I21: =INDEX('Нормо-час по специальностям'!$D$6:$D$26,MATCH(D21,'Нормо-час по специальностям'!$A$6:$A$26,0)) -> 1100 | J21: =INDEX('Нормо-час по специальностям'!$E$6:$E$26,MATCH(D21,'Нормо-час по специальностям'!$A$6:$A$26,0)) -> 1300 | K21: =IF(OR(F21="",F21=0,I21=0),"",ROUND(F21*I21,0)) -> 990 | L21: =IF(OR(F21="",F21=0,J21=0),"",ROUND(F21*J21,0)) -> 1170 | M21: =Расценки!L20 -> 650 | N21: =Расценки!M20 -> 747 | O21: =IF(OR(K21="",M21="",M21=0),"",K21/M21-1) -> 0.52307692 | P21: =IF(OR(L21="",N21="",N21=0),"",L21/N21-1) -> 0.56626506 | Q21: =IF(O21="","—",IF(O21<-$C$3,"нормо-часы",IF(O21>$C$3,"расценка","равно"))) -> расценка | R21: =IF(P21="","—",IF(P21<-$C$3,"нормо-часы",IF(P21>$C$3,"расценка","равно"))) -> расценка | S21: =IF(OR(F21="",F21=0,M21=""),"",ROUND(M21/F21,0)) -> 722 | T21: =IF(OR(F21="",F21=0,N21=""),"",ROUND(N21/F21,0)) -> 830 | U21: =Расценки!F20 -> 1100 | V21: =Расценки!G20 -> 1265 | W21: =IF(OR(K21="",U21="",U21=0),"",(U21-K21)/U21) -> 0.1 | X21: =IF(OR(L21="",V21="",V21=0),"",(V21-L21)/V21) -> 0.075098814 | Y21: =Расценки!H20 -> 1320 | Z21: =Расценки!I20 -> 1560 | AA21: =Расценки!J20 -> 0.2 | AB21: =Расценки!K20 -> 0.23320158 | AC21: =IF(OR(K21="",Y21="",Y21=0),"",(Y21-K21)/Y21) -> 0.25 | AD21: =IF(OR(L21="",Z21="",Z21=0),"",(Z21-L21)/Z21) -> 0.25 | AE21: =IF(OR(Y21="",Y21=0),"",(Y21-M21)/Y21) -> 0.50757576 | AF21: =IF(OR(Z21="",Z21=0),"",(Z21-N21)/Z21) -> 0.52115385 | AG21: =IF(OR(K21="",Y21=""),"",Y21-K21) -> 330 | AH21: =IF(OR(L21="",Z21=""),"",Z21-L21) -> 390
A22: 1.2.6 | B22: Демонтаж теплоизоляционного слоя стен | C22: м2 | D22: RAZ | E22: =INDEX('Нормо-час по специальностям'!$B$6:$B$26,MATCH(D22,'Нормо-час по специальностям'!$A$6:$A$26,0)) -> Разнорабочий / демонтажник | F22: 0.2 | G22: ГЭСНр 46-04 (разборка конструкций) ×0,85 | H22: =IF(OR(F22="",F22=0),"",ROUND($G$3/F22,2)) -> 35 | I22: =INDEX('Нормо-час по специальностям'!$D$6:$D$26,MATCH(D22,'Нормо-час по специальностям'!$A$6:$A$26,0)) -> 550 | J22: =INDEX('Нормо-час по специальностям'!$E$6:$E$26,MATCH(D22,'Нормо-час по специальностям'!$A$6:$A$26,0)) -> 660 | K22: =IF(OR(F22="",F22=0,I22=0),"",ROUND(F22*I22,0)) -> 110 | L22: =IF(OR(F22="",F22=0,J22=0),"",ROUND(F22*J22,0)) -> 132 | M22: =Расценки!L21 -> 120 | N22: =Расценки!M21 -> 138 | O22: =IF(OR(K22="",M22="",M22=0),"",K22/M22-1) -> -0.083333333 | P22: =IF(OR(L22="",N22="",N22=0),"",L22/N22-1) -> -0.043478261 | Q22: =IF(O22="","—",IF(O22<-$C$3,"нормо-часы",IF(O22>$C$3,"расценка","равно"))) -> равно | R22: =IF(P22="","—",IF(P22<-$C$3,"нормо-часы",IF(P22>$C$3,"расценка","равно"))) -> равно | S22: =IF(OR(F22="",F22=0,M22=""),"",ROUND(M22/F22,0)) -> 600 | T22: =IF(OR(F22="",F22=0,N22=""),"",ROUND(N22/F22,0)) -> 690 | U22: =Расценки!F21 -> 200 | V22: =Расценки!G21 -> 230 | W22: =IF(OR(K22="",U22="",U22=0),"",(U22-K22)/U22) -> 0.45 | X22: =IF(OR(L22="",V22="",V22=0),"",(V22-L22)/V22) -> 0.42608696 | Y22: =Расценки!H21 -> 200 | Z22: =Расценки!I21 -> 230 | AA22: =Расценки!J21 -> 0 | AB22: =Расценки!K21 -> 0 | AC22: =IF(OR(K22="",Y22="",Y22=0),"",(Y22-K22)/Y22) -> 0.45 | AD22: =IF(OR(L22="",Z22="",Z22=0),"",(Z22-L22)/Z22) -> 0.42608696 | AE22: =IF(OR(Y22="",Y22=0),"",(Y22-M22)/Y22) -> 0.4 | AF22: =IF(OR(Z22="",Z22=0),"",(Z22-N22)/Z22) -> 0.4 | AG22: =IF(OR(K22="",Y22=""),"",Y22-K22) -> 90 | AH22: =IF(OR(L22="",Z22=""),"",Z22-L22) -> 98
