Workbook

Sheet Свод
B1: СВОД: ТО инженерных систем ЦФКСиЗ Невского района, 2027 (44-ФЗ)
B2: Внутренний документ НЕОСТРОЙ — заказчику не передавать. Все суммы без НДС, если не указано иное. Сценарий штата — Б (базовый).
B3: НМЦК с НДС | C3: ='Паспорт тендера'!B8 -> 24436767
B4: НМЦК без НДС | C4: =C3/1.22 -> 20030137
B5: Снижение от НМЦК в форме, % (ввод) | C5: 0
B7: Себестоимость по статьям | C7: руб/год | D7: доля | E7: руб/мес
B8: ФОТ персонала (сценарий Б) | C8: =Персонал!J17 -> 29085000 | D8: =C8/$C$14 -> 0.78462301 | E8: =C8/12 -> 2423750
B9: Работы субподрядом / лаборатории (тарификатор, колонка L) | C9: =Работы!N33 -> 1043980 | D9: =C9/$C$14 -> 0.028163339 | E9: =C9/12 -> 86998.333
B10: Расходники к работам субподряда (ELM/SAN/VEN/HOL 2 % к оплате бригаде) | C10: =C9*0.02 -> 20879.6 | D10: =C10/$C$14 -> 0.00056326679 | E10: =C10/12 -> 1739.9667
B11: Материалы и ЗИП (лимит 2,5 млн с НДС + приборы) | C11: =Материалы!J10 -> 2085513.9 | D11: =C11/$C$14 -> 0.05626069 | E11: =C11/12 -> 173792.82
B12: Затраты до косвенных финансовых и резервов (база для резервов) | C12: =SUM(C8:C11)+Косвенные!F20 -> 34396373
B13: Косвенные (вкл. БГ, финансирование, резервы) | C13: =Косвенные!F25 -> 4833384.1 | D13: =C13/$C$14 -> 0.1303897 | E13: =C13/12 -> 402782.01
B14: ПОЛНАЯ СЕБЕСТОИМОСТЬ | C14: =SUM(C8:C11)+C13 -> 37068758 | D14: =C14/$C$14 -> 1 | E14: =C14/12 -> 3089063.1
B16: Цена и результат
B17: КП с НДС (сумма формы «Расчёт стоимости услуг») | C17: ='Паспорт тендера'!F57 -> 24436767
B18: КП без НДС | C18: =C17/1.22 -> 20030137
B19: Наценка на с/с (КП/с/с − 1) | C19: =C18/C14-1 -> -0.45964909
B20: Маржа (1 − с/с/КП) | C20: =1-C14/C18 -> -0.85064923
B21: Прибыль / убыток, руб | C21: =C18-C14 -> -17038621
B22: КП к НМЦК | C22: =C18/C4-1 -> 0
B23: С/с к НМЦК без НДС | C23: =C14/C4 -> 1.8506492
B24: Проверка по типу тендера (44-ФЗ: наценка 15–30 %) | C24: =IF(C19<0,"УБЫТОК: с/с выше цены",IF(C19<0.15,"ниже 15 % — согласование ГД",IF(C19>0.3,"выше диапазона","в диапазоне"))) -> УБЫТОК: с/с выше цены
B25: Допустимое снижение = НМЦК − с/с × 1,15 (руб без НДС) | C25: =C4-C14*1.15 -> -22598934
B26: ВЫВОД | C26: =IF(C14>C4,"НЕ УЧАСТВОВАТЬ: с/с выше НМЦК; участие только в минус на "&TEXT(C14-C4,"# ##0")&" руб б/НДС (решение ГД)",IF(C25<0,"Участвовать только с согласования ГД (наценка < 15 % даже по НМЦК)","Участвовать; минимальная цена — с/с × 1,15")) -> НЕ УЧАСТВОВАТЬ: с/с выше НМЦК; участие только в минус на 17038 621 руб б/НДС (решение ГД)
B28: Сценарии цены | C28: КП б/НДС | D28: КП с НДС | E28: Наценка | F28: Маржа | G28: Прибыль, руб | H28: К НМЦК
B29: Базовый (цена формы) | C29: =C18 -> 20030137 | D29: =C29*1.22 -> 24436767 | E29: =C29/$C$14-1 -> -0.45964909 | F29: =1-$C$14/C29 -> -0.85064923 | G29: =C29-$C$14 -> -17038621 | H29: =C29/$C$4-1 -> 0
B30: Переторжка / снижение −5 % | C30: =C18*0.95 -> 19028630 | D30: =C30*1.22 -> 23214929 | E30: =C30/$C$14-1 -> -0.48666663 | F30: =1-$C$14/C30 -> -0.94805182 | G30: =C30-$C$14 -> -18040127 | H30: =C30/$C$4-1 -> -0.05
B31: Снижение −10 % | C31: =C18*0.9 -> 18027123 | D31: =C31*1.22 -> 21993090 | E31: =C31/$C$14-1 -> -0.51368418 | F31: =1-$C$14/C31 -> -1.0562769 | G31: =C31-$C$14 -> -19041634 | H31: =C31/$C$4-1 -> -0.1
B32: Минимальная цена (наценка 15 %) | C32: =C14*1.15 -> 42629071 | D32: =C32*1.22 -> 52007467 | E32: =C32/$C$14-1 -> 0.15 | F32: =1-$C$14/C32 -> 0.13043478 | G32: =C32-$C$14 -> 5560313.6 | H32: =C32/$C$4-1 -> 1.1282466
B33: Безубыточность (с/с) | C33: =C14 -> 37068758 | D33: =C33*1.22 -> 45223884 | E33: =C33/$C$14-1 -> 0 | F33: =1-$C$14/C33 -> 0 | G33: =C33-$C$14 -> 0 | H33: =C33/$C$4-1 -> 0.85064923
B35: Сценарии штата (остальные статьи — как в базовом) | C35: ФОТ/год | D35: Числ., чел | E35: С/с полная | F35: С/с к НМЦК б/НДС | G35: Убыток при цене = НМЦК | H35: Наценка при НМЦК
B36: А — минимальный (2 инженера, 2 поста) | C36: =Персонал!I17 -> 20265000 | D36: =Персонал!E18 -> 10.5 | E36: =($C$14-$C$8+C36)+(C36-$C$8)*0.04 -> 27895958 | F36: =E36/$C$4 -> 1.3926993 | G36: =$C$4-E36 -> -7865820.6 | H36: =$C$4/E36-1 -> -0.28196991
B37: Б — базовый (4 инженера, 3 поста) | C37: =Персонал!J17 -> 29085000 | D37: =Персонал!F18 -> 16.5 | E37: =($C$14-$C$8+C37)+(C37-$C$8)*0.04 -> 37068758 | F37: =E37/$C$4 -> 1.8506492 | G37: =$C$4-E37 -> -17038621 | H37: =$C$4/E37-1 -> -0.45964909
B38: В — буквально по ТЗ (4 инженера, 4 поста) | C38: =Персонал!K17 -> 35280000 | D38: =Персонал!G18 -> 21 | E38: =($C$14-$C$8+C38)+(C38-$C$8)*0.04 -> 43511558 | F38: =E38/$C$4 -> 2.1723045 | G38: =$C$4-E38 -> -23481421 | H38: =$C$4/E38-1 -> -0.53965939
B39: С/с сценариев А и В: ФОТ заменён, резервы 1 % + 3 % пересчитаны на разницу ФОТ (приближённо).
B41: Точка безубыточности по зарплате
B42: Допустимый ФОТ при цене = НМЦК (НМЦК − все прочие статьи, руб/год) | C42: =C4-(C14-C8) -> 12046379
B43: Средняя зарплата на руки, руб/мес при численности Б | C43: =C42/1.5/14/Персонал!F18 -> 34765.886
B44: Средняя зарплата на руки по сценарию Б (для сравнения) | C44: =Персонал!J17/1.5/14/Персонал!F18 -> 83939.394
B45: Средняя зарплата на руки при численности А (2 поста) | C45: =C42/1.5/14/Персонал!E18 -> 54632.106
...

Sheet Паспорт тендера
A1: ПАСПОРТ ТЕНДЕРА
A3: Заказчик | B3: СПб ГБУ «Центр физической культуры, спорта и здоровья Невского района» (ИНН 7811588192), 192148, СПб, Железнодорожный пр., д. 32, лит. А
A4: Контроль / размещение | B4: Администрация Невского района СПб; извещение от 14.10.2026; ИКЗ 262781158819278110100100220018110247
A5: Способ / закон | B5: Открытый конкурс в электронной форме, 44-ФЗ. Критерии: цена 60 %, квалификация 40 % (общая цена исполненных договоров ТО зданий с ТО инженерных систем)
A6: Предмет | B6: Техническое обслуживание и техническая эксплуатация систем инженерно-технического обеспечения зданий и сооружений ЦФКСиЗ Невского района (29 позиций, мес × 12)
A7: Объекты | B7: ул. Бабушкина 30 стр.1 (ФОК с 2 ледовыми аренами); Железнодорожный пр. 32 лит. А (ФОК) и гараж (кад. 78:12:0007127:3430); ИТП ул. Седова 55 к.2 и внеплощадочные теплосети; стадион с модульным зданием, пр. Обуховской Обороны (кад. 78:12:0007021:3303)
A8: НМЦК с НДС 22 %, руб. | B8: 24436767
A9: НМЦК без НДС, руб. | B9: =B8/1.22 -> 20030137
A10: Срок оказания услуг | B10: 01.01.2027 – 31.12.2027, круглосуточно
A11: Цена | B11: Твёрдая; оплата помесячно в течение 7 р.д. после подписания документа о приёмке (документ — до 3 р.д. после месяца, приёмка до 20 р.д.); декабрь — до 25.12.2027. Аванса нет
A12: Обеспечение заявки | B12: Не указано в извлечённых документах — проверить в извещении на ЭТП
A13: Обеспечение исполнения | B13: 10 % НМЦК = 2 443 676,71 руб. (БГ или деньги); антидемпинг ×1,5 при снижении ≥ 25 %
A14: Гарантия на услуги | B14: 3 месяца
A15: Материалы / ЗИП | B15: Запчасти и материалы для планового и аварийного ремонта — в цене, в пределах 2 500 000 руб. с НДС; закупает Исполнитель, ежемесячная справка-отчёт по рыночным ценам СПб (п. 4.5–4.7 ТЗ)
A16: Отходы | B16: Вывоз и утилизация отходов (лампы, аккумуляторы, нефтепродукты и т.п.) — за Исполнителем (п. 4.9)
A17: Требование к участнику (допуск) | B17: ПП РФ 2571, поз. 14: опыт исполненного договора на ТО зданий/сооружений ≥ 20 % НМЦК (≈ 4 887 353 руб.) за 5 лет; договор должен быть заключён по 44-ФЗ или 223-ФЗ
A18: СМП / СОНКО | B18: Обязательное привлечение субподрядчиков из СМП/СОНКО на 30 % цены контракта (если участник не СМП); штраф 5 % от объёма недопривлечения
A19: Штрафы | B19: 5 % цены контракта (цена 3–50 млн), за нестоимостные нарушения 5 000 руб.; пеня 1/300 ключевой ставки
A20: Персонал (Прил. 7 ТЗ) | B20: 5/2: инженер вентиляции (IV гр.), инженер ответственный за ТЭУ (А.1, Б.8.2), инженер холодильного оборудования ледовых арен (IV гр.), инженер КИПиА (IV гр.). Круглосуточно: оператор-диспетчер (профстандарт АДС), техник-оператор автоматики (III гр. + оператор диспетчерской лифтов), электромонтёр (IV гр.), слесарь-сантехник (аттест. ремонтный персонал ТЭУ). По необходимости: координатор, инженер ОТ/высота, 2 монтажника с вышкой, специалист сварочного производства, ответственные по ОПО
A21: Основное оборудование | B21: 2 холодильные машины МВ 570.37-Т (Эйркул) по 562,5 кВт, по 3 винтовых компрессора HSK 85 (R507A, 40 % этиленгликоль), конденсаторы Guntner, НТМ-модули с пластинчатыми теплообменниками; ~10 приточных и ~12 вытяжных установок, 4 осушителя RL-71R; сплит-системы К1–К6 (8 наружных / 15 внутренних блоков); 4 роллетных ворот Alutech + 1 секционные в гараже; 3 ИТП, УУТЭ Седова
... A24: Дата расчёта | B24: 28.10.2026
A26: Позиции формы «Расчёт стоимости услуг» (Прил. 2 к контракту)
A27: № | B27: Позиция | C27: НМЦК позиции, год, с НДС | D27: НМЦК, мес, с НДС | E27: Цена КП за мес с НДС (округл.) | F27: КП, год, с НДС
A28: 1 | B28: Техническое обслуживание и техническая эксплуатация систем, сетей инженерно-технического обеспечения их элементов, оборудования системы диспетчеризации здания по адресу: ул. Бабушкина д.30 стр.1 | C28: 1573188.7 | D28: =C28/12 -> 131099.06 | E28: =ROUND(D28*(1-Свод!$C$5),2) -> 131099.06 | F28: =ROUND(E28*12,2) -> 1573188.7
A29: 2 | B29: Техническое обслуживание и техническая эксплуатация систем, сетей инженерно-технического обеспечения их элементов, оборудования системы теплоснабжения (в т. ч. индивидуальный тепловой пункт (ИТП) здания, наружные сети между объектовой котельной и зданием) здания по адресу: ул. Бабушкина д.30 стр.1 | C29: 1518086.6 | D29: =C29/12 -> 126507.22 | E29: =ROUND(D29*(1-Свод!$C$5),2) -> 126507.22 | F29: =ROUND(E29*12,2) -> 1518086.6
A30: 3 | B30: Техническое обслуживание и техническая эксплуатация систем, сетей инженерно-технического обеспечения их элементов, оборудования системы холодного и горячего водоснабжения и водоотведения здания по адресу: ул. Бабушкина д.30 стр.1 | C30: 1623777.6 | D30: =C30/12 -> 135314.8 | E30: =ROUND(D30*(1-Свод!$C$5),2) -> 135314.8 | F30: =ROUND(E30*12,2) -> 1623777.6
A31: 4 | B31: Техническое обслуживание и техническая эксплуатация систем, сетей инженерно-технического обеспечения их элементов, оборудования наружных сетей водоснабжения и общесплавной канализации до границ балансовой принадлежности и эксплуатационной ответственности, в т. ч. ливневая канализация по адресу: ул. Бабушкина д.30 стр.1 | C31: 961652.04 | D31: =C31/12 -> 80137.67 | E31: =ROUND(D31*(1-Свод!$C$5),2) -> 80137.67 | F31: =ROUND(E31*12,2) -> 961652.04
A32: 5 | B32: Техническое обслуживание и техническая эксплуатация систем, сетей инженерно-технического обеспечения их элементов, оборудования системы внутреннего электроснабжения здания по адресу: ул. Бабушкина д.30 стр.1 | C32: 1535858.9 | D32: =C32/12 -> 127988.24 | E32: =ROUND(D32*(1-Свод!$C$5),2) -> 127988.24 | F32: =ROUND(E32*12,2) -> 1535858.9
A33: 6 | B33: Техническое обслуживание и техническая эксплуатация систем, сетей инженерно-технического обеспечения их элементов, оборудования сети наружного электроснабжения (наружные кабельные линии от РТП до ГРЩ здания) по адресу: ул. Бабушкина д. 30 стр.1 | C33: 1021352.2 | D33: =C33/12 -> 85112.68 | E33: =ROUND(D33*(1-Свод!$C$5),2) -> 85112.68 | F33: =ROUND(E33*12,2) -> 1021352.2
A34: 7 | B34: Техническое обслуживание и техническая эксплуатация систем, сетей инженерно-технического обеспечения их элементов, оборудования системы наружного освещения (в т. ч. архитектурная подсветка) по адресу: ул. Бабушкина д. 30 стр.1 | C34: 641695.92 | D34: =C34/12 -> 53474.66 | E34: =ROUND(D34*(1-Свод!$C$5),2) -> 53474.66 | F34: =ROUND(E34*12,2) -> 641695.92
A35: 8 | B35: Техническое обслуживание и техническая эксплуатация систем, сетей инженерно-технического обеспечения их элементов, оборудования автоматизированной системы холодоснабжения ледовых полей здания по адресу: ул. Бабушкина д. 30 стр.1 | C35: 5488637 | D35: =C35/12 -> 457386.42 | E35: =ROUND(D35*(1-Свод!$C$5),2) -> 457386.42 | F35: =ROUND(E35*12,2) -> 5488637
A36: 9 | B36: Техническое обслуживание и техническая эксплуатация систем, сетей инженерно-технического обеспечения их элементов, оборудования системы вентиляции, осушения и обогрева ледовых полей здания по адресу: ул. Бабушкина д. 30 стр.1 | C36: 992202.6 | D36: =C36/12 -> 82683.55 | E36: =ROUND(D36*(1-Свод!$C$5),2) -> 82683.55 | F36: =ROUND(E36*12,2) -> 992202.6
A37: 10 | B37: Техническое обслуживание и техническая эксплуатация систем, сетей инженерно-технического обеспечения их элементов, оборудования системы общеобменной вентиляции здания по адресу: ул. Бабушкина д. 30 стр.1 | C37: 949095.72 | D37: =C37/12 -> 79091.31 | E37: =ROUND(D37*(1-Свод!$C$5),2) -> 79091.31 | F37: =ROUND(E37*12,2) -> 949095.72
A38: 11 | B38: Техническое обслуживание и техническая эксплуатация систем, сетей инженерно-технического обеспечения их элементов, оборудования системы кондиционирования воздуха помещений здания по адресу: ул. Бабушкина д. 30 стр.1 | C38: 902414.4 | D38: =C38/12 -> 75201.2 | E38: =ROUND(D38*(1-Свод!$C$5),2) -> 75201.2 | F38: =ROUND(E38*12,2) -> 902414.4
A39: 12 | B39: Техническое обслуживание сбалансированных промышленных секционных ворот здания по адресу: ул. Бабушкина д. 30 стр.1 | C39: 292476.48 | D39: =C39/12 -> 24373.04 | E39: =ROUND(D39*(1-Свод!$C$5),2) -> 24373.04 | F39: =ROUND(E39*12,2) -> 292476.48
... A56: 29 | B56: Техническое обслуживание и техническая эксплуатация систем, сетей инженерно-технического обеспечения их элементов, оборудования сети наружного электроснабжения (наружные кабельные линии от КК до ВРУ модульного здания) по адресу: пр. Обуховской Обороны, кадастровый номер 78:12:0007021:3303 | C56: 208676.88 | D56: =C56/12 -> 17389.74 | E56: =ROUND(D56*(1-Свод!$C$5),2) -> 17389.74 | F56: =ROUND(E56*12,2) -> 208676.88
B57: Итого | C57: =SUM(C28:C56) -> 24436767 | F57: =SUM(F28:F56) -> 24436767

Sheet Персонал
A1: ПЕРСОНАЛ И ФОТ (на руки → ФОТ × 1,5; × 14/12 на отпуска/замены в годовом расчёте)
A2: Сценарии: А — минимальный (2 инженера с совмещением, 2 круглосуточных поста); Б — базовый (4 инженера, 3 поста: диспетчер = техник-оператор автоматики); В — буквально по ТЗ (4 поста, координатор 1,0).
A3: Коэф. ФОТ (налоги) | C3: 1.5 | D3: Коэф. отпусков (мес/год) | F3: 14
A5: № | B5: Должность / требование ТЗ | C5: График | D5: На руки, руб/мес | E5: Кол-во А | F5: Кол-во Б | G5: Кол-во В | H5: ФОТ/мес Б | I5: ФОТ/год А | J5: ФОТ/год Б | K5: ФОТ/год В | L5: Обоснование ставки (источники — лист «Цены (источники)»)
A6: 1 | B6: Инженер холодильного оборудования ледовых арен (IV гр. ЭБ), отв. за холодильную установку | C6: 5/2 | D6: 120000 | E6: 1 | F6: 1 | G6: 1 | H6: =D6*F6*$C$3 -> 180000 | I6: =D6*E6*$C$3*$F$3 -> 2520000 | J6: =D6*F6*$C$3*$F$3 -> 2520000 | K6: =D6*G6*$C$3*$F$3 -> 2520000 | L6: рынок 75–130 тыс. (Звёздный лёд от 75, Динамо от 80, EhS от 125, Зенит-Арена от 130); винтовые машины 562 кВт → 120
A7: 2 | B7: Инженер, ответственный за ТЭУ (А.1, Б.8.2 ОПО) | C7: 5/2 | D7: 110000 | E7: 1 | F7: 1 | G7: 1 | H7: =D7*F7*$C$3 -> 165000 | I7: =D7*E7*$C$3*$F$3 -> 2310000 | J7: =D7*F7*$C$3*$F$3 -> 2310000 | K7: =D7*G7*$C$3*$F$3 -> 2310000 | L7: рынок 100–140 тыс. (Миракс 110, Дивайс от 100, Газпром перераб. 100–140 до налогов)
A8: 3 | B8: Инженер по вентиляции (IV гр. ЭБ) | C8: 5/2 | D8: 95000 | E8: 0 | F8: 1 | G8: 1 | H8: =D8*F8*$C$3 -> 142500 | I8: =D8*E8*$C$3*$F$3 -> 0 | J8: =D8*F8*$C$3*$F$3 -> 1995000 | K8: =D8*G8*$C$3*$F$3 -> 1995000 | L8: оценка в коридоре инженеров ТО 90–110 тыс.; в сценарии А функции — у инженера ТЭУ
A9: 4 | B9: Инженер КИПиА (IV гр. ЭБ) | C9: 5/2 | D9: 105000 | E9: 0 | F9: 1 | G9: 1 | H9: =D9*F9*$C$3 -> 157500 | I9: =D9*E9*$C$3*$F$3 -> 0 | J9: =D9*F9*$C$3*$F$3 -> 2205000 | K9: =D9*G9*$C$3*$F$3 -> 2205000 | L9: рынок 96–106 (СПб ГБУ ДУОАН, до налогов), Кип-Хауз от 100; в сценарии А — у холодильщика
A10: 5 | B10: Оператор-диспетчер (профстандарт АДС, 4 ур.) | C10: 1/3 сутки | D10: 55000 | E10: 0 | F10: 0 | G10: 4 | H10: =D10*F10*$C$3 -> 0 | I10: =D10*E10*$C$3*$F$3 -> 0 | J10: =D10*F10*$C$3*$F$3 -> 0 | K10: =D10*G10*$C$3*$F$3 -> 4620000 | L10: рынок 35–52 тыс. (Fort Group, ТСБ, Vertical Hotels) → 55 с учётом ночей и квалификации
A11: 6 | B11: Техник-оператор автоматики (III гр. ЭБ + оператор диспетчерской лифтов); в сц. Б совмещает диспетчера | C11: 1/3 сутки | D11: 60000 | E11: 0 | F11: 4 | G11: 4 | H11: =D11*F11*$C$3 -> 360000 | I11: =D11*E11*$C$3*$F$3 -> 0 | J11: =D11*F11*$C$3*$F$3 -> 5040000 | K11: =D11*G11*$C$3*$F$3 -> 5040000 | L11: диспетчер 35–52 + доплата за III гр. и лифты
A12: 7 | B12: Электромонтёр по обслуживанию электроустановок (IV гр.) | C12: 1/3 сутки | D12: 75000 | E12: 4 | F12: 4 | G12: 4 | H12: =D12*F12*$C$3 -> 450000 | I12: =D12*E12*$C$3*$F$3 -> 6300000 | J12: =D12*F12*$C$3*$F$3 -> 6300000 | K12: =D12*G12*$C$3*$F$3 -> 6300000 | L12: рынок 45–98 тыс. (СПбГУ 45 до налогов, ПЛК 59, Алмаз от 65, ГОИ от 98) → 75
A13: 8 | B13: Слесарь-сантехник (аттест. ремонтный персонал ТЭУ) | C13: 1/3 сутки | D13: 70000 | E13: 4 | F13: 4 | G13: 4 | H13: =D13*F13*$C$3 -> 420000 | I13: =D13*E13*$C$3*$F$3 -> 5880000 | J13: =D13*F13*$C$3*$F$3 -> 5880000 | K13: =D13*G13*$C$3*$F$3 -> 5880000 | L13: рынок 55–110 тыс. (НЕОСТРОЙ ТРК Лето от 55, Содружество 68, ЛСР от 70)
A14: 9 | B14: Координатор / руководитель проекта (доля ставки) | C14: 5/2 | D14: 150000 | E14: 0.5 | F14: 0.5 | G14: 1 | H14: =D14*F14*$C$3 -> 112500 | I14: =D14*E14*$C$3*$F$3 -> 1575000 | J14: =D14*F14*$C$3*$F$3 -> 1575000 | K14: =D14*G14*$C$3*$F$3 -> 3150000 | L14: штатный руководитель проектов НЕОСТРОЙ, оценка
A15: 10 | B15: Доплаты ответственным: ОПО (А.1/Б.8.2, замы), ОТ, работы на высоте, сварка, электрохозяйство | C15: — | D15: 10000 | E15: 4 | F15: 6 | G15: 6 | H15: =D15*F15*$C$3 -> 90000 | I15: =D15*E15*$C$3*$F$3 -> 840000 | J15: =D15*F15*$C$3*$F$3 -> 1260000 | K15: =D15*G15*$C$3*$F$3 -> 1260000 | L15: оценка: 10 тыс./мес за функцию
A16: 11 | B16: Доплата за совмещение: электромонтёр = оператор-диспетчер (сц. А) | C16: — | D16: 10000 | E16: 4 | F16: 0 | G16: 0 | H16: =D16*F16*$C$3 -> 0 | I16: =D16*E16*$C$3*$F$3 -> 840000 | J16: =D16*F16*$C$3*$F$3 -> 0 | K16: =D16*G16*$C$3*$F$3 -> 0 | L16: оценка
B17: Итого | H17: =SUM(H6:H16) -> 2077500 | I17: =SUM(I6:I16) -> 20265000 | J17: =SUM(J6:J16) -> 29085000 | K17: =SUM(K6:K16) -> 35280000
B18: Численность физлиц (без доплат), чел. | E18: =SUM(E6:E14) -> 10.5 | F18: =SUM(F6:F14) -> 16.5 | G18: =SUM(G6:G14) -> 21
B20: Круглосуточный пост: 8 760 ч/год ÷ 4 чел. = 2 190 ч/чел. (сутки через трое) при норме ~1 970 ч → переработка оплачивается в ставке; отпуска закрыты коэффициентом 14/12. Ставки целые.

Sheet Работы
A1: РЕГЛАМЕНТНЫЕ РАБОТЫ ПО ТЗ (год) — цены и нормы из тарификатора v2 (СПб, без НДС)
A2: Исполнитель «штат» — работа выполняется персоналом из листа «Персонал» (в с/с не добавляется, чел.-ч — для проверки загрузки). «Субподряд» — оплата бригаде/лаборатории (колонка L тарификатора) в с/с. Оранжевые — объём оценочный (в ТЗ не дан).
A4: № | B4: Позиция ТЗ / система | C4: Работа | D4: Артикул | E4: Метка | F4: Ед. | G4: Кол-во/год | H4: Цена тариф. H, руб/ед | I4: Бригада L, руб/ед | J4: Норма, ч/ед | K4: Чел.-ч | L4: Исполнитель | M4: Рыночная стоимость (H×кол.) | N4: С/с (субподряд L×кол.) | O4: Маржа строки, руб | P4: Основание объёма
A5: 1 | B5: 5, 17, 24, 28 | C5: Электроизмерения и техотчёт ЭТЛ — ФОК Бабушкина 30 (3 условных блока по 2–3 тыс. м²) | D5: 10.6.6 | E5: аналог | F5: шт | G5: 3 | H5: 59734 | I5: 25000 | J5: 32 | K5: =G5*J5 -> 96 | L5: субподряд | M5: =G5*H5 -> 179202 | N5: =IF(L5="субподряд",G5*I5,0) -> 75000 | O5: =M5-N5 -> 104202 | P5: ТЗ: электроизмерения аккредитованной ЭТЛ 1 раз в год; площади не даны
A6: 2 | B6: 17 | C6: Электроизмерения и техотчёт ЭТЛ — ФОК Железнодорожный 32 (2 блока) | D6: 10.6.6 | E6: аналог | F6: шт | G6: 2 | H6: 59734 | I6: 25000 | J6: 32 | K6: =G6*J6 -> 64 | L6: субподряд | M6: =G6*H6 -> 119468 | N6: =IF(L6="субподряд",G6*I6,0) -> 50000 | O6: =M6-N6 -> 69468 | P6: то же; площадь не дана
A7: 3 | B7: 24, 28, 20 | C7: Электроизмерения ЭТЛ — гараж, модульное здание, ИТП Седова | D7: 10.6.5 | E7: точно | F7: усл | G7: 3 | H7: 44800 | I7: 18000 | J7: 24 | K7: =G7*J7 -> 72 | L7: субподряд | M7: =G7*H7 -> 134400 | N7: =IF(L7="субподряд",G7*I7,0) -> 54000 | O7: =M7-N7 -> 80400 | P7: ТЗ 1 раз/год
A8: 4 | B8: 6, 7, 18, 19, 29 | C8: Протоколы испытаний наружных КЛ и сетей освещения | D8: 10.6.11 | E8: аналог | F8: шт | G8: 6 | H8: 11200 | I8: 4800 | J8: 6 | K8: =G8*J8 -> 36 | L8: субподряд | M8: =G8*H8 -> 67200 | N8: =IF(L8="субподряд",G8*I8,0) -> 28800 | O8: =M8-N8 -> 38400 | P8: 3 наружные КЛ + 3 сети освещения
A9: 5 | B9: 5, 17 | C9: Организация испытаний диэлектрических СИЗ (2 раза в год) | D9: 10.5.N1 | E9: точно | F9: компл | G9: 8 | H9: 1500 | I9: 900 | J9: 1 | K9: =G9*J9 -> 8 | L9: субподряд | M9: =G9*H9 -> 12000 | N9: =IF(L9="субподряд",G9*I9,0) -> 7200 | O9: =M9-N9 -> 4800 | P9: 4 комплекта × 2
A10: 6 | B10: 2, 3, 8, 14, 20 | C10: Поверка/замена манометров | D10: 9.2.96 | E10: точно | F10: шт | G10: 80 | H10: 800 | I10: 496 | J10: 0.5 | K10: =G10*J10 -> 40 | L10: субподряд | M10: =G10*H10 -> 64000 | N10: =IF(L10="субподряд",G10*I10,0) -> 39680 | O10: =M10-N10 -> 24320 | P10: по перечню оборудования 71 шт. + ИТП ~10 (оценка)
A11: 7 | B11: 2, 14, 20 | C11: Подготовка ИТП к отопительному сезону (ревизия, промывка, опрессовка, акт) | D11: 9.2.N6 | E11: точно | F11: усл | G11: 3 | H11: 45000 | I11: 27900 | J11: 32 | K11: =G11*J11 -> 96 | L11: штат | M11: =G11*H11 -> 135000 | N11: =IF(L11="субподряд",G11*I11,0) -> 0 | O11: =M11-N11 -> 135000 | P11: 3 ИТП (Бабушкина, ЖД32, Седова) × 1/год
A12: 8 | B12: 21 | C12: Гидроиспытание и промывка УУТЭ | D12: 9.2.7 | E12: точно | F12: шт | G12: 3 | H12: 12000 | I12: 7440 | J12: 8 | K12: =G12*J12 -> 24 | L12: штат | M12: =G12*H12 -> 36000 | N12: =IF(L12="субподряд",G12*I12,0) -> 0 | O12: =M12-N12 -> 36000 | P12: 3 узла учёта × 1/год
A13: 9 | B13: 22, 2 | C13: Опрессовка участков тепловой сети с актом | D13: 11.4.N3 | E13: точно | F13: усл | G13: 2 | H13: 9000 | I13: 5500 | J13: 6 | K13: =G13*J13 -> 12 | L13: штат | M13: =G13*H13 -> 18000 | N13: =IF(L13="субподряд",G13*I13,0) -> 0 | O13: =M13-N13 -> 18000 | P13: Седова–ЖД32 и Бабушкина
A14: 10 | B14: 22, 2 | C14: Гидропневмопромывка тепловых сетей | D14: 9.2.8 | E14: аналог | F14: мп | G14: 600 | H14: 45 | I14: 28 | J14: 0.03 | K14: =G14*J14 -> 18 | L14: субподряд | M14: =G14*H14 -> 27000 | N14: =IF(L14="субподряд",G14*I14,0) -> 16800 | O14: =M14-N14 -> 10200 | P14: ТЗ: прочистка теплосетей ≥1/год; протяжённость не дана — оценка 600 м
A15: 11 | B15: 4, 16, 23 | C15: Гидродинамическая промывка наружной канализации до 250 мм | D15: 11.2.11 | E15: точно | F15: мп | G15: 650 | H15: 260 | I15: 170 | J15: 0.07 | K15: =G15*J15 -> 45.5 | L15: субподряд | M15: =G15*H15 -> 169000 | N15: =IF(L15="субподряд",G15*I15,0) -> 110500 | O15: =M15-N15 -> 58500 | P15: ТЗ ≥1/год; протяжённость не дана — оценка 650 м
A16: 12 | B16: 4, 16, 27 | C16: Гидродинамическая промывка ливнёвки и дренажа стадионов до 150 мм | D16: 11.2.10 | E16: точно | F16: мп | G16: 400 | H16: 200 | I16: 130 | J16: 0.05 | K16: =G16*J16 -> 20 | L16: субподряд | M16: =G16*H16 -> 80000 | N16: =IF(L16="субподряд",G16*I16,0) -> 52000 | O16: =M16-N16 -> 28000 | P16: оценка 400 м
... A32: 28 | B32: 9 | C32: ТО осушителей воздуха RL-71R (ежеквартально) | D32: 9.3.N15 | E32: аналог | F32: шт | G32: 16 | H32: 8000 | I32: 4800 | J32: 3.5 | K32: =G32*J32 -> 56 | L32: штат | M32: =G32*H32 -> 128000 | N32: =IF(L32="субподряд",G32*I32,0) -> 0 | O32: =M32-N32 -> 128000 | P32: 4 осушителя × 4
C33: Итого | K33: =SUM(K5:K32) -> 1750.5 | M33: =SUM(M5:M32) -> 3184270 | N33: =SUM(N5:N32) -> 1043980 | O33: =SUM(O5:O32) -> 2140290
C34: в т.ч. чел.-ч штата (проверка загрузки) | K34: =SUMIF(L5:L32,"штат",K5:K32) -> 738
C35: Фонд времени 4 инженеров 5/2, ч/год (1 970 × 4); загрузка регламентом, % | K35: 7880 | M35: =K34/K35 -> 0.093654822

Sheet Материалы
A1: МАТЕРИАЛЫ И ЗИП
A2: Параметры: доставка СПб | D2: 0.03 | E2: стоимость денег, %/мес | G2: 0.02 | H2: резерв роста, %/мес сверх 2 мес | J2: 0.0125
A4: № | B4: Позиция | C4: Ед. | D4: Кол-во | E4: Цена с НДС (медиана) | F4: Закупка б/НДС | G4: Мес. до закупки | H4: Коэф. роста+деньги | I4: С/с ед. | J4: С/с итого | K4: Цена КП итого б/НДС | L4: В счёт лимита ЗИП? | M4: Источник / примечание
A5: 1 | B5: Лимит запчастей и материалов для планового и аварийного ремонта (п. 4.5 ТЗ) — 2 500 000 с НДС | C5: усл | D5: 1 | E5: 2500000 | F5: =E5/1.22 -> 2049180.3 | G5: — | H5: 1 | I5: =F5 -> 2049180.3 | J5: =D5*I5 -> 2049180.3 | K5: =D5*F5 -> 2049180.3 | L5: — | M5: Состав по факту, по рыночным ценам СПб с ежемесячной справкой. В КП без наценки (цена = с/с)
A6: 2 | B6: в т.ч. масло Bitzer BSE170 10 л для замены масла 6 компрессоров (~20 л на компрессор — уточнить по паспорту HSK 85) | C6: кан. | D6: 12 | E6: 45885.47 | F6: =E6/1.22 -> 37611.041 | G6: 8 | H6: =1+MAX(0,G6-2)*$J$2+$G$2 -> 1.095 | I6: =F6*(1+$D$2)*H6 -> 42419.613 | J6: =D6*I6 -> 509035.35 | K6: =0 -> 0 | L6: да (справочно) | M6: Цены (источники) №1–3; запросить КП дилера Bitzer
A7: 3 | B7: в т.ч. фильтры приточных установок (10 ПУ × 4 замены) | C7: компл | D7: 40 | E7: 6000 | F7: =E7/1.22 -> 4918.0328 | G7: 8 | H7: =1+MAX(0,G7-2)*$J$2+$G$2 -> 1.095 | I7: =F7*(1+$D$2)*H7 -> 5546.8033 | J7: =D7*I7 -> 221872.13 | K7: =0 -> 0 | L7: да (справочно) | M7: НЕТ ЦЕНЫ: типоразмеры фильтров в ТЗ не даны — запросить КП; оценка 6 000/компл. с НДС
A8: 4 | B8: Гигрометр психрометрический ВИТ-1 с поверкой (2 арены + 2 резерв) | C8: шт | D8: 4 | E8: 1803 | F8: =E8/1.22 -> 1477.8689 | G8: 1 | H8: =1+MAX(0,G8-2)*$J$2+$G$2 -> 1.02 | I8: =F8*(1+$D$2)*H8 -> 1552.649 | J8: =D8*I8 -> 6210.5961 | K8: =0 -> 0 | L8: нет | M8: Цены (источники) №4–6; требование ТЗ — приборы Исполнителя
A9: 5 | B9: Термометр-щуп/ИК testo 104-IR для замеров льда (по 1 на арену) | C9: шт | D9: 2 | E9: 17490 | F9: =E9/1.22 -> 14336.066 | G9: 1 | H9: =1+MAX(0,G9-2)*$J$2+$G$2 -> 1.02 | I9: =F9*(1+$D$2)*H9 -> 15061.47 | J9: =D9*I9 -> 30122.941 | K9: =0 -> 0 | L9: нет | M9: Цены (источники) №7–9
B10: Итого в с/с (лимит ЗИП + приборы Исполнителя; справочные строки «в т.ч.» не суммируются) | J10: =J5+J8+J9 -> 2085513.9 | K10: =K5 -> 2049180.3
B11: Проверка лимита: масло + фильтры (с/с) от лимита б/НДС, % | J11: =(J6+J7)/J5 -> 0.35668285
B12: Остаток лимита на ремонты/ЗИП, руб б/НДС | J12: =J5-J6-J7 -> 1318272.8
B14: Приборы (гигрометры, термометры) отнесены в с/с полностью (закупка до старта); в цену заказчика отдельной строкой не выходят — распределены в помесячную цену.

Sheet Цены (источники)
A1: ИСТОЧНИКИ ЦЕН (дата обращения 28.10.2026)
A3: № | B3: Позиция | C3: Источник / магазин | D3: URL | E3: Цена, руб | F3: С НДС / без | G3: Примечание
A4: 1 | B4: Масло Bitzer BSE170, 10 л | C4: Геофрост (прайс 26.09.2026) | D4: https://geofrost.ru/prices/sections/oilbitzer.pdf | E4: 45885.47 | F4: с НДС | G4: медиана → в расчёт
A5: 2 | B5: Масло Bitzer BSE170, 10 л | C5: Холод СПб | D5: https://holod-spb.ru/product/kompressornoe-maslo-dlya-vintovyh-kompressorov-bitzer-bse170-915115-05-10-l/ | E5: 37700 | F5: с НДС
A6: 3 | B6: Масло Bitzer BSE170, 10 л | C6: ХолодПС | D6: https://holodps.ru/catalog/refrigeration-oils/bitzer/bse-170-10.html | E6: 62900 | F6: с НДС | G6: запросить КП у дилера Bitzer
A7: 4 | B7: Гигрометр психрометрический ВИТ-1 (0…+25 °С) с поверкой | C7: СОЮЗ-ПРИБОР | D7: https://www.souz-pribor.ru/product/vit-2/ | E7: 1730 | F7: с НДС | G7: ВИТ-1 — для ледовых арен
A8: 5 | B8: Гигрометр психрометрический ВИТ-2 с поверкой (аналог) | C8: МЕРАТЭК СПб | D8: https://spb.mera-tek.ru/catalog/termometry/vit-2-15-40-s-gigrometr/ | E8: 1803 | F8: с НДС | G8: медиана → в расчёт
A9: 6 | B9: Гигрометр психрометрический ВИТ-2 с поверкой (аналог) | C9: МАКСПРОФИТ СПб | D9: https://spb.mprofit.ru/catalog/gigrometr-psikhrometricheskiy-vit-2-s-poverkoy/ | E9: 2408 | F9: с НДС
A10: 7 | B10: Термометр-щуп + ИК testo 104-IR | C10: testo-rus | D10: https://kzn.testo-rus.ru/cat/termometry-kontaktnye-testo/ | E10: 17490 | F10: с НДС | G10: медиана → в расчёт
A11: 8 | B11: Термометр-щуп + ИК testo 104-IR | C11: ПРИБОР-24 | D11: https://pribori24.ru/prod/infrakrasnyj-termometr-testo-104-ir/ | E11: 17420 | F11: с НДС
A12: 9 | B12: Термометр-щуп + ИК testo 104-IR | C12: СОЮЗ-ПРИБОР | D12: https://www.souz-pribor.ru/catalog/energy_laboratory/pirometry-infrakrasnye-termometry/filter/brand_testo/ | E12: 19253 | F12: с НДС
A13: 10 | B13: БГ на исполнение 44-ФЗ, % годовых | C13: trillioncredit.ru / vitte.app / 1000bankov.ru | D13: ВТБ от 1,85 %, Сбер от 1,99 %, средн. 2,8–3,2 % | E13: 0.035 | F13: — | G13: в расчёт 3,5 % (консервативно)
A14: 11 | B14: Зарплата: дежурный электромонтёр 1/3 | C14: СПбГУ / ПЛК / Алмаз / ГОИ | D14: hr.spbu.ru/vacansii/37262; dreamjob.ru/employers/391947/vakansii/133311030; spb.hh.ru/vacancy/136581090; dreamjob.ru/employers/195386/vakansii/136592632 | E14: 75000 | F14: на руки | G14: 45–98 тыс.
A15: 12 | B15: Зарплата: диспетчер 1/3 | C15: Fort Group / ТСБ / Vertical Hotels | D15: dreamjob.ru/employers/53998/vakansii/134804781; dreamjob.ru/employers/323252/vakansii/136230142; dreamjob.ru/employers/518065/vakansii/135423459 | E15: 55000 | F15: на руки | G15: 35–52 тыс.
A16: 13 | B16: Зарплата: слесарь-сантехник 1/3 | C16: Содружество Столиц / ЛСР / Атлантик Сити | D16: dreamjob.ru/employers/5976513/vakansii/135489062; dreamjob.ru/employers/109771/vakansii/135310231 | E16: 70000 | F16: на руки | G16: 55–110 тыс.
A17: 14 | B17: Зарплата: инженер-холодильщик | C17: Звёздный лёд / Динамо / EhS / Зенит-Арена | D17: spb.careerist.ru/vakansii/inzhener-kholodilnogo-oborudovaniya-zenit-arena-88279982.html; dreamjob.ru/employers/1000537/vakansii/134162627; spb.hh.ru/vacancy/136501745 | E17: 120000 | F17: на руки | G17: 75–130 тыс.
A18: 15 | B18: Зарплата: инженер КИПиА | C18: СПб ГБУ ДУОАН / Кип-Хауз | D18: spb.hh.ru/vacancy/136339294; dreamjob.ru/employers/6225392/vakansii/136562402 | E18: 105000 | F18: на руки | G18: 96–106 тыс.
A19: 16 | B19: Зарплата: теплотехник / отв. за ТЭУ | C19: Миракс / Газпром переработка / Дивайс | D19: nesiditsa.ru/vacancy/137236867; spb.hh.ru/vacancy/136483066; spb.hh.ru/vacancy/135604111 | E19: 110000 | F19: на руки | G19: 100–140 тыс.
A20: 17 | B20: Зарплата: прочие сверки | C20: hh.ru | D20: spb.hh.ru/vacancy/136555184; spb.hh.ru/vacancy/137141601 | F20: —

Sheet Косвенные
A1: КОСВЕННЫЕ ЗАТРАТЫ ПРОЕКТА (год, руб. без НДС)
A3: № | B3: Статья | C3: Кол-во | D3: Ед. | E3: Ставка, руб | F3: Сумма, руб | G3: Основание / расчёт
A4: 1 | B4: Спецодежда и СИЗ персонала | C4: =Персонал!F18 -> 16.5 | D4: чел | E4: 15000 | F4: =C4*E4 -> 247500 | G4: оценка: комплект летн./зимн. + обувь + СИЗ
A5: 2 | B5: Приборы и инструмент (мегаомметр, клещи, тепловизор, течеискатель, набор слесаря) | C5: 1 | D5: компл | E5: 300000 | F5: =C5*E5 -> 300000 | G5: оценка; часть — в наличии у НЕОСТРОЙ
A6: 3 | B6: ПО и модем для ежедневного снятия показаний УУТЭ Седова | C6: 1 | D6: усл | E6: 30000 | F6: =C6*E6 -> 30000 | G6: оценка; требование ТЗ
A7: 4 | B7: Мобильная связь дежурных постов | C7: 48 | D7: мес·пост | E7: 500 | F7: =C7*E7 -> 24000 | G7: 4 номера × 12 мес
A8: 5 | B8: Аттестация РТН А.1 / Б.8.2 (руководитель, отв. и замы ОПО) | C8: 4 | D8: чел | E8: 15000 | F8: =C8*E8 -> 60000 | G8: оценка; ТЗ — без совмещения, сроки — 3 дня после заключения
A9: 6 | B9: Проверка знаний ЭБ (II–IV гр.) | C9: 12 | D9: чел | E9: 6000 | F9: =C9*E9 -> 72000 | G9: оценка
A10: 7 | B10: Обучение ОТ (все), работы на высоте | C10: =Персонал!F18 -> 16.5 | D10: чел | E10: 4000 | F10: =C10*E10 -> 66000 | G10: оценка
A11: 8 | B11: Удостоверения: оператор диспетчерской лифтов, оператор подъёмных платформ (НОК) | C11: 6 | D11: чел | E11: 12000 | F11: =C11*E11 -> 72000 | G11: оценка
A12: 9 | B12: Аттестация технологии сварки (НАКС) / специалист сварочного производства | C12: 1 | D12: усл | E12: 150000 | F12: =C12*E12 -> 150000 | G12: оценка; требование ТЗ — запросить КП аттестационного центра
A13: 10 | B13: Медосмотры | C13: =Персонал!F18 -> 16.5 | D13: чел | E13: 3000 | F13: =C13*E13 -> 49500 | G13: оценка
A14: 11 | B14: Разъездной автомобиль (аренда + ГСМ) между 4 площадками | C14: 12 | D14: мес | E14: 40000 | F14: =C14*E14 -> 480000 | G14: оценка
A15: 12 | B15: Вывоз и утилизация отходов (лампы, аккумуляторы, масла) | C15: 12 | D15: мес | E15: 15000 | F15: =C15*E15 -> 180000 | G15: оценка; проверяемая услуга — запросить КП лицензиата
A16: 13 | B16: Регламенты, инструкции, актуализация схем, ПТО-документация | C16: 1 | D16: усл | E16: 150000 | F16: =C16*E16 -> 150000 | G16: оценка: ТЗ — регламенты 30 дн., инструкции 15 дн., схемы 30 дн. после ПТО
A17: 14 | B17: Высотные работы: 2 монтажника по необходимости (10 смен × 2 чел × 8 ч × 850) | C17: 160 | D17: чел.-ч | E17: 850 | F17: =C17*E17 -> 136000 | G17: ставка ELM/NAR тарификатора 850 руб/ч; кол-во смен — оценка
A18: 15 | B18: Аренда вышки/автовышки | C18: 10 | D18: сут | E18: 12000 | F18: =C18*E18 -> 120000 | G18: оценка
A19: 16 | B19: Испытания СИЗ в ЭТЛ (стоимость испытаний) | C19: 8 | D19: компл | E19: 3000 | F19: =C19*E19 -> 24000 | G19: оценка
B20: Итого прямые косвенные | F20: =SUM(F4:F19) -> 2161000
A21: 17 | B21: Банковская гарантия исполнения 10 % НМЦК, 13 мес | C21: ='Паспорт тендера'!B8*0.1 -> 2443676.7 | D21: руб | E21: ='Цены (источники)'!E13 -> 0.035 | F21: =C21*E21*13/12 -> 92656.075 | G21: ставка 3,5 % годовых (рынок 1,85–5 %), срок контракта + 1 мес
A22: 18 | B22: Финансирование кассового разрыва (без аванса, оплата ~1,5–2 мес после месяца) | C22: 1.75 | D22: мес оборота | E22: 0.02 | F22: =Свод!C12/12*C22*E22*12 -> 1203873.1 | G22: средний остаток долга = 1,75 мес. затрат × 2 %/мес × 12 мес (затраты без финансирования и резервов)
A23: 19 | B23: Резерв на гарантийные обязательства (гарантия 3 мес) | C23: =Свод!C12 -> 34396373 | D23: руб | E23: 0.01 | F23: =C23*E23 -> 343963.73 | G23: 1 % — нижняя граница: гарантия на услуги короткая
A24: 20 | B24: Резерв на риски (штрафы 5 %, аварии сверх лимита, неизвестные моточасы) | C24: =Свод!C12 -> 34396373 | D24: руб | E24: 0.03 | F24: =C24*E24 -> 1031891.2 | G24: 3 % — минимум диапазона 3–5 %, т.к. лимит ЗИП ограничен договором
B25: ИТОГО косвенные | F25: =F20+SUM(F21:F24) -> 4833384.1

Sheet Риски и вопросы
A1: РИСКИ И ВОПРОСЫ
A3: № | B3: Описание | C3: Влияние на цену, руб/год | D3: Что спросить у заказчика | E3: Допущение в расчёте
A4: 1 | B4: ДОПУСК: ПП 2571 поз. 14 — нужен исполненный договор ТО зданий ≥ 20 % НМЦК (~4,89 млн), заключённый по 44-ФЗ или 223-ФЗ. Все договоры КТО НЕОСТРОЙ (Тандер, Агроторг, Дикси, СПБ-ЛЕТО) — коммерческие; 223-ФЗ договоры (Ленэнерго, Тепловые сети Гатчина) — ремонт, не ТО. Риск отклонения заявки | C4: заявка отклоняется | D4: — | E4: Проверить, есть ли у Тандер/Агроторг/ЛЕТО закупка по 223-ФЗ (АО «Тандер» и ООО «Агроторг» закупают по 223-ФЗ только в отдельных случаях) — если нет, участие невозможно
A5: 2 | B5: Трактовка круглосуточных постов: 4 должности (диспетчер, техник-оператор, электромонтёр, сантехник) могут читаться как 4 отдельных поста по 4 чел. | C5: =Свод!E38-Свод!E37 -> 6442800 | D5: Допускается ли совмещение оператора-диспетчера и техника-оператора автоматики (и электромонтёра) одним лицом на смене? | E5: Сценарий Б — 3 поста (диспетчер = техник-оператор)
A6: 3 | B6: Лимит ЗИП 2,5 млн с НДС: аварийные ремонты «входят в цену». Если аварийная замена (компрессор, насос, ПТО) превысит лимит — за счёт Исполнителя? | C6: =Материалы!J5*0.3 -> 614754.1 | D6: Подтвердить, что сверх лимита 2,5 млн запчасти оплачиваются отдельно (доп. соглашение / капремонт) | E6: Лимит расходуется полностью, сверх — не несём (резерв на риски 3 %)
A7: 4 | B7: Капитальный ремонт винтовых компрессоров по регламенту 30 000 ч (разборка) — моточасы машин неизвестны | C7: =6*600000/1.22 -> 2950819.7 | D7: Текущие моточасы компрессоров HSK 85, дата последнего ТО/замены масла, есть ли сервисный договор с Эйркул | E7: Капремонт компрессоров в 2027 не наступает
A8: 5 | B8: Объёмы регламента не даны: площади для ЭТЛ, протяжённость сетей для промывки, кол-во колодцев К-2, СИ для поверки | C8: =Работы!N33*0.3 -> 313194 | D8: Площади зданий, протяжённость наружных сетей канализации/теплосетей, кол-во дождеприёмных колодцев и СИ | E8: Оценочные объёмы (оранжевые на листе «Работы»)
A9: 6 | B9: Обязательное привлечение СМП/СОНКО 30 % (если НЕОСТРОЙ не СМП) — штраф 5 % недопривлечения | C9: =Свод!C18*0.3*0.05 -> 300452.05 | D9: — | E9: НЕОСТРОЙ (ОГРН 2023) — вероятно СМП: проверить в Реестре МСП, тогда требование выполняется участием
A10: 7 | B10: Аттестации РТН (А.1, Б.8.2), НАКС, удостоверения лифтов/НОК — к началу оказания услуг (3 дня после заключения) | C10: =Косвенные!F8+Косвенные!F12 -> 210000 | D10: Достаточно ли действующих аттестаций на дату начала (01.01.2027)? | E10: Аттестации проводятся в декабре 2026 за счёт НЕОСТРОЙ
A11: 8 | B11: Штрафы 5 % цены за каждое нарушение, 5 000 за нестоимостные; уведомление об аварии 15 минут | C11: =Свод!C18*0.05 -> 1001506.8 | D11: — | E11: Покрывается резервом рисков 3 % частично
A12: 9 | B12: Запуск ледовых арен: замеры льда/влажности каждые 3 ч с 8 до 23 и 3 обхода в сутки — нагрузка на дежурную смену | C12: 0 | D12: Сезонность ледовых арен (месяцы работы льда) — можно ли сокращать замеры вне сезона? | E12: Выполняет дежурная смена без доп. штата
A13: 10 | B13: Требование 1 подписанта/координатора и 3 ИТР по ОТ — возможно, требуется больше ИТР, чем в сценарии Б | C13: =Персонал!D14*Персонал!C3*Персонал!F3*0.5 -> 1575000 | D13: Обязательно ли постоянное присутствие координатора на объекте? | E13: Координатор 0,5 ставки
A14: 11 | B14: В форме позиция 12 — «секционные ворота», в перечне оборудования — 4 роллетных ворот Alutech | C14: 0 | D14: Уточнить тип и количество ворот на Бабушкина 30 | E14: По перечню — 4 роллетных
A15: 12 | B15: Дата регистрации НЕОСТРОЙ — 2023 (ОГРН 1237800040939): договоры 2020–2022 в файле опыта, вероятно, исполнены другим юрлицом | C15: 0 | D15: — | E15: В форму опыта включены договоры 2023–2025

Sheet Добавить в тарификатор
A1: ДОБАВИТЬ В ТАРИФИКАТОР
A3: № | B3: Работа | C3: Ед. | D3: Спец. | E3: Рынок СПб (оценка), руб | F3: Бригада = норма × ставка | G3: Норма, ч | H3: Ставка, руб/ч | I3: Примечание
A4: 1 | B4: ТО настенной сплит-системы (внутр. блок: чистка фильтров, теплообменника, дренажа, проверка давления) | C4: шт | D4: HOL | E4: 3000 | F4: =G4*H4 -> 1800 | G4: 1.5 | H4: 1200 | I4: рынок 2 500–4 000 (сервисы кондиционеров СПб) — найти 2–3 прайса
A5: 2 | B5: Промывка разборного пластинчатого теплообменника (разборка, химическая/механическая очистка пластин, сборка, опрессовка) | C5: шт | D5: SAN | E5: 15000 | F5: =G5*H5 -> 5100 | G5: 6 | H5: 850 | I5: рынок 10 000–30 000 в зависимости от кол-ва пластин; химия отдельно
A6: 3 | B6: Лабораторный анализ холодильного масла (проба, отправка, заключение) | C6: проба | D6: HOL | E6: 6000 | F6: — | G6: 0 | H6: 0 | I6: лабораторная услуга — запросить прайс лабораторий
A7: 4 | B7: Замена масла и фильтров винтового компрессора Bitzer HSK (без масла) | C7: компр. | D7: HOL | E7: 25000 | F7: =G7*H7 -> 9600 | G7: 8 | H7: 1200 | I7: оценка; сверить с прайсом сервисных центров Bitzer
A8: 5 | B8: Ежемесячное ТО холодильной машины 500+ кВт (винтовые компрессоры, конденсатор, НТМ) | C8: маш./мес | D8: HOL | E8: нет данных | F8: =G8*H8 -> 19200 | G8: 16 | H8: 1200 | I8: в лоте — штатный инженер; для коммерческих лотов нужна расценка
A9: 6 | B9: Круглосуточный дежурный пост (1 чел. на смене), месяц | C9: пост/мес | D9: SAN/ELM | E9: нет данных | F9: — | G9: 730 | I9: ставка поста = 4 чел. 1/3 × на руки × 1,5 × 14/12; добавить блок «Эксплуатация» в тарификатор
A10: 7 | B10: Обход ледовой арены с замером температуры льда и влажности (каждые 3 ч) | C10: сутки | D10: HOL | E10: нет данных | F10: =G10*H10 -> 1800 | G10: 1.5 | H10: 1200 | I10: обычно в составе дежурства

Sheet Карта реализации
A1: КАРТА РЕАЛИЗАЦИИ: контрольные точки и кэш-план (руб. без НДС)
A3: Срок | B3: Контрольная точка / действие | C3: Ответственный
A4: до подачи заявки | B4: Решение ГД об участии; проверка допуска (договор ТО по 44/223-ФЗ ≥ 4,89 млн) | C4: ГД, тендерный отдел
A5: до подачи заявки | B5: Запрос КП: ЭТЛ, гидропромывка, ворота, сервис Bitzer/анализ масла, вывоз отходов, БГ | C5: Снабжение
A6: подписание + 3 дня | B6: Приказы об ответственных (ОПО, ТЭУ, электрохозяйство, ОТ), аттестации РТН, НАКС | C6: Координатор
A7: декабрь 2026 | B7: Найм: 4 инженера + 12 чел. дежурных смен (сц. Б), медосмотры, обучение, спецодежда | C7: HR, координатор
A8: до 31.12.2026 | B8: Получение БГ 10 % НМЦК, закупка приборов (гигрометры, термометры), ПО УУТЭ | C8: Финансы, снабжение
A9: январь 2027 | B9: Приём объектов, ПТО (первичное техническое освидетельствование), диспетчерская на Бабушкина 30 | C9: Инженеры
A10: до 30 дней | B10: Регламенты, актуализация схем; инструкции — 15 дней | C10: Инженеры, ПТО
A11: ежемесячно | B11: Фотоотчёт, справка по ЗИП, документ о приёмке до 3 р.д. | C11: Координатор
A12: по графику | B12: Ворота и сплиты 2 раза/год; ЭТЛ, аэродинамика, промывки, очистка воздуховодов 1 раз/год; подготовка ИТП — июнь–август | C12: Инженеры, субподряд
A15: Кэш-план
A16: Статья | B16: дек.26 | C16: янв.27 | D16: фев.27 | E16: мар.27 | F16: апр.27 | G16: май.27 | H16: июн.27 | I16: июл.27 | J16: авг.27 | K16: сен.27 | L16: окт.27 | M16: ноя.27 | N16: дек.27 | O16: янв.28
A17: Поступления (акт месяца m → оплата m+2; декабрь 2027 — в декабре) | B17: 0 | C17: 0 | D17: 0 | E17: =Свод!$C$18/12 -> 1669178.1 | F17: =Свод!$C$18/12 -> 1669178.1 | G17: =Свод!$C$18/12 -> 1669178.1 | H17: =Свод!$C$18/12 -> 1669178.1 | I17: =Свод!$C$18/12 -> 1669178.1 | J17: =Свод!$C$18/12 -> 1669178.1 | K17: =Свод!$C$18/12 -> 1669178.1 | L17: =Свод!$C$18/12 -> 1669178.1 | M17: =Свод!$C$18/12 -> 1669178.1 | N17: =Свод!$C$18/12*2 -> 3338356.2 | O17: =Свод!$C$18/12 -> 1669178.1
A18: Расходы (мобилизация в дек.26; затраты равномерно) | B18: =(Косвенные!F21+Материалы!J8+Материалы!J9+Косвенные!F4+Косвенные!F5+SUM(Косвенные!F8:F13)) -> 1145989.6 | C18: =(Свод!$C$14-(Косвенные!F21+Материалы!J8+Материалы!J9+Косвенные!F4+Косвенные!F5+SUM(Косвенные!F8:F13)))/12 -> 2993564 | D18: =(Свод!$C$14-(Косвенные!F21+Материалы!J8+Материалы!J9+Косвенные!F4+Косвенные!F5+SUM(Косвенные!F8:F13)))/12 -> 2993564 | E18: =(Свод!$C$14-(Косвенные!F21+Материалы!J8+Материалы!J9+Косвенные!F4+Косвенные!F5+SUM(Косвенные!F8:F13)))/12 -> 2993564 | F18: =(Свод!$C$14-(Косвенные!F21+Материалы!J8+Материалы!J9+Косвенные!F4+Косвенные!F5+SUM(Косвенные!F8:F13)))/12 -> 2993564 | G18: =(Свод!$C$14-(Косвенные!F21+Материалы!J8+Материалы!J9+Косвенные!F4+Косвенные!F5+SUM(Косвенные!F8:F13)))/12 -> 2993564 | H18: =(Свод!$C$14-(Косвенные!F21+Материалы!J8+Материалы!J9+Косвенные!F4+Косвенные!F5+SUM(Косвенные!F8:F13)))/12 -> 2993564 | I18: =(Свод!$C$14-(Косвенные!F21+Материалы!J8+Материалы!J9+Косвенные!F4+Косвенные!F5+SUM(Косвенные!F8:F13)))/12 -> 2993564 | J18: =(Свод!$C$14-(Косвенные!F21+Материалы!J8+Материалы!J9+Косвенные!F4+Косвенные!F5+SUM(Косвенные!F8:F13)))/12 -> 2993564 | K18: =(Свод!$C$14-(Косвенные!F21+Материалы!J8+Материалы!J9+Косвенные!F4+Косвенные!F5+SUM(Косвенные!F8:F13)))/12 -> 2993564 | L18: =(Свод!$C$14-(Косвенные!F21+Материалы!J8+Материалы!J9+Косвенные!F4+Косвенные!F5+SUM(Косвенные!F8:F13)))/12 -> 2993564 | M18: =(Свод!$C$14-(Косвенные!F21+Материалы!J8+Материалы!J9+Косвенные!F4+Косвенные!F5+SUM(Косвенные!F8:F13)))/12 -> 2993564 | N18: =(Свод!$C$14-(Косвенные!F21+Материалы!J8+Материалы!J9+Косвенные!F4+Косвенные!F5+SUM(Косвенные!F8:F13)))/12 -> 2993564 | O18: 0
A19: Сальдо месяца | B19: =B17-B18 -> -1145989.6 | C19: =C17-C18 -> -2993564 | D19: =D17-D18 -> -2993564 | E19: =E17-E18 -> -1324385.9 | F19: =F17-F18 -> -1324385.9 | G19: =G17-G18 -> -1324385.9 | H19: =H17-H18 -> -1324385.9 | I19: =I17-I18 -> -1324385.9 | ... O19: =O17-O18 -> 1669178.1
A20: Накопленное сальдо | B20: =B19 -> -1145989.6 | C20: =B20+C19 -> -4139553.6 | D20: =C20+D19 -> -7133117.6 | E20: =D20+E19 -> -8457503.5 | F20: =E20+F19 -> -9781889.4 | G20: =F20+G19 -> -11106275 | H20: =G20+H19 -> -12430661 | I20: =H20+I19 -> -13755047 | J20: =I20+J19 -> -15079433 | ... O20: =N20+O19 -> -17038621
A22: Максимальный кассовый разрыв | B22: =-MIN(B20:O20) -> 19052591
A23: Поступление за месяц m — в месяце m+2 (документ 3 р.д. + приёмка до 20 р.д. + оплата 7 р.д.); за декабрь 2027 — до 25.12.2027, за ноябрь 2027 — в январе 2028.
